Not Found: /search/
Internal Server Error: /search_author/
Traceback (most recent call last):
  File "/home/kalinins/.virtualenvs/zapsum/lib/python3.4/site-packages/django/core/handlers/base.py", line 112, in get_response
    response = wrapped_callback(request, *callback_args, **callback_kwargs)
  File "/home/kalinins/.virtualenvs/zapsum/zapsum/app_zapsum/views.py", line 36, in search_author
    authors_list = UserProfile.objects.filter(nickname__iregex='^.+?'+author+'.+?$', is_active=1, is_superuser=0).values_list('user_ptr_id', 'nickname')
TypeError: Can't convert 'bytes' object to str implicitly
Internal Server Error: /search_author/
Traceback (most recent call last):
  File "/home/kalinins/.virtualenvs/zapsum/lib/python3.4/site-packages/django/core/handlers/base.py", line 112, in get_response
    response = wrapped_callback(request, *callback_args, **callback_kwargs)
  File "/home/kalinins/.virtualenvs/zapsum/zapsum/app_zapsum/views.py", line 36, in search_author
    authors_list = UserProfile.objects.filter(nickname__iregex='^.+?'+author+'.+?$', is_active=1, is_superuser=0).values_list('user_ptr_id', 'nickname')
TypeError: Can't convert 'bytes' object to str implicitly
Internal Server Error: /search_author/
Traceback (most recent call last):
  File "/home/kalinins/.virtualenvs/zapsum/lib/python3.4/site-packages/django/core/handlers/base.py", line 112, in get_response
    response = wrapped_callback(request, *callback_args, **callback_kwargs)
  File "/home/kalinins/.virtualenvs/zapsum/zapsum/app_zapsum/views.py", line 36, in search_author
    authors_list = UserProfile.objects.filter(nickname__iregex='^.+?'+author+'.+?$', is_active=1, is_superuser=0).values_list('user_ptr_id', 'nickname')
TypeError: Can't convert 'bytes' object to str implicitly
Internal Server Error: /search_author/
Traceback (most recent call last):
  File "/home/kalinins/.virtualenvs/zapsum/lib/python3.4/site-packages/django/core/handlers/base.py", line 112, in get_response
    response = wrapped_callback(request, *callback_args, **callback_kwargs)
  File "/home/kalinins/.virtualenvs/zapsum/zapsum/app_zapsum/views.py", line 36, in search_author
    authors_list = UserProfile.objects.filter(nickname__iregex='^.+?'+author+'.+?$', is_active=1, is_superuser=0).values_list('user_ptr_id', 'nickname')
TypeError: Can't convert 'bytes' object to str implicitly
Not Found: /profile/
Not Found: /favicon.ico
Internal Server Error: /profile/2/
Traceback (most recent call last):
  File "/home/kalinins/.virtualenvs/zapsum/lib/python3.4/site-packages/django/core/handlers/base.py", line 112, in get_response
    response = wrapped_callback(request, *callback_args, **callback_kwargs)
  File "/home/kalinins/.virtualenvs/zapsum/zapsum/app_zapsum/views.py", line 50, in profile
    obj_gender = Gender.get_entry(gender_id=obj_author.gender)
NameError: name 'Gender' is not defined
Internal Server Error: /profile/2/
Traceback (most recent call last):
  File "/home/kalinins/.virtualenvs/zapsum/lib/python3.4/site-packages/django/core/handlers/base.py", line 112, in get_response
    response = wrapped_callback(request, *callback_args, **callback_kwargs)
  File "/home/kalinins/.virtualenvs/zapsum/zapsum/app_zapsum/views.py", line 50, in profile
    obj_gender = Gender.get_entry(gender_id=obj_author.gender)
  File "/home/kalinins/.virtualenvs/zapsum/zapsum/app_accounts/models.py", line 19, in get_entry
    result = Gender.objects.get(id=gender_id)
  File "/home/kalinins/.virtualenvs/zapsum/lib/python3.4/site-packages/django/db/models/manager.py", line 151, in get
    return self.get_queryset().get(*args, **kwargs)
  File "/home/kalinins/.virtualenvs/zapsum/lib/python3.4/site-packages/django/db/models/query.py", line 301, in get
    clone = self.filter(*args, **kwargs)
  File "/home/kalinins/.virtualenvs/zapsum/lib/python3.4/site-packages/django/db/models/query.py", line 593, in filter
    return self._filter_or_exclude(False, *args, **kwargs)
  File "/home/kalinins/.virtualenvs/zapsum/lib/python3.4/site-packages/django/db/models/query.py", line 611, in _filter_or_exclude
    clone.query.add_q(Q(*args, **kwargs))
  File "/home/kalinins/.virtualenvs/zapsum/lib/python3.4/site-packages/django/db/models/sql/query.py", line 1204, in add_q
    clause = self._add_q(where_part, used_aliases)
  File "/home/kalinins/.virtualenvs/zapsum/lib/python3.4/site-packages/django/db/models/sql/query.py", line 1240, in _add_q
    current_negated=current_negated)
  File "/home/kalinins/.virtualenvs/zapsum/lib/python3.4/site-packages/django/db/models/sql/query.py", line 1131, in build_filter
    clause.add(constraint, AND)
  File "/home/kalinins/.virtualenvs/zapsum/lib/python3.4/site-packages/django/utils/tree.py", line 104, in add
    data = self._prepare_data(data)
  File "/home/kalinins/.virtualenvs/zapsum/lib/python3.4/site-packages/django/db/models/sql/where.py", line 79, in _prepare_data
    value = obj.prepare(lookup_type, value)
  File "/home/kalinins/.virtualenvs/zapsum/lib/python3.4/site-packages/django/db/models/sql/where.py", line 352, in prepare
    return self.field.get_prep_lookup(lookup_type, value)
  File "/home/kalinins/.virtualenvs/zapsum/lib/python3.4/site-packages/django/db/models/fields/__init__.py", line 369, in get_prep_lookup
    return self.get_prep_value(value)
  File "/home/kalinins/.virtualenvs/zapsum/lib/python3.4/site-packages/django/db/models/fields/__init__.py", line 613, in get_prep_value
    return int(value)
TypeError: int() argument must be a string or a number, not 'Gender'
Internal Server Error: /profile/2/
Traceback (most recent call last):
  File "/home/kalinins/.virtualenvs/zapsum/lib/python3.4/site-packages/django/core/handlers/base.py", line 112, in get_response
    response = wrapped_callback(request, *callback_args, **callback_kwargs)
  File "/home/kalinins/.virtualenvs/zapsum/zapsum/app_zapsum/views.py", line 50, in profile
    obj_gender = Gender.get_entry(gender_id=obj_author.gender)
  File "/home/kalinins/.virtualenvs/zapsum/zapsum/app_accounts/models.py", line 19, in get_entry
    result = Gender.objects.get(id=gender_id)
  File "/home/kalinins/.virtualenvs/zapsum/lib/python3.4/site-packages/django/db/models/manager.py", line 151, in get
    return self.get_queryset().get(*args, **kwargs)
  File "/home/kalinins/.virtualenvs/zapsum/lib/python3.4/site-packages/django/db/models/query.py", line 301, in get
    clone = self.filter(*args, **kwargs)
  File "/home/kalinins/.virtualenvs/zapsum/lib/python3.4/site-packages/django/db/models/query.py", line 593, in filter
    return self._filter_or_exclude(False, *args, **kwargs)
  File "/home/kalinins/.virtualenvs/zapsum/lib/python3.4/site-packages/django/db/models/query.py", line 611, in _filter_or_exclude
    clone.query.add_q(Q(*args, **kwargs))
  File "/home/kalinins/.virtualenvs/zapsum/lib/python3.4/site-packages/django/db/models/sql/query.py", line 1204, in add_q
    clause = self._add_q(where_part, used_aliases)
  File "/home/kalinins/.virtualenvs/zapsum/lib/python3.4/site-packages/django/db/models/sql/query.py", line 1240, in _add_q
    current_negated=current_negated)
  File "/home/kalinins/.virtualenvs/zapsum/lib/python3.4/site-packages/django/db/models/sql/query.py", line 1131, in build_filter
    clause.add(constraint, AND)
  File "/home/kalinins/.virtualenvs/zapsum/lib/python3.4/site-packages/django/utils/tree.py", line 104, in add
    data = self._prepare_data(data)
  File "/home/kalinins/.virtualenvs/zapsum/lib/python3.4/site-packages/django/db/models/sql/where.py", line 79, in _prepare_data
    value = obj.prepare(lookup_type, value)
  File "/home/kalinins/.virtualenvs/zapsum/lib/python3.4/site-packages/django/db/models/sql/where.py", line 352, in prepare
    return self.field.get_prep_lookup(lookup_type, value)
  File "/home/kalinins/.virtualenvs/zapsum/lib/python3.4/site-packages/django/db/models/fields/__init__.py", line 369, in get_prep_lookup
    return self.get_prep_value(value)
  File "/home/kalinins/.virtualenvs/zapsum/lib/python3.4/site-packages/django/db/models/fields/__init__.py", line 613, in get_prep_value
    return int(value)
TypeError: int() argument must be a string or a number, not 'Gender'
Internal Server Error: /profile/2/
Traceback (most recent call last):
  File "/home/kalinins/.virtualenvs/zapsum/lib/python3.4/site-packages/django/core/handlers/base.py", line 112, in get_response
    response = wrapped_callback(request, *callback_args, **callback_kwargs)
  File "/home/kalinins/.virtualenvs/zapsum/zapsum/app_zapsum/views.py", line 50, in profile
    obj_gender = Gender.get_entry(gender_id=obj_author.gender)
  File "/home/kalinins/.virtualenvs/zapsum/zapsum/app_accounts/models.py", line 19, in get_entry
    result = Gender.objects.get(id=gender_id)
  File "/home/kalinins/.virtualenvs/zapsum/lib/python3.4/site-packages/django/db/models/manager.py", line 151, in get
    return self.get_queryset().get(*args, **kwargs)
  File "/home/kalinins/.virtualenvs/zapsum/lib/python3.4/site-packages/django/db/models/query.py", line 301, in get
    clone = self.filter(*args, **kwargs)
  File "/home/kalinins/.virtualenvs/zapsum/lib/python3.4/site-packages/django/db/models/query.py", line 593, in filter
    return self._filter_or_exclude(False, *args, **kwargs)
  File "/home/kalinins/.virtualenvs/zapsum/lib/python3.4/site-packages/django/db/models/query.py", line 611, in _filter_or_exclude
    clone.query.add_q(Q(*args, **kwargs))
  File "/home/kalinins/.virtualenvs/zapsum/lib/python3.4/site-packages/django/db/models/sql/query.py", line 1204, in add_q
    clause = self._add_q(where_part, used_aliases)
  File "/home/kalinins/.virtualenvs/zapsum/lib/python3.4/site-packages/django/db/models/sql/query.py", line 1240, in _add_q
    current_negated=current_negated)
  File "/home/kalinins/.virtualenvs/zapsum/lib/python3.4/site-packages/django/db/models/sql/query.py", line 1131, in build_filter
    clause.add(constraint, AND)
  File "/home/kalinins/.virtualenvs/zapsum/lib/python3.4/site-packages/django/utils/tree.py", line 104, in add
    data = self._prepare_data(data)
  File "/home/kalinins/.virtualenvs/zapsum/lib/python3.4/site-packages/django/db/models/sql/where.py", line 79, in _prepare_data
    value = obj.prepare(lookup_type, value)
  File "/home/kalinins/.virtualenvs/zapsum/lib/python3.4/site-packages/django/db/models/sql/where.py", line 352, in prepare
    return self.field.get_prep_lookup(lookup_type, value)
  File "/home/kalinins/.virtualenvs/zapsum/lib/python3.4/site-packages/django/db/models/fields/__init__.py", line 369, in get_prep_lookup
    return self.get_prep_value(value)
  File "/home/kalinins/.virtualenvs/zapsum/lib/python3.4/site-packages/django/db/models/fields/__init__.py", line 613, in get_prep_value
    return int(value)
TypeError: int() argument must be a string or a number, not 'Gender'
Internal Server Error: /profile/2/
Traceback (most recent call last):
  File "/home/kalinins/.virtualenvs/zapsum/lib/python3.4/site-packages/django/core/handlers/base.py", line 99, in get_response
    resolver_match = resolver.resolve(request.path_info)
  File "/home/kalinins/.virtualenvs/zapsum/lib/python3.4/site-packages/django/core/urlresolvers.py", line 339, in resolve
    sub_match = pattern.resolve(new_path)
  File "/home/kalinins/.virtualenvs/zapsum/lib/python3.4/site-packages/django/core/urlresolvers.py", line 339, in resolve
    sub_match = pattern.resolve(new_path)
  File "/home/kalinins/.virtualenvs/zapsum/lib/python3.4/site-packages/django/core/urlresolvers.py", line 223, in resolve
    return ResolverMatch(self.callback, args, kwargs, self.name)
  File "/home/kalinins/.virtualenvs/zapsum/lib/python3.4/site-packages/django/core/urlresolvers.py", line 230, in callback
    self._callback = get_callable(self._callback_str)
  File "/home/kalinins/.virtualenvs/zapsum/lib/python3.4/site-packages/django/utils/functional.py", line 32, in wrapper
    result = func(*args)
  File "/home/kalinins/.virtualenvs/zapsum/lib/python3.4/site-packages/django/core/urlresolvers.py", line 97, in get_callable
    mod = import_module(mod_name)
  File "/home/kalinins/.virtualenvs/zapsum/lib/python3.4/importlib/__init__.py", line 109, in import_module
    return _bootstrap._gcd_import(name[level:], package, level)
  File "<frozen importlib._bootstrap>", line 2231, in _gcd_import
  File "<frozen importlib._bootstrap>", line 2214, in _find_and_load
  File "<frozen importlib._bootstrap>", line 2203, in _find_and_load_unlocked
  File "<frozen importlib._bootstrap>", line 1200, in _load_unlocked
  File "<frozen importlib._bootstrap>", line 1129, in _exec
  File "<frozen importlib._bootstrap>", line 1444, in exec_module
  File "<frozen importlib._bootstrap>", line 1549, in get_code
  File "<frozen importlib._bootstrap>", line 1509, in source_to_code
  File "<frozen importlib._bootstrap>", line 321, in _call_with_frames_removed
  File "/home/kalinins/.virtualenvs/zapsum/zapsum/app_zapsum/views.py", line 52
    t = loader.get_template('page_profile.html')
    ^
SyntaxError: invalid syntax
Internal Server Error: /profile/2/
Traceback (most recent call last):
  File "/home/kalinins/.virtualenvs/zapsum/lib/python3.4/site-packages/django/core/handlers/base.py", line 99, in get_response
    resolver_match = resolver.resolve(request.path_info)
  File "/home/kalinins/.virtualenvs/zapsum/lib/python3.4/site-packages/django/core/urlresolvers.py", line 339, in resolve
    sub_match = pattern.resolve(new_path)
  File "/home/kalinins/.virtualenvs/zapsum/lib/python3.4/site-packages/django/core/urlresolvers.py", line 339, in resolve
    sub_match = pattern.resolve(new_path)
  File "/home/kalinins/.virtualenvs/zapsum/lib/python3.4/site-packages/django/core/urlresolvers.py", line 223, in resolve
    return ResolverMatch(self.callback, args, kwargs, self.name)
  File "/home/kalinins/.virtualenvs/zapsum/lib/python3.4/site-packages/django/core/urlresolvers.py", line 230, in callback
    self._callback = get_callable(self._callback_str)
  File "/home/kalinins/.virtualenvs/zapsum/lib/python3.4/site-packages/django/utils/functional.py", line 32, in wrapper
    result = func(*args)
  File "/home/kalinins/.virtualenvs/zapsum/lib/python3.4/site-packages/django/core/urlresolvers.py", line 97, in get_callable
    mod = import_module(mod_name)
  File "/home/kalinins/.virtualenvs/zapsum/lib/python3.4/importlib/__init__.py", line 109, in import_module
    return _bootstrap._gcd_import(name[level:], package, level)
  File "<frozen importlib._bootstrap>", line 2231, in _gcd_import
  File "<frozen importlib._bootstrap>", line 2214, in _find_and_load
  File "<frozen importlib._bootstrap>", line 2203, in _find_and_load_unlocked
  File "<frozen importlib._bootstrap>", line 1200, in _load_unlocked
  File "<frozen importlib._bootstrap>", line 1129, in _exec
  File "<frozen importlib._bootstrap>", line 1444, in exec_module
  File "<frozen importlib._bootstrap>", line 1549, in get_code
  File "<frozen importlib._bootstrap>", line 1509, in source_to_code
  File "<frozen importlib._bootstrap>", line 321, in _call_with_frames_removed
  File "/home/kalinins/.virtualenvs/zapsum/zapsum/app_zapsum/views.py", line 52
    t = loader.get_template('page_profile.html')
    ^
SyntaxError: invalid syntax
Internal Server Error: /profile/2/
Traceback (most recent call last):
  File "/home/kalinins/.virtualenvs/zapsum/lib/python3.4/site-packages/django/core/handlers/base.py", line 99, in get_response
    resolver_match = resolver.resolve(request.path_info)
  File "/home/kalinins/.virtualenvs/zapsum/lib/python3.4/site-packages/django/core/urlresolvers.py", line 339, in resolve
    sub_match = pattern.resolve(new_path)
  File "/home/kalinins/.virtualenvs/zapsum/lib/python3.4/site-packages/django/core/urlresolvers.py", line 339, in resolve
    sub_match = pattern.resolve(new_path)
  File "/home/kalinins/.virtualenvs/zapsum/lib/python3.4/site-packages/django/core/urlresolvers.py", line 223, in resolve
    return ResolverMatch(self.callback, args, kwargs, self.name)
  File "/home/kalinins/.virtualenvs/zapsum/lib/python3.4/site-packages/django/core/urlresolvers.py", line 230, in callback
    self._callback = get_callable(self._callback_str)
  File "/home/kalinins/.virtualenvs/zapsum/lib/python3.4/site-packages/django/utils/functional.py", line 32, in wrapper
    result = func(*args)
  File "/home/kalinins/.virtualenvs/zapsum/lib/python3.4/site-packages/django/core/urlresolvers.py", line 97, in get_callable
    mod = import_module(mod_name)
  File "/home/kalinins/.virtualenvs/zapsum/lib/python3.4/importlib/__init__.py", line 109, in import_module
    return _bootstrap._gcd_import(name[level:], package, level)
  File "<frozen importlib._bootstrap>", line 2231, in _gcd_import
  File "<frozen importlib._bootstrap>", line 2214, in _find_and_load
  File "<frozen importlib._bootstrap>", line 2203, in _find_and_load_unlocked
  File "<frozen importlib._bootstrap>", line 1200, in _load_unlocked
  File "<frozen importlib._bootstrap>", line 1129, in _exec
  File "<frozen importlib._bootstrap>", line 1444, in exec_module
  File "<frozen importlib._bootstrap>", line 1549, in get_code
  File "<frozen importlib._bootstrap>", line 1509, in source_to_code
  File "<frozen importlib._bootstrap>", line 321, in _call_with_frames_removed
  File "/home/kalinins/.virtualenvs/zapsum/zapsum/app_zapsum/views.py", line 52
    t = loader.get_template('page_profile.html')
    ^
SyntaxError: invalid syntax
Internal Server Error: /profile/2/
Traceback (most recent call last):
  File "/home/kalinins/.virtualenvs/zapsum/lib/python3.4/site-packages/django/core/handlers/base.py", line 112, in get_response
    response = wrapped_callback(request, *callback_args, **callback_kwargs)
  File "/home/kalinins/.virtualenvs/zapsum/zapsum/app_zapsum/views.py", line 50, in profile
    obj_gender = Gender.get_entry(gender_id=int(obj_author.gender))
TypeError: int() argument must be a string or a number, not 'Gender'
Internal Server Error: /profile/2/
Traceback (most recent call last):
  File "/home/kalinins/.virtualenvs/zapsum/lib/python3.4/site-packages/django/core/handlers/base.py", line 112, in get_response
    response = wrapped_callback(request, *callback_args, **callback_kwargs)
  File "/home/kalinins/.virtualenvs/zapsum/zapsum/app_zapsum/views.py", line 52, in profile
    print(int(obj_author.gender))
TypeError: int() argument must be a string or a number, not 'Gender'
Internal Server Error: /profile/2/
Traceback (most recent call last):
  File "/home/kalinins/.virtualenvs/zapsum/lib/python3.4/site-packages/django/core/handlers/base.py", line 112, in get_response
    response = wrapped_callback(request, *callback_args, **callback_kwargs)
  File "/home/kalinins/.virtualenvs/zapsum/zapsum/app_zapsum/views.py", line 52, in profile
    print(int(obj_author.gender.gender))
ValueError: invalid literal for int() with base 10: 'Ж'
Internal Server Error: /profile/2/
Traceback (most recent call last):
  File "/home/kalinins/.virtualenvs/zapsum/lib/python3.4/site-packages/django/core/handlers/base.py", line 112, in get_response
    response = wrapped_callback(request, *callback_args, **callback_kwargs)
  File "/home/kalinins/.virtualenvs/zapsum/zapsum/app_zapsum/views.py", line 52, in profile
    print(int(obj_author.gender.gender))
ValueError: invalid literal for int() with base 10: 'Ж'
Internal Server Error: /profile/2/
Traceback (most recent call last):
  File "/home/kalinins/.virtualenvs/zapsum/lib/python3.4/site-packages/django/core/handlers/base.py", line 112, in get_response
    response = wrapped_callback(request, *callback_args, **callback_kwargs)
  File "/home/kalinins/.virtualenvs/zapsum/zapsum/app_zapsum/views.py", line 52, in profile
    print(int(obj_author.gender.gender))
ValueError: invalid literal for int() with base 10: 'Ж'
Not Found: /profile/{{ key }}/
Internal Server Error: /profile/6/
Traceback (most recent call last):
  File "/home/kalinins/.virtualenvs/zapsum/lib/python3.4/site-packages/django/core/handlers/base.py", line 112, in get_response
    response = wrapped_callback(request, *callback_args, **callback_kwargs)
  File "/home/kalinins/.virtualenvs/zapsum/zapsum/app_zapsum/views.py", line 51, in profile
    print(obj_author.data_joined)
AttributeError: 'UserProfile' object has no attribute 'data_joined'
Not Found: /favicon.ico
Internal Server Error: /profile/6/
Traceback (most recent call last):
  File "/home/kalinins/.virtualenvs/zapsum/lib/python3.4/site-packages/django/core/handlers/base.py", line 99, in get_response
    resolver_match = resolver.resolve(request.path_info)
  File "/home/kalinins/.virtualenvs/zapsum/lib/python3.4/site-packages/django/core/urlresolvers.py", line 339, in resolve
    sub_match = pattern.resolve(new_path)
  File "/home/kalinins/.virtualenvs/zapsum/lib/python3.4/site-packages/django/core/urlresolvers.py", line 339, in resolve
    sub_match = pattern.resolve(new_path)
  File "/home/kalinins/.virtualenvs/zapsum/lib/python3.4/site-packages/django/core/urlresolvers.py", line 223, in resolve
    return ResolverMatch(self.callback, args, kwargs, self.name)
  File "/home/kalinins/.virtualenvs/zapsum/lib/python3.4/site-packages/django/core/urlresolvers.py", line 230, in callback
    self._callback = get_callable(self._callback_str)
  File "/home/kalinins/.virtualenvs/zapsum/lib/python3.4/site-packages/django/utils/functional.py", line 32, in wrapper
    result = func(*args)
  File "/home/kalinins/.virtualenvs/zapsum/lib/python3.4/site-packages/django/core/urlresolvers.py", line 97, in get_callable
    mod = import_module(mod_name)
  File "/home/kalinins/.virtualenvs/zapsum/lib/python3.4/importlib/__init__.py", line 109, in import_module
    return _bootstrap._gcd_import(name[level:], package, level)
  File "<frozen importlib._bootstrap>", line 2231, in _gcd_import
  File "<frozen importlib._bootstrap>", line 2214, in _find_and_load
  File "<frozen importlib._bootstrap>", line 2203, in _find_and_load_unlocked
  File "<frozen importlib._bootstrap>", line 1200, in _load_unlocked
  File "<frozen importlib._bootstrap>", line 1129, in _exec
  File "<frozen importlib._bootstrap>", line 1444, in exec_module
  File "<frozen importlib._bootstrap>", line 1549, in get_code
  File "<frozen importlib._bootstrap>", line 1509, in source_to_code
  File "<frozen importlib._bootstrap>", line 321, in _call_with_frames_removed
  File "/home/kalinins/.virtualenvs/zapsum/zapsum/app_zapsum/views.py", line 52
    if obj_user.is_active, == 0:
                         ^
SyntaxError: invalid syntax
Internal Server Error: /profile/6/
Traceback (most recent call last):
  File "/home/kalinins/.virtualenvs/zapsum/lib/python3.4/site-packages/django/core/handlers/base.py", line 112, in get_response
    response = wrapped_callback(request, *callback_args, **callback_kwargs)
  File "/home/kalinins/.virtualenvs/zapsum/zapsum/app_zapsum/views.py", line 60, in profile
    'obj_user_is_active': obj_user_is_active,
NameError: name 'obj_user_is_active' is not defined
Internal Server Error: /profile/6/
Traceback (most recent call last):
  File "/home/kalinins/.virtualenvs/zapsum/lib/python3.4/site-packages/django/core/handlers/base.py", line 112, in get_response
    response = wrapped_callback(request, *callback_args, **callback_kwargs)
  File "/home/kalinins/.virtualenvs/zapsum/zapsum/app_zapsum/views.py", line 60, in profile
    'obj_user_is_active': obj_user_is_active,
NameError: name 'obj_user_is_active' is not defined
Internal Server Error: /profile/6/
Traceback (most recent call last):
  File "/home/kalinins/.virtualenvs/zapsum/lib/python3.4/site-packages/django/core/handlers/base.py", line 112, in get_response
    response = wrapped_callback(request, *callback_args, **callback_kwargs)
  File "/home/kalinins/.virtualenvs/zapsum/zapsum/app_zapsum/views.py", line 60, in profile
    'obj_user_is_active': obj_user_is_active,
NameError: name 'obj_user_is_active' is not defined
Internal Server Error: /profile/6/
Traceback (most recent call last):
  File "/home/kalinins/.virtualenvs/zapsum/lib/python3.4/site-packages/django/core/handlers/base.py", line 112, in get_response
    response = wrapped_callback(request, *callback_args, **callback_kwargs)
  File "/home/kalinins/.virtualenvs/zapsum/zapsum/app_zapsum/views.py", line 60, in profile
    'obj_user_is_active': obj_user_is_active,
NameError: name 'obj_user_is_active' is not defined
Internal Server Error: /profile/6/
Traceback (most recent call last):
  File "/home/kalinins/.virtualenvs/zapsum/lib/python3.4/site-packages/django/core/handlers/base.py", line 112, in get_response
    response = wrapped_callback(request, *callback_args, **callback_kwargs)
  File "/home/kalinins/.virtualenvs/zapsum/zapsum/app_zapsum/views.py", line 55, in profile
    obj_user_is_active == False
NameError: name 'obj_user_is_active' is not defined
Internal Server Error: /profile/6/
Traceback (most recent call last):
  File "/home/kalinins/.virtualenvs/zapsum/lib/python3.4/site-packages/django/core/handlers/base.py", line 112, in get_response
    response = wrapped_callback(request, *callback_args, **callback_kwargs)
  File "/home/kalinins/.virtualenvs/zapsum/zapsum/app_zapsum/views.py", line 55, in profile
    obj_user_is_active == False
NameError: name 'obj_user_is_active' is not defined
Internal Server Error: /profile/6/
Traceback (most recent call last):
  File "/home/kalinins/.virtualenvs/zapsum/lib/python3.4/site-packages/django/core/handlers/base.py", line 112, in get_response
    response = wrapped_callback(request, *callback_args, **callback_kwargs)
  File "/home/kalinins/.virtualenvs/zapsum/zapsum/app_zapsum/views.py", line 55, in profile
    obj_user_is_active == False
NameError: name 'obj_user_is_active' is not defined
Internal Server Error: /profile/6/
Traceback (most recent call last):
  File "/home/kalinins/.virtualenvs/zapsum/lib/python3.4/site-packages/django/core/handlers/base.py", line 112, in get_response
    response = wrapped_callback(request, *callback_args, **callback_kwargs)
  File "/home/kalinins/.virtualenvs/zapsum/zapsum/app_zapsum/views.py", line 55, in profile
    obj_user_is_active == False
NameError: name 'obj_user_is_active' is not defined
Not Found: /diary/4/
Internal Server Error: /diary/2/
Traceback (most recent call last):
  File "/home/kalinins/.virtualenvs/zapsum/lib/python3.4/site-packages/django/core/handlers/base.py", line 112, in get_response
    response = wrapped_callback(request, *callback_args, **callback_kwargs)
  File "/home/kalinins/.virtualenvs/zapsum/zapsum/app_zapsum/views.py", line 50, in diary
    obj_diary = Diary.get_all_user_entries(user_id=id_author)
  File "/home/kalinins/.virtualenvs/zapsum/zapsum/app_zapsum/models.py", line 39, in get_all_user_entries
    return self.objects.filter(user_id=user_id, is_active=True, is_delete=False).values(title, date)
NameError: name 'title' is not defined
Internal Server Error: /diary/2/
Traceback (most recent call last):
  File "/home/kalinins/.virtualenvs/zapsum/lib/python3.4/site-packages/django/core/handlers/base.py", line 112, in get_response
    response = wrapped_callback(request, *callback_args, **callback_kwargs)
  File "/home/kalinins/.virtualenvs/zapsum/zapsum/app_zapsum/views.py", line 50, in diary
    obj_diary = Diary.get_all_user_entries(user_id=id_author)
  File "/home/kalinins/.virtualenvs/zapsum/zapsum/app_zapsum/models.py", line 39, in get_all_user_entries
    return self.objects.filter(user_id=user_id, is_active=True, is_delete=False).values(title, date)
NameError: name 'title' is not defined
Internal Server Error: /diary/2/
Traceback (most recent call last):
  File "/home/kalinins/.virtualenvs/zapsum/lib/python3.4/site-packages/django/core/handlers/base.py", line 112, in get_response
    response = wrapped_callback(request, *callback_args, **callback_kwargs)
  File "/home/kalinins/.virtualenvs/zapsum/zapsum/app_zapsum/views.py", line 50, in diary
    obj_diary = Diary.get_all_user_entries(user_id=id_author)
  File "/home/kalinins/.virtualenvs/zapsum/zapsum/app_zapsum/models.py", line 39, in get_all_user_entries
    return self.objects.filter(user_id=user_id, is_active=True, is_delete=False).values(title, date)
NameError: name 'title' is not defined
Internal Server Error: /diary/2/
Traceback (most recent call last):
  File "/home/kalinins/.virtualenvs/zapsum/lib/python3.4/site-packages/django/core/handlers/base.py", line 112, in get_response
    response = wrapped_callback(request, *callback_args, **callback_kwargs)
  File "/home/kalinins/.virtualenvs/zapsum/zapsum/app_zapsum/views.py", line 50, in diary
    obj_diary = Diary.get_all_user_entries(user_id=id_author)
  File "/home/kalinins/.virtualenvs/zapsum/zapsum/app_zapsum/models.py", line 39, in get_all_user_entries
    return self.objects.filter(user_id=user_id, is_active=True, is_delete=False).values('title', 'date')
NameError: name 'title' is not defined
Internal Server Error: /diary/2/
Traceback (most recent call last):
  File "/home/kalinins/.virtualenvs/zapsum/lib/python3.4/site-packages/django/core/handlers/base.py", line 112, in get_response
    response = wrapped_callback(request, *callback_args, **callback_kwargs)
  File "/home/kalinins/.virtualenvs/zapsum/zapsum/app_zapsum/views.py", line 50, in diary
    obj_diary = Diary.get_all_user_entries(user_id=id_author)
  File "/home/kalinins/.virtualenvs/zapsum/zapsum/app_zapsum/models.py", line 39, in get_all_user_entries
    return self.objects.filter(user_id=user_id, is_active=True, is_delete=False).values('title', 'date')
NameError: name 'title' is not defined
Internal Server Error: /diary/2/
Traceback (most recent call last):
  File "/home/kalinins/.virtualenvs/zapsum/lib/python3.4/site-packages/django/core/handlers/base.py", line 112, in get_response
    response = wrapped_callback(request, *callback_args, **callback_kwargs)
  File "/home/kalinins/.virtualenvs/zapsum/zapsum/app_zapsum/views.py", line 50, in diary
    obj_diary = Diary.get_all_user_entries(user_id=id_author)
  File "/home/kalinins/.virtualenvs/zapsum/zapsum/app_zapsum/models.py", line 39, in get_all_user_entries
    return self.objects.filter(user_id=user_id, is_active=True, is_delete=False).values('title', 'date')
NameError: name 'title' is not defined
Internal Server Error: /diary/2/
Traceback (most recent call last):
  File "/home/kalinins/.virtualenvs/zapsum/lib/python3.4/site-packages/django/core/handlers/base.py", line 112, in get_response
    response = wrapped_callback(request, *callback_args, **callback_kwargs)
  File "/home/kalinins/.virtualenvs/zapsum/zapsum/app_zapsum/views.py", line 50, in diary
    obj_diary = Diary.get_all_user_entries(user_id=id_author)
  File "/home/kalinins/.virtualenvs/zapsum/zapsum/app_zapsum/models.py", line 39, in get_all_user_entries
    return self.objects.filter(user_id=user_id, is_active=True, is_delete=False).values('title', 'date')
NameError: name 'title' is not defined
Internal Server Error: /diary/2/
Traceback (most recent call last):
  File "/home/kalinins/.virtualenvs/zapsum/lib/python3.4/site-packages/django/core/handlers/base.py", line 112, in get_response
    response = wrapped_callback(request, *callback_args, **callback_kwargs)
  File "/home/kalinins/.virtualenvs/zapsum/zapsum/app_zapsum/views.py", line 50, in diary
    obj_diary = Diary.get_all_user_entries(user_id=id_author)
  File "/home/kalinins/.virtualenvs/zapsum/zapsum/app_zapsum/models.py", line 39, in get_all_user_entries
    return self.objects.filter(user_id=user_id, is_active=True, is_delete=False).values('title', 'date')
NameError: name 'title' is not defined
Not Found: /entry//
Not Found: /favicon.ico
Not Found: /entry//
Not Found: /entry//
Not Found: /entry//
Internal Server Error: /my_records/
Traceback (most recent call last):
  File "/home/kalinins/.virtualenvs/zapsum/lib/python3.4/site-packages/django/core/handlers/base.py", line 112, in get_response
    response = wrapped_callback(request, *callback_args, **callback_kwargs)
  File "/home/kalinins/.virtualenvs/zapsum/lib/python3.4/site-packages/django/contrib/auth/decorators.py", line 22, in _wrapped_view
    return view_func(request, *args, **kwargs)
  File "/home/kalinins/.virtualenvs/zapsum/zapsum/app_zapsum/views.py", line 144, in my_records
    all_user_entries = Diary.get_all_user_entries(id=request.user.pk)
TypeError: get_all_user_entries() got an unexpected keyword argument 'id'
Internal Server Error: /my_records/
Traceback (most recent call last):
  File "/home/kalinins/.virtualenvs/zapsum/lib/python3.4/site-packages/django/core/handlers/base.py", line 112, in get_response
    response = wrapped_callback(request, *callback_args, **callback_kwargs)
  File "/home/kalinins/.virtualenvs/zapsum/lib/python3.4/site-packages/django/contrib/auth/decorators.py", line 22, in _wrapped_view
    return view_func(request, *args, **kwargs)
  File "/home/kalinins/.virtualenvs/zapsum/zapsum/app_zapsum/views.py", line 144, in my_records
    all_user_entries = Diary.get_all_user_entries(id=request.user.pk)
TypeError: get_all_user_entries() got an unexpected keyword argument 'id'
Internal Server Error: /my_records/
Traceback (most recent call last):
  File "/home/kalinins/.virtualenvs/zapsum/lib/python3.4/site-packages/django/core/handlers/base.py", line 112, in get_response
    response = wrapped_callback(request, *callback_args, **callback_kwargs)
  File "/home/kalinins/.virtualenvs/zapsum/lib/python3.4/site-packages/django/contrib/auth/decorators.py", line 22, in _wrapped_view
    return view_func(request, *args, **kwargs)
  File "/home/kalinins/.virtualenvs/zapsum/zapsum/app_zapsum/views.py", line 144, in my_records
    all_user_entries = Diary.get_all_user_entries(id=request.user.pk)
TypeError: get_all_user_entries() got an unexpected keyword argument 'id'
Internal Server Error: /my_records/
Traceback (most recent call last):
  File "/home/kalinins/.virtualenvs/zapsum/lib/python3.4/site-packages/django/core/handlers/base.py", line 112, in get_response
    response = wrapped_callback(request, *callback_args, **callback_kwargs)
  File "/home/kalinins/.virtualenvs/zapsum/lib/python3.4/site-packages/django/contrib/auth/decorators.py", line 22, in _wrapped_view
    return view_func(request, *args, **kwargs)
  File "/home/kalinins/.virtualenvs/zapsum/zapsum/app_zapsum/views.py", line 144, in my_records
    all_user_entries = Diary.get_all_user_entries(id=request.user.pk)
TypeError: get_all_user_entries() got an unexpected keyword argument 'id'
Internal Server Error: /my_records/
Traceback (most recent call last):
  File "/home/kalinins/.virtualenvs/zapsum/lib/python3.4/site-packages/django/core/handlers/base.py", line 112, in get_response
    response = wrapped_callback(request, *callback_args, **callback_kwargs)
  File "/home/kalinins/.virtualenvs/zapsum/lib/python3.4/site-packages/django/contrib/auth/decorators.py", line 22, in _wrapped_view
    return view_func(request, *args, **kwargs)
  File "/home/kalinins/.virtualenvs/zapsum/zapsum/app_zapsum/views.py", line 144, in my_records
    all_user_entries = Diary.get_all_user_entries(id=request.user.pk)
TypeError: get_all_user_entries() got an unexpected keyword argument 'id'
Not Found: /entry/1/
Not Found: /entry/2/
Not Found: /entry/1/
Internal Server Error: /new_authors/
Traceback (most recent call last):
  File "/home/kalinins/.virtualenvs/zapsum/lib/python3.4/site-packages/django/core/handlers/base.py", line 112, in get_response
    response = wrapped_callback(request, *callback_args, **callback_kwargs)
  File "/home/kalinins/.virtualenvs/zapsum/zapsum/app_zapsum/views.py", line 141, in new_authors
    new_authors = UserProfile.get_new_authors_entries(cut_begin=page_new_authors, cut_end=page_new_authors + 2)
TypeError: Can't convert 'int' object to str implicitly
Internal Server Error: /new_authors/
Traceback (most recent call last):
  File "/home/kalinins/.virtualenvs/zapsum/lib/python3.4/site-packages/django/core/handlers/base.py", line 112, in get_response
    response = wrapped_callback(request, *callback_args, **callback_kwargs)
  File "/home/kalinins/.virtualenvs/zapsum/zapsum/app_zapsum/views.py", line 141, in new_authors
    new_authors = UserProfile.get_new_authors_entries(cut_begin=page_new_authors, cut_end=2)
  File "/home/kalinins/.virtualenvs/zapsum/zapsum/app_accounts/models.py", line 57, in get_new_authors_entries
    return self.objects.filter(is_active=1, is_superuser=0).order_by('-date_joined')[cut_begin:cut_end]
  File "/home/kalinins/.virtualenvs/zapsum/lib/python3.4/site-packages/django/db/models/query.py", line 110, in __getitem__
    or (isinstance(k, slice) and (k.start is None or k.start >= 0)
TypeError: unorderable types: str() >= int()
Internal Server Error: /new_authors/
Traceback (most recent call last):
  File "/home/kalinins/.virtualenvs/zapsum/lib/python3.4/site-packages/django/core/handlers/base.py", line 99, in get_response
    resolver_match = resolver.resolve(request.path_info)
  File "/home/kalinins/.virtualenvs/zapsum/lib/python3.4/site-packages/django/core/urlresolvers.py", line 339, in resolve
    sub_match = pattern.resolve(new_path)
  File "/home/kalinins/.virtualenvs/zapsum/lib/python3.4/site-packages/django/core/urlresolvers.py", line 339, in resolve
    sub_match = pattern.resolve(new_path)
  File "/home/kalinins/.virtualenvs/zapsum/lib/python3.4/site-packages/django/core/urlresolvers.py", line 223, in resolve
    return ResolverMatch(self.callback, args, kwargs, self.name)
  File "/home/kalinins/.virtualenvs/zapsum/lib/python3.4/site-packages/django/core/urlresolvers.py", line 230, in callback
    self._callback = get_callable(self._callback_str)
  File "/home/kalinins/.virtualenvs/zapsum/lib/python3.4/site-packages/django/utils/functional.py", line 32, in wrapper
    result = func(*args)
  File "/home/kalinins/.virtualenvs/zapsum/lib/python3.4/site-packages/django/core/urlresolvers.py", line 97, in get_callable
    mod = import_module(mod_name)
  File "/home/kalinins/.virtualenvs/zapsum/lib/python3.4/importlib/__init__.py", line 109, in import_module
    return _bootstrap._gcd_import(name[level:], package, level)
  File "<frozen importlib._bootstrap>", line 2231, in _gcd_import
  File "<frozen importlib._bootstrap>", line 2214, in _find_and_load
  File "<frozen importlib._bootstrap>", line 2203, in _find_and_load_unlocked
  File "<frozen importlib._bootstrap>", line 1200, in _load_unlocked
  File "<frozen importlib._bootstrap>", line 1129, in _exec
  File "<frozen importlib._bootstrap>", line 1444, in exec_module
  File "<frozen importlib._bootstrap>", line 1549, in get_code
  File "<frozen importlib._bootstrap>", line 1509, in source_to_code
  File "<frozen importlib._bootstrap>", line 321, in _call_with_frames_removed
  File "/home/kalinins/.virtualenvs/zapsum/zapsum/app_zapsum/views.py", line 143
    data = {
       ^
SyntaxError: invalid syntax
Internal Server Error: /new_authors/
Traceback (most recent call last):
  File "/home/kalinins/.virtualenvs/zapsum/lib/python3.4/site-packages/django/core/handlers/base.py", line 112, in get_response
    response = wrapped_callback(request, *callback_args, **callback_kwargs)
  File "/home/kalinins/.virtualenvs/zapsum/zapsum/app_zapsum/views.py", line 141, in new_authors
    new_authors = UserProfile.get_new_authors_entries(cut_begin=int(page_new_authors), cut_end=int(page_new_authors + 2))
TypeError: Can't convert 'int' object to str implicitly
Internal Server Error: /new_authors/
Traceback (most recent call last):
  File "/home/kalinins/.virtualenvs/zapsum/lib/python3.4/site-packages/django/core/handlers/base.py", line 112, in get_response
    response = wrapped_callback(request, *callback_args, **callback_kwargs)
  File "/home/kalinins/.virtualenvs/zapsum/zapsum/app_zapsum/views.py", line 144, in new_authors
    'nickname': new_authors.nickname,
AttributeError: 'QuerySet' object has no attribute 'nickname'
Internal Server Error: /new_authors/
Traceback (most recent call last):
  File "/home/kalinins/.virtualenvs/zapsum/lib/python3.4/site-packages/django/core/handlers/base.py", line 112, in get_response
    response = wrapped_callback(request, *callback_args, **callback_kwargs)
  File "/home/kalinins/.virtualenvs/zapsum/zapsum/app_zapsum/views.py", line 147, in new_authors
    return HttpResponse(json.dumps(data), content_type='application/json')
  File "/usr/lib/python3.4/json/__init__.py", line 230, in dumps
    return _default_encoder.encode(obj)
  File "/usr/lib/python3.4/json/encoder.py", line 192, in encode
    chunks = self.iterencode(o, _one_shot=True)
  File "/usr/lib/python3.4/json/encoder.py", line 250, in iterencode
    return _iterencode(o, 0)
  File "/usr/lib/python3.4/json/encoder.py", line 173, in default
    raise TypeError(repr(o) + " is not JSON serializable")
TypeError: [<UserProfile: zzzzzz>, <UserProfile: wwwwww>] is not JSON serializable
Internal Server Error: /new_authors/
Traceback (most recent call last):
  File "/home/kalinins/.virtualenvs/zapsum/lib/python3.4/site-packages/django/core/handlers/base.py", line 112, in get_response
    response = wrapped_callback(request, *callback_args, **callback_kwargs)
  File "/home/kalinins/.virtualenvs/zapsum/zapsum/app_zapsum/views.py", line 147, in new_authors
    return HttpResponse(json.dumps(data), content_type='application/json')
  File "/usr/lib/python3.4/json/__init__.py", line 230, in dumps
    return _default_encoder.encode(obj)
  File "/usr/lib/python3.4/json/encoder.py", line 192, in encode
    chunks = self.iterencode(o, _one_shot=True)
  File "/usr/lib/python3.4/json/encoder.py", line 250, in iterencode
    return _iterencode(o, 0)
  File "/usr/lib/python3.4/json/encoder.py", line 173, in default
    raise TypeError(repr(o) + " is not JSON serializable")
TypeError: [<UserProfile: zzzzzz>, <UserProfile: wwwwww>] is not JSON serializable
Internal Server Error: /new_authors/
Traceback (most recent call last):
  File "/home/kalinins/.virtualenvs/zapsum/lib/python3.4/site-packages/django/core/handlers/base.py", line 112, in get_response
    response = wrapped_callback(request, *callback_args, **callback_kwargs)
  File "/home/kalinins/.virtualenvs/zapsum/zapsum/app_zapsum/views.py", line 149, in new_authors
    new_authors = UserProfile.get_new_authors_entries(cut_begin=0, cut_end=2)
  File "/home/kalinins/.virtualenvs/zapsum/zapsum/app_accounts/models.py", line 57, in get_new_authors_entries
    return self.objects.filter(is_active=1, is_superuser=0).valuse('nickname').order_by('-date_joined')[cut_begin:cut_end]
AttributeError: 'QuerySet' object has no attribute 'valuse'
Internal Server Error: /new_authors/
Traceback (most recent call last):
  File "/home/kalinins/.virtualenvs/zapsum/lib/python3.4/site-packages/django/core/handlers/base.py", line 112, in get_response
    response = wrapped_callback(request, *callback_args, **callback_kwargs)
  File "/home/kalinins/.virtualenvs/zapsum/zapsum/app_zapsum/views.py", line 149, in new_authors
    new_authors = UserProfile.get_new_authors_entries(cut_begin=0, cut_end=2)
  File "/home/kalinins/.virtualenvs/zapsum/zapsum/app_accounts/models.py", line 57, in get_new_authors_entries
    return self.objects.filter(is_active=1, is_superuser=0).value('nickname').order_by('-date_joined')[cut_begin:cut_end]
AttributeError: 'QuerySet' object has no attribute 'value'
Internal Server Error: /new_authors/
Traceback (most recent call last):
  File "/home/kalinins/.virtualenvs/zapsum/lib/python3.4/site-packages/django/core/handlers/base.py", line 112, in get_response
    response = wrapped_callback(request, *callback_args, **callback_kwargs)
  File "/home/kalinins/.virtualenvs/zapsum/zapsum/app_zapsum/views.py", line 149, in new_authors
    new_authors = UserProfile.get_new_authors_entries(cut_begin=0, cut_end=2)
  File "/home/kalinins/.virtualenvs/zapsum/zapsum/app_accounts/models.py", line 57, in get_new_authors_entries
    return self.objects.filter(is_active=1, is_superuser=0).value('nickname').order_by('-date_joined')[cut_begin:cut_end]
AttributeError: 'QuerySet' object has no attribute 'value'
Internal Server Error: /new_authors/
Traceback (most recent call last):
  File "/home/kalinins/.virtualenvs/zapsum/lib/python3.4/site-packages/django/core/handlers/base.py", line 112, in get_response
    response = wrapped_callback(request, *callback_args, **callback_kwargs)
  File "/home/kalinins/.virtualenvs/zapsum/zapsum/app_zapsum/views.py", line 144, in new_authors
    'nickname': new_authors.nickname,
AttributeError: 'ValuesQuerySet' object has no attribute 'nickname'
Internal Server Error: /new_authors/
Traceback (most recent call last):
  File "/home/kalinins/.virtualenvs/zapsum/lib/python3.4/site-packages/django/core/handlers/base.py", line 112, in get_response
    response = wrapped_callback(request, *callback_args, **callback_kwargs)
  File "/home/kalinins/.virtualenvs/zapsum/zapsum/app_zapsum/views.py", line 143, in new_authors
    return HttpResponse(json.dumps(new_authors), content_type='application/json')
  File "/usr/lib/python3.4/json/__init__.py", line 230, in dumps
    return _default_encoder.encode(obj)
  File "/usr/lib/python3.4/json/encoder.py", line 192, in encode
    chunks = self.iterencode(o, _one_shot=True)
  File "/usr/lib/python3.4/json/encoder.py", line 250, in iterencode
    return _iterencode(o, 0)
  File "/usr/lib/python3.4/json/encoder.py", line 173, in default
    raise TypeError(repr(o) + " is not JSON serializable")
TypeError: [{'id': 4, 'date_joined': datetime.datetime(2014, 9, 22, 13, 37, 25, 866974, tzinfo=<UTC>), 'username': 'zzzzzz'}, {'id': 5, 'date_joined': datetime.datetime(2014, 9, 22, 13, 37, 25, 866974, tzinfo=<UTC>), 'username': 'wwwwww'}] is not JSON serializable
Internal Server Error: /new_authors/
Traceback (most recent call last):
  File "/home/kalinins/.virtualenvs/zapsum/lib/python3.4/site-packages/django/core/handlers/base.py", line 112, in get_response
    response = wrapped_callback(request, *callback_args, **callback_kwargs)
  File "/home/kalinins/.virtualenvs/zapsum/zapsum/app_zapsum/views.py", line 143, in new_authors
    return HttpResponse(json.dumps(new_authors), content_type='application/json')
  File "/usr/lib/python3.4/json/__init__.py", line 230, in dumps
    return _default_encoder.encode(obj)
  File "/usr/lib/python3.4/json/encoder.py", line 192, in encode
    chunks = self.iterencode(o, _one_shot=True)
  File "/usr/lib/python3.4/json/encoder.py", line 250, in iterencode
    return _iterencode(o, 0)
  File "/usr/lib/python3.4/json/encoder.py", line 173, in default
    raise TypeError(repr(o) + " is not JSON serializable")
TypeError: [{'username': 'zzzzzz', 'id': 4}, {'username': 'wwwwww', 'id': 5}] is not JSON serializable
Internal Server Error: /new_authors/
Traceback (most recent call last):
  File "/home/kalinins/.virtualenvs/zapsum/lib/python3.4/site-packages/django/core/handlers/base.py", line 112, in get_response
    response = wrapped_callback(request, *callback_args, **callback_kwargs)
  File "/home/kalinins/.virtualenvs/zapsum/zapsum/app_zapsum/views.py", line 143, in new_authors
    return HttpResponse(json.dumps(new_authors[0]), content_type='application/json')
  File "/usr/lib/python3.4/json/__init__.py", line 230, in dumps
    return _default_encoder.encode(obj)
  File "/usr/lib/python3.4/json/encoder.py", line 192, in encode
    chunks = self.iterencode(o, _one_shot=True)
  File "/usr/lib/python3.4/json/encoder.py", line 250, in iterencode
    return _iterencode(o, 0)
  File "/usr/lib/python3.4/json/encoder.py", line 173, in default
    raise TypeError(repr(o) + " is not JSON serializable")
TypeError: datetime.datetime(2014, 9, 22, 13, 37, 25, 866974, tzinfo=<UTC>) is not JSON serializable
Internal Server Error: /new_authors/
Traceback (most recent call last):
  File "/home/kalinins/.virtualenvs/zapsum/lib/python3.4/site-packages/django/core/handlers/base.py", line 112, in get_response
    response = wrapped_callback(request, *callback_args, **callback_kwargs)
  File "/home/kalinins/.virtualenvs/zapsum/zapsum/app_zapsum/views.py", line 143, in new_authors
    data = [obj in new_authors]
NameError: name 'obj' is not defined
Internal Server Error: /new_authors/
Traceback (most recent call last):
  File "/home/kalinins/.virtualenvs/zapsum/lib/python3.4/site-packages/django/core/handlers/base.py", line 112, in get_response
    response = wrapped_callback(request, *callback_args, **callback_kwargs)
  File "/home/kalinins/.virtualenvs/zapsum/zapsum/app_zapsum/views.py", line 144, in new_authors
    data = [obj in new_authors]
NameError: name 'obj' is not defined
Internal Server Error: /new_authors/
Traceback (most recent call last):
  File "/home/kalinins/.virtualenvs/zapsum/lib/python3.4/site-packages/django/core/handlers/base.py", line 112, in get_response
    response = wrapped_callback(request, *callback_args, **callback_kwargs)
  File "/home/kalinins/.virtualenvs/zapsum/zapsum/app_zapsum/views.py", line 146, in new_authors
    return HttpResponse(json.dumps(data), content_type='application/json')
  File "/usr/lib/python3.4/json/__init__.py", line 230, in dumps
    return _default_encoder.encode(obj)
  File "/usr/lib/python3.4/json/encoder.py", line 192, in encode
    chunks = self.iterencode(o, _one_shot=True)
  File "/usr/lib/python3.4/json/encoder.py", line 250, in iterencode
    return _iterencode(o, 0)
  File "/usr/lib/python3.4/json/encoder.py", line 173, in default
    raise TypeError(repr(o) + " is not JSON serializable")
TypeError: [{'username': 'zzzzzz', 'id': 4}, {'username': 'wwwwww', 'id': 5}] is not JSON serializable
Internal Server Error: /new_authors/
Traceback (most recent call last):
  File "/home/kalinins/.virtualenvs/zapsum/lib/python3.4/site-packages/django/core/handlers/base.py", line 112, in get_response
    response = wrapped_callback(request, *callback_args, **callback_kwargs)
  File "/home/kalinins/.virtualenvs/zapsum/zapsum/app_zapsum/views.py", line 143, in new_authors
    return HttpResponse(json.dumps(new_authors), content_type='application/json')
  File "/usr/lib/python3.4/json/__init__.py", line 230, in dumps
    return _default_encoder.encode(obj)
  File "/usr/lib/python3.4/json/encoder.py", line 192, in encode
    chunks = self.iterencode(o, _one_shot=True)
  File "/usr/lib/python3.4/json/encoder.py", line 250, in iterencode
    return _iterencode(o, 0)
  File "/usr/lib/python3.4/json/encoder.py", line 173, in default
    raise TypeError(repr(o) + " is not JSON serializable")
TypeError: [{'id': 4, 'username': 'zzzzzz'}, {'id': 5, 'username': 'wwwwww'}] is not JSON serializable
Internal Server Error: /new_authors/
Traceback (most recent call last):
  File "/home/kalinins/.virtualenvs/zapsum/lib/python3.4/site-packages/django/core/handlers/base.py", line 112, in get_response
    response = wrapped_callback(request, *callback_args, **callback_kwargs)
  File "/home/kalinins/.virtualenvs/zapsum/zapsum/app_zapsum/views.py", line 143, in new_authors
    return HttpResponse(json.dumps(new_authors), content_type='application/json')
  File "/usr/lib/python3.4/json/__init__.py", line 230, in dumps
    return _default_encoder.encode(obj)
  File "/usr/lib/python3.4/json/encoder.py", line 192, in encode
    chunks = self.iterencode(o, _one_shot=True)
  File "/usr/lib/python3.4/json/encoder.py", line 250, in iterencode
    return _iterencode(o, 0)
  File "/usr/lib/python3.4/json/encoder.py", line 173, in default
    raise TypeError(repr(o) + " is not JSON serializable")
TypeError: [{'id': 4, 'username': 'zzzzzz'}, {'id': 5, 'username': 'wwwwww'}] is not JSON serializable
Internal Server Error: /new_authors/
Traceback (most recent call last):
  File "/home/kalinins/.virtualenvs/zapsum/lib/python3.4/site-packages/django/core/handlers/base.py", line 112, in get_response
    response = wrapped_callback(request, *callback_args, **callback_kwargs)
  File "/home/kalinins/.virtualenvs/zapsum/zapsum/app_zapsum/views.py", line 143, in new_authors
    return HttpResponse(json.dumps(new_authors), content_type='application/json')
  File "/usr/lib/python3.4/json/__init__.py", line 230, in dumps
    return _default_encoder.encode(obj)
  File "/usr/lib/python3.4/json/encoder.py", line 192, in encode
    chunks = self.iterencode(o, _one_shot=True)
  File "/usr/lib/python3.4/json/encoder.py", line 250, in iterencode
    return _iterencode(o, 0)
  File "/usr/lib/python3.4/json/encoder.py", line 173, in default
    raise TypeError(repr(o) + " is not JSON serializable")
TypeError: [{'id': 4, 'username': 'zzzzzz'}, {'id': 5, 'username': 'wwwwww'}] is not JSON serializable
Internal Server Error: /new_authors/
Traceback (most recent call last):
  File "/home/kalinins/.virtualenvs/zapsum/lib/python3.4/site-packages/django/core/handlers/base.py", line 112, in get_response
    response = wrapped_callback(request, *callback_args, **callback_kwargs)
  File "/home/kalinins/.virtualenvs/zapsum/zapsum/app_zapsum/views.py", line 143, in new_authors
    return HttpResponse(json.dumps(new_authors), content_type='application/json')
  File "/usr/lib/python3.4/json/__init__.py", line 230, in dumps
    return _default_encoder.encode(obj)
  File "/usr/lib/python3.4/json/encoder.py", line 192, in encode
    chunks = self.iterencode(o, _one_shot=True)
  File "/usr/lib/python3.4/json/encoder.py", line 250, in iterencode
    return _iterencode(o, 0)
  File "/usr/lib/python3.4/json/encoder.py", line 173, in default
    raise TypeError(repr(o) + " is not JSON serializable")
TypeError: [{'id': 4, 'username': 'zzzzzz'}, {'id': 5, 'username': 'wwwwww'}] is not JSON serializable
Internal Server Error: /new_authors/
Traceback (most recent call last):
  File "/home/kalinins/.virtualenvs/zapsum/lib/python3.4/site-packages/django/core/handlers/base.py", line 112, in get_response
    response = wrapped_callback(request, *callback_args, **callback_kwargs)
  File "/home/kalinins/.virtualenvs/zapsum/zapsum/app_zapsum/views.py", line 144, in new_authors
    new_authors_dict = model_to_dict(new_authors, fields=[], exclude=[])
  File "/home/kalinins/.virtualenvs/zapsum/lib/python3.4/site-packages/django/forms/models.py", line 124, in model_to_dict
    opts = instance._meta
AttributeError: 'ValuesQuerySet' object has no attribute '_meta'
Internal Server Error: /new_authors/
Traceback (most recent call last):
  File "/home/kalinins/.virtualenvs/zapsum/lib/python3.4/site-packages/django/core/handlers/base.py", line 112, in get_response
    response = wrapped_callback(request, *callback_args, **callback_kwargs)
  File "/home/kalinins/.virtualenvs/zapsum/zapsum/app_zapsum/views.py", line 143, in new_authors
    result = serializers.serialize('json', new_authors)
  File "/home/kalinins/.virtualenvs/zapsum/lib/python3.4/site-packages/django/core/serializers/__init__.py", line 122, in serialize
    s.serialize(queryset, **options)
  File "/home/kalinins/.virtualenvs/zapsum/lib/python3.4/site-packages/django/core/serializers/base.py", line 45, in serialize
    concrete_model = obj._meta.concrete_model
AttributeError: 'dict' object has no attribute '_meta'
Internal Server Error: /new_authors/
Traceback (most recent call last):
  File "/home/kalinins/.virtualenvs/zapsum/lib/python3.4/site-packages/django/core/handlers/base.py", line 112, in get_response
    response = wrapped_callback(request, *callback_args, **callback_kwargs)
  File "/home/kalinins/.virtualenvs/zapsum/zapsum/app_zapsum/views.py", line 143, in new_authors
    result = serializers.serialize('json', new_authors)
  File "/home/kalinins/.virtualenvs/zapsum/lib/python3.4/site-packages/django/core/serializers/__init__.py", line 122, in serialize
    s.serialize(queryset, **options)
  File "/home/kalinins/.virtualenvs/zapsum/lib/python3.4/site-packages/django/core/serializers/base.py", line 45, in serialize
    concrete_model = obj._meta.concrete_model
AttributeError: 'dict' object has no attribute '_meta'
Internal Server Error: /new_authors/
Traceback (most recent call last):
  File "/home/kalinins/.virtualenvs/zapsum/lib/python3.4/site-packages/django/core/handlers/base.py", line 112, in get_response
    response = wrapped_callback(request, *callback_args, **callback_kwargs)
  File "/home/kalinins/.virtualenvs/zapsum/zapsum/app_zapsum/views.py", line 143, in new_authors
    result = serializers.serialize('json', new_authors)
  File "/home/kalinins/.virtualenvs/zapsum/lib/python3.4/site-packages/django/core/serializers/__init__.py", line 122, in serialize
    s.serialize(queryset, **options)
  File "/home/kalinins/.virtualenvs/zapsum/lib/python3.4/site-packages/django/core/serializers/base.py", line 45, in serialize
    concrete_model = obj._meta.concrete_model
AttributeError: 'dict' object has no attribute '_meta'
Internal Server Error: /new_authors/
Traceback (most recent call last):
  File "/home/kalinins/.virtualenvs/zapsum/lib/python3.4/site-packages/django/core/handlers/base.py", line 112, in get_response
    response = wrapped_callback(request, *callback_args, **callback_kwargs)
  File "/home/kalinins/.virtualenvs/zapsum/zapsum/app_zapsum/views.py", line 145, in new_authors
    return HttpResponse(json.dumps(new_authors), content_type='application/json')
  File "/usr/lib/python3.4/json/__init__.py", line 230, in dumps
    return _default_encoder.encode(obj)
  File "/usr/lib/python3.4/json/encoder.py", line 192, in encode
    chunks = self.iterencode(o, _one_shot=True)
  File "/usr/lib/python3.4/json/encoder.py", line 250, in iterencode
    return _iterencode(o, 0)
  File "/usr/lib/python3.4/json/encoder.py", line 173, in default
    raise TypeError(repr(o) + " is not JSON serializable")
TypeError: [<UserProfile_Deferred_avatar_date_joined_email_fic679ed35161c7ba80f007b4235db5148: zzzzzz>, <UserProfile_Deferred_avatar_date_joined_email_fic679ed35161c7ba80f007b4235db5148: wwwwww>] is not JSON serializable
Forbidden (CSRF token missing or incorrect.): /new_authors/
Not Found: /favicon.ico
Forbidden (CSRF token missing or incorrect.): /new_authors/
Forbidden (CSRF token missing or incorrect.): /new_authors/
Internal Server Error: /new_authors/
Traceback (most recent call last):
  File "/home/kalinins/.virtualenvs/zapsum/lib/python3.4/site-packages/django/core/handlers/base.py", line 112, in get_response
    response = wrapped_callback(request, *callback_args, **callback_kwargs)
  File "/home/kalinins/.virtualenvs/zapsum/zapsum/app_zapsum/views.py", line 142, in new_authors
    new_authors = list(self.objects.filter(is_active=1, is_superuser=0)[page_new_authors:page_new_authors + 2]) + list(User.objects.all())
NameError: name 'self' is not defined
Internal Server Error: /new_authors/
Traceback (most recent call last):
  File "/home/kalinins/.virtualenvs/zapsum/lib/python3.4/site-packages/django/template/defaulttags.py", line 1080, in load
    lib = get_library(taglib)
  File "/home/kalinins/.virtualenvs/zapsum/lib/python3.4/site-packages/django/template/base.py", line 1326, in get_library
    ','.join(tried_modules)))
django.template.base.InvalidTemplateLibrary: Template library tags_app_zapsum not found, tried django.templatetags.tags_app_zapsum,django.contrib.admin.templatetags.tags_app_zapsum,django.contrib.staticfiles.templatetags.tags_app_zapsum,sorl.thumbnail.templatetags.tags_app_zapsum,app_accounts.templatetags.tags_app_zapsum

During handling of the above exception, another exception occurred:

Traceback (most recent call last):
  File "/home/kalinins/.virtualenvs/zapsum/lib/python3.4/site-packages/django/core/handlers/base.py", line 112, in get_response
    response = wrapped_callback(request, *callback_args, **callback_kwargs)
  File "/home/kalinins/.virtualenvs/zapsum/zapsum/app_zapsum/views.py", line 158, in new_authors
    return HttpResponse(t.render(c))
  File "/home/kalinins/.virtualenvs/zapsum/lib/python3.4/site-packages/django/template/base.py", line 140, in render
    return self._render(context)
  File "/home/kalinins/.virtualenvs/zapsum/lib/python3.4/site-packages/django/template/base.py", line 134, in _render
    return self.nodelist.render(context)
  File "/home/kalinins/.virtualenvs/zapsum/lib/python3.4/site-packages/django/template/base.py", line 840, in render
    bit = self.render_node(node, context)
  File "/home/kalinins/.virtualenvs/zapsum/lib/python3.4/site-packages/django/template/debug.py", line 78, in render_node
    return node.render(context)
  File "/home/kalinins/.virtualenvs/zapsum/lib/python3.4/site-packages/django/template/loader_tags.py", line 101, in render
    compiled_parent = self.get_parent(context)
  File "/home/kalinins/.virtualenvs/zapsum/lib/python3.4/site-packages/django/template/loader_tags.py", line 98, in get_parent
    return get_template(parent)
  File "/home/kalinins/.virtualenvs/zapsum/lib/python3.4/site-packages/django/template/loader.py", line 138, in get_template
    template, origin = find_template(template_name)
  File "/home/kalinins/.virtualenvs/zapsum/lib/python3.4/site-packages/django/template/loader.py", line 127, in find_template
    source, display_name = loader(name, dirs)
  File "/home/kalinins/.virtualenvs/zapsum/lib/python3.4/site-packages/django/template/loader.py", line 43, in __call__
    return self.load_template(template_name, template_dirs)
  File "/home/kalinins/.virtualenvs/zapsum/lib/python3.4/site-packages/django/template/loader.py", line 49, in load_template
    template = get_template_from_string(source, origin, template_name)
  File "/home/kalinins/.virtualenvs/zapsum/lib/python3.4/site-packages/django/template/loader.py", line 149, in get_template_from_string
    return Template(source, origin, name)
  File "/home/kalinins/.virtualenvs/zapsum/lib/python3.4/site-packages/django/template/base.py", line 125, in __init__
    self.nodelist = compile_string(template_string, origin)
  File "/home/kalinins/.virtualenvs/zapsum/lib/python3.4/site-packages/django/template/base.py", line 153, in compile_string
    return parser.parse()
  File "/home/kalinins/.virtualenvs/zapsum/lib/python3.4/site-packages/django/template/base.py", line 278, in parse
    compiled_result = compile_func(self, token)
  File "/home/kalinins/.virtualenvs/zapsum/lib/python3.4/site-packages/django/template/defaulttags.py", line 1084, in load
    (taglib, e))
django.template.base.TemplateSyntaxError: 'tags_app_zapsum' is not a valid tag library: Template library tags_app_zapsum not found, tried django.templatetags.tags_app_zapsum,django.contrib.admin.templatetags.tags_app_zapsum,django.contrib.staticfiles.templatetags.tags_app_zapsum,sorl.thumbnail.templatetags.tags_app_zapsum,app_accounts.templatetags.tags_app_zapsum
Not Found: /favicon.ico
Internal Server Error: /my_records/
Traceback (most recent call last):
  File "/home/kalinins/.virtualenvs/zapsum/lib/python3.4/site-packages/django/template/defaulttags.py", line 1080, in load
    lib = get_library(taglib)
  File "/home/kalinins/.virtualenvs/zapsum/lib/python3.4/site-packages/django/template/base.py", line 1326, in get_library
    ','.join(tried_modules)))
django.template.base.InvalidTemplateLibrary: Template library tags_app_zapsum not found, tried django.templatetags.tags_app_zapsum,django.contrib.admin.templatetags.tags_app_zapsum,django.contrib.staticfiles.templatetags.tags_app_zapsum,sorl.thumbnail.templatetags.tags_app_zapsum,app_accounts.templatetags.tags_app_zapsum

During handling of the above exception, another exception occurred:

Traceback (most recent call last):
  File "/home/kalinins/.virtualenvs/zapsum/lib/python3.4/site-packages/django/core/handlers/base.py", line 112, in get_response
    response = wrapped_callback(request, *callback_args, **callback_kwargs)
  File "/home/kalinins/.virtualenvs/zapsum/lib/python3.4/site-packages/django/contrib/auth/decorators.py", line 22, in _wrapped_view
    return view_func(request, *args, **kwargs)
  File "/home/kalinins/.virtualenvs/zapsum/zapsum/app_zapsum/views.py", line 179, in my_records
    t = loader.get_template('page_my_records.html')
  File "/home/kalinins/.virtualenvs/zapsum/lib/python3.4/site-packages/django/template/loader.py", line 138, in get_template
    template, origin = find_template(template_name)
  File "/home/kalinins/.virtualenvs/zapsum/lib/python3.4/site-packages/django/template/loader.py", line 127, in find_template
    source, display_name = loader(name, dirs)
  File "/home/kalinins/.virtualenvs/zapsum/lib/python3.4/site-packages/django/template/loader.py", line 43, in __call__
    return self.load_template(template_name, template_dirs)
  File "/home/kalinins/.virtualenvs/zapsum/lib/python3.4/site-packages/django/template/loader.py", line 49, in load_template
    template = get_template_from_string(source, origin, template_name)
  File "/home/kalinins/.virtualenvs/zapsum/lib/python3.4/site-packages/django/template/loader.py", line 149, in get_template_from_string
    return Template(source, origin, name)
  File "/home/kalinins/.virtualenvs/zapsum/lib/python3.4/site-packages/django/template/base.py", line 125, in __init__
    self.nodelist = compile_string(template_string, origin)
  File "/home/kalinins/.virtualenvs/zapsum/lib/python3.4/site-packages/django/template/base.py", line 153, in compile_string
    return parser.parse()
  File "/home/kalinins/.virtualenvs/zapsum/lib/python3.4/site-packages/django/template/base.py", line 278, in parse
    compiled_result = compile_func(self, token)
  File "/home/kalinins/.virtualenvs/zapsum/lib/python3.4/site-packages/django/template/loader_tags.py", line 215, in do_extends
    nodelist = parser.parse()
  File "/home/kalinins/.virtualenvs/zapsum/lib/python3.4/site-packages/django/template/base.py", line 278, in parse
    compiled_result = compile_func(self, token)
  File "/home/kalinins/.virtualenvs/zapsum/lib/python3.4/site-packages/django/template/defaulttags.py", line 1084, in load
    (taglib, e))
django.template.base.TemplateSyntaxError: 'tags_app_zapsum' is not a valid tag library: Template library tags_app_zapsum not found, tried django.templatetags.tags_app_zapsum,django.contrib.admin.templatetags.tags_app_zapsum,django.contrib.staticfiles.templatetags.tags_app_zapsum,sorl.thumbnail.templatetags.tags_app_zapsum,app_accounts.templatetags.tags_app_zapsum
Internal Server Error: /my_records/
Traceback (most recent call last):
  File "/home/kalinins/.virtualenvs/zapsum/lib/python3.4/site-packages/django/template/base.py", line 274, in parse
    compile_func = self.tags[command]
KeyError: 'tags_app_zapsum'

During handling of the above exception, another exception occurred:

Traceback (most recent call last):
  File "/home/kalinins/.virtualenvs/zapsum/lib/python3.4/site-packages/django/core/handlers/base.py", line 112, in get_response
    response = wrapped_callback(request, *callback_args, **callback_kwargs)
  File "/home/kalinins/.virtualenvs/zapsum/lib/python3.4/site-packages/django/contrib/auth/decorators.py", line 22, in _wrapped_view
    return view_func(request, *args, **kwargs)
  File "/home/kalinins/.virtualenvs/zapsum/zapsum/app_zapsum/views.py", line 179, in my_records
    t = loader.get_template('page_my_records.html')
  File "/home/kalinins/.virtualenvs/zapsum/lib/python3.4/site-packages/django/template/loader.py", line 138, in get_template
    template, origin = find_template(template_name)
  File "/home/kalinins/.virtualenvs/zapsum/lib/python3.4/site-packages/django/template/loader.py", line 127, in find_template
    source, display_name = loader(name, dirs)
  File "/home/kalinins/.virtualenvs/zapsum/lib/python3.4/site-packages/django/template/loader.py", line 43, in __call__
    return self.load_template(template_name, template_dirs)
  File "/home/kalinins/.virtualenvs/zapsum/lib/python3.4/site-packages/django/template/loader.py", line 49, in load_template
    template = get_template_from_string(source, origin, template_name)
  File "/home/kalinins/.virtualenvs/zapsum/lib/python3.4/site-packages/django/template/loader.py", line 149, in get_template_from_string
    return Template(source, origin, name)
  File "/home/kalinins/.virtualenvs/zapsum/lib/python3.4/site-packages/django/template/base.py", line 125, in __init__
    self.nodelist = compile_string(template_string, origin)
  File "/home/kalinins/.virtualenvs/zapsum/lib/python3.4/site-packages/django/template/base.py", line 153, in compile_string
    return parser.parse()
  File "/home/kalinins/.virtualenvs/zapsum/lib/python3.4/site-packages/django/template/base.py", line 278, in parse
    compiled_result = compile_func(self, token)
  File "/home/kalinins/.virtualenvs/zapsum/lib/python3.4/site-packages/django/template/loader_tags.py", line 215, in do_extends
    nodelist = parser.parse()
  File "/home/kalinins/.virtualenvs/zapsum/lib/python3.4/site-packages/django/template/base.py", line 276, in parse
    self.invalid_block_tag(token, command, parse_until)
  File "/home/kalinins/.virtualenvs/zapsum/lib/python3.4/site-packages/django/template/base.py", line 332, in invalid_block_tag
    raise self.error(token, "Invalid block tag: '%s'" % command)
django.template.base.TemplateSyntaxError: Invalid block tag: 'tags_app_zapsum'
Internal Server Error: /my_records/
Traceback (most recent call last):
  File "/home/kalinins/.virtualenvs/zapsum/lib/python3.4/site-packages/django/template/base.py", line 274, in parse
    compile_func = self.tags[command]
KeyError: 'part_auth_area'

During handling of the above exception, another exception occurred:

Traceback (most recent call last):
  File "/home/kalinins/.virtualenvs/zapsum/lib/python3.4/site-packages/django/core/handlers/base.py", line 112, in get_response
    response = wrapped_callback(request, *callback_args, **callback_kwargs)
  File "/home/kalinins/.virtualenvs/zapsum/lib/python3.4/site-packages/django/contrib/auth/decorators.py", line 22, in _wrapped_view
    return view_func(request, *args, **kwargs)
  File "/home/kalinins/.virtualenvs/zapsum/zapsum/app_zapsum/views.py", line 179, in my_records
    t = loader.get_template('page_my_records.html')
  File "/home/kalinins/.virtualenvs/zapsum/lib/python3.4/site-packages/django/template/loader.py", line 138, in get_template
    template, origin = find_template(template_name)
  File "/home/kalinins/.virtualenvs/zapsum/lib/python3.4/site-packages/django/template/loader.py", line 127, in find_template
    source, display_name = loader(name, dirs)
  File "/home/kalinins/.virtualenvs/zapsum/lib/python3.4/site-packages/django/template/loader.py", line 43, in __call__
    return self.load_template(template_name, template_dirs)
  File "/home/kalinins/.virtualenvs/zapsum/lib/python3.4/site-packages/django/template/loader.py", line 49, in load_template
    template = get_template_from_string(source, origin, template_name)
  File "/home/kalinins/.virtualenvs/zapsum/lib/python3.4/site-packages/django/template/loader.py", line 149, in get_template_from_string
    return Template(source, origin, name)
  File "/home/kalinins/.virtualenvs/zapsum/lib/python3.4/site-packages/django/template/base.py", line 125, in __init__
    self.nodelist = compile_string(template_string, origin)
  File "/home/kalinins/.virtualenvs/zapsum/lib/python3.4/site-packages/django/template/base.py", line 153, in compile_string
    return parser.parse()
  File "/home/kalinins/.virtualenvs/zapsum/lib/python3.4/site-packages/django/template/base.py", line 278, in parse
    compiled_result = compile_func(self, token)
  File "/home/kalinins/.virtualenvs/zapsum/lib/python3.4/site-packages/django/template/loader_tags.py", line 215, in do_extends
    nodelist = parser.parse()
  File "/home/kalinins/.virtualenvs/zapsum/lib/python3.4/site-packages/django/template/base.py", line 278, in parse
    compiled_result = compile_func(self, token)
  File "/home/kalinins/.virtualenvs/zapsum/lib/python3.4/site-packages/django/template/loader_tags.py", line 190, in do_block
    nodelist = parser.parse(('endblock',))
  File "/home/kalinins/.virtualenvs/zapsum/lib/python3.4/site-packages/django/template/base.py", line 276, in parse
    self.invalid_block_tag(token, command, parse_until)
  File "/home/kalinins/.virtualenvs/zapsum/lib/python3.4/site-packages/django/template/base.py", line 331, in invalid_block_tag
    (command, get_text_list(["'%s'" % p for p in parse_until])))
django.template.base.TemplateSyntaxError: Invalid block tag: 'part_auth_area', expected 'endblock'
Internal Server Error: /my_records/
Traceback (most recent call last):
  File "/home/kalinins/.virtualenvs/zapsum/lib/python3.4/site-packages/django/template/base.py", line 274, in parse
    compile_func = self.tags[command]
KeyError: 'part_pagination'

During handling of the above exception, another exception occurred:

Traceback (most recent call last):
  File "/home/kalinins/.virtualenvs/zapsum/lib/python3.4/site-packages/django/core/handlers/base.py", line 112, in get_response
    response = wrapped_callback(request, *callback_args, **callback_kwargs)
  File "/home/kalinins/.virtualenvs/zapsum/lib/python3.4/site-packages/django/contrib/auth/decorators.py", line 22, in _wrapped_view
    return view_func(request, *args, **kwargs)
  File "/home/kalinins/.virtualenvs/zapsum/zapsum/app_zapsum/views.py", line 179, in my_records
    t = loader.get_template('page_my_records.html')
  File "/home/kalinins/.virtualenvs/zapsum/lib/python3.4/site-packages/django/template/loader.py", line 138, in get_template
    template, origin = find_template(template_name)
  File "/home/kalinins/.virtualenvs/zapsum/lib/python3.4/site-packages/django/template/loader.py", line 127, in find_template
    source, display_name = loader(name, dirs)
  File "/home/kalinins/.virtualenvs/zapsum/lib/python3.4/site-packages/django/template/loader.py", line 43, in __call__
    return self.load_template(template_name, template_dirs)
  File "/home/kalinins/.virtualenvs/zapsum/lib/python3.4/site-packages/django/template/loader.py", line 49, in load_template
    template = get_template_from_string(source, origin, template_name)
  File "/home/kalinins/.virtualenvs/zapsum/lib/python3.4/site-packages/django/template/loader.py", line 149, in get_template_from_string
    return Template(source, origin, name)
  File "/home/kalinins/.virtualenvs/zapsum/lib/python3.4/site-packages/django/template/base.py", line 125, in __init__
    self.nodelist = compile_string(template_string, origin)
  File "/home/kalinins/.virtualenvs/zapsum/lib/python3.4/site-packages/django/template/base.py", line 153, in compile_string
    return parser.parse()
  File "/home/kalinins/.virtualenvs/zapsum/lib/python3.4/site-packages/django/template/base.py", line 278, in parse
    compiled_result = compile_func(self, token)
  File "/home/kalinins/.virtualenvs/zapsum/lib/python3.4/site-packages/django/template/loader_tags.py", line 215, in do_extends
    nodelist = parser.parse()
  File "/home/kalinins/.virtualenvs/zapsum/lib/python3.4/site-packages/django/template/base.py", line 278, in parse
    compiled_result = compile_func(self, token)
  File "/home/kalinins/.virtualenvs/zapsum/lib/python3.4/site-packages/django/template/loader_tags.py", line 190, in do_block
    nodelist = parser.parse(('endblock',))
  File "/home/kalinins/.virtualenvs/zapsum/lib/python3.4/site-packages/django/template/base.py", line 276, in parse
    self.invalid_block_tag(token, command, parse_until)
  File "/home/kalinins/.virtualenvs/zapsum/lib/python3.4/site-packages/django/template/base.py", line 331, in invalid_block_tag
    (command, get_text_list(["'%s'" % p for p in parse_until])))
django.template.base.TemplateSyntaxError: Invalid block tag: 'part_pagination', expected 'endblock'
Internal Server Error: /my_records/
Traceback (most recent call last):
  File "/home/kalinins/.virtualenvs/zapsum/lib/python3.4/site-packages/django/template/base.py", line 274, in parse
    compile_func = self.tags[command]
KeyError: 'part_pagination'

During handling of the above exception, another exception occurred:

Traceback (most recent call last):
  File "/home/kalinins/.virtualenvs/zapsum/lib/python3.4/site-packages/django/core/handlers/base.py", line 112, in get_response
    response = wrapped_callback(request, *callback_args, **callback_kwargs)
  File "/home/kalinins/.virtualenvs/zapsum/lib/python3.4/site-packages/django/contrib/auth/decorators.py", line 22, in _wrapped_view
    return view_func(request, *args, **kwargs)
  File "/home/kalinins/.virtualenvs/zapsum/zapsum/app_zapsum/views.py", line 179, in my_records
    t = loader.get_template('page_my_records.html')
  File "/home/kalinins/.virtualenvs/zapsum/lib/python3.4/site-packages/django/template/loader.py", line 138, in get_template
    template, origin = find_template(template_name)
  File "/home/kalinins/.virtualenvs/zapsum/lib/python3.4/site-packages/django/template/loader.py", line 127, in find_template
    source, display_name = loader(name, dirs)
  File "/home/kalinins/.virtualenvs/zapsum/lib/python3.4/site-packages/django/template/loader.py", line 43, in __call__
    return self.load_template(template_name, template_dirs)
  File "/home/kalinins/.virtualenvs/zapsum/lib/python3.4/site-packages/django/template/loader.py", line 49, in load_template
    template = get_template_from_string(source, origin, template_name)
  File "/home/kalinins/.virtualenvs/zapsum/lib/python3.4/site-packages/django/template/loader.py", line 149, in get_template_from_string
    return Template(source, origin, name)
  File "/home/kalinins/.virtualenvs/zapsum/lib/python3.4/site-packages/django/template/base.py", line 125, in __init__
    self.nodelist = compile_string(template_string, origin)
  File "/home/kalinins/.virtualenvs/zapsum/lib/python3.4/site-packages/django/template/base.py", line 153, in compile_string
    return parser.parse()
  File "/home/kalinins/.virtualenvs/zapsum/lib/python3.4/site-packages/django/template/base.py", line 278, in parse
    compiled_result = compile_func(self, token)
  File "/home/kalinins/.virtualenvs/zapsum/lib/python3.4/site-packages/django/template/loader_tags.py", line 215, in do_extends
    nodelist = parser.parse()
  File "/home/kalinins/.virtualenvs/zapsum/lib/python3.4/site-packages/django/template/base.py", line 278, in parse
    compiled_result = compile_func(self, token)
  File "/home/kalinins/.virtualenvs/zapsum/lib/python3.4/site-packages/django/template/loader_tags.py", line 190, in do_block
    nodelist = parser.parse(('endblock',))
  File "/home/kalinins/.virtualenvs/zapsum/lib/python3.4/site-packages/django/template/base.py", line 276, in parse
    self.invalid_block_tag(token, command, parse_until)
  File "/home/kalinins/.virtualenvs/zapsum/lib/python3.4/site-packages/django/template/base.py", line 331, in invalid_block_tag
    (command, get_text_list(["'%s'" % p for p in parse_until])))
django.template.base.TemplateSyntaxError: Invalid block tag: 'part_pagination', expected 'endblock'
Internal Server Error: /my_records/
Traceback (most recent call last):
  File "/home/kalinins/.virtualenvs/zapsum/lib/python3.4/site-packages/django/template/base.py", line 274, in parse
    compile_func = self.tags[command]
KeyError: 'part_pagination'

During handling of the above exception, another exception occurred:

Traceback (most recent call last):
  File "/home/kalinins/.virtualenvs/zapsum/lib/python3.4/site-packages/django/core/handlers/base.py", line 112, in get_response
    response = wrapped_callback(request, *callback_args, **callback_kwargs)
  File "/home/kalinins/.virtualenvs/zapsum/lib/python3.4/site-packages/django/contrib/auth/decorators.py", line 22, in _wrapped_view
    return view_func(request, *args, **kwargs)
  File "/home/kalinins/.virtualenvs/zapsum/zapsum/app_zapsum/views.py", line 179, in my_records
    t = loader.get_template('page_my_records.html')
  File "/home/kalinins/.virtualenvs/zapsum/lib/python3.4/site-packages/django/template/loader.py", line 138, in get_template
    template, origin = find_template(template_name)
  File "/home/kalinins/.virtualenvs/zapsum/lib/python3.4/site-packages/django/template/loader.py", line 127, in find_template
    source, display_name = loader(name, dirs)
  File "/home/kalinins/.virtualenvs/zapsum/lib/python3.4/site-packages/django/template/loader.py", line 43, in __call__
    return self.load_template(template_name, template_dirs)
  File "/home/kalinins/.virtualenvs/zapsum/lib/python3.4/site-packages/django/template/loader.py", line 49, in load_template
    template = get_template_from_string(source, origin, template_name)
  File "/home/kalinins/.virtualenvs/zapsum/lib/python3.4/site-packages/django/template/loader.py", line 149, in get_template_from_string
    return Template(source, origin, name)
  File "/home/kalinins/.virtualenvs/zapsum/lib/python3.4/site-packages/django/template/base.py", line 125, in __init__
    self.nodelist = compile_string(template_string, origin)
  File "/home/kalinins/.virtualenvs/zapsum/lib/python3.4/site-packages/django/template/base.py", line 153, in compile_string
    return parser.parse()
  File "/home/kalinins/.virtualenvs/zapsum/lib/python3.4/site-packages/django/template/base.py", line 278, in parse
    compiled_result = compile_func(self, token)
  File "/home/kalinins/.virtualenvs/zapsum/lib/python3.4/site-packages/django/template/loader_tags.py", line 215, in do_extends
    nodelist = parser.parse()
  File "/home/kalinins/.virtualenvs/zapsum/lib/python3.4/site-packages/django/template/base.py", line 278, in parse
    compiled_result = compile_func(self, token)
  File "/home/kalinins/.virtualenvs/zapsum/lib/python3.4/site-packages/django/template/loader_tags.py", line 190, in do_block
    nodelist = parser.parse(('endblock',))
  File "/home/kalinins/.virtualenvs/zapsum/lib/python3.4/site-packages/django/template/base.py", line 276, in parse
    self.invalid_block_tag(token, command, parse_until)
  File "/home/kalinins/.virtualenvs/zapsum/lib/python3.4/site-packages/django/template/base.py", line 331, in invalid_block_tag
    (command, get_text_list(["'%s'" % p for p in parse_until])))
django.template.base.TemplateSyntaxError: Invalid block tag: 'part_pagination', expected 'endblock'
Internal Server Error: /my_records/
Traceback (most recent call last):
  File "/home/kalinins/.virtualenvs/zapsum/lib/python3.4/site-packages/django/core/handlers/base.py", line 112, in get_response
    response = wrapped_callback(request, *callback_args, **callback_kwargs)
  File "/home/kalinins/.virtualenvs/zapsum/lib/python3.4/site-packages/django/contrib/auth/decorators.py", line 22, in _wrapped_view
    return view_func(request, *args, **kwargs)
  File "/home/kalinins/.virtualenvs/zapsum/zapsum/app_zapsum/views.py", line 179, in my_records
    t = loader.get_template('page_my_records.html')
  File "/home/kalinins/.virtualenvs/zapsum/lib/python3.4/site-packages/django/template/loader.py", line 138, in get_template
    template, origin = find_template(template_name)
  File "/home/kalinins/.virtualenvs/zapsum/lib/python3.4/site-packages/django/template/loader.py", line 127, in find_template
    source, display_name = loader(name, dirs)
  File "/home/kalinins/.virtualenvs/zapsum/lib/python3.4/site-packages/django/template/loader.py", line 43, in __call__
    return self.load_template(template_name, template_dirs)
  File "/home/kalinins/.virtualenvs/zapsum/lib/python3.4/site-packages/django/template/loader.py", line 49, in load_template
    template = get_template_from_string(source, origin, template_name)
  File "/home/kalinins/.virtualenvs/zapsum/lib/python3.4/site-packages/django/template/loader.py", line 149, in get_template_from_string
    return Template(source, origin, name)
  File "/home/kalinins/.virtualenvs/zapsum/lib/python3.4/site-packages/django/template/base.py", line 125, in __init__
    self.nodelist = compile_string(template_string, origin)
  File "/home/kalinins/.virtualenvs/zapsum/lib/python3.4/site-packages/django/template/base.py", line 153, in compile_string
    return parser.parse()
  File "/home/kalinins/.virtualenvs/zapsum/lib/python3.4/site-packages/django/template/base.py", line 278, in parse
    compiled_result = compile_func(self, token)
  File "/home/kalinins/.virtualenvs/zapsum/lib/python3.4/site-packages/django/template/loader_tags.py", line 215, in do_extends
    nodelist = parser.parse()
  File "/home/kalinins/.virtualenvs/zapsum/lib/python3.4/site-packages/django/template/base.py", line 278, in parse
    compiled_result = compile_func(self, token)
  File "/home/kalinins/.virtualenvs/zapsum/lib/python3.4/site-packages/django/template/loader_tags.py", line 190, in do_block
    nodelist = parser.parse(('endblock',))
  File "/home/kalinins/.virtualenvs/zapsum/lib/python3.4/site-packages/django/template/base.py", line 278, in parse
    compiled_result = compile_func(self, token)
  File "/home/kalinins/.virtualenvs/zapsum/lib/python3.4/site-packages/django/template/base.py", line 1025, in generic_tag_compiler
    defaults, takes_context, name)
  File "/home/kalinins/.virtualenvs/zapsum/lib/python3.4/site-packages/django/template/base.py", line 1015, in parse_bits
    (name, ", ".join(["'%s'" % p for p in unhandled_params])))
django.template.base.TemplateSyntaxError: 'part_pagination' did not receive value(s) for the argument(s): 'entries'
Internal Server Error: /my_records/
Traceback (most recent call last):
  File "/home/kalinins/.virtualenvs/zapsum/lib/python3.4/site-packages/django/core/handlers/base.py", line 112, in get_response
    response = wrapped_callback(request, *callback_args, **callback_kwargs)
  File "/home/kalinins/.virtualenvs/zapsum/lib/python3.4/site-packages/django/contrib/auth/decorators.py", line 22, in _wrapped_view
    return view_func(request, *args, **kwargs)
  File "/home/kalinins/.virtualenvs/zapsum/zapsum/app_zapsum/views.py", line 179, in my_records
    t = loader.get_template('page_my_records.html')
  File "/home/kalinins/.virtualenvs/zapsum/lib/python3.4/site-packages/django/template/loader.py", line 138, in get_template
    template, origin = find_template(template_name)
  File "/home/kalinins/.virtualenvs/zapsum/lib/python3.4/site-packages/django/template/loader.py", line 127, in find_template
    source, display_name = loader(name, dirs)
  File "/home/kalinins/.virtualenvs/zapsum/lib/python3.4/site-packages/django/template/loader.py", line 43, in __call__
    return self.load_template(template_name, template_dirs)
  File "/home/kalinins/.virtualenvs/zapsum/lib/python3.4/site-packages/django/template/loader.py", line 49, in load_template
    template = get_template_from_string(source, origin, template_name)
  File "/home/kalinins/.virtualenvs/zapsum/lib/python3.4/site-packages/django/template/loader.py", line 149, in get_template_from_string
    return Template(source, origin, name)
  File "/home/kalinins/.virtualenvs/zapsum/lib/python3.4/site-packages/django/template/base.py", line 125, in __init__
    self.nodelist = compile_string(template_string, origin)
  File "/home/kalinins/.virtualenvs/zapsum/lib/python3.4/site-packages/django/template/base.py", line 153, in compile_string
    return parser.parse()
  File "/home/kalinins/.virtualenvs/zapsum/lib/python3.4/site-packages/django/template/base.py", line 278, in parse
    compiled_result = compile_func(self, token)
  File "/home/kalinins/.virtualenvs/zapsum/lib/python3.4/site-packages/django/template/loader_tags.py", line 215, in do_extends
    nodelist = parser.parse()
  File "/home/kalinins/.virtualenvs/zapsum/lib/python3.4/site-packages/django/template/base.py", line 278, in parse
    compiled_result = compile_func(self, token)
  File "/home/kalinins/.virtualenvs/zapsum/lib/python3.4/site-packages/django/template/loader_tags.py", line 190, in do_block
    nodelist = parser.parse(('endblock',))
  File "/home/kalinins/.virtualenvs/zapsum/lib/python3.4/site-packages/django/template/base.py", line 278, in parse
    compiled_result = compile_func(self, token)
  File "/home/kalinins/.virtualenvs/zapsum/lib/python3.4/site-packages/django/template/base.py", line 1025, in generic_tag_compiler
    defaults, takes_context, name)
  File "/home/kalinins/.virtualenvs/zapsum/lib/python3.4/site-packages/django/template/base.py", line 1015, in parse_bits
    (name, ", ".join(["'%s'" % p for p in unhandled_params])))
django.template.base.TemplateSyntaxError: 'part_pagination' did not receive value(s) for the argument(s): 'entries'
Internal Server Error: /my_records/
Traceback (most recent call last):
  File "/home/kalinins/.virtualenvs/zapsum/lib/python3.4/site-packages/django/template/base.py", line 274, in parse
    compile_func = self.tags[command]
KeyError: 'part_pagination'

During handling of the above exception, another exception occurred:

Traceback (most recent call last):
  File "/home/kalinins/.virtualenvs/zapsum/lib/python3.4/site-packages/django/core/handlers/base.py", line 112, in get_response
    response = wrapped_callback(request, *callback_args, **callback_kwargs)
  File "/home/kalinins/.virtualenvs/zapsum/lib/python3.4/site-packages/django/contrib/auth/decorators.py", line 22, in _wrapped_view
    return view_func(request, *args, **kwargs)
  File "/home/kalinins/.virtualenvs/zapsum/zapsum/app_zapsum/views.py", line 179, in my_records
    t = loader.get_template('page_my_records.html')
  File "/home/kalinins/.virtualenvs/zapsum/lib/python3.4/site-packages/django/template/loader.py", line 138, in get_template
    template, origin = find_template(template_name)
  File "/home/kalinins/.virtualenvs/zapsum/lib/python3.4/site-packages/django/template/loader.py", line 127, in find_template
    source, display_name = loader(name, dirs)
  File "/home/kalinins/.virtualenvs/zapsum/lib/python3.4/site-packages/django/template/loader.py", line 43, in __call__
    return self.load_template(template_name, template_dirs)
  File "/home/kalinins/.virtualenvs/zapsum/lib/python3.4/site-packages/django/template/loader.py", line 49, in load_template
    template = get_template_from_string(source, origin, template_name)
  File "/home/kalinins/.virtualenvs/zapsum/lib/python3.4/site-packages/django/template/loader.py", line 149, in get_template_from_string
    return Template(source, origin, name)
  File "/home/kalinins/.virtualenvs/zapsum/lib/python3.4/site-packages/django/template/base.py", line 125, in __init__
    self.nodelist = compile_string(template_string, origin)
  File "/home/kalinins/.virtualenvs/zapsum/lib/python3.4/site-packages/django/template/base.py", line 153, in compile_string
    return parser.parse()
  File "/home/kalinins/.virtualenvs/zapsum/lib/python3.4/site-packages/django/template/base.py", line 278, in parse
    compiled_result = compile_func(self, token)
  File "/home/kalinins/.virtualenvs/zapsum/lib/python3.4/site-packages/django/template/loader_tags.py", line 215, in do_extends
    nodelist = parser.parse()
  File "/home/kalinins/.virtualenvs/zapsum/lib/python3.4/site-packages/django/template/base.py", line 278, in parse
    compiled_result = compile_func(self, token)
  File "/home/kalinins/.virtualenvs/zapsum/lib/python3.4/site-packages/django/template/loader_tags.py", line 190, in do_block
    nodelist = parser.parse(('endblock',))
  File "/home/kalinins/.virtualenvs/zapsum/lib/python3.4/site-packages/django/template/base.py", line 276, in parse
    self.invalid_block_tag(token, command, parse_until)
  File "/home/kalinins/.virtualenvs/zapsum/lib/python3.4/site-packages/django/template/base.py", line 331, in invalid_block_tag
    (command, get_text_list(["'%s'" % p for p in parse_until])))
django.template.base.TemplateSyntaxError: Invalid block tag: 'part_pagination', expected 'endblock'
Internal Server Error: /my_records/
Traceback (most recent call last):
  File "/home/kalinins/.virtualenvs/zapsum/lib/python3.4/site-packages/django/template/base.py", line 274, in parse
    compile_func = self.tags[command]
KeyError: 'part_pagination'

During handling of the above exception, another exception occurred:

Traceback (most recent call last):
  File "/home/kalinins/.virtualenvs/zapsum/lib/python3.4/site-packages/django/core/handlers/base.py", line 112, in get_response
    response = wrapped_callback(request, *callback_args, **callback_kwargs)
  File "/home/kalinins/.virtualenvs/zapsum/lib/python3.4/site-packages/django/contrib/auth/decorators.py", line 22, in _wrapped_view
    return view_func(request, *args, **kwargs)
  File "/home/kalinins/.virtualenvs/zapsum/zapsum/app_zapsum/views.py", line 179, in my_records
    t = loader.get_template('page_my_records.html')
  File "/home/kalinins/.virtualenvs/zapsum/lib/python3.4/site-packages/django/template/loader.py", line 138, in get_template
    template, origin = find_template(template_name)
  File "/home/kalinins/.virtualenvs/zapsum/lib/python3.4/site-packages/django/template/loader.py", line 127, in find_template
    source, display_name = loader(name, dirs)
  File "/home/kalinins/.virtualenvs/zapsum/lib/python3.4/site-packages/django/template/loader.py", line 43, in __call__
    return self.load_template(template_name, template_dirs)
  File "/home/kalinins/.virtualenvs/zapsum/lib/python3.4/site-packages/django/template/loader.py", line 49, in load_template
    template = get_template_from_string(source, origin, template_name)
  File "/home/kalinins/.virtualenvs/zapsum/lib/python3.4/site-packages/django/template/loader.py", line 149, in get_template_from_string
    return Template(source, origin, name)
  File "/home/kalinins/.virtualenvs/zapsum/lib/python3.4/site-packages/django/template/base.py", line 125, in __init__
    self.nodelist = compile_string(template_string, origin)
  File "/home/kalinins/.virtualenvs/zapsum/lib/python3.4/site-packages/django/template/base.py", line 153, in compile_string
    return parser.parse()
  File "/home/kalinins/.virtualenvs/zapsum/lib/python3.4/site-packages/django/template/base.py", line 278, in parse
    compiled_result = compile_func(self, token)
  File "/home/kalinins/.virtualenvs/zapsum/lib/python3.4/site-packages/django/template/loader_tags.py", line 215, in do_extends
    nodelist = parser.parse()
  File "/home/kalinins/.virtualenvs/zapsum/lib/python3.4/site-packages/django/template/base.py", line 278, in parse
    compiled_result = compile_func(self, token)
  File "/home/kalinins/.virtualenvs/zapsum/lib/python3.4/site-packages/django/template/loader_tags.py", line 190, in do_block
    nodelist = parser.parse(('endblock',))
  File "/home/kalinins/.virtualenvs/zapsum/lib/python3.4/site-packages/django/template/base.py", line 276, in parse
    self.invalid_block_tag(token, command, parse_until)
  File "/home/kalinins/.virtualenvs/zapsum/lib/python3.4/site-packages/django/template/base.py", line 331, in invalid_block_tag
    (command, get_text_list(["'%s'" % p for p in parse_until])))
django.template.base.TemplateSyntaxError: Invalid block tag: 'part_pagination', expected 'endblock'
Internal Server Error: /my_records/
Traceback (most recent call last):
  File "/home/kalinins/.virtualenvs/zapsum/lib/python3.4/site-packages/django/template/base.py", line 274, in parse
    compile_func = self.tags[command]
KeyError: 'part_pagination'

During handling of the above exception, another exception occurred:

Traceback (most recent call last):
  File "/home/kalinins/.virtualenvs/zapsum/lib/python3.4/site-packages/django/core/handlers/base.py", line 112, in get_response
    response = wrapped_callback(request, *callback_args, **callback_kwargs)
  File "/home/kalinins/.virtualenvs/zapsum/lib/python3.4/site-packages/django/contrib/auth/decorators.py", line 22, in _wrapped_view
    return view_func(request, *args, **kwargs)
  File "/home/kalinins/.virtualenvs/zapsum/zapsum/app_zapsum/views.py", line 179, in my_records
    t = loader.get_template('page_my_records.html')
  File "/home/kalinins/.virtualenvs/zapsum/lib/python3.4/site-packages/django/template/loader.py", line 138, in get_template
    template, origin = find_template(template_name)
  File "/home/kalinins/.virtualenvs/zapsum/lib/python3.4/site-packages/django/template/loader.py", line 127, in find_template
    source, display_name = loader(name, dirs)
  File "/home/kalinins/.virtualenvs/zapsum/lib/python3.4/site-packages/django/template/loader.py", line 43, in __call__
    return self.load_template(template_name, template_dirs)
  File "/home/kalinins/.virtualenvs/zapsum/lib/python3.4/site-packages/django/template/loader.py", line 49, in load_template
    template = get_template_from_string(source, origin, template_name)
  File "/home/kalinins/.virtualenvs/zapsum/lib/python3.4/site-packages/django/template/loader.py", line 149, in get_template_from_string
    return Template(source, origin, name)
  File "/home/kalinins/.virtualenvs/zapsum/lib/python3.4/site-packages/django/template/base.py", line 125, in __init__
    self.nodelist = compile_string(template_string, origin)
  File "/home/kalinins/.virtualenvs/zapsum/lib/python3.4/site-packages/django/template/base.py", line 153, in compile_string
    return parser.parse()
  File "/home/kalinins/.virtualenvs/zapsum/lib/python3.4/site-packages/django/template/base.py", line 278, in parse
    compiled_result = compile_func(self, token)
  File "/home/kalinins/.virtualenvs/zapsum/lib/python3.4/site-packages/django/template/loader_tags.py", line 215, in do_extends
    nodelist = parser.parse()
  File "/home/kalinins/.virtualenvs/zapsum/lib/python3.4/site-packages/django/template/base.py", line 278, in parse
    compiled_result = compile_func(self, token)
  File "/home/kalinins/.virtualenvs/zapsum/lib/python3.4/site-packages/django/template/loader_tags.py", line 190, in do_block
    nodelist = parser.parse(('endblock',))
  File "/home/kalinins/.virtualenvs/zapsum/lib/python3.4/site-packages/django/template/base.py", line 276, in parse
    self.invalid_block_tag(token, command, parse_until)
  File "/home/kalinins/.virtualenvs/zapsum/lib/python3.4/site-packages/django/template/base.py", line 331, in invalid_block_tag
    (command, get_text_list(["'%s'" % p for p in parse_until])))
django.template.base.TemplateSyntaxError: Invalid block tag: 'part_pagination', expected 'endblock'
Internal Server Error: /my_records/
Traceback (most recent call last):
  File "/home/kalinins/.virtualenvs/zapsum/lib/python3.4/site-packages/django/template/base.py", line 274, in parse
    compile_func = self.tags[command]
KeyError: 'part_pagination'

During handling of the above exception, another exception occurred:

Traceback (most recent call last):
  File "/home/kalinins/.virtualenvs/zapsum/lib/python3.4/site-packages/django/core/handlers/base.py", line 112, in get_response
    response = wrapped_callback(request, *callback_args, **callback_kwargs)
  File "/home/kalinins/.virtualenvs/zapsum/lib/python3.4/site-packages/django/contrib/auth/decorators.py", line 22, in _wrapped_view
    return view_func(request, *args, **kwargs)
  File "/home/kalinins/.virtualenvs/zapsum/zapsum/app_zapsum/views.py", line 179, in my_records
    t = loader.get_template('page_my_records.html')
  File "/home/kalinins/.virtualenvs/zapsum/lib/python3.4/site-packages/django/template/loader.py", line 138, in get_template
    template, origin = find_template(template_name)
  File "/home/kalinins/.virtualenvs/zapsum/lib/python3.4/site-packages/django/template/loader.py", line 127, in find_template
    source, display_name = loader(name, dirs)
  File "/home/kalinins/.virtualenvs/zapsum/lib/python3.4/site-packages/django/template/loader.py", line 43, in __call__
    return self.load_template(template_name, template_dirs)
  File "/home/kalinins/.virtualenvs/zapsum/lib/python3.4/site-packages/django/template/loader.py", line 49, in load_template
    template = get_template_from_string(source, origin, template_name)
  File "/home/kalinins/.virtualenvs/zapsum/lib/python3.4/site-packages/django/template/loader.py", line 149, in get_template_from_string
    return Template(source, origin, name)
  File "/home/kalinins/.virtualenvs/zapsum/lib/python3.4/site-packages/django/template/base.py", line 125, in __init__
    self.nodelist = compile_string(template_string, origin)
  File "/home/kalinins/.virtualenvs/zapsum/lib/python3.4/site-packages/django/template/base.py", line 153, in compile_string
    return parser.parse()
  File "/home/kalinins/.virtualenvs/zapsum/lib/python3.4/site-packages/django/template/base.py", line 278, in parse
    compiled_result = compile_func(self, token)
  File "/home/kalinins/.virtualenvs/zapsum/lib/python3.4/site-packages/django/template/loader_tags.py", line 215, in do_extends
    nodelist = parser.parse()
  File "/home/kalinins/.virtualenvs/zapsum/lib/python3.4/site-packages/django/template/base.py", line 278, in parse
    compiled_result = compile_func(self, token)
  File "/home/kalinins/.virtualenvs/zapsum/lib/python3.4/site-packages/django/template/loader_tags.py", line 190, in do_block
    nodelist = parser.parse(('endblock',))
  File "/home/kalinins/.virtualenvs/zapsum/lib/python3.4/site-packages/django/template/base.py", line 276, in parse
    self.invalid_block_tag(token, command, parse_until)
  File "/home/kalinins/.virtualenvs/zapsum/lib/python3.4/site-packages/django/template/base.py", line 331, in invalid_block_tag
    (command, get_text_list(["'%s'" % p for p in parse_until])))
django.template.base.TemplateSyntaxError: Invalid block tag: 'part_pagination', expected 'endblock'
Internal Server Error: /new_authors/
Traceback (most recent call last):
  File "/home/kalinins/.virtualenvs/zapsum/lib/python3.4/site-packages/django/core/handlers/base.py", line 112, in get_response
    response = wrapped_callback(request, *callback_args, **callback_kwargs)
  File "/home/kalinins/.virtualenvs/zapsum/zapsum/app_zapsum/views.py", line 133, in new_authors
    new_authors = UserProfile.get_new_authors_entries()
AttributeError: type object 'UserProfile' has no attribute 'get_new_authors_entries'
Internal Server Error: /new_authors/
Traceback (most recent call last):
  File "/home/kalinins/.virtualenvs/zapsum/lib/python3.4/site-packages/django/core/handlers/base.py", line 112, in get_response
    response = wrapped_callback(request, *callback_args, **callback_kwargs)
  File "/home/kalinins/.virtualenvs/zapsum/zapsum/app_zapsum/views.py", line 171, in new_authors
    return HttpResponse(json.dumps(new_authors), content_type='application/json')
  File "/usr/lib/python3.4/json/__init__.py", line 230, in dumps
    return _default_encoder.encode(obj)
  File "/usr/lib/python3.4/json/encoder.py", line 192, in encode
    chunks = self.iterencode(o, _one_shot=True)
  File "/usr/lib/python3.4/json/encoder.py", line 250, in iterencode
    return _iterencode(o, 0)
  File "/usr/lib/python3.4/json/encoder.py", line 173, in default
    raise TypeError(repr(o) + " is not JSON serializable")
TypeError: [{'id': 2, 'username': 'qqqqqq'}, {'id': 3, 'username': 'aaaaaa'}] is not JSON serializable
Internal Server Error: /new_authors/
Traceback (most recent call last):
  File "/home/kalinins/.virtualenvs/zapsum/lib/python3.4/site-packages/django/core/handlers/base.py", line 112, in get_response
    response = wrapped_callback(request, *callback_args, **callback_kwargs)
  File "/home/kalinins/.virtualenvs/zapsum/zapsum/app_zapsum/views.py", line 171, in new_authors
    return HttpResponse(json.dumps(new_authors), content_type='application/json')
  File "/usr/lib/python3.4/json/__init__.py", line 230, in dumps
    return _default_encoder.encode(obj)
  File "/usr/lib/python3.4/json/encoder.py", line 192, in encode
    chunks = self.iterencode(o, _one_shot=True)
  File "/usr/lib/python3.4/json/encoder.py", line 250, in iterencode
    return _iterencode(o, 0)
  File "/usr/lib/python3.4/json/encoder.py", line 173, in default
    raise TypeError(repr(o) + " is not JSON serializable")
TypeError: [{'id': 4, 'username': 'zzzzzz'}, {'id': 5, 'username': 'wwwwww'}] is not JSON serializable
Internal Server Error: /new_authors/
Traceback (most recent call last):
  File "/home/kalinins/.virtualenvs/zapsum/lib/python3.4/site-packages/django/core/handlers/base.py", line 112, in get_response
    response = wrapped_callback(request, *callback_args, **callback_kwargs)
  File "/home/kalinins/.virtualenvs/zapsum/zapsum/app_zapsum/views.py", line 169, in new_authors
    result = serializers.serialize('json', new_authors)
  File "/home/kalinins/.virtualenvs/zapsum/lib/python3.4/site-packages/django/core/serializers/__init__.py", line 122, in serialize
    s.serialize(queryset, **options)
  File "/home/kalinins/.virtualenvs/zapsum/lib/python3.4/site-packages/django/core/serializers/base.py", line 45, in serialize
    concrete_model = obj._meta.concrete_model
AttributeError: 'dict' object has no attribute '_meta'
Forbidden (CSRF token missing or incorrect.): /new_authors/
Internal Server Error: /new_authors/
Traceback (most recent call last):
  File "/home/kalinins/.virtualenvs/zapsum/lib/python3.4/site-packages/django/db/models/options.py", line 371, in get_field_by_name
    return self._name_map[name]
KeyError: 'is_delete'

During handling of the above exception, another exception occurred:

Traceback (most recent call last):
  File "/home/kalinins/.virtualenvs/zapsum/lib/python3.4/site-packages/django/db/models/sql/query.py", line 1271, in names_to_path
    field, model, direct, m2m = opts.get_field_by_name(name)
  File "/home/kalinins/.virtualenvs/zapsum/lib/python3.4/site-packages/django/db/models/options.py", line 377, in get_field_by_name
    % (self.object_name, name))
django.db.models.fields.FieldDoesNotExist: UserProfile has no field named 'is_delete'

During handling of the above exception, another exception occurred:

Traceback (most recent call last):
  File "/home/kalinins/.virtualenvs/zapsum/lib/python3.4/site-packages/django/core/handlers/base.py", line 112, in get_response
    response = wrapped_callback(request, *callback_args, **callback_kwargs)
  File "/home/kalinins/.virtualenvs/zapsum/zapsum/app_zapsum/views.py", line 161, in new_authors
    count_new_authors = UserProfile.get_count_authors_entries()
  File "/home/kalinins/.virtualenvs/zapsum/zapsum/app_accounts/models.py", line 65, in get_count_authors_entries
    return self.objects.filter(is_active=1, is_delete=0, is_superuser=0).count()
  File "/home/kalinins/.virtualenvs/zapsum/lib/python3.4/site-packages/django/db/models/manager.py", line 163, in filter
    return self.get_queryset().filter(*args, **kwargs)
  File "/home/kalinins/.virtualenvs/zapsum/lib/python3.4/site-packages/django/db/models/query.py", line 593, in filter
    return self._filter_or_exclude(False, *args, **kwargs)
  File "/home/kalinins/.virtualenvs/zapsum/lib/python3.4/site-packages/django/db/models/query.py", line 611, in _filter_or_exclude
    clone.query.add_q(Q(*args, **kwargs))
  File "/home/kalinins/.virtualenvs/zapsum/lib/python3.4/site-packages/django/db/models/sql/query.py", line 1204, in add_q
    clause = self._add_q(where_part, used_aliases)
  File "/home/kalinins/.virtualenvs/zapsum/lib/python3.4/site-packages/django/db/models/sql/query.py", line 1240, in _add_q
    current_negated=current_negated)
  File "/home/kalinins/.virtualenvs/zapsum/lib/python3.4/site-packages/django/db/models/sql/query.py", line 1103, in build_filter
    allow_explicit_fk=True)
  File "/home/kalinins/.virtualenvs/zapsum/lib/python3.4/site-packages/django/db/models/sql/query.py", line 1363, in setup_joins
    names, opts, allow_many, allow_explicit_fk)
  File "/home/kalinins/.virtualenvs/zapsum/lib/python3.4/site-packages/django/db/models/sql/query.py", line 1283, in names_to_path
    "Choices are: %s" % (name, ", ".join(available)))
django.core.exceptions.FieldError: Cannot resolve keyword 'is_delete' into field. Choices are: avatar, date_joined, email, first_name, gender, groups, id, is_active, is_staff, is_superuser, last_login, last_name, logentry, nickname, other, password, phone, skype, user_permissions, user_ptr, username
Internal Server Error: /new_authors/
Traceback (most recent call last):
  File "/home/kalinins/.virtualenvs/zapsum/lib/python3.4/site-packages/django/db/models/options.py", line 371, in get_field_by_name
    return self._name_map[name]
KeyError: 'is_delete'

During handling of the above exception, another exception occurred:

Traceback (most recent call last):
  File "/home/kalinins/.virtualenvs/zapsum/lib/python3.4/site-packages/django/db/models/sql/query.py", line 1271, in names_to_path
    field, model, direct, m2m = opts.get_field_by_name(name)
  File "/home/kalinins/.virtualenvs/zapsum/lib/python3.4/site-packages/django/db/models/options.py", line 377, in get_field_by_name
    % (self.object_name, name))
django.db.models.fields.FieldDoesNotExist: UserProfile has no field named 'is_delete'

During handling of the above exception, another exception occurred:

Traceback (most recent call last):
  File "/home/kalinins/.virtualenvs/zapsum/lib/python3.4/site-packages/django/core/handlers/base.py", line 112, in get_response
    response = wrapped_callback(request, *callback_args, **callback_kwargs)
  File "/home/kalinins/.virtualenvs/zapsum/zapsum/app_zapsum/views.py", line 161, in new_authors
    count_new_authors = UserProfile.get_count_authors_entries()
  File "/home/kalinins/.virtualenvs/zapsum/zapsum/app_accounts/models.py", line 65, in get_count_authors_entries
    return self.objects.filter(is_active=1, is_delete=0, is_superuser=0).count()
  File "/home/kalinins/.virtualenvs/zapsum/lib/python3.4/site-packages/django/db/models/manager.py", line 163, in filter
    return self.get_queryset().filter(*args, **kwargs)
  File "/home/kalinins/.virtualenvs/zapsum/lib/python3.4/site-packages/django/db/models/query.py", line 593, in filter
    return self._filter_or_exclude(False, *args, **kwargs)
  File "/home/kalinins/.virtualenvs/zapsum/lib/python3.4/site-packages/django/db/models/query.py", line 611, in _filter_or_exclude
    clone.query.add_q(Q(*args, **kwargs))
  File "/home/kalinins/.virtualenvs/zapsum/lib/python3.4/site-packages/django/db/models/sql/query.py", line 1204, in add_q
    clause = self._add_q(where_part, used_aliases)
  File "/home/kalinins/.virtualenvs/zapsum/lib/python3.4/site-packages/django/db/models/sql/query.py", line 1240, in _add_q
    current_negated=current_negated)
  File "/home/kalinins/.virtualenvs/zapsum/lib/python3.4/site-packages/django/db/models/sql/query.py", line 1103, in build_filter
    allow_explicit_fk=True)
  File "/home/kalinins/.virtualenvs/zapsum/lib/python3.4/site-packages/django/db/models/sql/query.py", line 1363, in setup_joins
    names, opts, allow_many, allow_explicit_fk)
  File "/home/kalinins/.virtualenvs/zapsum/lib/python3.4/site-packages/django/db/models/sql/query.py", line 1283, in names_to_path
    "Choices are: %s" % (name, ", ".join(available)))
django.core.exceptions.FieldError: Cannot resolve keyword 'is_delete' into field. Choices are: avatar, date_joined, email, first_name, gender, groups, id, is_active, is_staff, is_superuser, last_login, last_name, logentry, nickname, other, password, phone, skype, user_permissions, user_ptr, username
Internal Server Error: /new_authors/
Traceback (most recent call last):
  File "/home/kalinins/.virtualenvs/zapsum/lib/python3.4/site-packages/django/db/models/options.py", line 371, in get_field_by_name
    return self._name_map[name]
KeyError: 'is_delete'

During handling of the above exception, another exception occurred:

Traceback (most recent call last):
  File "/home/kalinins/.virtualenvs/zapsum/lib/python3.4/site-packages/django/db/models/sql/query.py", line 1271, in names_to_path
    field, model, direct, m2m = opts.get_field_by_name(name)
  File "/home/kalinins/.virtualenvs/zapsum/lib/python3.4/site-packages/django/db/models/options.py", line 377, in get_field_by_name
    % (self.object_name, name))
django.db.models.fields.FieldDoesNotExist: UserProfile has no field named 'is_delete'

During handling of the above exception, another exception occurred:

Traceback (most recent call last):
  File "/home/kalinins/.virtualenvs/zapsum/lib/python3.4/site-packages/django/core/handlers/base.py", line 112, in get_response
    response = wrapped_callback(request, *callback_args, **callback_kwargs)
  File "/home/kalinins/.virtualenvs/zapsum/zapsum/app_zapsum/views.py", line 161, in new_authors
    count_new_authors = UserProfile.get_count_authors_entries()
  File "/home/kalinins/.virtualenvs/zapsum/zapsum/app_accounts/models.py", line 65, in get_count_authors_entries
    return self.objects.filter(is_active=1, is_delete=0, is_superuser=0).count()
  File "/home/kalinins/.virtualenvs/zapsum/lib/python3.4/site-packages/django/db/models/manager.py", line 163, in filter
    return self.get_queryset().filter(*args, **kwargs)
  File "/home/kalinins/.virtualenvs/zapsum/lib/python3.4/site-packages/django/db/models/query.py", line 593, in filter
    return self._filter_or_exclude(False, *args, **kwargs)
  File "/home/kalinins/.virtualenvs/zapsum/lib/python3.4/site-packages/django/db/models/query.py", line 611, in _filter_or_exclude
    clone.query.add_q(Q(*args, **kwargs))
  File "/home/kalinins/.virtualenvs/zapsum/lib/python3.4/site-packages/django/db/models/sql/query.py", line 1204, in add_q
    clause = self._add_q(where_part, used_aliases)
  File "/home/kalinins/.virtualenvs/zapsum/lib/python3.4/site-packages/django/db/models/sql/query.py", line 1240, in _add_q
    current_negated=current_negated)
  File "/home/kalinins/.virtualenvs/zapsum/lib/python3.4/site-packages/django/db/models/sql/query.py", line 1103, in build_filter
    allow_explicit_fk=True)
  File "/home/kalinins/.virtualenvs/zapsum/lib/python3.4/site-packages/django/db/models/sql/query.py", line 1363, in setup_joins
    names, opts, allow_many, allow_explicit_fk)
  File "/home/kalinins/.virtualenvs/zapsum/lib/python3.4/site-packages/django/db/models/sql/query.py", line 1283, in names_to_path
    "Choices are: %s" % (name, ", ".join(available)))
django.core.exceptions.FieldError: Cannot resolve keyword 'is_delete' into field. Choices are: avatar, date_joined, email, first_name, gender, groups, id, is_active, is_staff, is_superuser, last_login, last_name, logentry, nickname, other, password, phone, skype, user_permissions, user_ptr, username
Internal Server Error: /new_authors/
Traceback (most recent call last):
  File "/home/kalinins/.virtualenvs/zapsum/lib/python3.4/site-packages/django/db/models/options.py", line 371, in get_field_by_name
    return self._name_map[name]
KeyError: 'is_delete'

During handling of the above exception, another exception occurred:

Traceback (most recent call last):
  File "/home/kalinins/.virtualenvs/zapsum/lib/python3.4/site-packages/django/db/models/sql/query.py", line 1271, in names_to_path
    field, model, direct, m2m = opts.get_field_by_name(name)
  File "/home/kalinins/.virtualenvs/zapsum/lib/python3.4/site-packages/django/db/models/options.py", line 377, in get_field_by_name
    % (self.object_name, name))
django.db.models.fields.FieldDoesNotExist: UserProfile has no field named 'is_delete'

During handling of the above exception, another exception occurred:

Traceback (most recent call last):
  File "/home/kalinins/.virtualenvs/zapsum/lib/python3.4/site-packages/django/core/handlers/base.py", line 112, in get_response
    response = wrapped_callback(request, *callback_args, **callback_kwargs)
  File "/home/kalinins/.virtualenvs/zapsum/zapsum/app_zapsum/views.py", line 161, in new_authors
    count_new_authors = UserProfile.get_count_authors_entries()
  File "/home/kalinins/.virtualenvs/zapsum/zapsum/app_accounts/models.py", line 65, in get_count_authors_entries
    return self.objects.filter(is_active=1, is_delete=0, is_superuser=0).count()
  File "/home/kalinins/.virtualenvs/zapsum/lib/python3.4/site-packages/django/db/models/manager.py", line 163, in filter
    return self.get_queryset().filter(*args, **kwargs)
  File "/home/kalinins/.virtualenvs/zapsum/lib/python3.4/site-packages/django/db/models/query.py", line 593, in filter
    return self._filter_or_exclude(False, *args, **kwargs)
  File "/home/kalinins/.virtualenvs/zapsum/lib/python3.4/site-packages/django/db/models/query.py", line 611, in _filter_or_exclude
    clone.query.add_q(Q(*args, **kwargs))
  File "/home/kalinins/.virtualenvs/zapsum/lib/python3.4/site-packages/django/db/models/sql/query.py", line 1204, in add_q
    clause = self._add_q(where_part, used_aliases)
  File "/home/kalinins/.virtualenvs/zapsum/lib/python3.4/site-packages/django/db/models/sql/query.py", line 1240, in _add_q
    current_negated=current_negated)
  File "/home/kalinins/.virtualenvs/zapsum/lib/python3.4/site-packages/django/db/models/sql/query.py", line 1103, in build_filter
    allow_explicit_fk=True)
  File "/home/kalinins/.virtualenvs/zapsum/lib/python3.4/site-packages/django/db/models/sql/query.py", line 1363, in setup_joins
    names, opts, allow_many, allow_explicit_fk)
  File "/home/kalinins/.virtualenvs/zapsum/lib/python3.4/site-packages/django/db/models/sql/query.py", line 1283, in names_to_path
    "Choices are: %s" % (name, ", ".join(available)))
django.core.exceptions.FieldError: Cannot resolve keyword 'is_delete' into field. Choices are: avatar, date_joined, email, first_name, gender, groups, id, is_active, is_staff, is_superuser, last_login, last_name, logentry, nickname, other, password, phone, skype, user_permissions, user_ptr, username
Internal Server Error: /new_authors/
Traceback (most recent call last):
  File "/home/kalinins/.virtualenvs/zapsum/lib/python3.4/site-packages/django/db/models/options.py", line 371, in get_field_by_name
    return self._name_map[name]
KeyError: 'is_delete'

During handling of the above exception, another exception occurred:

Traceback (most recent call last):
  File "/home/kalinins/.virtualenvs/zapsum/lib/python3.4/site-packages/django/db/models/sql/query.py", line 1271, in names_to_path
    field, model, direct, m2m = opts.get_field_by_name(name)
  File "/home/kalinins/.virtualenvs/zapsum/lib/python3.4/site-packages/django/db/models/options.py", line 377, in get_field_by_name
    % (self.object_name, name))
django.db.models.fields.FieldDoesNotExist: UserProfile has no field named 'is_delete'

During handling of the above exception, another exception occurred:

Traceback (most recent call last):
  File "/home/kalinins/.virtualenvs/zapsum/lib/python3.4/site-packages/django/core/handlers/base.py", line 112, in get_response
    response = wrapped_callback(request, *callback_args, **callback_kwargs)
  File "/home/kalinins/.virtualenvs/zapsum/zapsum/app_zapsum/views.py", line 161, in new_authors
    count_new_authors = UserProfile.get_count_authors_entries()
  File "/home/kalinins/.virtualenvs/zapsum/zapsum/app_accounts/models.py", line 65, in get_count_authors_entries
    return self.objects.filter(is_active=1, is_delete=0, is_superuser=0).count()
  File "/home/kalinins/.virtualenvs/zapsum/lib/python3.4/site-packages/django/db/models/manager.py", line 163, in filter
    return self.get_queryset().filter(*args, **kwargs)
  File "/home/kalinins/.virtualenvs/zapsum/lib/python3.4/site-packages/django/db/models/query.py", line 593, in filter
    return self._filter_or_exclude(False, *args, **kwargs)
  File "/home/kalinins/.virtualenvs/zapsum/lib/python3.4/site-packages/django/db/models/query.py", line 611, in _filter_or_exclude
    clone.query.add_q(Q(*args, **kwargs))
  File "/home/kalinins/.virtualenvs/zapsum/lib/python3.4/site-packages/django/db/models/sql/query.py", line 1204, in add_q
    clause = self._add_q(where_part, used_aliases)
  File "/home/kalinins/.virtualenvs/zapsum/lib/python3.4/site-packages/django/db/models/sql/query.py", line 1240, in _add_q
    current_negated=current_negated)
  File "/home/kalinins/.virtualenvs/zapsum/lib/python3.4/site-packages/django/db/models/sql/query.py", line 1103, in build_filter
    allow_explicit_fk=True)
  File "/home/kalinins/.virtualenvs/zapsum/lib/python3.4/site-packages/django/db/models/sql/query.py", line 1363, in setup_joins
    names, opts, allow_many, allow_explicit_fk)
  File "/home/kalinins/.virtualenvs/zapsum/lib/python3.4/site-packages/django/db/models/sql/query.py", line 1283, in names_to_path
    "Choices are: %s" % (name, ", ".join(available)))
django.core.exceptions.FieldError: Cannot resolve keyword 'is_delete' into field. Choices are: avatar, date_joined, email, first_name, gender, groups, id, is_active, is_staff, is_superuser, last_login, last_name, logentry, nickname, other, password, phone, skype, user_permissions, user_ptr, username
Internal Server Error: /new_authors/
Traceback (most recent call last):
  File "/home/kalinins/.virtualenvs/zapsum/lib/python3.4/site-packages/django/db/models/options.py", line 371, in get_field_by_name
    return self._name_map[name]
KeyError: 'is_delete'

During handling of the above exception, another exception occurred:

Traceback (most recent call last):
  File "/home/kalinins/.virtualenvs/zapsum/lib/python3.4/site-packages/django/db/models/sql/query.py", line 1271, in names_to_path
    field, model, direct, m2m = opts.get_field_by_name(name)
  File "/home/kalinins/.virtualenvs/zapsum/lib/python3.4/site-packages/django/db/models/options.py", line 377, in get_field_by_name
    % (self.object_name, name))
django.db.models.fields.FieldDoesNotExist: UserProfile has no field named 'is_delete'

During handling of the above exception, another exception occurred:

Traceback (most recent call last):
  File "/home/kalinins/.virtualenvs/zapsum/lib/python3.4/site-packages/django/core/handlers/base.py", line 112, in get_response
    response = wrapped_callback(request, *callback_args, **callback_kwargs)
  File "/home/kalinins/.virtualenvs/zapsum/zapsum/app_zapsum/views.py", line 161, in new_authors
    count_new_authors = UserProfile.get_count_authors_entries()
  File "/home/kalinins/.virtualenvs/zapsum/zapsum/app_accounts/models.py", line 65, in get_count_authors_entries
    return self.objects.filter(is_active=1, is_delete=0, is_superuser=0).count()
  File "/home/kalinins/.virtualenvs/zapsum/lib/python3.4/site-packages/django/db/models/manager.py", line 163, in filter
    return self.get_queryset().filter(*args, **kwargs)
  File "/home/kalinins/.virtualenvs/zapsum/lib/python3.4/site-packages/django/db/models/query.py", line 593, in filter
    return self._filter_or_exclude(False, *args, **kwargs)
  File "/home/kalinins/.virtualenvs/zapsum/lib/python3.4/site-packages/django/db/models/query.py", line 611, in _filter_or_exclude
    clone.query.add_q(Q(*args, **kwargs))
  File "/home/kalinins/.virtualenvs/zapsum/lib/python3.4/site-packages/django/db/models/sql/query.py", line 1204, in add_q
    clause = self._add_q(where_part, used_aliases)
  File "/home/kalinins/.virtualenvs/zapsum/lib/python3.4/site-packages/django/db/models/sql/query.py", line 1240, in _add_q
    current_negated=current_negated)
  File "/home/kalinins/.virtualenvs/zapsum/lib/python3.4/site-packages/django/db/models/sql/query.py", line 1103, in build_filter
    allow_explicit_fk=True)
  File "/home/kalinins/.virtualenvs/zapsum/lib/python3.4/site-packages/django/db/models/sql/query.py", line 1363, in setup_joins
    names, opts, allow_many, allow_explicit_fk)
  File "/home/kalinins/.virtualenvs/zapsum/lib/python3.4/site-packages/django/db/models/sql/query.py", line 1283, in names_to_path
    "Choices are: %s" % (name, ", ".join(available)))
django.core.exceptions.FieldError: Cannot resolve keyword 'is_delete' into field. Choices are: avatar, date_joined, email, first_name, gender, groups, id, is_active, is_staff, is_superuser, last_login, last_name, logentry, nickname, other, password, phone, skype, user_permissions, user_ptr, username
Forbidden (CSRF token missing or incorrect.): /new_authors/
Forbidden (CSRF token missing or incorrect.): /new_authors/
Forbidden (CSRF token missing or incorrect.): /new_authors/
Forbidden (CSRF token missing or incorrect.): /new_authors/
Forbidden (CSRF token missing or incorrect.): /new_authors/
Forbidden (CSRF token missing or incorrect.): /new_authors/
Not Found: /new_authors/4
Internal Server Error: /new_authors/
Traceback (most recent call last):
  File "/home/kalinins/.virtualenvs/zapsum/lib/python3.4/site-packages/django/core/handlers/base.py", line 112, in get_response
    response = wrapped_callback(request, *callback_args, **callback_kwargs)
  File "/home/kalinins/.virtualenvs/zapsum/zapsum/app_zapsum/views.py", line 175, in new_authors
    t = loader.get_template('page_new_authors.html')
  File "/home/kalinins/.virtualenvs/zapsum/lib/python3.4/site-packages/django/template/loader.py", line 138, in get_template
    template, origin = find_template(template_name)
  File "/home/kalinins/.virtualenvs/zapsum/lib/python3.4/site-packages/django/template/loader.py", line 127, in find_template
    source, display_name = loader(name, dirs)
  File "/home/kalinins/.virtualenvs/zapsum/lib/python3.4/site-packages/django/template/loader.py", line 43, in __call__
    return self.load_template(template_name, template_dirs)
  File "/home/kalinins/.virtualenvs/zapsum/lib/python3.4/site-packages/django/template/loader.py", line 49, in load_template
    template = get_template_from_string(source, origin, template_name)
  File "/home/kalinins/.virtualenvs/zapsum/lib/python3.4/site-packages/django/template/loader.py", line 149, in get_template_from_string
    return Template(source, origin, name)
  File "/home/kalinins/.virtualenvs/zapsum/lib/python3.4/site-packages/django/template/base.py", line 125, in __init__
    self.nodelist = compile_string(template_string, origin)
  File "/home/kalinins/.virtualenvs/zapsum/lib/python3.4/site-packages/django/template/base.py", line 153, in compile_string
    return parser.parse()
  File "/home/kalinins/.virtualenvs/zapsum/lib/python3.4/site-packages/django/template/base.py", line 278, in parse
    compiled_result = compile_func(self, token)
  File "/home/kalinins/.virtualenvs/zapsum/lib/python3.4/site-packages/django/template/loader_tags.py", line 215, in do_extends
    nodelist = parser.parse()
  File "/home/kalinins/.virtualenvs/zapsum/lib/python3.4/site-packages/django/template/base.py", line 278, in parse
    compiled_result = compile_func(self, token)
  File "/home/kalinins/.virtualenvs/zapsum/lib/python3.4/site-packages/django/template/loader_tags.py", line 190, in do_block
    nodelist = parser.parse(('endblock',))
  File "/home/kalinins/.virtualenvs/zapsum/lib/python3.4/site-packages/django/template/base.py", line 278, in parse
    compiled_result = compile_func(self, token)
  File "/home/kalinins/.virtualenvs/zapsum/lib/python3.4/site-packages/django/template/defaulttags.py", line 806, in do_for
    nodelist_loop = parser.parse(('empty', 'endfor',))
  File "/home/kalinins/.virtualenvs/zapsum/lib/python3.4/site-packages/django/template/base.py", line 254, in parse
    filter_expression = self.compile_filter(token.contents)
  File "/home/kalinins/.virtualenvs/zapsum/lib/python3.4/site-packages/django/template/base.py", line 360, in compile_filter
    return FilterExpression(token, self)
  File "/home/kalinins/.virtualenvs/zapsum/lib/python3.4/site-packages/django/template/base.py", line 577, in __init__
    "from '%s'" % (token[upto:], token))
django.template.base.TemplateSyntaxError: Could not parse the remainder: '/profile/entry.id/' from '/profile/entry.id/'
Internal Server Error: /new_authors/
Traceback (most recent call last):
  File "/home/kalinins/.virtualenvs/zapsum/lib/python3.4/site-packages/django/core/handlers/base.py", line 112, in get_response
    response = wrapped_callback(request, *callback_args, **callback_kwargs)
  File "/home/kalinins/.virtualenvs/zapsum/zapsum/app_zapsum/views.py", line 175, in new_authors
    t = loader.get_template('page_new_authors.html')
  File "/home/kalinins/.virtualenvs/zapsum/lib/python3.4/site-packages/django/template/loader.py", line 138, in get_template
    template, origin = find_template(template_name)
  File "/home/kalinins/.virtualenvs/zapsum/lib/python3.4/site-packages/django/template/loader.py", line 127, in find_template
    source, display_name = loader(name, dirs)
  File "/home/kalinins/.virtualenvs/zapsum/lib/python3.4/site-packages/django/template/loader.py", line 43, in __call__
    return self.load_template(template_name, template_dirs)
  File "/home/kalinins/.virtualenvs/zapsum/lib/python3.4/site-packages/django/template/loader.py", line 49, in load_template
    template = get_template_from_string(source, origin, template_name)
  File "/home/kalinins/.virtualenvs/zapsum/lib/python3.4/site-packages/django/template/loader.py", line 149, in get_template_from_string
    return Template(source, origin, name)
  File "/home/kalinins/.virtualenvs/zapsum/lib/python3.4/site-packages/django/template/base.py", line 125, in __init__
    self.nodelist = compile_string(template_string, origin)
  File "/home/kalinins/.virtualenvs/zapsum/lib/python3.4/site-packages/django/template/base.py", line 153, in compile_string
    return parser.parse()
  File "/home/kalinins/.virtualenvs/zapsum/lib/python3.4/site-packages/django/template/base.py", line 278, in parse
    compiled_result = compile_func(self, token)
  File "/home/kalinins/.virtualenvs/zapsum/lib/python3.4/site-packages/django/template/loader_tags.py", line 215, in do_extends
    nodelist = parser.parse()
  File "/home/kalinins/.virtualenvs/zapsum/lib/python3.4/site-packages/django/template/base.py", line 278, in parse
    compiled_result = compile_func(self, token)
  File "/home/kalinins/.virtualenvs/zapsum/lib/python3.4/site-packages/django/template/loader_tags.py", line 190, in do_block
    nodelist = parser.parse(('endblock',))
  File "/home/kalinins/.virtualenvs/zapsum/lib/python3.4/site-packages/django/template/base.py", line 278, in parse
    compiled_result = compile_func(self, token)
  File "/home/kalinins/.virtualenvs/zapsum/lib/python3.4/site-packages/django/template/defaulttags.py", line 806, in do_for
    nodelist_loop = parser.parse(('empty', 'endfor',))
  File "/home/kalinins/.virtualenvs/zapsum/lib/python3.4/site-packages/django/template/base.py", line 254, in parse
    filter_expression = self.compile_filter(token.contents)
  File "/home/kalinins/.virtualenvs/zapsum/lib/python3.4/site-packages/django/template/base.py", line 360, in compile_filter
    return FilterExpression(token, self)
  File "/home/kalinins/.virtualenvs/zapsum/lib/python3.4/site-packages/django/template/base.py", line 577, in __init__
    "from '%s'" % (token[upto:], token))
django.template.base.TemplateSyntaxError: Could not parse the remainder: '/' from 'entry.id/'
Internal Server Error: /new_authors/
Traceback (most recent call last):
  File "/home/kalinins/.virtualenvs/zapsum/lib/python3.4/site-packages/django/core/handlers/base.py", line 112, in get_response
    response = wrapped_callback(request, *callback_args, **callback_kwargs)
  File "/home/kalinins/.virtualenvs/zapsum/zapsum/app_zapsum/views.py", line 175, in new_authors
    t = loader.get_template('page_new_authors.html')
  File "/home/kalinins/.virtualenvs/zapsum/lib/python3.4/site-packages/django/template/loader.py", line 138, in get_template
    template, origin = find_template(template_name)
  File "/home/kalinins/.virtualenvs/zapsum/lib/python3.4/site-packages/django/template/loader.py", line 127, in find_template
    source, display_name = loader(name, dirs)
  File "/home/kalinins/.virtualenvs/zapsum/lib/python3.4/site-packages/django/template/loader.py", line 43, in __call__
    return self.load_template(template_name, template_dirs)
  File "/home/kalinins/.virtualenvs/zapsum/lib/python3.4/site-packages/django/template/loader.py", line 49, in load_template
    template = get_template_from_string(source, origin, template_name)
  File "/home/kalinins/.virtualenvs/zapsum/lib/python3.4/site-packages/django/template/loader.py", line 149, in get_template_from_string
    return Template(source, origin, name)
  File "/home/kalinins/.virtualenvs/zapsum/lib/python3.4/site-packages/django/template/base.py", line 125, in __init__
    self.nodelist = compile_string(template_string, origin)
  File "/home/kalinins/.virtualenvs/zapsum/lib/python3.4/site-packages/django/template/base.py", line 153, in compile_string
    return parser.parse()
  File "/home/kalinins/.virtualenvs/zapsum/lib/python3.4/site-packages/django/template/base.py", line 278, in parse
    compiled_result = compile_func(self, token)
  File "/home/kalinins/.virtualenvs/zapsum/lib/python3.4/site-packages/django/template/loader_tags.py", line 215, in do_extends
    nodelist = parser.parse()
  File "/home/kalinins/.virtualenvs/zapsum/lib/python3.4/site-packages/django/template/base.py", line 278, in parse
    compiled_result = compile_func(self, token)
  File "/home/kalinins/.virtualenvs/zapsum/lib/python3.4/site-packages/django/template/loader_tags.py", line 190, in do_block
    nodelist = parser.parse(('endblock',))
  File "/home/kalinins/.virtualenvs/zapsum/lib/python3.4/site-packages/django/template/base.py", line 278, in parse
    compiled_result = compile_func(self, token)
  File "/home/kalinins/.virtualenvs/zapsum/lib/python3.4/site-packages/django/template/defaulttags.py", line 806, in do_for
    nodelist_loop = parser.parse(('empty', 'endfor',))
  File "/home/kalinins/.virtualenvs/zapsum/lib/python3.4/site-packages/django/template/base.py", line 254, in parse
    filter_expression = self.compile_filter(token.contents)
  File "/home/kalinins/.virtualenvs/zapsum/lib/python3.4/site-packages/django/template/base.py", line 360, in compile_filter
    return FilterExpression(token, self)
  File "/home/kalinins/.virtualenvs/zapsum/lib/python3.4/site-packages/django/template/base.py", line 577, in __init__
    "from '%s'" % (token[upto:], token))
django.template.base.TemplateSyntaxError: Could not parse the remainder: '/' from 'entry.id/'
Internal Server Error: /new_authors/
Traceback (most recent call last):
  File "/home/kalinins/.virtualenvs/zapsum/lib/python3.4/site-packages/django/core/handlers/base.py", line 112, in get_response
    response = wrapped_callback(request, *callback_args, **callback_kwargs)
  File "/home/kalinins/.virtualenvs/zapsum/zapsum/app_zapsum/views.py", line 175, in new_authors
    t = loader.get_template('page_new_authors.html')
  File "/home/kalinins/.virtualenvs/zapsum/lib/python3.4/site-packages/django/template/loader.py", line 138, in get_template
    template, origin = find_template(template_name)
  File "/home/kalinins/.virtualenvs/zapsum/lib/python3.4/site-packages/django/template/loader.py", line 127, in find_template
    source, display_name = loader(name, dirs)
  File "/home/kalinins/.virtualenvs/zapsum/lib/python3.4/site-packages/django/template/loader.py", line 43, in __call__
    return self.load_template(template_name, template_dirs)
  File "/home/kalinins/.virtualenvs/zapsum/lib/python3.4/site-packages/django/template/loader.py", line 49, in load_template
    template = get_template_from_string(source, origin, template_name)
  File "/home/kalinins/.virtualenvs/zapsum/lib/python3.4/site-packages/django/template/loader.py", line 149, in get_template_from_string
    return Template(source, origin, name)
  File "/home/kalinins/.virtualenvs/zapsum/lib/python3.4/site-packages/django/template/base.py", line 125, in __init__
    self.nodelist = compile_string(template_string, origin)
  File "/home/kalinins/.virtualenvs/zapsum/lib/python3.4/site-packages/django/template/base.py", line 153, in compile_string
    return parser.parse()
  File "/home/kalinins/.virtualenvs/zapsum/lib/python3.4/site-packages/django/template/base.py", line 278, in parse
    compiled_result = compile_func(self, token)
  File "/home/kalinins/.virtualenvs/zapsum/lib/python3.4/site-packages/django/template/loader_tags.py", line 215, in do_extends
    nodelist = parser.parse()
  File "/home/kalinins/.virtualenvs/zapsum/lib/python3.4/site-packages/django/template/base.py", line 278, in parse
    compiled_result = compile_func(self, token)
  File "/home/kalinins/.virtualenvs/zapsum/lib/python3.4/site-packages/django/template/loader_tags.py", line 190, in do_block
    nodelist = parser.parse(('endblock',))
  File "/home/kalinins/.virtualenvs/zapsum/lib/python3.4/site-packages/django/template/base.py", line 278, in parse
    compiled_result = compile_func(self, token)
  File "/home/kalinins/.virtualenvs/zapsum/lib/python3.4/site-packages/django/template/defaulttags.py", line 806, in do_for
    nodelist_loop = parser.parse(('empty', 'endfor',))
  File "/home/kalinins/.virtualenvs/zapsum/lib/python3.4/site-packages/django/template/base.py", line 254, in parse
    filter_expression = self.compile_filter(token.contents)
  File "/home/kalinins/.virtualenvs/zapsum/lib/python3.4/site-packages/django/template/base.py", line 360, in compile_filter
    return FilterExpression(token, self)
  File "/home/kalinins/.virtualenvs/zapsum/lib/python3.4/site-packages/django/template/base.py", line 577, in __init__
    "from '%s'" % (token[upto:], token))
django.template.base.TemplateSyntaxError: Could not parse the remainder: '/' from 'entry.id/'
Internal Server Error: /new_authors/
Traceback (most recent call last):
  File "/home/kalinins/.virtualenvs/zapsum/lib/python3.4/site-packages/django/core/handlers/base.py", line 112, in get_response
    response = wrapped_callback(request, *callback_args, **callback_kwargs)
  File "/home/kalinins/.virtualenvs/zapsum/zapsum/app_zapsum/views.py", line 175, in new_authors
    t = loader.get_template('page_new_authors.html')
  File "/home/kalinins/.virtualenvs/zapsum/lib/python3.4/site-packages/django/template/loader.py", line 138, in get_template
    template, origin = find_template(template_name)
  File "/home/kalinins/.virtualenvs/zapsum/lib/python3.4/site-packages/django/template/loader.py", line 127, in find_template
    source, display_name = loader(name, dirs)
  File "/home/kalinins/.virtualenvs/zapsum/lib/python3.4/site-packages/django/template/loader.py", line 43, in __call__
    return self.load_template(template_name, template_dirs)
  File "/home/kalinins/.virtualenvs/zapsum/lib/python3.4/site-packages/django/template/loader.py", line 49, in load_template
    template = get_template_from_string(source, origin, template_name)
  File "/home/kalinins/.virtualenvs/zapsum/lib/python3.4/site-packages/django/template/loader.py", line 149, in get_template_from_string
    return Template(source, origin, name)
  File "/home/kalinins/.virtualenvs/zapsum/lib/python3.4/site-packages/django/template/base.py", line 125, in __init__
    self.nodelist = compile_string(template_string, origin)
  File "/home/kalinins/.virtualenvs/zapsum/lib/python3.4/site-packages/django/template/base.py", line 153, in compile_string
    return parser.parse()
  File "/home/kalinins/.virtualenvs/zapsum/lib/python3.4/site-packages/django/template/base.py", line 278, in parse
    compiled_result = compile_func(self, token)
  File "/home/kalinins/.virtualenvs/zapsum/lib/python3.4/site-packages/django/template/loader_tags.py", line 215, in do_extends
    nodelist = parser.parse()
  File "/home/kalinins/.virtualenvs/zapsum/lib/python3.4/site-packages/django/template/base.py", line 278, in parse
    compiled_result = compile_func(self, token)
  File "/home/kalinins/.virtualenvs/zapsum/lib/python3.4/site-packages/django/template/loader_tags.py", line 190, in do_block
    nodelist = parser.parse(('endblock',))
  File "/home/kalinins/.virtualenvs/zapsum/lib/python3.4/site-packages/django/template/base.py", line 278, in parse
    compiled_result = compile_func(self, token)
  File "/home/kalinins/.virtualenvs/zapsum/lib/python3.4/site-packages/django/template/defaulttags.py", line 806, in do_for
    nodelist_loop = parser.parse(('empty', 'endfor',))
  File "/home/kalinins/.virtualenvs/zapsum/lib/python3.4/site-packages/django/template/base.py", line 254, in parse
    filter_expression = self.compile_filter(token.contents)
  File "/home/kalinins/.virtualenvs/zapsum/lib/python3.4/site-packages/django/template/base.py", line 360, in compile_filter
    return FilterExpression(token, self)
  File "/home/kalinins/.virtualenvs/zapsum/lib/python3.4/site-packages/django/template/base.py", line 577, in __init__
    "from '%s'" % (token[upto:], token))
django.template.base.TemplateSyntaxError: Could not parse the remainder: '/' from 'entry.id/'
Internal Server Error: /new_authors/
Traceback (most recent call last):
  File "/home/kalinins/.virtualenvs/zapsum/lib/python3.4/site-packages/django/core/handlers/base.py", line 112, in get_response
    response = wrapped_callback(request, *callback_args, **callback_kwargs)
  File "/home/kalinins/.virtualenvs/zapsum/zapsum/app_zapsum/views.py", line 175, in new_authors
    t = loader.get_template('page_new_authors.html')
  File "/home/kalinins/.virtualenvs/zapsum/lib/python3.4/site-packages/django/template/loader.py", line 138, in get_template
    template, origin = find_template(template_name)
  File "/home/kalinins/.virtualenvs/zapsum/lib/python3.4/site-packages/django/template/loader.py", line 127, in find_template
    source, display_name = loader(name, dirs)
  File "/home/kalinins/.virtualenvs/zapsum/lib/python3.4/site-packages/django/template/loader.py", line 43, in __call__
    return self.load_template(template_name, template_dirs)
  File "/home/kalinins/.virtualenvs/zapsum/lib/python3.4/site-packages/django/template/loader.py", line 49, in load_template
    template = get_template_from_string(source, origin, template_name)
  File "/home/kalinins/.virtualenvs/zapsum/lib/python3.4/site-packages/django/template/loader.py", line 149, in get_template_from_string
    return Template(source, origin, name)
  File "/home/kalinins/.virtualenvs/zapsum/lib/python3.4/site-packages/django/template/base.py", line 125, in __init__
    self.nodelist = compile_string(template_string, origin)
  File "/home/kalinins/.virtualenvs/zapsum/lib/python3.4/site-packages/django/template/base.py", line 153, in compile_string
    return parser.parse()
  File "/home/kalinins/.virtualenvs/zapsum/lib/python3.4/site-packages/django/template/base.py", line 278, in parse
    compiled_result = compile_func(self, token)
  File "/home/kalinins/.virtualenvs/zapsum/lib/python3.4/site-packages/django/template/loader_tags.py", line 215, in do_extends
    nodelist = parser.parse()
  File "/home/kalinins/.virtualenvs/zapsum/lib/python3.4/site-packages/django/template/base.py", line 278, in parse
    compiled_result = compile_func(self, token)
  File "/home/kalinins/.virtualenvs/zapsum/lib/python3.4/site-packages/django/template/loader_tags.py", line 190, in do_block
    nodelist = parser.parse(('endblock',))
  File "/home/kalinins/.virtualenvs/zapsum/lib/python3.4/site-packages/django/template/base.py", line 278, in parse
    compiled_result = compile_func(self, token)
  File "/home/kalinins/.virtualenvs/zapsum/lib/python3.4/site-packages/django/template/defaulttags.py", line 806, in do_for
    nodelist_loop = parser.parse(('empty', 'endfor',))
  File "/home/kalinins/.virtualenvs/zapsum/lib/python3.4/site-packages/django/template/base.py", line 254, in parse
    filter_expression = self.compile_filter(token.contents)
  File "/home/kalinins/.virtualenvs/zapsum/lib/python3.4/site-packages/django/template/base.py", line 360, in compile_filter
    return FilterExpression(token, self)
  File "/home/kalinins/.virtualenvs/zapsum/lib/python3.4/site-packages/django/template/base.py", line 577, in __init__
    "from '%s'" % (token[upto:], token))
django.template.base.TemplateSyntaxError: Could not parse the remainder: '/' from 'entry.id/'
Forbidden (CSRF token missing or incorrect.): /new_authors/
Forbidden (CSRF token missing or incorrect.): /new_authors/
Forbidden (CSRF token missing or incorrect.): /new_authors/
Forbidden (CSRF token missing or incorrect.): /new_authors/
Forbidden (CSRF token missing or incorrect.): /new_authors/
Forbidden (CSRF token missing or incorrect.): /new_authors/
Forbidden (CSRF token missing or incorrect.): /new_authors/
Forbidden (CSRF token missing or incorrect.): /new_authors/
Forbidden (CSRF token missing or incorrect.): /new_authors/
Forbidden (CSRF token missing or incorrect.): /new_authors/
Forbidden (CSRF token missing or incorrect.): /new_authors/
Forbidden (CSRF token missing or incorrect.): /new_authors/
Forbidden (CSRF token missing or incorrect.): /new_authors/
Forbidden (CSRF token missing or incorrect.): /new_authors/
Forbidden (CSRF token missing or incorrect.): /new_authors/
Forbidden (CSRF token missing or incorrect.): /new_authors/
Internal Server Error: /search_record/
Traceback (most recent call last):
  File "/home/kalinins/.virtualenvs/zapsum/lib/python3.4/site-packages/django/core/handlers/base.py", line 112, in get_response
    response = wrapped_callback(request, *callback_args, **callback_kwargs)
  File "/home/kalinins/.virtualenvs/zapsum/zapsum/app_zapsum/views.py", line 116, in search_record
    return HttpResponse(json.dumps(record_list), content_type='application/json')
  File "/usr/lib/python3.4/json/__init__.py", line 230, in dumps
    return _default_encoder.encode(obj)
  File "/usr/lib/python3.4/json/encoder.py", line 192, in encode
    chunks = self.iterencode(o, _one_shot=True)
  File "/usr/lib/python3.4/json/encoder.py", line 250, in iterencode
    return _iterencode(o, 0)
  File "/usr/lib/python3.4/json/encoder.py", line 173, in default
    raise TypeError(repr(o) + " is not JSON serializable")
TypeError: [<Diary: Diary object>, <Diary: Diary object>, <Diary: Diary object>, <Diary: Diary object>, <Diary: Diary object>, <Diary: Diary object>, <Diary: Diary object>, <Diary: Diary object>, <Diary: Diary object>, <Diary: Diary object>, <Diary: Diary object>] is not JSON serializable
Internal Server Error: /search_record/
Traceback (most recent call last):
  File "/home/kalinins/.virtualenvs/zapsum/lib/python3.4/site-packages/django/core/handlers/base.py", line 112, in get_response
    response = wrapped_callback(request, *callback_args, **callback_kwargs)
  File "/home/kalinins/.virtualenvs/zapsum/zapsum/app_zapsum/views.py", line 117, in search_record
    print(rec.title)
AttributeError: 'dict' object has no attribute 'title'
Internal Server Error: /search_record/
Traceback (most recent call last):
  File "/home/kalinins/.virtualenvs/zapsum/lib/python3.4/site-packages/django/core/handlers/base.py", line 112, in get_response
    response = wrapped_callback(request, *callback_args, **callback_kwargs)
  File "/home/kalinins/.virtualenvs/zapsum/zapsum/app_zapsum/views.py", line 117, in search_record
    print(rec.title)
AttributeError: 'dict' object has no attribute 'title'
Internal Server Error: /search_record/
Traceback (most recent call last):
  File "/home/kalinins/.virtualenvs/zapsum/lib/python3.4/site-packages/django/core/handlers/base.py", line 112, in get_response
    response = wrapped_callback(request, *callback_args, **callback_kwargs)
  File "/home/kalinins/.virtualenvs/zapsum/zapsum/app_zapsum/views.py", line 117, in search_record
    print(rec.title)
AttributeError: 'dict' object has no attribute 'title'
Internal Server Error: /search_record/
Traceback (most recent call last):
  File "/home/kalinins/.virtualenvs/zapsum/lib/python3.4/site-packages/django/core/handlers/base.py", line 112, in get_response
    response = wrapped_callback(request, *callback_args, **callback_kwargs)
  File "/home/kalinins/.virtualenvs/zapsum/zapsum/app_zapsum/views.py", line 117, in search_record
    print(rec.id)
AttributeError: 'dict' object has no attribute 'id'
Internal Server Error: /profile/1/
Traceback (most recent call last):
  File "/home/kalinins/.virtualenvs/zapsum/lib/python3.4/site-packages/django/core/handlers/base.py", line 112, in get_response
    response = wrapped_callback(request, *callback_args, **callback_kwargs)
  File "/home/kalinins/.virtualenvs/zapsum/zapsum/app_zapsum/views.py", line 90, in profile
    obj_author = UserProfile.get_entry(user_id=id_author)
  File "/home/kalinins/.virtualenvs/zapsum/zapsum/app_accounts/models.py", line 69, in get_entry
    result = UserProfile.objects.get(user_ptr_id=user_id)
  File "/home/kalinins/.virtualenvs/zapsum/lib/python3.4/site-packages/django/db/models/manager.py", line 151, in get
    return self.get_queryset().get(*args, **kwargs)
  File "/home/kalinins/.virtualenvs/zapsum/lib/python3.4/site-packages/django/db/models/query.py", line 310, in get
    self.model._meta.object_name)
app_accounts.models.DoesNotExist: UserProfile matching query does not exist.
Not Found: /favicon.ico
Not Found: /record/3/2
Not Found: /author/2/
Internal Server Error: /record/3/
Traceback (most recent call last):
  File "/home/kalinins/.virtualenvs/zapsum/lib/python3.4/site-packages/django/core/handlers/base.py", line 112, in get_response
    response = wrapped_callback(request, *callback_args, **callback_kwargs)
  File "/home/kalinins/.virtualenvs/zapsum/zapsum/app_zapsum/views.py", line 47, in record
    nickname = UserProfile.get(id=request.user.pk).values('nickname')
AttributeError: type object 'UserProfile' has no attribute 'get'
Internal Server Error: /record/3/
Traceback (most recent call last):
  File "/home/kalinins/.virtualenvs/zapsum/lib/python3.4/site-packages/django/core/handlers/base.py", line 112, in get_response
    response = wrapped_callback(request, *callback_args, **callback_kwargs)
  File "/home/kalinins/.virtualenvs/zapsum/zapsum/app_zapsum/views.py", line 47, in record
    nickname = UserProfile.objects.get(id=request.user.pk).values('nickname')
AttributeError: 'UserProfile' object has no attribute 'values'
Internal Server Error: /record/3/
Traceback (most recent call last):
  File "/home/kalinins/.virtualenvs/zapsum/lib/python3.4/site-packages/django/core/handlers/base.py", line 112, in get_response
    response = wrapped_callback(request, *callback_args, **callback_kwargs)
  File "/home/kalinins/.virtualenvs/zapsum/zapsum/app_zapsum/views.py", line 47, in record
    nickname = UserProfile.objects.get(id=request.user.pk).only('nickname')
AttributeError: 'UserProfile' object has no attribute 'only'
Internal Server Error: /record/3/
Traceback (most recent call last):
  File "/home/kalinins/.virtualenvs/zapsum/lib/python3.4/site-packages/django/core/handlers/base.py", line 112, in get_response
    response = wrapped_callback(request, *callback_args, **callback_kwargs)
  File "/home/kalinins/.virtualenvs/zapsum/zapsum/app_zapsum/views.py", line 47, in record
    nickname = UserProfile.objects.get(id=request.user.pk).only('nickname')
AttributeError: 'UserProfile' object has no attribute 'only'
Internal Server Error: /record/3/
Traceback (most recent call last):
  File "/home/kalinins/.virtualenvs/zapsum/lib/python3.4/site-packages/django/core/handlers/base.py", line 112, in get_response
    response = wrapped_callback(request, *callback_args, **callback_kwargs)
  File "/home/kalinins/.virtualenvs/zapsum/zapsum/app_zapsum/views.py", line 47, in record
    nickname = UserProfile.objects.get(id=request.user.pk).only('nickname')
AttributeError: 'UserProfile' object has no attribute 'only'
Internal Server Error: /record/3/
Traceback (most recent call last):
  File "/home/kalinins/.virtualenvs/zapsum/lib/python3.4/site-packages/django/core/handlers/base.py", line 112, in get_response
    response = wrapped_callback(request, *callback_args, **callback_kwargs)
  File "/home/kalinins/.virtualenvs/zapsum/zapsum/app_zapsum/views.py", line 47, in record
    nickname = UserProfile.objects.get(id=request.user.pk).only('nickname')
AttributeError: 'UserProfile' object has no attribute 'only'
Not Found: /author/2/
Internal Server Error: /search_author/
Traceback (most recent call last):
  File "/home/kalinins/.virtualenvs/zapsum/lib/python3.4/site-packages/django/core/handlers/base.py", line 99, in get_response
    resolver_match = resolver.resolve(request.path_info)
  File "/home/kalinins/.virtualenvs/zapsum/lib/python3.4/site-packages/django/core/urlresolvers.py", line 339, in resolve
    sub_match = pattern.resolve(new_path)
  File "/home/kalinins/.virtualenvs/zapsum/lib/python3.4/site-packages/django/core/urlresolvers.py", line 339, in resolve
    sub_match = pattern.resolve(new_path)
  File "/home/kalinins/.virtualenvs/zapsum/lib/python3.4/site-packages/django/core/urlresolvers.py", line 223, in resolve
    return ResolverMatch(self.callback, args, kwargs, self.name)
  File "/home/kalinins/.virtualenvs/zapsum/lib/python3.4/site-packages/django/core/urlresolvers.py", line 230, in callback
    self._callback = get_callable(self._callback_str)
  File "/home/kalinins/.virtualenvs/zapsum/lib/python3.4/site-packages/django/utils/functional.py", line 32, in wrapper
    result = func(*args)
  File "/home/kalinins/.virtualenvs/zapsum/lib/python3.4/site-packages/django/core/urlresolvers.py", line 97, in get_callable
    mod = import_module(mod_name)
  File "/home/kalinins/.virtualenvs/zapsum/lib/python3.4/importlib/__init__.py", line 109, in import_module
    return _bootstrap._gcd_import(name[level:], package, level)
  File "<frozen importlib._bootstrap>", line 2231, in _gcd_import
  File "<frozen importlib._bootstrap>", line 2214, in _find_and_load
  File "<frozen importlib._bootstrap>", line 2203, in _find_and_load_unlocked
  File "<frozen importlib._bootstrap>", line 1200, in _load_unlocked
  File "<frozen importlib._bootstrap>", line 1129, in _exec
  File "<frozen importlib._bootstrap>", line 1444, in exec_module
  File "<frozen importlib._bootstrap>", line 1549, in get_code
  File "<frozen importlib._bootstrap>", line 1509, in source_to_code
  File "<frozen importlib._bootstrap>", line 321, in _call_with_frames_removed
  File "/home/kalinins/.virtualenvs/zapsum/zapsum/app_zapsum/views.py", line 40
    return HttpResponse(json.dumps(authors_list_obj), content_type='application/json')
         ^
SyntaxError: invalid syntax
Forbidden (CSRF token missing or incorrect.): /new_authors/
Forbidden (CSRF token missing or incorrect.): /new_authors/
Not Found: /last_authors/
Internal Server Error: /last_records/
Traceback (most recent call last):
  File "/home/kalinins/.virtualenvs/zapsum/lib/python3.4/site-packages/django/core/handlers/base.py", line 112, in get_response
    response = wrapped_callback(request, *callback_args, **callback_kwargs)
  File "/home/kalinins/.virtualenvs/zapsum/zapsum/app_zapsum/views.py", line 148, in last_records
    page_new_authors = int(request.POST.get('page_new_authors', ''))
ValueError: invalid literal for int() with base 10: ''
Internal Server Error: /profile/1/
Traceback (most recent call last):
  File "/home/kalinins/.virtualenvs/zapsum/lib/python3.4/site-packages/django/core/handlers/base.py", line 112, in get_response
    response = wrapped_callback(request, *callback_args, **callback_kwargs)
  File "/home/kalinins/.virtualenvs/zapsum/zapsum/app_zapsum/views.py", line 97, in profile
    obj_author = UserProfile.get_entry(user_id=id_author)
  File "/home/kalinins/.virtualenvs/zapsum/zapsum/app_accounts/models.py", line 69, in get_entry
    result = UserProfile.objects.get(user_ptr_id=user_id)
  File "/home/kalinins/.virtualenvs/zapsum/lib/python3.4/site-packages/django/db/models/manager.py", line 151, in get
    return self.get_queryset().get(*args, **kwargs)
  File "/home/kalinins/.virtualenvs/zapsum/lib/python3.4/site-packages/django/db/models/query.py", line 310, in get
    self.model._meta.object_name)
app_accounts.models.DoesNotExist: UserProfile matching query does not exist.
Forbidden (CSRF token missing or incorrect.): /new_authors/
Forbidden (CSRF token missing or incorrect.): /new_authors/
Forbidden (CSRF token missing or incorrect.): /new_authors/
Forbidden (CSRF token missing or incorrect.): /new_authors/
Forbidden (CSRF token missing or incorrect.): /new_authors/
Forbidden (CSRF token missing or incorrect.): /new_authors/
