Not Found: /search/
Internal Server Error: /search_author/
Traceback (most recent call last):
  File "/home/kalinins/.virtualenvs/zapsum/lib/python3.4/site-packages/django/core/handlers/base.py", line 112, in get_response
    response = wrapped_callback(request, *callback_args, **callback_kwargs)
  File "/home/kalinins/.virtualenvs/zapsum/zapsum/app_zapsum/views.py", line 36, in search_author
    authors_list = UserProfile.objects.filter(nickname__iregex='^.+?'+author+'.+?$', is_active=1, is_superuser=0).values_list('user_ptr_id', 'nickname')
TypeError: Can't convert 'bytes' object to str implicitly
Internal Server Error: /search_author/
Traceback (most recent call last):
  File "/home/kalinins/.virtualenvs/zapsum/lib/python3.4/site-packages/django/core/handlers/base.py", line 112, in get_response
    response = wrapped_callback(request, *callback_args, **callback_kwargs)
  File "/home/kalinins/.virtualenvs/zapsum/zapsum/app_zapsum/views.py", line 36, in search_author
    authors_list = UserProfile.objects.filter(nickname__iregex='^.+?'+author+'.+?$', is_active=1, is_superuser=0).values_list('user_ptr_id', 'nickname')
TypeError: Can't convert 'bytes' object to str implicitly
Internal Server Error: /search_author/
Traceback (most recent call last):
  File "/home/kalinins/.virtualenvs/zapsum/lib/python3.4/site-packages/django/core/handlers/base.py", line 112, in get_response
    response = wrapped_callback(request, *callback_args, **callback_kwargs)
  File "/home/kalinins/.virtualenvs/zapsum/zapsum/app_zapsum/views.py", line 36, in search_author
    authors_list = UserProfile.objects.filter(nickname__iregex='^.+?'+author+'.+?$', is_active=1, is_superuser=0).values_list('user_ptr_id', 'nickname')
TypeError: Can't convert 'bytes' object to str implicitly
Internal Server Error: /search_author/
Traceback (most recent call last):
  File "/home/kalinins/.virtualenvs/zapsum/lib/python3.4/site-packages/django/core/handlers/base.py", line 112, in get_response
    response = wrapped_callback(request, *callback_args, **callback_kwargs)
  File "/home/kalinins/.virtualenvs/zapsum/zapsum/app_zapsum/views.py", line 36, in search_author
    authors_list = UserProfile.objects.filter(nickname__iregex='^.+?'+author+'.+?$', is_active=1, is_superuser=0).values_list('user_ptr_id', 'nickname')
TypeError: Can't convert 'bytes' object to str implicitly
Not Found: /profile/
Not Found: /favicon.ico
Internal Server Error: /profile/2/
Traceback (most recent call last):
  File "/home/kalinins/.virtualenvs/zapsum/lib/python3.4/site-packages/django/core/handlers/base.py", line 112, in get_response
    response = wrapped_callback(request, *callback_args, **callback_kwargs)
  File "/home/kalinins/.virtualenvs/zapsum/zapsum/app_zapsum/views.py", line 50, in profile
    obj_gender = Gender.get_entry(gender_id=obj_author.gender)
NameError: name 'Gender' is not defined
Internal Server Error: /profile/2/
Traceback (most recent call last):
  File "/home/kalinins/.virtualenvs/zapsum/lib/python3.4/site-packages/django/core/handlers/base.py", line 112, in get_response
    response = wrapped_callback(request, *callback_args, **callback_kwargs)
  File "/home/kalinins/.virtualenvs/zapsum/zapsum/app_zapsum/views.py", line 50, in profile
    obj_gender = Gender.get_entry(gender_id=obj_author.gender)
  File "/home/kalinins/.virtualenvs/zapsum/zapsum/app_accounts/models.py", line 19, in get_entry
    result = Gender.objects.get(id=gender_id)
  File "/home/kalinins/.virtualenvs/zapsum/lib/python3.4/site-packages/django/db/models/manager.py", line 151, in get
    return self.get_queryset().get(*args, **kwargs)
  File "/home/kalinins/.virtualenvs/zapsum/lib/python3.4/site-packages/django/db/models/query.py", line 301, in get
    clone = self.filter(*args, **kwargs)
  File "/home/kalinins/.virtualenvs/zapsum/lib/python3.4/site-packages/django/db/models/query.py", line 593, in filter
    return self._filter_or_exclude(False, *args, **kwargs)
  File "/home/kalinins/.virtualenvs/zapsum/lib/python3.4/site-packages/django/db/models/query.py", line 611, in _filter_or_exclude
    clone.query.add_q(Q(*args, **kwargs))
  File "/home/kalinins/.virtualenvs/zapsum/lib/python3.4/site-packages/django/db/models/sql/query.py", line 1204, in add_q
    clause = self._add_q(where_part, used_aliases)
  File "/home/kalinins/.virtualenvs/zapsum/lib/python3.4/site-packages/django/db/models/sql/query.py", line 1240, in _add_q
    current_negated=current_negated)
  File "/home/kalinins/.virtualenvs/zapsum/lib/python3.4/site-packages/django/db/models/sql/query.py", line 1131, in build_filter
    clause.add(constraint, AND)
  File "/home/kalinins/.virtualenvs/zapsum/lib/python3.4/site-packages/django/utils/tree.py", line 104, in add
    data = self._prepare_data(data)
  File "/home/kalinins/.virtualenvs/zapsum/lib/python3.4/site-packages/django/db/models/sql/where.py", line 79, in _prepare_data
    value = obj.prepare(lookup_type, value)
  File "/home/kalinins/.virtualenvs/zapsum/lib/python3.4/site-packages/django/db/models/sql/where.py", line 352, in prepare
    return self.field.get_prep_lookup(lookup_type, value)
  File "/home/kalinins/.virtualenvs/zapsum/lib/python3.4/site-packages/django/db/models/fields/__init__.py", line 369, in get_prep_lookup
    return self.get_prep_value(value)
  File "/home/kalinins/.virtualenvs/zapsum/lib/python3.4/site-packages/django/db/models/fields/__init__.py", line 613, in get_prep_value
    return int(value)
TypeError: int() argument must be a string or a number, not 'Gender'
Internal Server Error: /profile/2/
Traceback (most recent call last):
  File "/home/kalinins/.virtualenvs/zapsum/lib/python3.4/site-packages/django/core/handlers/base.py", line 112, in get_response
    response = wrapped_callback(request, *callback_args, **callback_kwargs)
  File "/home/kalinins/.virtualenvs/zapsum/zapsum/app_zapsum/views.py", line 50, in profile
    obj_gender = Gender.get_entry(gender_id=obj_author.gender)
  File "/home/kalinins/.virtualenvs/zapsum/zapsum/app_accounts/models.py", line 19, in get_entry
    result = Gender.objects.get(id=gender_id)
  File "/home/kalinins/.virtualenvs/zapsum/lib/python3.4/site-packages/django/db/models/manager.py", line 151, in get
    return self.get_queryset().get(*args, **kwargs)
  File "/home/kalinins/.virtualenvs/zapsum/lib/python3.4/site-packages/django/db/models/query.py", line 301, in get
    clone = self.filter(*args, **kwargs)
  File "/home/kalinins/.virtualenvs/zapsum/lib/python3.4/site-packages/django/db/models/query.py", line 593, in filter
    return self._filter_or_exclude(False, *args, **kwargs)
  File "/home/kalinins/.virtualenvs/zapsum/lib/python3.4/site-packages/django/db/models/query.py", line 611, in _filter_or_exclude
    clone.query.add_q(Q(*args, **kwargs))
  File "/home/kalinins/.virtualenvs/zapsum/lib/python3.4/site-packages/django/db/models/sql/query.py", line 1204, in add_q
    clause = self._add_q(where_part, used_aliases)
  File "/home/kalinins/.virtualenvs/zapsum/lib/python3.4/site-packages/django/db/models/sql/query.py", line 1240, in _add_q
    current_negated=current_negated)
  File "/home/kalinins/.virtualenvs/zapsum/lib/python3.4/site-packages/django/db/models/sql/query.py", line 1131, in build_filter
    clause.add(constraint, AND)
  File "/home/kalinins/.virtualenvs/zapsum/lib/python3.4/site-packages/django/utils/tree.py", line 104, in add
    data = self._prepare_data(data)
  File "/home/kalinins/.virtualenvs/zapsum/lib/python3.4/site-packages/django/db/models/sql/where.py", line 79, in _prepare_data
    value = obj.prepare(lookup_type, value)
  File "/home/kalinins/.virtualenvs/zapsum/lib/python3.4/site-packages/django/db/models/sql/where.py", line 352, in prepare
    return self.field.get_prep_lookup(lookup_type, value)
  File "/home/kalinins/.virtualenvs/zapsum/lib/python3.4/site-packages/django/db/models/fields/__init__.py", line 369, in get_prep_lookup
    return self.get_prep_value(value)
  File "/home/kalinins/.virtualenvs/zapsum/lib/python3.4/site-packages/django/db/models/fields/__init__.py", line 613, in get_prep_value
    return int(value)
TypeError: int() argument must be a string or a number, not 'Gender'
Internal Server Error: /profile/2/
Traceback (most recent call last):
  File "/home/kalinins/.virtualenvs/zapsum/lib/python3.4/site-packages/django/core/handlers/base.py", line 112, in get_response
    response = wrapped_callback(request, *callback_args, **callback_kwargs)
  File "/home/kalinins/.virtualenvs/zapsum/zapsum/app_zapsum/views.py", line 50, in profile
    obj_gender = Gender.get_entry(gender_id=obj_author.gender)
  File "/home/kalinins/.virtualenvs/zapsum/zapsum/app_accounts/models.py", line 19, in get_entry
    result = Gender.objects.get(id=gender_id)
  File "/home/kalinins/.virtualenvs/zapsum/lib/python3.4/site-packages/django/db/models/manager.py", line 151, in get
    return self.get_queryset().get(*args, **kwargs)
  File "/home/kalinins/.virtualenvs/zapsum/lib/python3.4/site-packages/django/db/models/query.py", line 301, in get
    clone = self.filter(*args, **kwargs)
  File "/home/kalinins/.virtualenvs/zapsum/lib/python3.4/site-packages/django/db/models/query.py", line 593, in filter
    return self._filter_or_exclude(False, *args, **kwargs)
  File "/home/kalinins/.virtualenvs/zapsum/lib/python3.4/site-packages/django/db/models/query.py", line 611, in _filter_or_exclude
    clone.query.add_q(Q(*args, **kwargs))
  File "/home/kalinins/.virtualenvs/zapsum/lib/python3.4/site-packages/django/db/models/sql/query.py", line 1204, in add_q
    clause = self._add_q(where_part, used_aliases)
  File "/home/kalinins/.virtualenvs/zapsum/lib/python3.4/site-packages/django/db/models/sql/query.py", line 1240, in _add_q
    current_negated=current_negated)
  File "/home/kalinins/.virtualenvs/zapsum/lib/python3.4/site-packages/django/db/models/sql/query.py", line 1131, in build_filter
    clause.add(constraint, AND)
  File "/home/kalinins/.virtualenvs/zapsum/lib/python3.4/site-packages/django/utils/tree.py", line 104, in add
    data = self._prepare_data(data)
  File "/home/kalinins/.virtualenvs/zapsum/lib/python3.4/site-packages/django/db/models/sql/where.py", line 79, in _prepare_data
    value = obj.prepare(lookup_type, value)
  File "/home/kalinins/.virtualenvs/zapsum/lib/python3.4/site-packages/django/db/models/sql/where.py", line 352, in prepare
    return self.field.get_prep_lookup(lookup_type, value)
  File "/home/kalinins/.virtualenvs/zapsum/lib/python3.4/site-packages/django/db/models/fields/__init__.py", line 369, in get_prep_lookup
    return self.get_prep_value(value)
  File "/home/kalinins/.virtualenvs/zapsum/lib/python3.4/site-packages/django/db/models/fields/__init__.py", line 613, in get_prep_value
    return int(value)
TypeError: int() argument must be a string or a number, not 'Gender'
Internal Server Error: /profile/2/
Traceback (most recent call last):
  File "/home/kalinins/.virtualenvs/zapsum/lib/python3.4/site-packages/django/core/handlers/base.py", line 99, in get_response
    resolver_match = resolver.resolve(request.path_info)
  File "/home/kalinins/.virtualenvs/zapsum/lib/python3.4/site-packages/django/core/urlresolvers.py", line 339, in resolve
    sub_match = pattern.resolve(new_path)
  File "/home/kalinins/.virtualenvs/zapsum/lib/python3.4/site-packages/django/core/urlresolvers.py", line 339, in resolve
    sub_match = pattern.resolve(new_path)
  File "/home/kalinins/.virtualenvs/zapsum/lib/python3.4/site-packages/django/core/urlresolvers.py", line 223, in resolve
    return ResolverMatch(self.callback, args, kwargs, self.name)
  File "/home/kalinins/.virtualenvs/zapsum/lib/python3.4/site-packages/django/core/urlresolvers.py", line 230, in callback
    self._callback = get_callable(self._callback_str)
  File "/home/kalinins/.virtualenvs/zapsum/lib/python3.4/site-packages/django/utils/functional.py", line 32, in wrapper
    result = func(*args)
  File "/home/kalinins/.virtualenvs/zapsum/lib/python3.4/site-packages/django/core/urlresolvers.py", line 97, in get_callable
    mod = import_module(mod_name)
  File "/home/kalinins/.virtualenvs/zapsum/lib/python3.4/importlib/__init__.py", line 109, in import_module
    return _bootstrap._gcd_import(name[level:], package, level)
  File "<frozen importlib._bootstrap>", line 2231, in _gcd_import
  File "<frozen importlib._bootstrap>", line 2214, in _find_and_load
  File "<frozen importlib._bootstrap>", line 2203, in _find_and_load_unlocked
  File "<frozen importlib._bootstrap>", line 1200, in _load_unlocked
  File "<frozen importlib._bootstrap>", line 1129, in _exec
  File "<frozen importlib._bootstrap>", line 1444, in exec_module
  File "<frozen importlib._bootstrap>", line 1549, in get_code
  File "<frozen importlib._bootstrap>", line 1509, in source_to_code
  File "<frozen importlib._bootstrap>", line 321, in _call_with_frames_removed
  File "/home/kalinins/.virtualenvs/zapsum/zapsum/app_zapsum/views.py", line 52
    t = loader.get_template('page_profile.html')
    ^
SyntaxError: invalid syntax
Internal Server Error: /profile/2/
Traceback (most recent call last):
  File "/home/kalinins/.virtualenvs/zapsum/lib/python3.4/site-packages/django/core/handlers/base.py", line 99, in get_response
    resolver_match = resolver.resolve(request.path_info)
  File "/home/kalinins/.virtualenvs/zapsum/lib/python3.4/site-packages/django/core/urlresolvers.py", line 339, in resolve
    sub_match = pattern.resolve(new_path)
  File "/home/kalinins/.virtualenvs/zapsum/lib/python3.4/site-packages/django/core/urlresolvers.py", line 339, in resolve
    sub_match = pattern.resolve(new_path)
  File "/home/kalinins/.virtualenvs/zapsum/lib/python3.4/site-packages/django/core/urlresolvers.py", line 223, in resolve
    return ResolverMatch(self.callback, args, kwargs, self.name)
  File "/home/kalinins/.virtualenvs/zapsum/lib/python3.4/site-packages/django/core/urlresolvers.py", line 230, in callback
    self._callback = get_callable(self._callback_str)
  File "/home/kalinins/.virtualenvs/zapsum/lib/python3.4/site-packages/django/utils/functional.py", line 32, in wrapper
    result = func(*args)
  File "/home/kalinins/.virtualenvs/zapsum/lib/python3.4/site-packages/django/core/urlresolvers.py", line 97, in get_callable
    mod = import_module(mod_name)
  File "/home/kalinins/.virtualenvs/zapsum/lib/python3.4/importlib/__init__.py", line 109, in import_module
    return _bootstrap._gcd_import(name[level:], package, level)
  File "<frozen importlib._bootstrap>", line 2231, in _gcd_import
  File "<frozen importlib._bootstrap>", line 2214, in _find_and_load
  File "<frozen importlib._bootstrap>", line 2203, in _find_and_load_unlocked
  File "<frozen importlib._bootstrap>", line 1200, in _load_unlocked
  File "<frozen importlib._bootstrap>", line 1129, in _exec
  File "<frozen importlib._bootstrap>", line 1444, in exec_module
  File "<frozen importlib._bootstrap>", line 1549, in get_code
  File "<frozen importlib._bootstrap>", line 1509, in source_to_code
  File "<frozen importlib._bootstrap>", line 321, in _call_with_frames_removed
  File "/home/kalinins/.virtualenvs/zapsum/zapsum/app_zapsum/views.py", line 52
    t = loader.get_template('page_profile.html')
    ^
SyntaxError: invalid syntax
Internal Server Error: /profile/2/
Traceback (most recent call last):
  File "/home/kalinins/.virtualenvs/zapsum/lib/python3.4/site-packages/django/core/handlers/base.py", line 99, in get_response
    resolver_match = resolver.resolve(request.path_info)
  File "/home/kalinins/.virtualenvs/zapsum/lib/python3.4/site-packages/django/core/urlresolvers.py", line 339, in resolve
    sub_match = pattern.resolve(new_path)
  File "/home/kalinins/.virtualenvs/zapsum/lib/python3.4/site-packages/django/core/urlresolvers.py", line 339, in resolve
    sub_match = pattern.resolve(new_path)
  File "/home/kalinins/.virtualenvs/zapsum/lib/python3.4/site-packages/django/core/urlresolvers.py", line 223, in resolve
    return ResolverMatch(self.callback, args, kwargs, self.name)
  File "/home/kalinins/.virtualenvs/zapsum/lib/python3.4/site-packages/django/core/urlresolvers.py", line 230, in callback
    self._callback = get_callable(self._callback_str)
  File "/home/kalinins/.virtualenvs/zapsum/lib/python3.4/site-packages/django/utils/functional.py", line 32, in wrapper
    result = func(*args)
  File "/home/kalinins/.virtualenvs/zapsum/lib/python3.4/site-packages/django/core/urlresolvers.py", line 97, in get_callable
    mod = import_module(mod_name)
  File "/home/kalinins/.virtualenvs/zapsum/lib/python3.4/importlib/__init__.py", line 109, in import_module
    return _bootstrap._gcd_import(name[level:], package, level)
  File "<frozen importlib._bootstrap>", line 2231, in _gcd_import
  File "<frozen importlib._bootstrap>", line 2214, in _find_and_load
  File "<frozen importlib._bootstrap>", line 2203, in _find_and_load_unlocked
  File "<frozen importlib._bootstrap>", line 1200, in _load_unlocked
  File "<frozen importlib._bootstrap>", line 1129, in _exec
  File "<frozen importlib._bootstrap>", line 1444, in exec_module
  File "<frozen importlib._bootstrap>", line 1549, in get_code
  File "<frozen importlib._bootstrap>", line 1509, in source_to_code
  File "<frozen importlib._bootstrap>", line 321, in _call_with_frames_removed
  File "/home/kalinins/.virtualenvs/zapsum/zapsum/app_zapsum/views.py", line 52
    t = loader.get_template('page_profile.html')
    ^
SyntaxError: invalid syntax
Internal Server Error: /profile/2/
Traceback (most recent call last):
  File "/home/kalinins/.virtualenvs/zapsum/lib/python3.4/site-packages/django/core/handlers/base.py", line 112, in get_response
    response = wrapped_callback(request, *callback_args, **callback_kwargs)
  File "/home/kalinins/.virtualenvs/zapsum/zapsum/app_zapsum/views.py", line 50, in profile
    obj_gender = Gender.get_entry(gender_id=int(obj_author.gender))
TypeError: int() argument must be a string or a number, not 'Gender'
Internal Server Error: /profile/2/
Traceback (most recent call last):
  File "/home/kalinins/.virtualenvs/zapsum/lib/python3.4/site-packages/django/core/handlers/base.py", line 112, in get_response
    response = wrapped_callback(request, *callback_args, **callback_kwargs)
  File "/home/kalinins/.virtualenvs/zapsum/zapsum/app_zapsum/views.py", line 52, in profile
    print(int(obj_author.gender))
TypeError: int() argument must be a string or a number, not 'Gender'
Internal Server Error: /profile/2/
Traceback (most recent call last):
  File "/home/kalinins/.virtualenvs/zapsum/lib/python3.4/site-packages/django/core/handlers/base.py", line 112, in get_response
    response = wrapped_callback(request, *callback_args, **callback_kwargs)
  File "/home/kalinins/.virtualenvs/zapsum/zapsum/app_zapsum/views.py", line 52, in profile
    print(int(obj_author.gender.gender))
ValueError: invalid literal for int() with base 10: 'Ж'
Internal Server Error: /profile/2/
Traceback (most recent call last):
  File "/home/kalinins/.virtualenvs/zapsum/lib/python3.4/site-packages/django/core/handlers/base.py", line 112, in get_response
    response = wrapped_callback(request, *callback_args, **callback_kwargs)
  File "/home/kalinins/.virtualenvs/zapsum/zapsum/app_zapsum/views.py", line 52, in profile
    print(int(obj_author.gender.gender))
ValueError: invalid literal for int() with base 10: 'Ж'
Internal Server Error: /profile/2/
Traceback (most recent call last):
  File "/home/kalinins/.virtualenvs/zapsum/lib/python3.4/site-packages/django/core/handlers/base.py", line 112, in get_response
    response = wrapped_callback(request, *callback_args, **callback_kwargs)
  File "/home/kalinins/.virtualenvs/zapsum/zapsum/app_zapsum/views.py", line 52, in profile
    print(int(obj_author.gender.gender))
ValueError: invalid literal for int() with base 10: 'Ж'
Not Found: /profile/{{ key }}/
Internal Server Error: /profile/6/
Traceback (most recent call last):
  File "/home/kalinins/.virtualenvs/zapsum/lib/python3.4/site-packages/django/core/handlers/base.py", line 112, in get_response
    response = wrapped_callback(request, *callback_args, **callback_kwargs)
  File "/home/kalinins/.virtualenvs/zapsum/zapsum/app_zapsum/views.py", line 51, in profile
    print(obj_author.data_joined)
AttributeError: 'UserProfile' object has no attribute 'data_joined'
Not Found: /favicon.ico
Internal Server Error: /profile/6/
Traceback (most recent call last):
  File "/home/kalinins/.virtualenvs/zapsum/lib/python3.4/site-packages/django/core/handlers/base.py", line 99, in get_response
    resolver_match = resolver.resolve(request.path_info)
  File "/home/kalinins/.virtualenvs/zapsum/lib/python3.4/site-packages/django/core/urlresolvers.py", line 339, in resolve
    sub_match = pattern.resolve(new_path)
  File "/home/kalinins/.virtualenvs/zapsum/lib/python3.4/site-packages/django/core/urlresolvers.py", line 339, in resolve
    sub_match = pattern.resolve(new_path)
  File "/home/kalinins/.virtualenvs/zapsum/lib/python3.4/site-packages/django/core/urlresolvers.py", line 223, in resolve
    return ResolverMatch(self.callback, args, kwargs, self.name)
  File "/home/kalinins/.virtualenvs/zapsum/lib/python3.4/site-packages/django/core/urlresolvers.py", line 230, in callback
    self._callback = get_callable(self._callback_str)
  File "/home/kalinins/.virtualenvs/zapsum/lib/python3.4/site-packages/django/utils/functional.py", line 32, in wrapper
    result = func(*args)
  File "/home/kalinins/.virtualenvs/zapsum/lib/python3.4/site-packages/django/core/urlresolvers.py", line 97, in get_callable
    mod = import_module(mod_name)
  File "/home/kalinins/.virtualenvs/zapsum/lib/python3.4/importlib/__init__.py", line 109, in import_module
    return _bootstrap._gcd_import(name[level:], package, level)
  File "<frozen importlib._bootstrap>", line 2231, in _gcd_import
  File "<frozen importlib._bootstrap>", line 2214, in _find_and_load
  File "<frozen importlib._bootstrap>", line 2203, in _find_and_load_unlocked
  File "<frozen importlib._bootstrap>", line 1200, in _load_unlocked
  File "<frozen importlib._bootstrap>", line 1129, in _exec
  File "<frozen importlib._bootstrap>", line 1444, in exec_module
  File "<frozen importlib._bootstrap>", line 1549, in get_code
  File "<frozen importlib._bootstrap>", line 1509, in source_to_code
  File "<frozen importlib._bootstrap>", line 321, in _call_with_frames_removed
  File "/home/kalinins/.virtualenvs/zapsum/zapsum/app_zapsum/views.py", line 52
    if obj_user.is_active, == 0:
                         ^
SyntaxError: invalid syntax
Internal Server Error: /profile/6/
Traceback (most recent call last):
  File "/home/kalinins/.virtualenvs/zapsum/lib/python3.4/site-packages/django/core/handlers/base.py", line 112, in get_response
    response = wrapped_callback(request, *callback_args, **callback_kwargs)
  File "/home/kalinins/.virtualenvs/zapsum/zapsum/app_zapsum/views.py", line 60, in profile
    'obj_user_is_active': obj_user_is_active,
NameError: name 'obj_user_is_active' is not defined
Internal Server Error: /profile/6/
Traceback (most recent call last):
  File "/home/kalinins/.virtualenvs/zapsum/lib/python3.4/site-packages/django/core/handlers/base.py", line 112, in get_response
    response = wrapped_callback(request, *callback_args, **callback_kwargs)
  File "/home/kalinins/.virtualenvs/zapsum/zapsum/app_zapsum/views.py", line 60, in profile
    'obj_user_is_active': obj_user_is_active,
NameError: name 'obj_user_is_active' is not defined
Internal Server Error: /profile/6/
Traceback (most recent call last):
  File "/home/kalinins/.virtualenvs/zapsum/lib/python3.4/site-packages/django/core/handlers/base.py", line 112, in get_response
    response = wrapped_callback(request, *callback_args, **callback_kwargs)
  File "/home/kalinins/.virtualenvs/zapsum/zapsum/app_zapsum/views.py", line 60, in profile
    'obj_user_is_active': obj_user_is_active,
NameError: name 'obj_user_is_active' is not defined
Internal Server Error: /profile/6/
Traceback (most recent call last):
  File "/home/kalinins/.virtualenvs/zapsum/lib/python3.4/site-packages/django/core/handlers/base.py", line 112, in get_response
    response = wrapped_callback(request, *callback_args, **callback_kwargs)
  File "/home/kalinins/.virtualenvs/zapsum/zapsum/app_zapsum/views.py", line 60, in profile
    'obj_user_is_active': obj_user_is_active,
NameError: name 'obj_user_is_active' is not defined
Internal Server Error: /profile/6/
Traceback (most recent call last):
  File "/home/kalinins/.virtualenvs/zapsum/lib/python3.4/site-packages/django/core/handlers/base.py", line 112, in get_response
    response = wrapped_callback(request, *callback_args, **callback_kwargs)
  File "/home/kalinins/.virtualenvs/zapsum/zapsum/app_zapsum/views.py", line 55, in profile
    obj_user_is_active == False
NameError: name 'obj_user_is_active' is not defined
Internal Server Error: /profile/6/
Traceback (most recent call last):
  File "/home/kalinins/.virtualenvs/zapsum/lib/python3.4/site-packages/django/core/handlers/base.py", line 112, in get_response
    response = wrapped_callback(request, *callback_args, **callback_kwargs)
  File "/home/kalinins/.virtualenvs/zapsum/zapsum/app_zapsum/views.py", line 55, in profile
    obj_user_is_active == False
NameError: name 'obj_user_is_active' is not defined
Internal Server Error: /profile/6/
Traceback (most recent call last):
  File "/home/kalinins/.virtualenvs/zapsum/lib/python3.4/site-packages/django/core/handlers/base.py", line 112, in get_response
    response = wrapped_callback(request, *callback_args, **callback_kwargs)
  File "/home/kalinins/.virtualenvs/zapsum/zapsum/app_zapsum/views.py", line 55, in profile
    obj_user_is_active == False
NameError: name 'obj_user_is_active' is not defined
Internal Server Error: /profile/6/
Traceback (most recent call last):
  File "/home/kalinins/.virtualenvs/zapsum/lib/python3.4/site-packages/django/core/handlers/base.py", line 112, in get_response
    response = wrapped_callback(request, *callback_args, **callback_kwargs)
  File "/home/kalinins/.virtualenvs/zapsum/zapsum/app_zapsum/views.py", line 55, in profile
    obj_user_is_active == False
NameError: name 'obj_user_is_active' is not defined
Not Found: /diary/4/
Internal Server Error: /diary/2/
Traceback (most recent call last):
  File "/home/kalinins/.virtualenvs/zapsum/lib/python3.4/site-packages/django/core/handlers/base.py", line 112, in get_response
    response = wrapped_callback(request, *callback_args, **callback_kwargs)
  File "/home/kalinins/.virtualenvs/zapsum/zapsum/app_zapsum/views.py", line 50, in diary
    obj_diary = Diary.get_all_user_entries(user_id=id_author)
  File "/home/kalinins/.virtualenvs/zapsum/zapsum/app_zapsum/models.py", line 39, in get_all_user_entries
    return self.objects.filter(user_id=user_id, is_active=True, is_delete=False).values(title, date)
NameError: name 'title' is not defined
Internal Server Error: /diary/2/
Traceback (most recent call last):
  File "/home/kalinins/.virtualenvs/zapsum/lib/python3.4/site-packages/django/core/handlers/base.py", line 112, in get_response
    response = wrapped_callback(request, *callback_args, **callback_kwargs)
  File "/home/kalinins/.virtualenvs/zapsum/zapsum/app_zapsum/views.py", line 50, in diary
    obj_diary = Diary.get_all_user_entries(user_id=id_author)
  File "/home/kalinins/.virtualenvs/zapsum/zapsum/app_zapsum/models.py", line 39, in get_all_user_entries
    return self.objects.filter(user_id=user_id, is_active=True, is_delete=False).values(title, date)
NameError: name 'title' is not defined
Internal Server Error: /diary/2/
Traceback (most recent call last):
  File "/home/kalinins/.virtualenvs/zapsum/lib/python3.4/site-packages/django/core/handlers/base.py", line 112, in get_response
    response = wrapped_callback(request, *callback_args, **callback_kwargs)
  File "/home/kalinins/.virtualenvs/zapsum/zapsum/app_zapsum/views.py", line 50, in diary
    obj_diary = Diary.get_all_user_entries(user_id=id_author)
  File "/home/kalinins/.virtualenvs/zapsum/zapsum/app_zapsum/models.py", line 39, in get_all_user_entries
    return self.objects.filter(user_id=user_id, is_active=True, is_delete=False).values(title, date)
NameError: name 'title' is not defined
Internal Server Error: /diary/2/
Traceback (most recent call last):
  File "/home/kalinins/.virtualenvs/zapsum/lib/python3.4/site-packages/django/core/handlers/base.py", line 112, in get_response
    response = wrapped_callback(request, *callback_args, **callback_kwargs)
  File "/home/kalinins/.virtualenvs/zapsum/zapsum/app_zapsum/views.py", line 50, in diary
    obj_diary = Diary.get_all_user_entries(user_id=id_author)
  File "/home/kalinins/.virtualenvs/zapsum/zapsum/app_zapsum/models.py", line 39, in get_all_user_entries
    return self.objects.filter(user_id=user_id, is_active=True, is_delete=False).values('title', 'date')
NameError: name 'title' is not defined
Internal Server Error: /diary/2/
Traceback (most recent call last):
  File "/home/kalinins/.virtualenvs/zapsum/lib/python3.4/site-packages/django/core/handlers/base.py", line 112, in get_response
    response = wrapped_callback(request, *callback_args, **callback_kwargs)
  File "/home/kalinins/.virtualenvs/zapsum/zapsum/app_zapsum/views.py", line 50, in diary
    obj_diary = Diary.get_all_user_entries(user_id=id_author)
  File "/home/kalinins/.virtualenvs/zapsum/zapsum/app_zapsum/models.py", line 39, in get_all_user_entries
    return self.objects.filter(user_id=user_id, is_active=True, is_delete=False).values('title', 'date')
NameError: name 'title' is not defined
Internal Server Error: /diary/2/
Traceback (most recent call last):
  File "/home/kalinins/.virtualenvs/zapsum/lib/python3.4/site-packages/django/core/handlers/base.py", line 112, in get_response
    response = wrapped_callback(request, *callback_args, **callback_kwargs)
  File "/home/kalinins/.virtualenvs/zapsum/zapsum/app_zapsum/views.py", line 50, in diary
    obj_diary = Diary.get_all_user_entries(user_id=id_author)
  File "/home/kalinins/.virtualenvs/zapsum/zapsum/app_zapsum/models.py", line 39, in get_all_user_entries
    return self.objects.filter(user_id=user_id, is_active=True, is_delete=False).values('title', 'date')
NameError: name 'title' is not defined
Internal Server Error: /diary/2/
Traceback (most recent call last):
  File "/home/kalinins/.virtualenvs/zapsum/lib/python3.4/site-packages/django/core/handlers/base.py", line 112, in get_response
    response = wrapped_callback(request, *callback_args, **callback_kwargs)
  File "/home/kalinins/.virtualenvs/zapsum/zapsum/app_zapsum/views.py", line 50, in diary
    obj_diary = Diary.get_all_user_entries(user_id=id_author)
  File "/home/kalinins/.virtualenvs/zapsum/zapsum/app_zapsum/models.py", line 39, in get_all_user_entries
    return self.objects.filter(user_id=user_id, is_active=True, is_delete=False).values('title', 'date')
NameError: name 'title' is not defined
Internal Server Error: /diary/2/
Traceback (most recent call last):
  File "/home/kalinins/.virtualenvs/zapsum/lib/python3.4/site-packages/django/core/handlers/base.py", line 112, in get_response
    response = wrapped_callback(request, *callback_args, **callback_kwargs)
  File "/home/kalinins/.virtualenvs/zapsum/zapsum/app_zapsum/views.py", line 50, in diary
    obj_diary = Diary.get_all_user_entries(user_id=id_author)
  File "/home/kalinins/.virtualenvs/zapsum/zapsum/app_zapsum/models.py", line 39, in get_all_user_entries
    return self.objects.filter(user_id=user_id, is_active=True, is_delete=False).values('title', 'date')
NameError: name 'title' is not defined
Not Found: /entry//
Not Found: /favicon.ico
Not Found: /entry//
Not Found: /entry//
Not Found: /entry//
Internal Server Error: /my_records/
Traceback (most recent call last):
  File "/home/kalinins/.virtualenvs/zapsum/lib/python3.4/site-packages/django/core/handlers/base.py", line 112, in get_response
    response = wrapped_callback(request, *callback_args, **callback_kwargs)
  File "/home/kalinins/.virtualenvs/zapsum/lib/python3.4/site-packages/django/contrib/auth/decorators.py", line 22, in _wrapped_view
    return view_func(request, *args, **kwargs)
  File "/home/kalinins/.virtualenvs/zapsum/zapsum/app_zapsum/views.py", line 144, in my_records
    all_user_entries = Diary.get_all_user_entries(id=request.user.pk)
TypeError: get_all_user_entries() got an unexpected keyword argument 'id'
Internal Server Error: /my_records/
Traceback (most recent call last):
  File "/home/kalinins/.virtualenvs/zapsum/lib/python3.4/site-packages/django/core/handlers/base.py", line 112, in get_response
    response = wrapped_callback(request, *callback_args, **callback_kwargs)
  File "/home/kalinins/.virtualenvs/zapsum/lib/python3.4/site-packages/django/contrib/auth/decorators.py", line 22, in _wrapped_view
    return view_func(request, *args, **kwargs)
  File "/home/kalinins/.virtualenvs/zapsum/zapsum/app_zapsum/views.py", line 144, in my_records
    all_user_entries = Diary.get_all_user_entries(id=request.user.pk)
TypeError: get_all_user_entries() got an unexpected keyword argument 'id'
Internal Server Error: /my_records/
Traceback (most recent call last):
  File "/home/kalinins/.virtualenvs/zapsum/lib/python3.4/site-packages/django/core/handlers/base.py", line 112, in get_response
    response = wrapped_callback(request, *callback_args, **callback_kwargs)
  File "/home/kalinins/.virtualenvs/zapsum/lib/python3.4/site-packages/django/contrib/auth/decorators.py", line 22, in _wrapped_view
    return view_func(request, *args, **kwargs)
  File "/home/kalinins/.virtualenvs/zapsum/zapsum/app_zapsum/views.py", line 144, in my_records
    all_user_entries = Diary.get_all_user_entries(id=request.user.pk)
TypeError: get_all_user_entries() got an unexpected keyword argument 'id'
Internal Server Error: /my_records/
Traceback (most recent call last):
  File "/home/kalinins/.virtualenvs/zapsum/lib/python3.4/site-packages/django/core/handlers/base.py", line 112, in get_response
    response = wrapped_callback(request, *callback_args, **callback_kwargs)
  File "/home/kalinins/.virtualenvs/zapsum/lib/python3.4/site-packages/django/contrib/auth/decorators.py", line 22, in _wrapped_view
    return view_func(request, *args, **kwargs)
  File "/home/kalinins/.virtualenvs/zapsum/zapsum/app_zapsum/views.py", line 144, in my_records
    all_user_entries = Diary.get_all_user_entries(id=request.user.pk)
TypeError: get_all_user_entries() got an unexpected keyword argument 'id'
Internal Server Error: /my_records/
Traceback (most recent call last):
  File "/home/kalinins/.virtualenvs/zapsum/lib/python3.4/site-packages/django/core/handlers/base.py", line 112, in get_response
    response = wrapped_callback(request, *callback_args, **callback_kwargs)
  File "/home/kalinins/.virtualenvs/zapsum/lib/python3.4/site-packages/django/contrib/auth/decorators.py", line 22, in _wrapped_view
    return view_func(request, *args, **kwargs)
  File "/home/kalinins/.virtualenvs/zapsum/zapsum/app_zapsum/views.py", line 144, in my_records
    all_user_entries = Diary.get_all_user_entries(id=request.user.pk)
TypeError: get_all_user_entries() got an unexpected keyword argument 'id'
Not Found: /entry/1/
Not Found: /entry/2/
Not Found: /entry/1/
Internal Server Error: /new_authors/
Traceback (most recent call last):
  File "/home/kalinins/.virtualenvs/zapsum/lib/python3.4/site-packages/django/core/handlers/base.py", line 112, in get_response
    response = wrapped_callback(request, *callback_args, **callback_kwargs)
  File "/home/kalinins/.virtualenvs/zapsum/zapsum/app_zapsum/views.py", line 141, in new_authors
    new_authors = UserProfile.get_new_authors_entries(cut_begin=page_new_authors, cut_end=page_new_authors + 2)
TypeError: Can't convert 'int' object to str implicitly
Internal Server Error: /new_authors/
Traceback (most recent call last):
  File "/home/kalinins/.virtualenvs/zapsum/lib/python3.4/site-packages/django/core/handlers/base.py", line 112, in get_response
    response = wrapped_callback(request, *callback_args, **callback_kwargs)
  File "/home/kalinins/.virtualenvs/zapsum/zapsum/app_zapsum/views.py", line 141, in new_authors
    new_authors = UserProfile.get_new_authors_entries(cut_begin=page_new_authors, cut_end=2)
  File "/home/kalinins/.virtualenvs/zapsum/zapsum/app_accounts/models.py", line 57, in get_new_authors_entries
    return self.objects.filter(is_active=1, is_superuser=0).order_by('-date_joined')[cut_begin:cut_end]
  File "/home/kalinins/.virtualenvs/zapsum/lib/python3.4/site-packages/django/db/models/query.py", line 110, in __getitem__
    or (isinstance(k, slice) and (k.start is None or k.start >= 0)
TypeError: unorderable types: str() >= int()
Internal Server Error: /new_authors/
Traceback (most recent call last):
  File "/home/kalinins/.virtualenvs/zapsum/lib/python3.4/site-packages/django/core/handlers/base.py", line 99, in get_response
    resolver_match = resolver.resolve(request.path_info)
  File "/home/kalinins/.virtualenvs/zapsum/lib/python3.4/site-packages/django/core/urlresolvers.py", line 339, in resolve
    sub_match = pattern.resolve(new_path)
  File "/home/kalinins/.virtualenvs/zapsum/lib/python3.4/site-packages/django/core/urlresolvers.py", line 339, in resolve
    sub_match = pattern.resolve(new_path)
  File "/home/kalinins/.virtualenvs/zapsum/lib/python3.4/site-packages/django/core/urlresolvers.py", line 223, in resolve
    return ResolverMatch(self.callback, args, kwargs, self.name)
  File "/home/kalinins/.virtualenvs/zapsum/lib/python3.4/site-packages/django/core/urlresolvers.py", line 230, in callback
    self._callback = get_callable(self._callback_str)
  File "/home/kalinins/.virtualenvs/zapsum/lib/python3.4/site-packages/django/utils/functional.py", line 32, in wrapper
    result = func(*args)
  File "/home/kalinins/.virtualenvs/zapsum/lib/python3.4/site-packages/django/core/urlresolvers.py", line 97, in get_callable
    mod = import_module(mod_name)
  File "/home/kalinins/.virtualenvs/zapsum/lib/python3.4/importlib/__init__.py", line 109, in import_module
    return _bootstrap._gcd_import(name[level:], package, level)
  File "<frozen importlib._bootstrap>", line 2231, in _gcd_import
  File "<frozen importlib._bootstrap>", line 2214, in _find_and_load
  File "<frozen importlib._bootstrap>", line 2203, in _find_and_load_unlocked
  File "<frozen importlib._bootstrap>", line 1200, in _load_unlocked
  File "<frozen importlib._bootstrap>", line 1129, in _exec
  File "<frozen importlib._bootstrap>", line 1444, in exec_module
  File "<frozen importlib._bootstrap>", line 1549, in get_code
  File "<frozen importlib._bootstrap>", line 1509, in source_to_code
  File "<frozen importlib._bootstrap>", line 321, in _call_with_frames_removed
  File "/home/kalinins/.virtualenvs/zapsum/zapsum/app_zapsum/views.py", line 143
    data = {
       ^
SyntaxError: invalid syntax
Internal Server Error: /new_authors/
Traceback (most recent call last):
  File "/home/kalinins/.virtualenvs/zapsum/lib/python3.4/site-packages/django/core/handlers/base.py", line 112, in get_response
    response = wrapped_callback(request, *callback_args, **callback_kwargs)
  File "/home/kalinins/.virtualenvs/zapsum/zapsum/app_zapsum/views.py", line 141, in new_authors
    new_authors = UserProfile.get_new_authors_entries(cut_begin=int(page_new_authors), cut_end=int(page_new_authors + 2))
TypeError: Can't convert 'int' object to str implicitly
Internal Server Error: /new_authors/
Traceback (most recent call last):
  File "/home/kalinins/.virtualenvs/zapsum/lib/python3.4/site-packages/django/core/handlers/base.py", line 112, in get_response
    response = wrapped_callback(request, *callback_args, **callback_kwargs)
  File "/home/kalinins/.virtualenvs/zapsum/zapsum/app_zapsum/views.py", line 144, in new_authors
    'nickname': new_authors.nickname,
AttributeError: 'QuerySet' object has no attribute 'nickname'
Internal Server Error: /new_authors/
Traceback (most recent call last):
  File "/home/kalinins/.virtualenvs/zapsum/lib/python3.4/site-packages/django/core/handlers/base.py", line 112, in get_response
    response = wrapped_callback(request, *callback_args, **callback_kwargs)
  File "/home/kalinins/.virtualenvs/zapsum/zapsum/app_zapsum/views.py", line 147, in new_authors
    return HttpResponse(json.dumps(data), content_type='application/json')
  File "/usr/lib/python3.4/json/__init__.py", line 230, in dumps
    return _default_encoder.encode(obj)
  File "/usr/lib/python3.4/json/encoder.py", line 192, in encode
    chunks = self.iterencode(o, _one_shot=True)
  File "/usr/lib/python3.4/json/encoder.py", line 250, in iterencode
    return _iterencode(o, 0)
  File "/usr/lib/python3.4/json/encoder.py", line 173, in default
    raise TypeError(repr(o) + " is not JSON serializable")
TypeError: [<UserProfile: zzzzzz>, <UserProfile: wwwwww>] is not JSON serializable
Internal Server Error: /new_authors/
Traceback (most recent call last):
  File "/home/kalinins/.virtualenvs/zapsum/lib/python3.4/site-packages/django/core/handlers/base.py", line 112, in get_response
    response = wrapped_callback(request, *callback_args, **callback_kwargs)
  File "/home/kalinins/.virtualenvs/zapsum/zapsum/app_zapsum/views.py", line 147, in new_authors
    return HttpResponse(json.dumps(data), content_type='application/json')
  File "/usr/lib/python3.4/json/__init__.py", line 230, in dumps
    return _default_encoder.encode(obj)
  File "/usr/lib/python3.4/json/encoder.py", line 192, in encode
    chunks = self.iterencode(o, _one_shot=True)
  File "/usr/lib/python3.4/json/encoder.py", line 250, in iterencode
    return _iterencode(o, 0)
  File "/usr/lib/python3.4/json/encoder.py", line 173, in default
    raise TypeError(repr(o) + " is not JSON serializable")
TypeError: [<UserProfile: zzzzzz>, <UserProfile: wwwwww>] is not JSON serializable
Internal Server Error: /new_authors/
Traceback (most recent call last):
  File "/home/kalinins/.virtualenvs/zapsum/lib/python3.4/site-packages/django/core/handlers/base.py", line 112, in get_response
    response = wrapped_callback(request, *callback_args, **callback_kwargs)
  File "/home/kalinins/.virtualenvs/zapsum/zapsum/app_zapsum/views.py", line 149, in new_authors
    new_authors = UserProfile.get_new_authors_entries(cut_begin=0, cut_end=2)
  File "/home/kalinins/.virtualenvs/zapsum/zapsum/app_accounts/models.py", line 57, in get_new_authors_entries
    return self.objects.filter(is_active=1, is_superuser=0).valuse('nickname').order_by('-date_joined')[cut_begin:cut_end]
AttributeError: 'QuerySet' object has no attribute 'valuse'
Internal Server Error: /new_authors/
Traceback (most recent call last):
  File "/home/kalinins/.virtualenvs/zapsum/lib/python3.4/site-packages/django/core/handlers/base.py", line 112, in get_response
    response = wrapped_callback(request, *callback_args, **callback_kwargs)
  File "/home/kalinins/.virtualenvs/zapsum/zapsum/app_zapsum/views.py", line 149, in new_authors
    new_authors = UserProfile.get_new_authors_entries(cut_begin=0, cut_end=2)
  File "/home/kalinins/.virtualenvs/zapsum/zapsum/app_accounts/models.py", line 57, in get_new_authors_entries
    return self.objects.filter(is_active=1, is_superuser=0).value('nickname').order_by('-date_joined')[cut_begin:cut_end]
AttributeError: 'QuerySet' object has no attribute 'value'
Internal Server Error: /new_authors/
Traceback (most recent call last):
  File "/home/kalinins/.virtualenvs/zapsum/lib/python3.4/site-packages/django/core/handlers/base.py", line 112, in get_response
    response = wrapped_callback(request, *callback_args, **callback_kwargs)
  File "/home/kalinins/.virtualenvs/zapsum/zapsum/app_zapsum/views.py", line 149, in new_authors
    new_authors = UserProfile.get_new_authors_entries(cut_begin=0, cut_end=2)
  File "/home/kalinins/.virtualenvs/zapsum/zapsum/app_accounts/models.py", line 57, in get_new_authors_entries
    return self.objects.filter(is_active=1, is_superuser=0).value('nickname').order_by('-date_joined')[cut_begin:cut_end]
AttributeError: 'QuerySet' object has no attribute 'value'
Internal Server Error: /new_authors/
Traceback (most recent call last):
  File "/home/kalinins/.virtualenvs/zapsum/lib/python3.4/site-packages/django/core/handlers/base.py", line 112, in get_response
    response = wrapped_callback(request, *callback_args, **callback_kwargs)
  File "/home/kalinins/.virtualenvs/zapsum/zapsum/app_zapsum/views.py", line 144, in new_authors
    'nickname': new_authors.nickname,
AttributeError: 'ValuesQuerySet' object has no attribute 'nickname'
Internal Server Error: /new_authors/
Traceback (most recent call last):
  File "/home/kalinins/.virtualenvs/zapsum/lib/python3.4/site-packages/django/core/handlers/base.py", line 112, in get_response
    response = wrapped_callback(request, *callback_args, **callback_kwargs)
  File "/home/kalinins/.virtualenvs/zapsum/zapsum/app_zapsum/views.py", line 143, in new_authors
    return HttpResponse(json.dumps(new_authors), content_type='application/json')
  File "/usr/lib/python3.4/json/__init__.py", line 230, in dumps
    return _default_encoder.encode(obj)
  File "/usr/lib/python3.4/json/encoder.py", line 192, in encode
    chunks = self.iterencode(o, _one_shot=True)
  File "/usr/lib/python3.4/json/encoder.py", line 250, in iterencode
    return _iterencode(o, 0)
  File "/usr/lib/python3.4/json/encoder.py", line 173, in default
    raise TypeError(repr(o) + " is not JSON serializable")
TypeError: [{'id': 4, 'date_joined': datetime.datetime(2014, 9, 22, 13, 37, 25, 866974, tzinfo=<UTC>), 'username': 'zzzzzz'}, {'id': 5, 'date_joined': datetime.datetime(2014, 9, 22, 13, 37, 25, 866974, tzinfo=<UTC>), 'username': 'wwwwww'}] is not JSON serializable
Internal Server Error: /new_authors/
Traceback (most recent call last):
  File "/home/kalinins/.virtualenvs/zapsum/lib/python3.4/site-packages/django/core/handlers/base.py", line 112, in get_response
    response = wrapped_callback(request, *callback_args, **callback_kwargs)
  File "/home/kalinins/.virtualenvs/zapsum/zapsum/app_zapsum/views.py", line 143, in new_authors
    return HttpResponse(json.dumps(new_authors), content_type='application/json')
  File "/usr/lib/python3.4/json/__init__.py", line 230, in dumps
    return _default_encoder.encode(obj)
  File "/usr/lib/python3.4/json/encoder.py", line 192, in encode
    chunks = self.iterencode(o, _one_shot=True)
  File "/usr/lib/python3.4/json/encoder.py", line 250, in iterencode
    return _iterencode(o, 0)
  File "/usr/lib/python3.4/json/encoder.py", line 173, in default
    raise TypeError(repr(o) + " is not JSON serializable")
TypeError: [{'username': 'zzzzzz', 'id': 4}, {'username': 'wwwwww', 'id': 5}] is not JSON serializable
Internal Server Error: /new_authors/
Traceback (most recent call last):
  File "/home/kalinins/.virtualenvs/zapsum/lib/python3.4/site-packages/django/core/handlers/base.py", line 112, in get_response
    response = wrapped_callback(request, *callback_args, **callback_kwargs)
  File "/home/kalinins/.virtualenvs/zapsum/zapsum/app_zapsum/views.py", line 143, in new_authors
    return HttpResponse(json.dumps(new_authors[0]), content_type='application/json')
  File "/usr/lib/python3.4/json/__init__.py", line 230, in dumps
    return _default_encoder.encode(obj)
  File "/usr/lib/python3.4/json/encoder.py", line 192, in encode
    chunks = self.iterencode(o, _one_shot=True)
  File "/usr/lib/python3.4/json/encoder.py", line 250, in iterencode
    return _iterencode(o, 0)
  File "/usr/lib/python3.4/json/encoder.py", line 173, in default
    raise TypeError(repr(o) + " is not JSON serializable")
TypeError: datetime.datetime(2014, 9, 22, 13, 37, 25, 866974, tzinfo=<UTC>) is not JSON serializable
Internal Server Error: /new_authors/
Traceback (most recent call last):
  File "/home/kalinins/.virtualenvs/zapsum/lib/python3.4/site-packages/django/core/handlers/base.py", line 112, in get_response
    response = wrapped_callback(request, *callback_args, **callback_kwargs)
  File "/home/kalinins/.virtualenvs/zapsum/zapsum/app_zapsum/views.py", line 143, in new_authors
    data = [obj in new_authors]
NameError: name 'obj' is not defined
Internal Server Error: /new_authors/
Traceback (most recent call last):
  File "/home/kalinins/.virtualenvs/zapsum/lib/python3.4/site-packages/django/core/handlers/base.py", line 112, in get_response
    response = wrapped_callback(request, *callback_args, **callback_kwargs)
  File "/home/kalinins/.virtualenvs/zapsum/zapsum/app_zapsum/views.py", line 144, in new_authors
    data = [obj in new_authors]
NameError: name 'obj' is not defined
Internal Server Error: /new_authors/
Traceback (most recent call last):
  File "/home/kalinins/.virtualenvs/zapsum/lib/python3.4/site-packages/django/core/handlers/base.py", line 112, in get_response
    response = wrapped_callback(request, *callback_args, **callback_kwargs)
  File "/home/kalinins/.virtualenvs/zapsum/zapsum/app_zapsum/views.py", line 146, in new_authors
    return HttpResponse(json.dumps(data), content_type='application/json')
  File "/usr/lib/python3.4/json/__init__.py", line 230, in dumps
    return _default_encoder.encode(obj)
  File "/usr/lib/python3.4/json/encoder.py", line 192, in encode
    chunks = self.iterencode(o, _one_shot=True)
  File "/usr/lib/python3.4/json/encoder.py", line 250, in iterencode
    return _iterencode(o, 0)
  File "/usr/lib/python3.4/json/encoder.py", line 173, in default
    raise TypeError(repr(o) + " is not JSON serializable")
TypeError: [{'username': 'zzzzzz', 'id': 4}, {'username': 'wwwwww', 'id': 5}] is not JSON serializable
Internal Server Error: /new_authors/
Traceback (most recent call last):
  File "/home/kalinins/.virtualenvs/zapsum/lib/python3.4/site-packages/django/core/handlers/base.py", line 112, in get_response
    response = wrapped_callback(request, *callback_args, **callback_kwargs)
  File "/home/kalinins/.virtualenvs/zapsum/zapsum/app_zapsum/views.py", line 143, in new_authors
    return HttpResponse(json.dumps(new_authors), content_type='application/json')
  File "/usr/lib/python3.4/json/__init__.py", line 230, in dumps
    return _default_encoder.encode(obj)
  File "/usr/lib/python3.4/json/encoder.py", line 192, in encode
    chunks = self.iterencode(o, _one_shot=True)
  File "/usr/lib/python3.4/json/encoder.py", line 250, in iterencode
    return _iterencode(o, 0)
  File "/usr/lib/python3.4/json/encoder.py", line 173, in default
    raise TypeError(repr(o) + " is not JSON serializable")
TypeError: [{'id': 4, 'username': 'zzzzzz'}, {'id': 5, 'username': 'wwwwww'}] is not JSON serializable
Internal Server Error: /new_authors/
Traceback (most recent call last):
  File "/home/kalinins/.virtualenvs/zapsum/lib/python3.4/site-packages/django/core/handlers/base.py", line 112, in get_response
    response = wrapped_callback(request, *callback_args, **callback_kwargs)
  File "/home/kalinins/.virtualenvs/zapsum/zapsum/app_zapsum/views.py", line 143, in new_authors
    return HttpResponse(json.dumps(new_authors), content_type='application/json')
  File "/usr/lib/python3.4/json/__init__.py", line 230, in dumps
    return _default_encoder.encode(obj)
  File "/usr/lib/python3.4/json/encoder.py", line 192, in encode
    chunks = self.iterencode(o, _one_shot=True)
  File "/usr/lib/python3.4/json/encoder.py", line 250, in iterencode
    return _iterencode(o, 0)
  File "/usr/lib/python3.4/json/encoder.py", line 173, in default
    raise TypeError(repr(o) + " is not JSON serializable")
TypeError: [{'id': 4, 'username': 'zzzzzz'}, {'id': 5, 'username': 'wwwwww'}] is not JSON serializable
