Internal Server Error: /accounts/ajax_username_check/
Traceback (most recent call last):
  File "/home/kalinins/.virtualenvs/zapsum/lib/python3.4/site-packages/django/core/handlers/base.py", line 112, in get_response
    response = wrapped_callback(request, *callback_args, **callback_kwargs)
  File "/home/kalinins/.virtualenvs/zapsum/zapsum/app_accounts/views.py", line 90, in ajax_username_check
    f.write(bytes(username_exist, 'UTF-8'))
TypeError: encoding or errors without a string argument
Internal Server Error: /accounts/ajax_username_check/
Traceback (most recent call last):
  File "/home/kalinins/.virtualenvs/zapsum/lib/python3.4/site-packages/django/core/handlers/base.py", line 112, in get_response
    response = wrapped_callback(request, *callback_args, **callback_kwargs)
  File "/home/kalinins/.virtualenvs/zapsum/zapsum/app_accounts/views.py", line 95, in ajax_username_check
    return HttpResponse(json.dumps({'result':'result'}))
NameError: name 'json' is not defined
Internal Server Error: /accounts/ajax_username_check/
Traceback (most recent call last):
  File "/home/kalinins/.virtualenvs/zapsum/lib/python3.4/site-packages/django/core/handlers/base.py", line 112, in get_response
    response = wrapped_callback(request, *callback_args, **callback_kwargs)
  File "/home/kalinins/.virtualenvs/zapsum/zapsum/app_accounts/views.py", line 96, in ajax_username_check
    return HttpResponse(json.dumps({'result':'result'}))
NameError: name 'json' is not defined
Internal Server Error: /accounts/ajax_username_check/
Traceback (most recent call last):
  File "/home/kalinins/.virtualenvs/zapsum/lib/python3.4/site-packages/django/core/handlers/base.py", line 112, in get_response
    response = wrapped_callback(request, *callback_args, **callback_kwargs)
  File "/home/kalinins/.virtualenvs/zapsum/zapsum/app_accounts/views.py", line 96, in ajax_username_check
    return HttpResponse(json.dumps({'result': result}))
NameError: name 'json' is not defined
Internal Server Error: /accounts/ajax_username_check/
Traceback (most recent call last):
  File "/home/kalinins/.virtualenvs/zapsum/lib/python3.4/site-packages/django/core/handlers/base.py", line 112, in get_response
    response = wrapped_callback(request, *callback_args, **callback_kwargs)
  File "/home/kalinins/.virtualenvs/zapsum/zapsum/app_accounts/views.py", line 94, in ajax_username_check
    json_data = json.dumps(data)
  File "/usr/lib/python3.4/json/__init__.py", line 230, in dumps
    return _default_encoder.encode(obj)
  File "/usr/lib/python3.4/json/encoder.py", line 192, in encode
    chunks = self.iterencode(o, _one_shot=True)
  File "/usr/lib/python3.4/json/encoder.py", line 250, in iterencode
    return _iterencode(o, 0)
  File "/usr/lib/python3.4/json/encoder.py", line 173, in default
    raise TypeError(repr(o) + " is not JSON serializable")
TypeError: <User: admin> is not JSON serializable
Internal Server Error: /accounts/ajax_username_check/
Traceback (most recent call last):
  File "/home/kalinins/.virtualenvs/zapsum/lib/python3.4/site-packages/django/core/handlers/base.py", line 112, in get_response
    response = wrapped_callback(request, *callback_args, **callback_kwargs)
  File "/home/kalinins/.virtualenvs/zapsum/zapsum/app_accounts/views.py", line 88, in ajax_username_check
    username_exist = User.objects.get(username=username)
  File "/home/kalinins/.virtualenvs/zapsum/lib/python3.4/site-packages/django/db/models/manager.py", line 151, in get
    return self.get_queryset().get(*args, **kwargs)
  File "/home/kalinins/.virtualenvs/zapsum/lib/python3.4/site-packages/django/db/models/query.py", line 310, in get
    self.model._meta.object_name)
django.contrib.auth.models.DoesNotExist: User matching query does not exist.
Internal Server Error: /accounts/ajax_username_check/
Traceback (most recent call last):
  File "/home/kalinins/.virtualenvs/zapsum/lib/python3.4/site-packages/django/core/handlers/base.py", line 112, in get_response
    response = wrapped_callback(request, *callback_args, **callback_kwargs)
  File "/home/kalinins/.virtualenvs/zapsum/zapsum/app_accounts/views.py", line 88, in ajax_username_check
    username_exist = User.objects.get(username=username)
  File "/home/kalinins/.virtualenvs/zapsum/lib/python3.4/site-packages/django/db/models/manager.py", line 151, in get
    return self.get_queryset().get(*args, **kwargs)
  File "/home/kalinins/.virtualenvs/zapsum/lib/python3.4/site-packages/django/db/models/query.py", line 310, in get
    self.model._meta.object_name)
django.contrib.auth.models.DoesNotExist: User matching query does not exist.
Internal Server Error: /accounts/ajax_username_check/
Traceback (most recent call last):
  File "/home/kalinins/.virtualenvs/zapsum/lib/python3.4/site-packages/django/core/handlers/base.py", line 112, in get_response
    response = wrapped_callback(request, *callback_args, **callback_kwargs)
  File "/home/kalinins/.virtualenvs/zapsum/zapsum/app_accounts/views.py", line 88, in ajax_username_check
    username_exist = User.objects.get(username=username)
  File "/home/kalinins/.virtualenvs/zapsum/lib/python3.4/site-packages/django/db/models/manager.py", line 151, in get
    return self.get_queryset().get(*args, **kwargs)
  File "/home/kalinins/.virtualenvs/zapsum/lib/python3.4/site-packages/django/db/models/query.py", line 310, in get
    self.model._meta.object_name)
django.contrib.auth.models.DoesNotExist: User matching query does not exist.
Internal Server Error: /accounts/ajax_username_check/
Traceback (most recent call last):
  File "/home/kalinins/.virtualenvs/zapsum/lib/python3.4/site-packages/django/core/handlers/base.py", line 112, in get_response
    response = wrapped_callback(request, *callback_args, **callback_kwargs)
  File "/home/kalinins/.virtualenvs/zapsum/zapsum/app_accounts/views.py", line 86, in ajax_username_check
    username_exist = User.objects.get(username=username)
  File "/home/kalinins/.virtualenvs/zapsum/lib/python3.4/site-packages/django/db/models/manager.py", line 151, in get
    return self.get_queryset().get(*args, **kwargs)
  File "/home/kalinins/.virtualenvs/zapsum/lib/python3.4/site-packages/django/db/models/query.py", line 310, in get
    self.model._meta.object_name)
django.contrib.auth.models.DoesNotExist: User matching query does not exist.
Internal Server Error: /accounts/ajax_username_check/
Traceback (most recent call last):
  File "/home/kalinins/.virtualenvs/zapsum/lib/python3.4/site-packages/django/core/handlers/base.py", line 112, in get_response
    response = wrapped_callback(request, *callback_args, **callback_kwargs)
  File "/home/kalinins/.virtualenvs/zapsum/zapsum/app_accounts/views.py", line 86, in ajax_username_check
    username_exist = User.objects.get(username=username)
  File "/home/kalinins/.virtualenvs/zapsum/lib/python3.4/site-packages/django/db/models/manager.py", line 151, in get
    return self.get_queryset().get(*args, **kwargs)
  File "/home/kalinins/.virtualenvs/zapsum/lib/python3.4/site-packages/django/db/models/query.py", line 310, in get
    self.model._meta.object_name)
django.contrib.auth.models.DoesNotExist: User matching query does not exist.
Internal Server Error: /accounts/ajax_username_check/
Traceback (most recent call last):
  File "/home/kalinins/.virtualenvs/zapsum/lib/python3.4/site-packages/django/core/handlers/base.py", line 112, in get_response
    response = wrapped_callback(request, *callback_args, **callback_kwargs)
  File "/home/kalinins/.virtualenvs/zapsum/zapsum/app_accounts/views.py", line 86, in ajax_username_check
    username_exist = User.objects.get(username=username)
  File "/home/kalinins/.virtualenvs/zapsum/lib/python3.4/site-packages/django/db/models/manager.py", line 151, in get
    return self.get_queryset().get(*args, **kwargs)
  File "/home/kalinins/.virtualenvs/zapsum/lib/python3.4/site-packages/django/db/models/query.py", line 310, in get
    self.model._meta.object_name)
django.contrib.auth.models.DoesNotExist: User matching query does not exist.
Internal Server Error: /accounts/ajax_username_check/
Traceback (most recent call last):
  File "/home/kalinins/.virtualenvs/zapsum/lib/python3.4/site-packages/django/core/handlers/base.py", line 112, in get_response
    response = wrapped_callback(request, *callback_args, **callback_kwargs)
  File "/home/kalinins/.virtualenvs/zapsum/zapsum/app_accounts/views.py", line 86, in ajax_username_check
    username_exist = User.objects.get(username=username)
  File "/home/kalinins/.virtualenvs/zapsum/lib/python3.4/site-packages/django/db/models/manager.py", line 151, in get
    return self.get_queryset().get(*args, **kwargs)
  File "/home/kalinins/.virtualenvs/zapsum/lib/python3.4/site-packages/django/db/models/query.py", line 310, in get
    self.model._meta.object_name)
django.contrib.auth.models.DoesNotExist: User matching query does not exist.
Internal Server Error: /accounts/ajax_username_check/
Traceback (most recent call last):
  File "/home/kalinins/.virtualenvs/zapsum/lib/python3.4/site-packages/django/core/handlers/base.py", line 112, in get_response
    response = wrapped_callback(request, *callback_args, **callback_kwargs)
  File "/home/kalinins/.virtualenvs/zapsum/zapsum/app_accounts/views.py", line 86, in ajax_username_check
    username_exist = User.objects.get(username=username).exist()
AttributeError: 'User' object has no attribute 'exist'
Internal Server Error: /accounts/ajax_username_check/
Traceback (most recent call last):
  File "/home/kalinins/.virtualenvs/zapsum/lib/python3.4/site-packages/django/core/handlers/base.py", line 112, in get_response
    response = wrapped_callback(request, *callback_args, **callback_kwargs)
  File "/home/kalinins/.virtualenvs/zapsum/zapsum/app_accounts/views.py", line 86, in ajax_username_check
    username_exist = User.objects.get(username=username).exist()
  File "/home/kalinins/.virtualenvs/zapsum/lib/python3.4/site-packages/django/db/models/manager.py", line 151, in get
    return self.get_queryset().get(*args, **kwargs)
  File "/home/kalinins/.virtualenvs/zapsum/lib/python3.4/site-packages/django/db/models/query.py", line 310, in get
    self.model._meta.object_name)
django.contrib.auth.models.DoesNotExist: User matching query does not exist.
Internal Server Error: /accounts/ajax_username_check/
Traceback (most recent call last):
  File "/home/kalinins/.virtualenvs/zapsum/lib/python3.4/site-packages/django/core/handlers/base.py", line 112, in get_response
    response = wrapped_callback(request, *callback_args, **callback_kwargs)
  File "/home/kalinins/.virtualenvs/zapsum/zapsum/app_accounts/views.py", line 87, in ajax_username_check
    username_exist = username_req.exist()
AttributeError: 'User' object has no attribute 'exist'
Internal Server Error: /accounts/ajax_username_check/
Traceback (most recent call last):
  File "/home/kalinins/.virtualenvs/zapsum/lib/python3.4/site-packages/django/core/handlers/base.py", line 112, in get_response
    response = wrapped_callback(request, *callback_args, **callback_kwargs)
  File "/home/kalinins/.virtualenvs/zapsum/zapsum/app_accounts/views.py", line 86, in ajax_username_check
    username_req = User.objects.get(username=username)
  File "/home/kalinins/.virtualenvs/zapsum/lib/python3.4/site-packages/django/db/models/manager.py", line 151, in get
    return self.get_queryset().get(*args, **kwargs)
  File "/home/kalinins/.virtualenvs/zapsum/lib/python3.4/site-packages/django/db/models/query.py", line 310, in get
    self.model._meta.object_name)
django.contrib.auth.models.DoesNotExist: User matching query does not exist.
Internal Server Error: /accounts/ajax_username_check/
Traceback (most recent call last):
  File "/home/kalinins/.virtualenvs/zapsum/lib/python3.4/site-packages/django/core/handlers/base.py", line 112, in get_response
    response = wrapped_callback(request, *callback_args, **callback_kwargs)
  File "/home/kalinins/.virtualenvs/zapsum/zapsum/app_accounts/views.py", line 88, in ajax_username_check
    if username_req.exist():
AttributeError: 'User' object has no attribute 'exist'
Internal Server Error: /accounts/ajax_username_check/
Traceback (most recent call last):
  File "/home/kalinins/.virtualenvs/zapsum/lib/python3.4/site-packages/django/core/handlers/base.py", line 112, in get_response
    response = wrapped_callback(request, *callback_args, **callback_kwargs)
  File "/home/kalinins/.virtualenvs/zapsum/zapsum/app_accounts/views.py", line 88, in ajax_username_check
    if username_req.exist():
AttributeError: 'User' object has no attribute 'exist'
Internal Server Error: /accounts/ajax_username_check/
Traceback (most recent call last):
  File "/home/kalinins/.virtualenvs/zapsum/lib/python3.4/site-packages/django/core/handlers/base.py", line 112, in get_response
    response = wrapped_callback(request, *callback_args, **callback_kwargs)
  File "/home/kalinins/.virtualenvs/zapsum/zapsum/app_accounts/views.py", line 88, in ajax_username_check
    if username_req.exist():
AttributeError: 'User' object has no attribute 'exist'
Internal Server Error: /accounts/ajax_username_check/
Traceback (most recent call last):
  File "/home/kalinins/.virtualenvs/zapsum/lib/python3.4/site-packages/django/core/handlers/base.py", line 112, in get_response
    response = wrapped_callback(request, *callback_args, **callback_kwargs)
  File "/home/kalinins/.virtualenvs/zapsum/zapsum/app_accounts/views.py", line 88, in ajax_username_check
    if username_req.exist():
AttributeError: 'User' object has no attribute 'exist'
Internal Server Error: /accounts/ajax_username_check/
Traceback (most recent call last):
  File "/home/kalinins/.virtualenvs/zapsum/lib/python3.4/site-packages/django/core/handlers/base.py", line 112, in get_response
    response = wrapped_callback(request, *callback_args, **callback_kwargs)
  File "/home/kalinins/.virtualenvs/zapsum/zapsum/app_accounts/views.py", line 90, in ajax_username_check
    if username_req.exist():
AttributeError: 'User' object has no attribute 'exist'
Internal Server Error: /accounts/ajax_username_check/
Traceback (most recent call last):
  File "/home/kalinins/.virtualenvs/zapsum/lib/python3.4/site-packages/django/core/handlers/base.py", line 112, in get_response
    response = wrapped_callback(request, *callback_args, **callback_kwargs)
  File "/home/kalinins/.virtualenvs/zapsum/zapsum/app_accounts/views.py", line 90, in ajax_username_check
    if username_req.exist():
AttributeError: 'User' object has no attribute 'exist'
Internal Server Error: /accounts/ajax_username_check/
Traceback (most recent call last):
  File "/home/kalinins/.virtualenvs/zapsum/lib/python3.4/site-packages/django/core/handlers/base.py", line 112, in get_response
    response = wrapped_callback(request, *callback_args, **callback_kwargs)
  File "/home/kalinins/.virtualenvs/zapsum/zapsum/app_accounts/views.py", line 88, in ajax_username_check
    f.write(bytes(username_req, 'UTF-8'))
TypeError: encoding or errors without a string argument
Internal Server Error: /accounts/ajax_username_check/
Traceback (most recent call last):
  File "/home/kalinins/.virtualenvs/zapsum/lib/python3.4/site-packages/django/core/handlers/base.py", line 112, in get_response
    response = wrapped_callback(request, *callback_args, **callback_kwargs)
  File "/home/kalinins/.virtualenvs/zapsum/zapsum/app_accounts/views.py", line 88, in ajax_username_check
    f.write(bytes(username_req.exist(), 'UTF-8'))
AttributeError: 'User' object has no attribute 'exist'
Internal Server Error: /accounts/ajax_username_check/
Traceback (most recent call last):
  File "/home/kalinins/.virtualenvs/zapsum/lib/python3.4/site-packages/django/core/handlers/base.py", line 112, in get_response
    response = wrapped_callback(request, *callback_args, **callback_kwargs)
  File "/home/kalinins/.virtualenvs/zapsum/zapsum/app_accounts/views.py", line 88, in ajax_username_check
    f.write(bytes(username_req, 'UTF-8'))
TypeError: encoding or errors without a string argument
Internal Server Error: /accounts/ajax_username_check/
Traceback (most recent call last):
  File "/home/kalinins/.virtualenvs/zapsum/lib/python3.4/site-packages/django/core/handlers/base.py", line 112, in get_response
    response = wrapped_callback(request, *callback_args, **callback_kwargs)
  File "/home/kalinins/.virtualenvs/zapsum/zapsum/app_accounts/views.py", line 88, in ajax_username_check
    f.write(bytes(username_req, 'UTF-8'))
TypeError: encoding or errors without a string argument
Internal Server Error: /accounts/ajax_username_check/
Traceback (most recent call last):
  File "/home/kalinins/.virtualenvs/zapsum/lib/python3.4/site-packages/django/core/handlers/base.py", line 112, in get_response
    response = wrapped_callback(request, *callback_args, **callback_kwargs)
  File "/home/kalinins/.virtualenvs/zapsum/zapsum/app_accounts/views.py", line 90, in ajax_username_check
    if username_req.exist():
AttributeError: 'User' object has no attribute 'exist'
Internal Server Error: /accounts/authentication/
Traceback (most recent call last):
  File "/home/kalinins/.virtualenvs/zapsum/lib/python3.4/site-packages/django/core/handlers/base.py", line 99, in get_response
    resolver_match = resolver.resolve(request.path_info)
  File "/home/kalinins/.virtualenvs/zapsum/lib/python3.4/site-packages/django/core/urlresolvers.py", line 339, in resolve
    sub_match = pattern.resolve(new_path)
  File "/home/kalinins/.virtualenvs/zapsum/lib/python3.4/site-packages/django/core/urlresolvers.py", line 339, in resolve
    sub_match = pattern.resolve(new_path)
  File "/home/kalinins/.virtualenvs/zapsum/lib/python3.4/site-packages/django/core/urlresolvers.py", line 223, in resolve
    return ResolverMatch(self.callback, args, kwargs, self.name)
  File "/home/kalinins/.virtualenvs/zapsum/lib/python3.4/site-packages/django/core/urlresolvers.py", line 230, in callback
    self._callback = get_callable(self._callback_str)
  File "/home/kalinins/.virtualenvs/zapsum/lib/python3.4/site-packages/django/utils/functional.py", line 32, in wrapper
    result = func(*args)
  File "/home/kalinins/.virtualenvs/zapsum/lib/python3.4/site-packages/django/core/urlresolvers.py", line 97, in get_callable
    mod = import_module(mod_name)
  File "/home/kalinins/.virtualenvs/zapsum/lib/python3.4/importlib/__init__.py", line 109, in import_module
    return _bootstrap._gcd_import(name[level:], package, level)
  File "<frozen importlib._bootstrap>", line 2231, in _gcd_import
  File "<frozen importlib._bootstrap>", line 2214, in _find_and_load
  File "<frozen importlib._bootstrap>", line 2203, in _find_and_load_unlocked
  File "<frozen importlib._bootstrap>", line 1200, in _load_unlocked
  File "<frozen importlib._bootstrap>", line 1129, in _exec
  File "<frozen importlib._bootstrap>", line 1444, in exec_module
  File "<frozen importlib._bootstrap>", line 1549, in get_code
  File "<frozen importlib._bootstrap>", line 1509, in source_to_code
  File "<frozen importlib._bootstrap>", line 321, in _call_with_frames_removed
  File "/home/kalinins/.virtualenvs/zapsum/zapsum/app_accounts/views.py", line 92
    with open(os.path.join(settings.BASE_DIR, "debug_local.txt"), "wb") as f:
       ^
IndentationError: expected an indented block
Internal Server Error: /accounts/ajax_username_check/
Traceback (most recent call last):
  File "/home/kalinins/.virtualenvs/zapsum/lib/python3.4/site-packages/django/core/handlers/base.py", line 112, in get_response
    response = wrapped_callback(request, *callback_args, **callback_kwargs)
  File "/home/kalinins/.virtualenvs/zapsum/zapsum/app_accounts/views.py", line 88, in ajax_username_check
    if username_req.exist():
AttributeError: 'User' object has no attribute 'exist'
Internal Server Error: /accounts/ajax_username_check/
Traceback (most recent call last):
  File "/home/kalinins/.virtualenvs/zapsum/lib/python3.4/site-packages/django/core/handlers/base.py", line 112, in get_response
    response = wrapped_callback(request, *callback_args, **callback_kwargs)
  File "/home/kalinins/.virtualenvs/zapsum/zapsum/app_accounts/views.py", line 88, in ajax_username_check
    if username_req.exist():
AttributeError: 'User' object has no attribute 'exist'
Internal Server Error: /accounts/ajax_username_check/
Traceback (most recent call last):
  File "/home/kalinins/.virtualenvs/zapsum/lib/python3.4/site-packages/django/core/handlers/base.py", line 112, in get_response
    response = wrapped_callback(request, *callback_args, **callback_kwargs)
  File "/home/kalinins/.virtualenvs/zapsum/zapsum/app_accounts/views.py", line 88, in ajax_username_check
    if username_req.count() > 0:
AttributeError: 'User' object has no attribute 'count'
Internal Server Error: /accounts/authentication/
Traceback (most recent call last):
  File "/home/kalinins/.virtualenvs/zapsum/lib/python3.4/site-packages/django/core/handlers/base.py", line 99, in get_response
    resolver_match = resolver.resolve(request.path_info)
  File "/home/kalinins/.virtualenvs/zapsum/lib/python3.4/site-packages/django/core/urlresolvers.py", line 339, in resolve
    sub_match = pattern.resolve(new_path)
  File "/home/kalinins/.virtualenvs/zapsum/lib/python3.4/site-packages/django/core/urlresolvers.py", line 339, in resolve
    sub_match = pattern.resolve(new_path)
  File "/home/kalinins/.virtualenvs/zapsum/lib/python3.4/site-packages/django/core/urlresolvers.py", line 223, in resolve
    return ResolverMatch(self.callback, args, kwargs, self.name)
  File "/home/kalinins/.virtualenvs/zapsum/lib/python3.4/site-packages/django/core/urlresolvers.py", line 230, in callback
    self._callback = get_callable(self._callback_str)
  File "/home/kalinins/.virtualenvs/zapsum/lib/python3.4/site-packages/django/utils/functional.py", line 32, in wrapper
    result = func(*args)
  File "/home/kalinins/.virtualenvs/zapsum/lib/python3.4/site-packages/django/core/urlresolvers.py", line 97, in get_callable
    mod = import_module(mod_name)
  File "/home/kalinins/.virtualenvs/zapsum/lib/python3.4/importlib/__init__.py", line 109, in import_module
    return _bootstrap._gcd_import(name[level:], package, level)
  File "<frozen importlib._bootstrap>", line 2231, in _gcd_import
  File "<frozen importlib._bootstrap>", line 2214, in _find_and_load
  File "<frozen importlib._bootstrap>", line 2203, in _find_and_load_unlocked
  File "<frozen importlib._bootstrap>", line 1200, in _load_unlocked
  File "<frozen importlib._bootstrap>", line 1129, in _exec
  File "<frozen importlib._bootstrap>", line 1444, in exec_module
  File "<frozen importlib._bootstrap>", line 1549, in get_code
  File "<frozen importlib._bootstrap>", line 1509, in source_to_code
  File "<frozen importlib._bootstrap>", line 321, in _call_with_frames_removed
  File "/home/kalinins/.virtualenvs/zapsum/zapsum/app_accounts/views.py", line 89
    f.write(bytes(username_req.count() 'UTF-8'))
                                             ^
SyntaxError: invalid syntax
Internal Server Error: /accounts/ajax_username_check/
Traceback (most recent call last):
  File "/home/kalinins/.virtualenvs/zapsum/lib/python3.4/site-packages/django/core/handlers/base.py", line 112, in get_response
    response = wrapped_callback(request, *callback_args, **callback_kwargs)
  File "/home/kalinins/.virtualenvs/zapsum/zapsum/app_accounts/views.py", line 89, in ajax_username_check
    f.write(bytes(username_req.count(), 'UTF-8'))
AttributeError: 'User' object has no attribute 'count'
Internal Server Error: /accounts/ajax_username_check/
Traceback (most recent call last):
  File "/home/kalinins/.virtualenvs/zapsum/lib/python3.4/site-packages/django/core/handlers/base.py", line 112, in get_response
    response = wrapped_callback(request, *callback_args, **callback_kwargs)
  File "/home/kalinins/.virtualenvs/zapsum/zapsum/app_accounts/views.py", line 89, in ajax_username_check
    f.write(bytes(len(username_req), 'UTF-8'))
TypeError: object of type 'User' has no len()
Internal Server Error: /accounts/ajax_username_check/
Traceback (most recent call last):
  File "/home/kalinins/.virtualenvs/zapsum/lib/python3.4/site-packages/django/core/handlers/base.py", line 112, in get_response
    response = wrapped_callback(request, *callback_args, **callback_kwargs)
  File "/home/kalinins/.virtualenvs/zapsum/zapsum/app_accounts/views.py", line 90, in ajax_username_check
    f.write(bytes('e' 'UTF-8'))
TypeError: string argument without an encoding
Internal Server Error: /accounts/ajax_username_check/
Traceback (most recent call last):
  File "/home/kalinins/.virtualenvs/zapsum/lib/python3.4/site-packages/django/core/handlers/base.py", line 112, in get_response
    response = wrapped_callback(request, *callback_args, **callback_kwargs)
  File "/home/kalinins/.virtualenvs/zapsum/zapsum/app_accounts/views.py", line 90, in ajax_username_check
    f.write(bytes('e' 'UTF-8'))
TypeError: string argument without an encoding
Internal Server Error: /accounts/ajax_username_check/
Traceback (most recent call last):
  File "/home/kalinins/.virtualenvs/zapsum/lib/python3.4/site-packages/django/core/handlers/base.py", line 112, in get_response
    response = wrapped_callback(request, *callback_args, **callback_kwargs)
  File "/home/kalinins/.virtualenvs/zapsum/zapsum/app_accounts/views.py", line 86, in ajax_username_check
    username_req = User.objects.get(username=username)
  File "/home/kalinins/.virtualenvs/zapsum/lib/python3.4/site-packages/django/db/models/manager.py", line 151, in get
    return self.get_queryset().get(*args, **kwargs)
  File "/home/kalinins/.virtualenvs/zapsum/lib/python3.4/site-packages/django/db/models/query.py", line 310, in get
    self.model._meta.object_name)
django.contrib.auth.models.DoesNotExist: User matching query does not exist.
Internal Server Error: /accounts/ajax_username_check/
Traceback (most recent call last):
  File "/home/kalinins/.virtualenvs/zapsum/lib/python3.4/site-packages/django/core/handlers/base.py", line 112, in get_response
    response = wrapped_callback(request, *callback_args, **callback_kwargs)
  File "/home/kalinins/.virtualenvs/zapsum/zapsum/app_accounts/views.py", line 86, in ajax_username_check
    username_req = User.objects.get(username=username)
  File "/home/kalinins/.virtualenvs/zapsum/lib/python3.4/site-packages/django/db/models/manager.py", line 151, in get
    return self.get_queryset().get(*args, **kwargs)
  File "/home/kalinins/.virtualenvs/zapsum/lib/python3.4/site-packages/django/db/models/query.py", line 310, in get
    self.model._meta.object_name)
django.contrib.auth.models.DoesNotExist: User matching query does not exist.
Internal Server Error: /accounts/authentication/
Traceback (most recent call last):
  File "/home/kalinins/.virtualenvs/zapsum/lib/python3.4/site-packages/django/core/handlers/base.py", line 99, in get_response
    resolver_match = resolver.resolve(request.path_info)
  File "/home/kalinins/.virtualenvs/zapsum/lib/python3.4/site-packages/django/core/urlresolvers.py", line 339, in resolve
    sub_match = pattern.resolve(new_path)
  File "/home/kalinins/.virtualenvs/zapsum/lib/python3.4/site-packages/django/core/urlresolvers.py", line 339, in resolve
    sub_match = pattern.resolve(new_path)
  File "/home/kalinins/.virtualenvs/zapsum/lib/python3.4/site-packages/django/core/urlresolvers.py", line 223, in resolve
    return ResolverMatch(self.callback, args, kwargs, self.name)
  File "/home/kalinins/.virtualenvs/zapsum/lib/python3.4/site-packages/django/core/urlresolvers.py", line 230, in callback
    self._callback = get_callable(self._callback_str)
  File "/home/kalinins/.virtualenvs/zapsum/lib/python3.4/site-packages/django/utils/functional.py", line 32, in wrapper
    result = func(*args)
  File "/home/kalinins/.virtualenvs/zapsum/lib/python3.4/site-packages/django/core/urlresolvers.py", line 97, in get_callable
    mod = import_module(mod_name)
  File "/home/kalinins/.virtualenvs/zapsum/lib/python3.4/importlib/__init__.py", line 109, in import_module
    return _bootstrap._gcd_import(name[level:], package, level)
  File "<frozen importlib._bootstrap>", line 2231, in _gcd_import
  File "<frozen importlib._bootstrap>", line 2214, in _find_and_load
  File "<frozen importlib._bootstrap>", line 2203, in _find_and_load_unlocked
  File "<frozen importlib._bootstrap>", line 1200, in _load_unlocked
  File "<frozen importlib._bootstrap>", line 1129, in _exec
  File "<frozen importlib._bootstrap>", line 1444, in exec_module
  File "<frozen importlib._bootstrap>", line 1549, in get_code
  File "<frozen importlib._bootstrap>", line 1509, in source_to_code
  File "<frozen importlib._bootstrap>", line 321, in _call_with_frames_removed
  File "/home/kalinins/.virtualenvs/zapsum/zapsum/app_accounts/views.py", line 92
    with open(os.path.join(settings.BASE_DIR, "debug_local.txt"), "wb") as f:
       ^
IndentationError: expected an indented block
Internal Server Error: /accounts/ajax_username_check/
Traceback (most recent call last):
  File "/home/kalinins/.virtualenvs/zapsum/lib/python3.4/site-packages/django/core/handlers/base.py", line 112, in get_response
    response = wrapped_callback(request, *callback_args, **callback_kwargs)
  File "/home/kalinins/.virtualenvs/zapsum/zapsum/app_accounts/views.py", line 88, in ajax_username_check
    if username_req.exists():
AttributeError: 'User' object has no attribute 'exists'
Internal Server Error: /accounts/ajax_username_check/
Traceback (most recent call last):
  File "/home/kalinins/.virtualenvs/zapsum/lib/python3.4/site-packages/django/core/handlers/base.py", line 112, in get_response
    response = wrapped_callback(request, *callback_args, **callback_kwargs)
  File "/home/kalinins/.virtualenvs/zapsum/zapsum/app_accounts/views.py", line 86, in ajax_username_check
    username_req = User.objects.get(username=username)
  File "/home/kalinins/.virtualenvs/zapsum/lib/python3.4/site-packages/django/db/models/manager.py", line 151, in get
    return self.get_queryset().get(*args, **kwargs)
  File "/home/kalinins/.virtualenvs/zapsum/lib/python3.4/site-packages/django/db/models/query.py", line 310, in get
    self.model._meta.object_name)
django.contrib.auth.models.DoesNotExist: User matching query does not exist.
Internal Server Error: /accounts/ajax_username_check/
Traceback (most recent call last):
  File "/home/kalinins/.virtualenvs/zapsum/lib/python3.4/site-packages/django/core/handlers/base.py", line 112, in get_response
    response = wrapped_callback(request, *callback_args, **callback_kwargs)
  File "/home/kalinins/.virtualenvs/zapsum/zapsum/app_accounts/views.py", line 88, in ajax_username_check
    if username_req.exists():
AttributeError: 'User' object has no attribute 'exists'
Internal Server Error: /accounts/ajax_username_check/
Traceback (most recent call last):
  File "/home/kalinins/.virtualenvs/zapsum/lib/python3.4/site-packages/django/core/handlers/base.py", line 112, in get_response
    response = wrapped_callback(request, *callback_args, **callback_kwargs)
  File "/home/kalinins/.virtualenvs/zapsum/zapsum/app_accounts/views.py", line 88, in ajax_username_check
    if username_req.exists():
AttributeError: 'User' object has no attribute 'exists'
Internal Server Error: /accounts/ajax_username_check/
Traceback (most recent call last):
  File "/home/kalinins/.virtualenvs/zapsum/lib/python3.4/site-packages/django/core/handlers/base.py", line 112, in get_response
    response = wrapped_callback(request, *callback_args, **callback_kwargs)
  File "/home/kalinins/.virtualenvs/zapsum/zapsum/app_accounts/views.py", line 86, in ajax_username_check
    username_req = User.objects.get(username=username)
  File "/home/kalinins/.virtualenvs/zapsum/lib/python3.4/site-packages/django/db/models/manager.py", line 151, in get
    return self.get_queryset().get(*args, **kwargs)
  File "/home/kalinins/.virtualenvs/zapsum/lib/python3.4/site-packages/django/db/models/query.py", line 310, in get
    self.model._meta.object_name)
django.contrib.auth.models.DoesNotExist: User matching query does not exist.
Internal Server Error: /accounts/ajax_username_check/
Traceback (most recent call last):
  File "/home/kalinins/.virtualenvs/zapsum/lib/python3.4/site-packages/django/core/handlers/base.py", line 112, in get_response
    response = wrapped_callback(request, *callback_args, **callback_kwargs)
  File "/home/kalinins/.virtualenvs/zapsum/zapsum/app_accounts/views.py", line 86, in ajax_username_check
    username_req = User.objects.get(username=username)
  File "/home/kalinins/.virtualenvs/zapsum/lib/python3.4/site-packages/django/db/models/manager.py", line 151, in get
    return self.get_queryset().get(*args, **kwargs)
  File "/home/kalinins/.virtualenvs/zapsum/lib/python3.4/site-packages/django/db/models/query.py", line 310, in get
    self.model._meta.object_name)
django.contrib.auth.models.DoesNotExist: User matching query does not exist.
Internal Server Error: /accounts/ajax_username_check/
Traceback (most recent call last):
  File "/home/kalinins/.virtualenvs/zapsum/lib/python3.4/site-packages/django/core/handlers/base.py", line 112, in get_response
    response = wrapped_callback(request, *callback_args, **callback_kwargs)
  File "/home/kalinins/.virtualenvs/zapsum/zapsum/app_accounts/views.py", line 88, in ajax_username_check
    if username_req.username.exists():
AttributeError: 'str' object has no attribute 'exists'
Internal Server Error: /accounts/ajax_username_check/
Traceback (most recent call last):
  File "/home/kalinins/.virtualenvs/zapsum/lib/python3.4/site-packages/django/core/handlers/base.py", line 112, in get_response
    response = wrapped_callback(request, *callback_args, **callback_kwargs)
  File "/home/kalinins/.virtualenvs/zapsum/zapsum/app_accounts/views.py", line 88, in ajax_username_check
    if username_req.count():
AttributeError: 'User' object has no attribute 'count'
Internal Server Error: /accounts/ajax_username_check/
Traceback (most recent call last):
  File "/home/kalinins/.virtualenvs/zapsum/lib/python3.4/site-packages/django/core/handlers/base.py", line 112, in get_response
    response = wrapped_callback(request, *callback_args, **callback_kwargs)
  File "/home/kalinins/.virtualenvs/zapsum/zapsum/app_accounts/views.py", line 86, in ajax_username_check
    username_req = User.objects.get(username=username)
  File "/home/kalinins/.virtualenvs/zapsum/lib/python3.4/site-packages/django/db/models/manager.py", line 151, in get
    return self.get_queryset().get(*args, **kwargs)
  File "/home/kalinins/.virtualenvs/zapsum/lib/python3.4/site-packages/django/db/models/query.py", line 310, in get
    self.model._meta.object_name)
django.contrib.auth.models.DoesNotExist: User matching query does not exist.
Internal Server Error: /accounts/ajax_username_check/
Traceback (most recent call last):
  File "/home/kalinins/.virtualenvs/zapsum/lib/python3.4/site-packages/django/core/handlers/base.py", line 112, in get_response
    response = wrapped_callback(request, *callback_args, **callback_kwargs)
  File "/home/kalinins/.virtualenvs/zapsum/zapsum/app_accounts/views.py", line 88, in ajax_username_check
    result = username_req.count()
AttributeError: 'User' object has no attribute 'count'
Internal Server Error: /accounts/ajax_username_check/
Traceback (most recent call last):
  File "/home/kalinins/.virtualenvs/zapsum/lib/python3.4/site-packages/django/core/handlers/base.py", line 112, in get_response
    response = wrapped_callback(request, *callback_args, **callback_kwargs)
  File "/home/kalinins/.virtualenvs/zapsum/zapsum/app_accounts/views.py", line 88, in ajax_username_check
    if username_req.username.exists():
AttributeError: 'str' object has no attribute 'exists'
Internal Server Error: /accounts/ajax_username_check/
Traceback (most recent call last):
  File "/home/kalinins/.virtualenvs/zapsum/lib/python3.4/site-packages/django/core/handlers/base.py", line 112, in get_response
    response = wrapped_callback(request, *callback_args, **callback_kwargs)
  File "/home/kalinins/.virtualenvs/zapsum/zapsum/app_accounts/views.py", line 88, in ajax_username_check
    if username_req.exists():
AttributeError: 'User' object has no attribute 'exists'
Internal Server Error: /accounts/ajax_username_check/
Traceback (most recent call last):
  File "/home/kalinins/.virtualenvs/zapsum/lib/python3.4/site-packages/django/core/handlers/base.py", line 112, in get_response
    response = wrapped_callback(request, *callback_args, **callback_kwargs)
  File "/home/kalinins/.virtualenvs/zapsum/zapsum/app_accounts/views.py", line 88, in ajax_username_check
    if username_req.exists():
AttributeError: 'User' object has no attribute 'exists'
Internal Server Error: /accounts/ajax_username_check/
Traceback (most recent call last):
  File "/home/kalinins/.virtualenvs/zapsum/lib/python3.4/site-packages/django/core/handlers/base.py", line 112, in get_response
    response = wrapped_callback(request, *callback_args, **callback_kwargs)
  File "/home/kalinins/.virtualenvs/zapsum/zapsum/app_accounts/views.py", line 89, in ajax_username_check
    result = username_req.username
AttributeError: 'QuerySet' object has no attribute 'username'
Internal Server Error: /accounts/ajax_username_check/
Traceback (most recent call last):
  File "/home/kalinins/.virtualenvs/zapsum/lib/python3.4/site-packages/django/core/handlers/base.py", line 112, in get_response
    response = wrapped_callback(request, *callback_args, **callback_kwargs)
  File "/home/kalinins/.virtualenvs/zapsum/zapsum/app_accounts/views.py", line 101, in ajax_username_check
    'error_login_login': error_login_login,
UnboundLocalError: local variable 'error_login_login' referenced before assignment
Internal Server Error: /accounts/ajax_username_check/
Traceback (most recent call last):
  File "/home/kalinins/.virtualenvs/zapsum/lib/python3.4/site-packages/django/core/handlers/base.py", line 112, in get_response
    response = wrapped_callback(request, *callback_args, **callback_kwargs)
  File "/home/kalinins/.virtualenvs/zapsum/zapsum/app_accounts/views.py", line 101, in ajax_username_check
    'error_login_login': error_login_login,
UnboundLocalError: local variable 'error_login_login' referenced before assignment
Internal Server Error: /accounts/ajax_username_check/
Traceback (most recent call last):
  File "/home/kalinins/.virtualenvs/zapsum/lib/python3.4/site-packages/django/core/handlers/base.py", line 112, in get_response
    response = wrapped_callback(request, *callback_args, **callback_kwargs)
  File "/home/kalinins/.virtualenvs/zapsum/zapsum/app_accounts/views.py", line 91, in ajax_username_check
    f.write(bytes(username_req[0].username, 'UTF-8'))
  File "/home/kalinins/.virtualenvs/zapsum/lib/python3.4/site-packages/django/db/models/query.py", line 132, in __getitem__
    return list(qs)[0]
IndexError: list index out of range
Internal Server Error: /accounts/ajax_username_check/
Traceback (most recent call last):
  File "/home/kalinins/.virtualenvs/zapsum/lib/python3.4/site-packages/django/core/handlers/base.py", line 112, in get_response
    response = wrapped_callback(request, *callback_args, **callback_kwargs)
  File "/home/kalinins/.virtualenvs/zapsum/zapsum/app_accounts/views.py", line 91, in ajax_username_check
    if username_req[0].username == username:
  File "/home/kalinins/.virtualenvs/zapsum/lib/python3.4/site-packages/django/db/models/query.py", line 132, in __getitem__
    return list(qs)[0]
IndexError: list index out of range
Internal Server Error: /accounts/ajax_username_check/
Traceback (most recent call last):
  File "/home/kalinins/.virtualenvs/zapsum/lib/python3.4/site-packages/django/core/handlers/base.py", line 112, in get_response
    response = wrapped_callback(request, *callback_args, **callback_kwargs)
  File "/home/kalinins/.virtualenvs/zapsum/zapsum/app_accounts/views.py", line 106, in ajax_username_check
    f.write(bytes(username_req.password, 'UTF-8'))
AttributeError: 'QuerySet' object has no attribute 'password'
Internal Server Error: /accounts/ajax_username_check/
Traceback (most recent call last):
  File "/home/kalinins/.virtualenvs/zapsum/lib/python3.4/site-packages/django/core/handlers/base.py", line 112, in get_response
    response = wrapped_callback(request, *callback_args, **callback_kwargs)
  File "/home/kalinins/.virtualenvs/zapsum/zapsum/app_accounts/views.py", line 110, in ajax_username_check
    'pass': username_req.password,
AttributeError: 'QuerySet' object has no attribute 'password'
Internal Server Error: /accounts/ajax_username_check/
Traceback (most recent call last):
  File "/home/kalinins/.virtualenvs/zapsum/lib/python3.4/site-packages/django/core/handlers/base.py", line 112, in get_response
    response = wrapped_callback(request, *callback_args, **callback_kwargs)
  File "/home/kalinins/.virtualenvs/zapsum/zapsum/app_accounts/views.py", line 110, in ajax_username_check
    'pass': username_req[0].password,
  File "/home/kalinins/.virtualenvs/zapsum/lib/python3.4/site-packages/django/db/models/query.py", line 132, in __getitem__
    return list(qs)[0]
IndexError: list index out of range
Internal Server Error: /accounts/ajax_registration_check/
Traceback (most recent call last):
  File "/home/kalinins/.virtualenvs/zapsum/lib/python3.4/site-packages/django/core/handlers/base.py", line 112, in get_response
    response = wrapped_callback(request, *callback_args, **callback_kwargs)
  File "/home/kalinins/.virtualenvs/zapsum/zapsum/app_accounts/views.py", line 197, in ajax_registration_check
    if(password1 != password2):
NameError: name 'password2' is not defined
Internal Server Error: /accounts/ajax_registration_check/
Traceback (most recent call last):
  File "/home/kalinins/.virtualenvs/zapsum/lib/python3.4/site-packages/django/core/handlers/base.py", line 112, in get_response
    response = wrapped_callback(request, *callback_args, **callback_kwargs)
  File "/home/kalinins/.virtualenvs/zapsum/zapsum/app_accounts/views.py", line 201, in ajax_registration_check
    console.log(error_password1);
NameError: name 'console' is not defined
Internal Server Error: /accounts/ajax_registration_check/
Traceback (most recent call last):
  File "/home/kalinins/.virtualenvs/zapsum/lib/python3.4/site-packages/django/core/handlers/base.py", line 112, in get_response
    response = wrapped_callback(request, *callback_args, **callback_kwargs)
  File "/home/kalinins/.virtualenvs/zapsum/zapsum/app_accounts/views.py", line 201, in ajax_registration_check
    console.log(error_password1);
NameError: name 'console' is not defined
Internal Server Error: /accounts/ajax_registration_check/
Traceback (most recent call last):
  File "/home/kalinins/.virtualenvs/zapsum/lib/python3.4/site-packages/django/core/handlers/base.py", line 112, in get_response
    response = wrapped_callback(request, *callback_args, **callback_kwargs)
  File "/home/kalinins/.virtualenvs/zapsum/zapsum/app_accounts/views.py", line 178, in ajax_registration_check
    EMAIL_REGEX = re.compile(r')@(?:[A-Z0-9-]+\.)+[A-Z]{2,6}$')
  File "/home/kalinins/.virtualenvs/zapsum/lib/python3.4/re.py", line 219, in compile
    return _compile(pattern, flags)
  File "/home/kalinins/.virtualenvs/zapsum/lib/python3.4/re.py", line 288, in _compile
    p = sre_compile.compile(pattern, flags)
  File "/home/kalinins/.virtualenvs/zapsum/lib/python3.4/sre_compile.py", line 465, in compile
    p = sre_parse.parse(p, flags)
  File "/home/kalinins/.virtualenvs/zapsum/lib/python3.4/sre_parse.py", line 751, in parse
    raise error("unbalanced parenthesis")
sre_constants.error: unbalanced parenthesis
Internal Server Error: /accounts/registration/
Traceback (most recent call last):
  File "/home/kalinins/.virtualenvs/zapsum/lib/python3.4/site-packages/django/core/handlers/base.py", line 112, in get_response
    response = wrapped_callback(request, *callback_args, **callback_kwargs)
  File "/home/kalinins/.virtualenvs/zapsum/zapsum/app_accounts/views.py", line 27, in registration
    auth.login(request, user)
NameError: name 'user' is not defined
Not Found: /favicon.ico
Internal Server Error: /accounts/registration/
Traceback (most recent call last):
  File "/home/kalinins/.virtualenvs/zapsum/lib/python3.4/site-packages/django/core/handlers/base.py", line 112, in get_response
    response = wrapped_callback(request, *callback_args, **callback_kwargs)
  File "/home/kalinins/.virtualenvs/zapsum/zapsum/app_accounts/views.py", line 31, in registration
    auth.login(request, user)
  File "/home/kalinins/.virtualenvs/zapsum/lib/python3.4/site-packages/django/contrib/auth/__init__.py", line 85, in login
    request.session[BACKEND_SESSION_KEY] = user.backend
  File "/home/kalinins/.virtualenvs/zapsum/lib/python3.4/site-packages/django/utils/functional.py", line 214, in inner
    return func(self._wrapped, *args)
AttributeError: 'AnonymousUser' object has no attribute 'backend'
Internal Server Error: /accounts/registration/
Traceback (most recent call last):
  File "/home/kalinins/.virtualenvs/zapsum/lib/python3.4/site-packages/django/core/handlers/base.py", line 112, in get_response
    response = wrapped_callback(request, *callback_args, **callback_kwargs)
  File "/home/kalinins/.virtualenvs/zapsum/zapsum/app_accounts/views.py", line 31, in registration
    auth.login(request, user)
  File "/home/kalinins/.virtualenvs/zapsum/lib/python3.4/site-packages/django/contrib/auth/__init__.py", line 85, in login
    request.session[BACKEND_SESSION_KEY] = user.backend
  File "/home/kalinins/.virtualenvs/zapsum/lib/python3.4/site-packages/django/utils/functional.py", line 214, in inner
    return func(self._wrapped, *args)
AttributeError: 'AnonymousUser' object has no attribute 'backend'
Internal Server Error: /accounts/ajax_login_check/
Traceback (most recent call last):
  File "/home/kalinins/.virtualenvs/zapsum/lib/python3.4/site-packages/django/core/handlers/base.py", line 112, in get_response
    response = wrapped_callback(request, *callback_args, **callback_kwargs)
  File "/home/kalinins/.virtualenvs/zapsum/zapsum/app_accounts/views.py", line 101, in ajax_login_check
    if username_req.active == 0:
AttributeError: 'QuerySet' object has no attribute 'active'
Internal Server Error: /accounts/ajax_login_check/
Traceback (most recent call last):
  File "/home/kalinins/.virtualenvs/zapsum/lib/python3.4/site-packages/django/core/handlers/base.py", line 112, in get_response
    response = wrapped_callback(request, *callback_args, **callback_kwargs)
  File "/home/kalinins/.virtualenvs/zapsum/zapsum/app_accounts/views.py", line 101, in ajax_login_check
    if username_req.active == 0:
AttributeError: 'QuerySet' object has no attribute 'active'
Internal Server Error: /accounts/ajax_login_check/
Traceback (most recent call last):
  File "/home/kalinins/.virtualenvs/zapsum/lib/python3.4/site-packages/django/core/handlers/base.py", line 112, in get_response
    response = wrapped_callback(request, *callback_args, **callback_kwargs)
  File "/home/kalinins/.virtualenvs/zapsum/zapsum/app_accounts/views.py", line 101, in ajax_login_check
    if username_req.active == 0:
AttributeError: 'QuerySet' object has no attribute 'active'
Internal Server Error: /accounts/ajax_login_check/
Traceback (most recent call last):
  File "/home/kalinins/.virtualenvs/zapsum/lib/python3.4/site-packages/django/core/handlers/base.py", line 112, in get_response
    response = wrapped_callback(request, *callback_args, **callback_kwargs)
  File "/home/kalinins/.virtualenvs/zapsum/zapsum/app_accounts/views.py", line 101, in ajax_login_check
    if username_req.active == 0:
AttributeError: 'QuerySet' object has no attribute 'active'
Internal Server Error: /accounts/ajax_login_check/
Traceback (most recent call last):
  File "/home/kalinins/.virtualenvs/zapsum/lib/python3.4/site-packages/django/core/handlers/base.py", line 112, in get_response
    response = wrapped_callback(request, *callback_args, **callback_kwargs)
  File "/home/kalinins/.virtualenvs/zapsum/zapsum/app_accounts/views.py", line 101, in ajax_login_check
    if username_req.active == 0:
AttributeError: 'QuerySet' object has no attribute 'active'
Internal Server Error: /accounts/ajax_login_check/
Traceback (most recent call last):
  File "/home/kalinins/.virtualenvs/zapsum/lib/python3.4/site-packages/django/core/handlers/base.py", line 112, in get_response
    response = wrapped_callback(request, *callback_args, **callback_kwargs)
  File "/home/kalinins/.virtualenvs/zapsum/zapsum/app_accounts/views.py", line 101, in ajax_login_check
    if username_req.active == 0:
AttributeError: 'QuerySet' object has no attribute 'active'
Internal Server Error: /accounts/ajax_login_check/
Traceback (most recent call last):
  File "/home/kalinins/.virtualenvs/zapsum/lib/python3.4/site-packages/django/core/handlers/base.py", line 112, in get_response
    response = wrapped_callback(request, *callback_args, **callback_kwargs)
  File "/home/kalinins/.virtualenvs/zapsum/zapsum/app_accounts/views.py", line 101, in ajax_login_check
    if username_req.active == 0:
AttributeError: 'QuerySet' object has no attribute 'active'
Internal Server Error: /accounts/ajax_login_check/
Traceback (most recent call last):
  File "/home/kalinins/.virtualenvs/zapsum/lib/python3.4/site-packages/django/core/handlers/base.py", line 112, in get_response
    response = wrapped_callback(request, *callback_args, **callback_kwargs)
  File "/home/kalinins/.virtualenvs/zapsum/zapsum/app_accounts/views.py", line 101, in ajax_login_check
    if username_req.active == 0:
AttributeError: 'QuerySet' object has no attribute 'active'
Internal Server Error: /accounts/ajax_login_check/
Traceback (most recent call last):
  File "/home/kalinins/.virtualenvs/zapsum/lib/python3.4/site-packages/django/core/handlers/base.py", line 112, in get_response
    response = wrapped_callback(request, *callback_args, **callback_kwargs)
  File "/home/kalinins/.virtualenvs/zapsum/zapsum/app_accounts/views.py", line 101, in ajax_login_check
    if username_req.active == 0:
AttributeError: 'QuerySet' object has no attribute 'active'
Internal Server Error: /accounts/ajax_login_check/
Traceback (most recent call last):
  File "/home/kalinins/.virtualenvs/zapsum/lib/python3.4/site-packages/django/core/handlers/base.py", line 112, in get_response
    response = wrapped_callback(request, *callback_args, **callback_kwargs)
  File "/home/kalinins/.virtualenvs/zapsum/zapsum/app_accounts/views.py", line 101, in ajax_login_check
    if username_req.active == 0:
AttributeError: 'QuerySet' object has no attribute 'active'
Internal Server Error: /accounts/ajax_login_check/
Traceback (most recent call last):
  File "/home/kalinins/.virtualenvs/zapsum/lib/python3.4/site-packages/django/core/handlers/base.py", line 112, in get_response
    response = wrapped_callback(request, *callback_args, **callback_kwargs)
  File "/home/kalinins/.virtualenvs/zapsum/zapsum/app_accounts/views.py", line 101, in ajax_login_check
    if username_req.active == 0:
AttributeError: 'QuerySet' object has no attribute 'active'
Internal Server Error: /accounts/ajax_login_check/
Traceback (most recent call last):
  File "/home/kalinins/.virtualenvs/zapsum/lib/python3.4/site-packages/django/core/handlers/base.py", line 112, in get_response
    response = wrapped_callback(request, *callback_args, **callback_kwargs)
  File "/home/kalinins/.virtualenvs/zapsum/zapsum/app_accounts/views.py", line 101, in ajax_login_check
    if username_req.active == 0:
AttributeError: 'QuerySet' object has no attribute 'active'
Internal Server Error: /accounts/ajax_login_check/
Traceback (most recent call last):
  File "/home/kalinins/.virtualenvs/zapsum/lib/python3.4/site-packages/django/core/handlers/base.py", line 112, in get_response
    response = wrapped_callback(request, *callback_args, **callback_kwargs)
  File "/home/kalinins/.virtualenvs/zapsum/zapsum/app_accounts/views.py", line 101, in ajax_login_check
    if username_req.active == 0:
AttributeError: 'QuerySet' object has no attribute 'active'
Internal Server Error: /accounts/ajax_login_check/
Traceback (most recent call last):
  File "/home/kalinins/.virtualenvs/zapsum/lib/python3.4/site-packages/django/core/handlers/base.py", line 112, in get_response
    response = wrapped_callback(request, *callback_args, **callback_kwargs)
  File "/home/kalinins/.virtualenvs/zapsum/zapsum/app_accounts/views.py", line 101, in ajax_login_check
    if username_req.active == 0:
AttributeError: 'QuerySet' object has no attribute 'active'
Internal Server Error: /accounts/ajax_login_check/
Traceback (most recent call last):
  File "/home/kalinins/.virtualenvs/zapsum/lib/python3.4/site-packages/django/core/handlers/base.py", line 112, in get_response
    response = wrapped_callback(request, *callback_args, **callback_kwargs)
  File "/home/kalinins/.virtualenvs/zapsum/zapsum/app_accounts/views.py", line 101, in ajax_login_check
    if username_req.active == 0:
AttributeError: 'QuerySet' object has no attribute 'active'
Internal Server Error: /accounts/ajax_login_check/
Traceback (most recent call last):
  File "/home/kalinins/.virtualenvs/zapsum/lib/python3.4/site-packages/django/core/handlers/base.py", line 112, in get_response
    response = wrapped_callback(request, *callback_args, **callback_kwargs)
  File "/home/kalinins/.virtualenvs/zapsum/zapsum/app_accounts/views.py", line 101, in ajax_login_check
    if username_req.active == 0:
AttributeError: 'QuerySet' object has no attribute 'active'
Internal Server Error: /accounts/ajax_login_check/
Traceback (most recent call last):
  File "/home/kalinins/.virtualenvs/zapsum/lib/python3.4/site-packages/django/core/handlers/base.py", line 112, in get_response
    response = wrapped_callback(request, *callback_args, **callback_kwargs)
  File "/home/kalinins/.virtualenvs/zapsum/zapsum/app_accounts/views.py", line 101, in ajax_login_check
    if username_req.active == 0:
AttributeError: 'QuerySet' object has no attribute 'active'
Internal Server Error: /accounts/ajax_login_check/
Traceback (most recent call last):
  File "/home/kalinins/.virtualenvs/zapsum/lib/python3.4/site-packages/django/core/handlers/base.py", line 112, in get_response
    response = wrapped_callback(request, *callback_args, **callback_kwargs)
  File "/home/kalinins/.virtualenvs/zapsum/zapsum/app_accounts/views.py", line 101, in ajax_login_check
    if username_req.active == 0:
AttributeError: 'QuerySet' object has no attribute 'active'
Internal Server Error: /accounts/ajax_login_check/
Traceback (most recent call last):
  File "/home/kalinins/.virtualenvs/zapsum/lib/python3.4/site-packages/django/core/handlers/base.py", line 112, in get_response
    response = wrapped_callback(request, *callback_args, **callback_kwargs)
  File "/home/kalinins/.virtualenvs/zapsum/zapsum/app_accounts/views.py", line 101, in ajax_login_check
    if username_req.active == 0:
AttributeError: 'QuerySet' object has no attribute 'active'
Internal Server Error: /accounts/ajax_login_check/
Traceback (most recent call last):
  File "/home/kalinins/.virtualenvs/zapsum/lib/python3.4/site-packages/django/core/handlers/base.py", line 112, in get_response
    response = wrapped_callback(request, *callback_args, **callback_kwargs)
  File "/home/kalinins/.virtualenvs/zapsum/zapsum/app_accounts/views.py", line 101, in ajax_login_check
    if username_req.active == 0:
AttributeError: 'QuerySet' object has no attribute 'active'
Internal Server Error: /accounts/ajax_login_check/
Traceback (most recent call last):
  File "/home/kalinins/.virtualenvs/zapsum/lib/python3.4/site-packages/django/core/handlers/base.py", line 112, in get_response
    response = wrapped_callback(request, *callback_args, **callback_kwargs)
  File "/home/kalinins/.virtualenvs/zapsum/zapsum/app_accounts/views.py", line 101, in ajax_login_check
    if username_req.active == 0:
AttributeError: 'QuerySet' object has no attribute 'active'
Internal Server Error: /accounts/ajax_login_check/
Traceback (most recent call last):
  File "/home/kalinins/.virtualenvs/zapsum/lib/python3.4/site-packages/django/core/handlers/base.py", line 112, in get_response
    response = wrapped_callback(request, *callback_args, **callback_kwargs)
  File "/home/kalinins/.virtualenvs/zapsum/zapsum/app_accounts/views.py", line 101, in ajax_login_check
    if username_req.active == 0:
AttributeError: 'QuerySet' object has no attribute 'active'
Internal Server Error: /accounts/ajax_login_check/
Traceback (most recent call last):
  File "/home/kalinins/.virtualenvs/zapsum/lib/python3.4/site-packages/django/core/handlers/base.py", line 112, in get_response
    response = wrapped_callback(request, *callback_args, **callback_kwargs)
  File "/home/kalinins/.virtualenvs/zapsum/zapsum/app_accounts/views.py", line 101, in ajax_login_check
    if username_req.active == 0:
AttributeError: 'QuerySet' object has no attribute 'active'
Internal Server Error: /accounts/ajax_login_check/
Traceback (most recent call last):
  File "/home/kalinins/.virtualenvs/zapsum/lib/python3.4/site-packages/django/core/handlers/base.py", line 112, in get_response
    response = wrapped_callback(request, *callback_args, **callback_kwargs)
  File "/home/kalinins/.virtualenvs/zapsum/zapsum/app_accounts/views.py", line 101, in ajax_login_check
    if username_req.active == 0:
AttributeError: 'QuerySet' object has no attribute 'active'
Internal Server Error: /accounts/ajax_login_check/
Traceback (most recent call last):
  File "/home/kalinins/.virtualenvs/zapsum/lib/python3.4/site-packages/django/core/handlers/base.py", line 112, in get_response
    response = wrapped_callback(request, *callback_args, **callback_kwargs)
  File "/home/kalinins/.virtualenvs/zapsum/zapsum/app_accounts/views.py", line 101, in ajax_login_check
    if username_req.active == 0:
AttributeError: 'QuerySet' object has no attribute 'active'
Internal Server Error: /accounts/ajax_login_check/
Traceback (most recent call last):
  File "/home/kalinins/.virtualenvs/zapsum/lib/python3.4/site-packages/django/core/handlers/base.py", line 112, in get_response
    response = wrapped_callback(request, *callback_args, **callback_kwargs)
  File "/home/kalinins/.virtualenvs/zapsum/zapsum/app_accounts/views.py", line 101, in ajax_login_check
    if username_req.active == 0:
AttributeError: 'QuerySet' object has no attribute 'active'
Internal Server Error: /accounts/ajax_login_check/
Traceback (most recent call last):
  File "/home/kalinins/.virtualenvs/zapsum/lib/python3.4/site-packages/django/core/handlers/base.py", line 112, in get_response
    response = wrapped_callback(request, *callback_args, **callback_kwargs)
  File "/home/kalinins/.virtualenvs/zapsum/zapsum/app_accounts/views.py", line 101, in ajax_login_check
    if username_req.active == 0:
AttributeError: 'QuerySet' object has no attribute 'active'
Internal Server Error: /accounts/ajax_login_check/
Traceback (most recent call last):
  File "/home/kalinins/.virtualenvs/zapsum/lib/python3.4/site-packages/django/core/handlers/base.py", line 112, in get_response
    response = wrapped_callback(request, *callback_args, **callback_kwargs)
  File "/home/kalinins/.virtualenvs/zapsum/zapsum/app_accounts/views.py", line 101, in ajax_login_check
    if username_req.active == 0:
AttributeError: 'QuerySet' object has no attribute 'active'
Internal Server Error: /accounts/ajax_login_check/
Traceback (most recent call last):
  File "/home/kalinins/.virtualenvs/zapsum/lib/python3.4/site-packages/django/core/handlers/base.py", line 112, in get_response
    response = wrapped_callback(request, *callback_args, **callback_kwargs)
  File "/home/kalinins/.virtualenvs/zapsum/zapsum/app_accounts/views.py", line 101, in ajax_login_check
    if username_req.active == 0:
AttributeError: 'QuerySet' object has no attribute 'active'
Internal Server Error: /accounts/ajax_login_check/
Traceback (most recent call last):
  File "/home/kalinins/.virtualenvs/zapsum/lib/python3.4/site-packages/django/core/handlers/base.py", line 112, in get_response
    response = wrapped_callback(request, *callback_args, **callback_kwargs)
  File "/home/kalinins/.virtualenvs/zapsum/zapsum/app_accounts/views.py", line 101, in ajax_login_check
    if username_req.is_active == 0:
AttributeError: 'QuerySet' object has no attribute 'is_active'
Not Found: /account/delete_profile/
Forbidden (CSRF token missing or incorrect.): /accounts/delete_profile/
Forbidden (CSRF token missing or incorrect.): /accounts/delete_profile/
Forbidden (CSRF token missing or incorrect.): /accounts/delete_profile/
Not Found: /accounts/login/
Internal Server Error: /change_password/
Traceback (most recent call last):
  File "/home/kalinins/.virtualenvs/zapsum/lib/python3.4/site-packages/django/core/handlers/base.py", line 112, in get_response
    response = wrapped_callback(request, *callback_args, **callback_kwargs)
  File "/home/kalinins/.virtualenvs/zapsum/lib/python3.4/site-packages/django/contrib/auth/decorators.py", line 22, in _wrapped_view
    return view_func(request, *args, **kwargs)
  File "/home/kalinins/.virtualenvs/zapsum/zapsum/app_zapsum/views.py", line 86, in change_password
    form = ChangePasswordForm(instance=request)
  File "/home/kalinins/.virtualenvs/zapsum/zapsum/app_zapsum/forms.py", line 24, in __init__
    super(ChangePasswordForm, self).__init__(*args, **kwargs)
TypeError: __init__() got an unexpected keyword argument 'instance'
Internal Server Error: /change_password/
Traceback (most recent call last):
  File "/home/kalinins/.virtualenvs/zapsum/lib/python3.4/site-packages/django/core/handlers/base.py", line 112, in get_response
    response = wrapped_callback(request, *callback_args, **callback_kwargs)
  File "/home/kalinins/.virtualenvs/zapsum/lib/python3.4/site-packages/django/contrib/auth/decorators.py", line 22, in _wrapped_view
    return view_func(request, *args, **kwargs)
  File "/home/kalinins/.virtualenvs/zapsum/zapsum/app_zapsum/views.py", line 86, in change_password
    form = ChangePasswordForm(instance=request)
TypeError: __init__() got an unexpected keyword argument 'instance'
Internal Server Error: /change_password/
Traceback (most recent call last):
  File "/home/kalinins/.virtualenvs/zapsum/lib/python3.4/site-packages/django/core/handlers/base.py", line 112, in get_response
    response = wrapped_callback(request, *callback_args, **callback_kwargs)
  File "/home/kalinins/.virtualenvs/zapsum/lib/python3.4/site-packages/django/contrib/auth/decorators.py", line 22, in _wrapped_view
    return view_func(request, *args, **kwargs)
  File "/home/kalinins/.virtualenvs/zapsum/zapsum/app_zapsum/views.py", line 86, in change_password
    form = ChangePasswordForm(instance=request)
TypeError: __init__() got an unexpected keyword argument 'instance'
Internal Server Error: /change_password/
Traceback (most recent call last):
  File "/home/kalinins/.virtualenvs/zapsum/lib/python3.4/site-packages/django/core/handlers/base.py", line 112, in get_response
    response = wrapped_callback(request, *callback_args, **callback_kwargs)
  File "/home/kalinins/.virtualenvs/zapsum/lib/python3.4/site-packages/django/contrib/auth/decorators.py", line 22, in _wrapped_view
    return view_func(request, *args, **kwargs)
  File "/home/kalinins/.virtualenvs/zapsum/zapsum/app_zapsum/views.py", line 86, in change_password
    form = ChangePasswordForm(instance=request)
TypeError: __init__() got an unexpected keyword argument 'instance'
Internal Server Error: /change_password/
Traceback (most recent call last):
  File "/home/kalinins/.virtualenvs/zapsum/lib/python3.4/site-packages/django/core/handlers/base.py", line 112, in get_response
    response = wrapped_callback(request, *callback_args, **callback_kwargs)
  File "/home/kalinins/.virtualenvs/zapsum/lib/python3.4/site-packages/django/contrib/auth/decorators.py", line 22, in _wrapped_view
    return view_func(request, *args, **kwargs)
  File "/home/kalinins/.virtualenvs/zapsum/zapsum/app_zapsum/views.py", line 86, in change_password
    form = ChangePasswordForm(instance=request)
TypeError: __init__() got an unexpected keyword argument 'instance'
Internal Server Error: /change_password/
Traceback (most recent call last):
  File "/home/kalinins/.virtualenvs/zapsum/lib/python3.4/site-packages/django/core/handlers/base.py", line 112, in get_response
    response = wrapped_callback(request, *callback_args, **callback_kwargs)
  File "/home/kalinins/.virtualenvs/zapsum/lib/python3.4/site-packages/django/contrib/auth/decorators.py", line 22, in _wrapped_view
    return view_func(request, *args, **kwargs)
  File "/home/kalinins/.virtualenvs/zapsum/zapsum/app_zapsum/views.py", line 86, in change_password
    form = ChangePasswordForm(instance=request)
TypeError: __init__() got an unexpected keyword argument 'instance'
Internal Server Error: /change_password/
Traceback (most recent call last):
  File "/home/kalinins/.virtualenvs/zapsum/lib/python3.4/site-packages/django/core/handlers/base.py", line 112, in get_response
    response = wrapped_callback(request, *callback_args, **callback_kwargs)
  File "/home/kalinins/.virtualenvs/zapsum/lib/python3.4/site-packages/django/contrib/auth/decorators.py", line 22, in _wrapped_view
    return view_func(request, *args, **kwargs)
  File "/home/kalinins/.virtualenvs/zapsum/zapsum/app_zapsum/views.py", line 86, in change_password
    form = ChangePasswordForm(instance=request)
TypeError: __init__() got an unexpected keyword argument 'instance'
Internal Server Error: /change_password/
Traceback (most recent call last):
  File "/home/kalinins/.virtualenvs/zapsum/lib/python3.4/site-packages/django/core/handlers/base.py", line 112, in get_response
    response = wrapped_callback(request, *callback_args, **callback_kwargs)
  File "/home/kalinins/.virtualenvs/zapsum/lib/python3.4/site-packages/django/contrib/auth/decorators.py", line 22, in _wrapped_view
    return view_func(request, *args, **kwargs)
  File "/home/kalinins/.virtualenvs/zapsum/zapsum/app_zapsum/views.py", line 86, in change_password
    form = ChangePasswordForm(request=request)
TypeError: __init__() got an unexpected keyword argument 'request'
Internal Server Error: /change_password/
Traceback (most recent call last):
  File "/home/kalinins/.virtualenvs/zapsum/lib/python3.4/site-packages/django/core/handlers/base.py", line 112, in get_response
    response = wrapped_callback(request, *callback_args, **callback_kwargs)
  File "/home/kalinins/.virtualenvs/zapsum/lib/python3.4/site-packages/django/contrib/auth/decorators.py", line 22, in _wrapped_view
    return view_func(request, *args, **kwargs)
  File "/home/kalinins/.virtualenvs/zapsum/zapsum/app_zapsum/views.py", line 86, in change_password
    form = ChangePasswordForm(request=request)
TypeError: __init__() got an unexpected keyword argument 'request'
Internal Server Error: /change_password/
Traceback (most recent call last):
  File "/home/kalinins/.virtualenvs/zapsum/lib/python3.4/site-packages/django/core/handlers/base.py", line 112, in get_response
    response = wrapped_callback(request, *callback_args, **callback_kwargs)
  File "/home/kalinins/.virtualenvs/zapsum/lib/python3.4/site-packages/django/contrib/auth/decorators.py", line 22, in _wrapped_view
    return view_func(request, *args, **kwargs)
  File "/home/kalinins/.virtualenvs/zapsum/zapsum/app_zapsum/views.py", line 86, in change_password
    form = ChangePasswordForm(request=request)
TypeError: __init__() got an unexpected keyword argument 'request'
Internal Server Error: /change_password/
Traceback (most recent call last):
  File "/home/kalinins/.virtualenvs/zapsum/lib/python3.4/site-packages/django/core/handlers/base.py", line 112, in get_response
    response = wrapped_callback(request, *callback_args, **callback_kwargs)
  File "/home/kalinins/.virtualenvs/zapsum/lib/python3.4/site-packages/django/contrib/auth/decorators.py", line 22, in _wrapped_view
    return view_func(request, *args, **kwargs)
  File "/home/kalinins/.virtualenvs/zapsum/zapsum/app_zapsum/views.py", line 86, in change_password
    form = ChangePasswordForm(request=request)
TypeError: __init__() got an unexpected keyword argument 'request'
Internal Server Error: /change_password/
Traceback (most recent call last):
  File "/home/kalinins/.virtualenvs/zapsum/lib/python3.4/site-packages/django/core/urlresolvers.py", line 109, in get_callable
    lookup_view = getattr(mod, func_name)
AttributeError: 'module' object has no attribute 'changed_password'

During handling of the above exception, another exception occurred:

Traceback (most recent call last):
  File "/home/kalinins/.virtualenvs/zapsum/lib/python3.4/site-packages/django/core/handlers/base.py", line 112, in get_response
    response = wrapped_callback(request, *callback_args, **callback_kwargs)
  File "/home/kalinins/.virtualenvs/zapsum/lib/python3.4/site-packages/django/contrib/auth/decorators.py", line 22, in _wrapped_view
    return view_func(request, *args, **kwargs)
  File "/home/kalinins/.virtualenvs/zapsum/zapsum/app_zapsum/views.py", line 101, in change_password
    return HttpResponse(t.render(c))
  File "/home/kalinins/.virtualenvs/zapsum/lib/python3.4/site-packages/django/template/base.py", line 140, in render
    return self._render(context)
  File "/home/kalinins/.virtualenvs/zapsum/lib/python3.4/site-packages/django/template/base.py", line 134, in _render
    return self.nodelist.render(context)
  File "/home/kalinins/.virtualenvs/zapsum/lib/python3.4/site-packages/django/template/base.py", line 840, in render
    bit = self.render_node(node, context)
  File "/home/kalinins/.virtualenvs/zapsum/lib/python3.4/site-packages/django/template/debug.py", line 78, in render_node
    return node.render(context)
  File "/home/kalinins/.virtualenvs/zapsum/lib/python3.4/site-packages/django/template/loader_tags.py", line 123, in render
    return compiled_parent._render(context)
  File "/home/kalinins/.virtualenvs/zapsum/lib/python3.4/site-packages/django/template/base.py", line 134, in _render
    return self.nodelist.render(context)
  File "/home/kalinins/.virtualenvs/zapsum/lib/python3.4/site-packages/django/template/base.py", line 840, in render
    bit = self.render_node(node, context)
  File "/home/kalinins/.virtualenvs/zapsum/lib/python3.4/site-packages/django/template/debug.py", line 78, in render_node
    return node.render(context)
  File "/home/kalinins/.virtualenvs/zapsum/lib/python3.4/site-packages/django/template/defaulttags.py", line 433, in render
    url = reverse(view_name, args=args, kwargs=kwargs, current_app=context.current_app)
  File "/home/kalinins/.virtualenvs/zapsum/lib/python3.4/site-packages/django/core/urlresolvers.py", line 532, in reverse
    return iri_to_uri(resolver._reverse_with_prefix(view, prefix, *args, **kwargs))
  File "/home/kalinins/.virtualenvs/zapsum/lib/python3.4/site-packages/django/core/urlresolvers.py", line 403, in _reverse_with_prefix
    self._populate()
  File "/home/kalinins/.virtualenvs/zapsum/lib/python3.4/site-packages/django/core/urlresolvers.py", line 290, in _populate
    for name in pattern.reverse_dict:
  File "/home/kalinins/.virtualenvs/zapsum/lib/python3.4/site-packages/django/core/urlresolvers.py", line 315, in reverse_dict
    self._populate()
  File "/home/kalinins/.virtualenvs/zapsum/lib/python3.4/site-packages/django/core/urlresolvers.py", line 303, in _populate
    lookups.appendlist(pattern.callback, (bits, p_pattern, pattern.default_args))
  File "/home/kalinins/.virtualenvs/zapsum/lib/python3.4/site-packages/django/core/urlresolvers.py", line 230, in callback
    self._callback = get_callable(self._callback_str)
  File "/home/kalinins/.virtualenvs/zapsum/lib/python3.4/site-packages/django/utils/functional.py", line 32, in wrapper
    result = func(*args)
  File "/home/kalinins/.virtualenvs/zapsum/lib/python3.4/site-packages/django/core/urlresolvers.py", line 118, in get_callable
    (lookup_view, mod_name))
django.core.exceptions.ViewDoesNotExist: Could not import app_zapsum.views.changed_password. View does not exist in module app_zapsum.views.
Internal Server Error: /change_password/
Traceback (most recent call last):
  File "/home/kalinins/.virtualenvs/zapsum/lib/python3.4/site-packages/django/core/handlers/base.py", line 112, in get_response
    response = wrapped_callback(request, *callback_args, **callback_kwargs)
  File "/home/kalinins/.virtualenvs/zapsum/lib/python3.4/site-packages/django/contrib/auth/decorators.py", line 22, in _wrapped_view
    return view_func(request, *args, **kwargs)
  File "/home/kalinins/.virtualenvs/zapsum/zapsum/app_zapsum/views.py", line 90, in change_password
    if form.is_valid():
  File "/home/kalinins/.virtualenvs/zapsum/lib/python3.4/site-packages/django/forms/forms.py", line 129, in is_valid
    return self.is_bound and not bool(self.errors)
  File "/home/kalinins/.virtualenvs/zapsum/lib/python3.4/site-packages/django/forms/forms.py", line 121, in errors
    self.full_clean()
  File "/home/kalinins/.virtualenvs/zapsum/lib/python3.4/site-packages/django/forms/forms.py", line 273, in full_clean
    self._clean_fields()
  File "/home/kalinins/.virtualenvs/zapsum/lib/python3.4/site-packages/django/forms/forms.py", line 291, in _clean_fields
    value = getattr(self, 'clean_%s' % name)()
  File "/home/kalinins/.virtualenvs/zapsum/zapsum/app_zapsum/forms.py", line 33, in clean_password_old
    if not self.request.user.check_password(password_old):
AttributeError: 'ChangePasswordForm' object has no attribute 'request'
Internal Server Error: /change_password/
Traceback (most recent call last):
  File "/home/kalinins/.virtualenvs/zapsum/lib/python3.4/site-packages/django/core/handlers/base.py", line 112, in get_response
    response = wrapped_callback(request, *callback_args, **callback_kwargs)
  File "/home/kalinins/.virtualenvs/zapsum/lib/python3.4/site-packages/django/contrib/auth/decorators.py", line 22, in _wrapped_view
    return view_func(request, *args, **kwargs)
  File "/home/kalinins/.virtualenvs/zapsum/zapsum/app_zapsum/views.py", line 86, in change_password
    form = ChangePasswordForm(instance=request.POST)
TypeError: __init__() got an unexpected keyword argument 'instance'
Internal Server Error: /change_password/
Traceback (most recent call last):
  File "/home/kalinins/.virtualenvs/zapsum/lib/python3.4/site-packages/django/core/handlers/base.py", line 112, in get_response
    response = wrapped_callback(request, *callback_args, **callback_kwargs)
  File "/home/kalinins/.virtualenvs/zapsum/lib/python3.4/site-packages/django/contrib/auth/decorators.py", line 22, in _wrapped_view
    return view_func(request, *args, **kwargs)
  File "/home/kalinins/.virtualenvs/zapsum/zapsum/app_zapsum/views.py", line 86, in change_password
    form = ChangePasswordForm(request=request)
TypeError: __init__() got an unexpected keyword argument 'request'
Internal Server Error: /change_password/
Traceback (most recent call last):
  File "/home/kalinins/.virtualenvs/zapsum/lib/python3.4/site-packages/django/core/handlers/base.py", line 112, in get_response
    response = wrapped_callback(request, *callback_args, **callback_kwargs)
  File "/home/kalinins/.virtualenvs/zapsum/lib/python3.4/site-packages/django/contrib/auth/decorators.py", line 22, in _wrapped_view
    return view_func(request, *args, **kwargs)
  File "/home/kalinins/.virtualenvs/zapsum/zapsum/app_zapsum/views.py", line 96, in change_password
    form = ChangePasswordForm(request=request)
TypeError: __init__() got an unexpected keyword argument 'request'
Internal Server Error: /change_password/
Traceback (most recent call last):
  File "/home/kalinins/.virtualenvs/zapsum/lib/python3.4/site-packages/django/core/handlers/base.py", line 112, in get_response
    response = wrapped_callback(request, *callback_args, **callback_kwargs)
  File "/home/kalinins/.virtualenvs/zapsum/lib/python3.4/site-packages/django/contrib/auth/decorators.py", line 22, in _wrapped_view
    return view_func(request, *args, **kwargs)
  File "/home/kalinins/.virtualenvs/zapsum/zapsum/app_zapsum/views.py", line 96, in change_password
    form = ChangePasswordForm(request=request)
TypeError: __init__() got an unexpected keyword argument 'request'
Internal Server Error: /change_password/
Traceback (most recent call last):
  File "/home/kalinins/.virtualenvs/zapsum/lib/python3.4/site-packages/django/core/handlers/base.py", line 112, in get_response
    response = wrapped_callback(request, *callback_args, **callback_kwargs)
  File "/home/kalinins/.virtualenvs/zapsum/lib/python3.4/site-packages/django/contrib/auth/decorators.py", line 22, in _wrapped_view
    return view_func(request, *args, **kwargs)
  File "/home/kalinins/.virtualenvs/zapsum/zapsum/app_zapsum/views.py", line 96, in change_password
    form = ChangePasswordForm(request=request)
TypeError: __init__() got an unexpected keyword argument 'request'
Internal Server Error: /change_password/
Traceback (most recent call last):
  File "/home/kalinins/.virtualenvs/zapsum/lib/python3.4/site-packages/django/core/handlers/base.py", line 112, in get_response
    response = wrapped_callback(request, *callback_args, **callback_kwargs)
  File "/home/kalinins/.virtualenvs/zapsum/lib/python3.4/site-packages/django/contrib/auth/decorators.py", line 22, in _wrapped_view
    return view_func(request, *args, **kwargs)
  File "/home/kalinins/.virtualenvs/zapsum/zapsum/app_zapsum/views.py", line 96, in change_password
    form = ChangePasswordForm(request=request)
TypeError: __init__() got an unexpected keyword argument 'request'
Internal Server Error: /change_password/
Traceback (most recent call last):
  File "/home/kalinins/.virtualenvs/zapsum/lib/python3.4/site-packages/django/core/handlers/base.py", line 112, in get_response
    response = wrapped_callback(request, *callback_args, **callback_kwargs)
  File "/home/kalinins/.virtualenvs/zapsum/lib/python3.4/site-packages/django/contrib/auth/decorators.py", line 22, in _wrapped_view
    return view_func(request, *args, **kwargs)
  File "/home/kalinins/.virtualenvs/zapsum/zapsum/app_zapsum/views.py", line 96, in change_password
    form = ChangePasswordForm(request=request)
TypeError: __init__() got an unexpected keyword argument 'request'
Internal Server Error: /change_password/
Traceback (most recent call last):
  File "/home/kalinins/.virtualenvs/zapsum/lib/python3.4/site-packages/django/core/handlers/base.py", line 112, in get_response
    response = wrapped_callback(request, *callback_args, **callback_kwargs)
  File "/home/kalinins/.virtualenvs/zapsum/lib/python3.4/site-packages/django/contrib/auth/decorators.py", line 22, in _wrapped_view
    return view_func(request, *args, **kwargs)
  File "/home/kalinins/.virtualenvs/zapsum/zapsum/app_zapsum/views.py", line 96, in change_password
    form = ChangePasswordForm(request=request)
TypeError: __init__() got an unexpected keyword argument 'request'
Internal Server Error: /change_password/
Traceback (most recent call last):
  File "/home/kalinins/.virtualenvs/zapsum/lib/python3.4/site-packages/django/core/handlers/base.py", line 112, in get_response
    response = wrapped_callback(request, *callback_args, **callback_kwargs)
  File "/home/kalinins/.virtualenvs/zapsum/lib/python3.4/site-packages/django/contrib/auth/decorators.py", line 22, in _wrapped_view
    return view_func(request, *args, **kwargs)
  File "/home/kalinins/.virtualenvs/zapsum/zapsum/app_zapsum/views.py", line 96, in change_password
    form = ChangePasswordForm(request=request)
TypeError: __init__() got an unexpected keyword argument 'request'
Internal Server Error: /change_password/
Traceback (most recent call last):
  File "/home/kalinins/.virtualenvs/zapsum/lib/python3.4/site-packages/django/core/handlers/base.py", line 112, in get_response
    response = wrapped_callback(request, *callback_args, **callback_kwargs)
  File "/home/kalinins/.virtualenvs/zapsum/lib/python3.4/site-packages/django/contrib/auth/decorators.py", line 22, in _wrapped_view
    return view_func(request, *args, **kwargs)
  File "/home/kalinins/.virtualenvs/zapsum/zapsum/app_zapsum/views.py", line 96, in change_password
    form = ChangePasswordForm(request=request)
TypeError: __init__() got an unexpected keyword argument 'request'
Internal Server Error: /change_password/
Traceback (most recent call last):
  File "/home/kalinins/.virtualenvs/zapsum/lib/python3.4/site-packages/django/core/handlers/base.py", line 112, in get_response
    response = wrapped_callback(request, *callback_args, **callback_kwargs)
  File "/home/kalinins/.virtualenvs/zapsum/lib/python3.4/site-packages/django/contrib/auth/decorators.py", line 22, in _wrapped_view
    return view_func(request, *args, **kwargs)
  File "/home/kalinins/.virtualenvs/zapsum/zapsum/app_zapsum/views.py", line 90, in change_password
    if form.is_valid():
  File "/home/kalinins/.virtualenvs/zapsum/lib/python3.4/site-packages/django/forms/forms.py", line 129, in is_valid
    return self.is_bound and not bool(self.errors)
  File "/home/kalinins/.virtualenvs/zapsum/lib/python3.4/site-packages/django/forms/forms.py", line 121, in errors
    self.full_clean()
  File "/home/kalinins/.virtualenvs/zapsum/lib/python3.4/site-packages/django/forms/forms.py", line 273, in full_clean
    self._clean_fields()
  File "/home/kalinins/.virtualenvs/zapsum/lib/python3.4/site-packages/django/forms/forms.py", line 291, in _clean_fields
    value = getattr(self, 'clean_%s' % name)()
  File "/home/kalinins/.virtualenvs/zapsum/zapsum/app_zapsum/forms.py", line 36, in clean_password_old
    if not self.request.user.check_password(password_old):
AttributeError: 'ChangePasswordForm' object has no attribute 'request'
Internal Server Error: /change_password/
Traceback (most recent call last):
  File "/home/kalinins/.virtualenvs/zapsum/lib/python3.4/site-packages/django/core/handlers/base.py", line 112, in get_response
    response = wrapped_callback(request, *callback_args, **callback_kwargs)
  File "/home/kalinins/.virtualenvs/zapsum/lib/python3.4/site-packages/django/contrib/auth/decorators.py", line 22, in _wrapped_view
    return view_func(request, *args, **kwargs)
  File "/home/kalinins/.virtualenvs/zapsum/zapsum/app_zapsum/views.py", line 91, in change_password
    username = User.objects.get(username__exact=request.user.username)
NameError: name 'User' is not defined
Not Found: /accounts/page_changed_password/
Not Found: /accounts/page_changed_password/
Not Found: /accounts/page_changed_password/
Not Found: /accounts/page_changed_password/
Not Found: /accounts/page_changed_password/
Not Found: /accounts/page_changed_password/
Not Found: /accounts/page_changed_password/
Not Found: /accounts/page_changed_password/
Not Found: /accounts/page_changed_password/
Not Found: /accounts/page_changed_password/
Not Found: /accounts/page_changed_password/
Not Found: /accounts/page_changed_password/
Not Found: /accounts/page_changed_password/
Not Found: /accounts/page_changed_password/
Not Found: /accounts/page_changed_password/
Not Found: /accounts/page_changed_password/
Not Found: /accounts/page_changed_password/
Not Found: /accounts/page_changed_password/
Not Found: /accounts/page_changed_password/
Not Found: /accounts/page_changed_password/
Not Found: /accounts/page_changed_password/
Not Found: /accounts/page_changed_password/
Not Found: /accounts/page_changed_password/
Not Found: /accounts/page_changed_password/
Not Found: /accounts/page_changed_password/
Not Found: /accounts/page_changed_password/
Not Found: /accounts/page_changed_password/
Not Found: /accounts/page_changed_password/
Not Found: /accounts/page_changed_password/
Not Found: /accounts/page_changed_password/
Not Found: /accounts/page_changed_password/
Not Found: /accounts/page_changed_password/
Not Found: /accounts/page_changed_password/
Not Found: /accounts/page_changed_password/
Not Found: /accounts/page_changed_password/
Not Found: /accounts/page_changed_password/
Not Found: /accounts/page_changed_password/
Not Found: /accounts/page_changed_password/
Not Found: /accounts/page_changed_password/
Not Found: /accounts/page_changed_password/
Not Found: /accounts/page_changed_password/
Not Found: /accounts/page_changed_password/
Internal Server Error: /accounts/changed_password/
Traceback (most recent call last):
  File "/home/kalinins/.virtualenvs/zapsum/lib/python3.4/site-packages/django/core/handlers/base.py", line 99, in get_response
    resolver_match = resolver.resolve(request.path_info)
  File "/home/kalinins/.virtualenvs/zapsum/lib/python3.4/site-packages/django/core/urlresolvers.py", line 339, in resolve
    sub_match = pattern.resolve(new_path)
  File "/home/kalinins/.virtualenvs/zapsum/lib/python3.4/site-packages/django/core/urlresolvers.py", line 339, in resolve
    sub_match = pattern.resolve(new_path)
  File "/home/kalinins/.virtualenvs/zapsum/lib/python3.4/site-packages/django/core/urlresolvers.py", line 223, in resolve
    return ResolverMatch(self.callback, args, kwargs, self.name)
  File "/home/kalinins/.virtualenvs/zapsum/lib/python3.4/site-packages/django/core/urlresolvers.py", line 230, in callback
    self._callback = get_callable(self._callback_str)
  File "/home/kalinins/.virtualenvs/zapsum/lib/python3.4/site-packages/django/utils/functional.py", line 32, in wrapper
    result = func(*args)
  File "/home/kalinins/.virtualenvs/zapsum/lib/python3.4/site-packages/django/core/urlresolvers.py", line 97, in get_callable
    mod = import_module(mod_name)
  File "/home/kalinins/.virtualenvs/zapsum/lib/python3.4/importlib/__init__.py", line 109, in import_module
    return _bootstrap._gcd_import(name[level:], package, level)
  File "<frozen importlib._bootstrap>", line 2231, in _gcd_import
  File "<frozen importlib._bootstrap>", line 2214, in _find_and_load
  File "<frozen importlib._bootstrap>", line 2203, in _find_and_load_unlocked
  File "<frozen importlib._bootstrap>", line 1200, in _load_unlocked
  File "<frozen importlib._bootstrap>", line 1129, in _exec
  File "<frozen importlib._bootstrap>", line 1448, in exec_module
  File "<frozen importlib._bootstrap>", line 321, in _call_with_frames_removed
  File "/home/kalinins/.virtualenvs/zapsum/zapsum/app_accounts/views.py", line 81, in <module>
    @login_required
NameError: name 'login_required' is not defined
Internal Server Error: /
Traceback (most recent call last):
  File "/home/kalinins/.virtualenvs/zapsum/lib/python3.4/site-packages/django/core/handlers/base.py", line 112, in get_response
    response = wrapped_callback(request, *callback_args, **callback_kwargs)
  File "/home/kalinins/.virtualenvs/zapsum/zapsum/app_zapsum/views.py", line 23, in rules
    return HttpResponse(t.render(c))
  File "/home/kalinins/.virtualenvs/zapsum/lib/python3.4/site-packages/django/template/base.py", line 140, in render
    return self._render(context)
  File "/home/kalinins/.virtualenvs/zapsum/lib/python3.4/site-packages/django/template/base.py", line 134, in _render
    return self.nodelist.render(context)
  File "/home/kalinins/.virtualenvs/zapsum/lib/python3.4/site-packages/django/template/base.py", line 840, in render
    bit = self.render_node(node, context)
  File "/home/kalinins/.virtualenvs/zapsum/lib/python3.4/site-packages/django/template/debug.py", line 78, in render_node
    return node.render(context)
  File "/home/kalinins/.virtualenvs/zapsum/lib/python3.4/site-packages/django/template/loader_tags.py", line 123, in render
    return compiled_parent._render(context)
  File "/home/kalinins/.virtualenvs/zapsum/lib/python3.4/site-packages/django/template/base.py", line 134, in _render
    return self.nodelist.render(context)
  File "/home/kalinins/.virtualenvs/zapsum/lib/python3.4/site-packages/django/template/base.py", line 840, in render
    bit = self.render_node(node, context)
  File "/home/kalinins/.virtualenvs/zapsum/lib/python3.4/site-packages/django/template/debug.py", line 78, in render_node
    return node.render(context)
  File "/home/kalinins/.virtualenvs/zapsum/lib/python3.4/site-packages/django/template/defaulttags.py", line 433, in render
    url = reverse(view_name, args=args, kwargs=kwargs, current_app=context.current_app)
  File "/home/kalinins/.virtualenvs/zapsum/lib/python3.4/site-packages/django/core/urlresolvers.py", line 532, in reverse
    return iri_to_uri(resolver._reverse_with_prefix(view, prefix, *args, **kwargs))
  File "/home/kalinins/.virtualenvs/zapsum/lib/python3.4/site-packages/django/core/urlresolvers.py", line 403, in _reverse_with_prefix
    self._populate()
  File "/home/kalinins/.virtualenvs/zapsum/lib/python3.4/site-packages/django/core/urlresolvers.py", line 290, in _populate
    for name in pattern.reverse_dict:
  File "/home/kalinins/.virtualenvs/zapsum/lib/python3.4/site-packages/django/core/urlresolvers.py", line 315, in reverse_dict
    self._populate()
  File "/home/kalinins/.virtualenvs/zapsum/lib/python3.4/site-packages/django/core/urlresolvers.py", line 303, in _populate
    lookups.appendlist(pattern.callback, (bits, p_pattern, pattern.default_args))
  File "/home/kalinins/.virtualenvs/zapsum/lib/python3.4/site-packages/django/core/urlresolvers.py", line 230, in callback
    self._callback = get_callable(self._callback_str)
  File "/home/kalinins/.virtualenvs/zapsum/lib/python3.4/site-packages/django/utils/functional.py", line 32, in wrapper
    result = func(*args)
  File "/home/kalinins/.virtualenvs/zapsum/lib/python3.4/site-packages/django/core/urlresolvers.py", line 97, in get_callable
    mod = import_module(mod_name)
  File "/home/kalinins/.virtualenvs/zapsum/lib/python3.4/importlib/__init__.py", line 109, in import_module
    return _bootstrap._gcd_import(name[level:], package, level)
  File "<frozen importlib._bootstrap>", line 2231, in _gcd_import
  File "<frozen importlib._bootstrap>", line 2214, in _find_and_load
  File "<frozen importlib._bootstrap>", line 2203, in _find_and_load_unlocked
  File "<frozen importlib._bootstrap>", line 1200, in _load_unlocked
  File "<frozen importlib._bootstrap>", line 1129, in _exec
  File "<frozen importlib._bootstrap>", line 1448, in exec_module
  File "<frozen importlib._bootstrap>", line 321, in _call_with_frames_removed
  File "/home/kalinins/.virtualenvs/zapsum/zapsum/app_accounts/views.py", line 81, in <module>
    @login_required
NameError: name 'login_required' is not defined
Not Found: /favicon.ico
Not Found: /favicon.ico
Internal Server Error: /change_avatar/
Traceback (most recent call last):
  File "/home/kalinins/.virtualenvs/zapsum/lib/python3.4/site-packages/django/template/base.py", line 274, in parse
    compile_func = self.tags[command]
KeyError: 'thumbnail'

During handling of the above exception, another exception occurred:

Traceback (most recent call last):
  File "/home/kalinins/.virtualenvs/zapsum/lib/python3.4/site-packages/django/core/handlers/base.py", line 112, in get_response
    response = wrapped_callback(request, *callback_args, **callback_kwargs)
  File "/home/kalinins/.virtualenvs/zapsum/lib/python3.4/site-packages/django/contrib/auth/decorators.py", line 22, in _wrapped_view
    return view_func(request, *args, **kwargs)
  File "/home/kalinins/.virtualenvs/zapsum/zapsum/app_zapsum/views.py", line 79, in change_avatar
    t = loader.get_template('page_change_avatar.html')
  File "/home/kalinins/.virtualenvs/zapsum/lib/python3.4/site-packages/django/template/loader.py", line 138, in get_template
    template, origin = find_template(template_name)
  File "/home/kalinins/.virtualenvs/zapsum/lib/python3.4/site-packages/django/template/loader.py", line 127, in find_template
    source, display_name = loader(name, dirs)
  File "/home/kalinins/.virtualenvs/zapsum/lib/python3.4/site-packages/django/template/loader.py", line 43, in __call__
    return self.load_template(template_name, template_dirs)
  File "/home/kalinins/.virtualenvs/zapsum/lib/python3.4/site-packages/django/template/loader.py", line 49, in load_template
    template = get_template_from_string(source, origin, template_name)
  File "/home/kalinins/.virtualenvs/zapsum/lib/python3.4/site-packages/django/template/loader.py", line 149, in get_template_from_string
    return Template(source, origin, name)
  File "/home/kalinins/.virtualenvs/zapsum/lib/python3.4/site-packages/django/template/base.py", line 125, in __init__
    self.nodelist = compile_string(template_string, origin)
  File "/home/kalinins/.virtualenvs/zapsum/lib/python3.4/site-packages/django/template/base.py", line 153, in compile_string
    return parser.parse()
  File "/home/kalinins/.virtualenvs/zapsum/lib/python3.4/site-packages/django/template/base.py", line 278, in parse
    compiled_result = compile_func(self, token)
  File "/home/kalinins/.virtualenvs/zapsum/lib/python3.4/site-packages/django/template/loader_tags.py", line 215, in do_extends
    nodelist = parser.parse()
  File "/home/kalinins/.virtualenvs/zapsum/lib/python3.4/site-packages/django/template/base.py", line 278, in parse
    compiled_result = compile_func(self, token)
  File "/home/kalinins/.virtualenvs/zapsum/lib/python3.4/site-packages/django/template/loader_tags.py", line 190, in do_block
    nodelist = parser.parse(('endblock',))
  File "/home/kalinins/.virtualenvs/zapsum/lib/python3.4/site-packages/django/template/base.py", line 278, in parse
    compiled_result = compile_func(self, token)
  File "/home/kalinins/.virtualenvs/zapsum/lib/python3.4/site-packages/django/template/defaulttags.py", line 942, in do_if
    nodelist = parser.parse(('elif', 'else', 'endif'))
  File "/home/kalinins/.virtualenvs/zapsum/lib/python3.4/site-packages/django/template/base.py", line 276, in parse
    self.invalid_block_tag(token, command, parse_until)
  File "/home/kalinins/.virtualenvs/zapsum/lib/python3.4/site-packages/django/template/base.py", line 331, in invalid_block_tag
    (command, get_text_list(["'%s'" % p for p in parse_until])))
django.template.base.TemplateSyntaxError: Invalid block tag: 'thumbnail', expected 'elif','else' или 'endif'
Internal Server Error: /change_avatar/
Traceback (most recent call last):
  File "/home/kalinins/.virtualenvs/zapsum/lib/python3.4/site-packages/django/core/handlers/base.py", line 112, in get_response
    response = wrapped_callback(request, *callback_args, **callback_kwargs)
  File "/home/kalinins/.virtualenvs/zapsum/lib/python3.4/site-packages/django/contrib/auth/decorators.py", line 22, in _wrapped_view
    return view_func(request, *args, **kwargs)
  File "/home/kalinins/.virtualenvs/zapsum/zapsum/app_zapsum/views.py", line 82, in change_avatar
    form = ChangeAvatarForm(instance=entry_user_profile)
NameError: name 'ChangeAvatarForm' is not defined
Not Found: /media/cache/c7/a7/c7a7ce5c7a285c455f98981e07e3aa3d.jpg
Not Found: /media/cache/c7/a7/c7a7ce5c7a285c455f98981e07e3aa3d.jpg
Not Found: /media/cache/82/83/82832df1859da409d8f702557c0a043a.jpg
Not Found: /media/userprofile/avatar/x_2b8e0c5d.jpg
Not Found: /media/cache/82/83/82832df1859da409d8f702557c0a043a.jpg
Not Found: /media/cache/82/83/82832df1859da409d8f702557c0a043a.jpg
Not Found: /media/cache/82/83/82832df1859da409d8f702557c0a043a.jpg
Not Found: /media/cache/82/83/82832df1859da409d8f702557c0a043a.jpg
Not Found: /media/cache/82/83/82832df1859da409d8f702557c0a043a.jpg
Not Found: /media/cache/82/83/82832df1859da409d8f702557c0a043a.jpg
Not Found: /media/cache/82/83/82832df1859da409d8f702557c0a043a.jpg
Not Found: /media/cache/82/83/82832df1859da409d8f702557c0a043a.jpg
Not Found: /media/cache/82/83/82832df1859da409d8f702557c0a043a.jpg
Not Found: /media/cache/82/83/82832df1859da409d8f702557c0a043a.jpg
Not Found: /media/cache/82/83/82832df1859da409d8f702557c0a043a.jpg
Not Found: /media/cache/82/83/82832df1859da409d8f702557c0a043a.jpg
Not Found: /media/cache/82/83/82832df1859da409d8f702557c0a043a.jpg
Not Found: /media/cache/82/83/82832df1859da409d8f702557c0a043a.jpg
Not Found: /media/cache/82/83/82832df1859da409d8f702557c0a043a.jpg
Not Found: /media/cache/82/83/82832df1859da409d8f702557c0a043a.jpg
Not Found: /media/cache/82/83/82832df1859da409d8f702557c0a043a.jpg
Not Found: /media/cache/82/83/82832df1859da409d8f702557c0a043a.jpg
Not Found: /media/cache/82/83/82832df1859da409d8f702557c0a043a.jpg
Not Found: /media/cache/82/83/82832df1859da409d8f702557c0a043a.jpg
Not Found: /media/cache/82/83/82832df1859da409d8f702557c0a043a.jpg
Not Found: /media/cache/82/83/82832df1859da409d8f702557c0a043a.jpg
Not Found: /media/cache/82/83/82832df1859da409d8f702557c0a043a.jpg
Not Found: /media/cache/82/83/82832df1859da409d8f702557c0a043a.jpg
Not Found: /media/cache/82/83/82832df1859da409d8f702557c0a043a.jpg
Not Found: /media/cache/82/83/82832df1859da409d8f702557c0a043a.jpg
Not Found: /media/cache/82/83/82832df1859da409d8f702557c0a043a.jpg
Not Found: /media/cache/82/83/82832df1859da409d8f702557c0a043a.jpg
Not Found: /media/cache/82/83/82832df1859da409d8f702557c0a043a.jpg
Not Found: /media/cache/82/83/82832df1859da409d8f702557c0a043a.jpg
Not Found: /media/cache/82/83/82832df1859da409d8f702557c0a043a.jpg
Not Found: /media/userprofile/avatar/x_2b8e0c5d.jpg
Not Found: /media/cache/82/83/82832df1859da409d8f702557c0a043a.jpg
Not Found: /media/userprofile/avatar/x_2b8e0c5d.jpg
Not Found: /media/cache/82/83/82832df1859da409d8f702557c0a043a.jpg
Not Found: /media/userprofile/avatar/x_2b8e0c5d.jpg
Not Found: /media/cache/82/83/82832df1859da409d8f702557c0a043a.jpg
Not Found: /media/userprofile/avatar/x_2b8e0c5d.jpg
Not Found: /media/cache/82/83/82832df1859da409d8f702557c0a043a.jpg
Not Found: /media/userprofile/avatar/x_2b8e0c5d.jpg
Not Found: /media/userprofile/avatar/x_2b8e0c5d.jpg
Not Found: /media/cache/82/83/82832df1859da409d8f702557c0a043a.jpg
Not Found: /media/userprofile/avatar/x_2b8e0c5d.jpg
Not Found: /media/cache/82/83/82832df1859da409d8f702557c0a043a.jpg
Not Found: /media/userprofile/avatar/x_2b8e0c5d.jpg
Not Found: /media/cache/82/83/82832df1859da409d8f702557c0a043a.jpg
Not Found: /media/userprofile/avatar/x_2b8e0c5d.jpg
Not Found: /media/cache/82/83/82832df1859da409d8f702557c0a043a.jpg
Not Found: /media/userprofile/avatar/x_2b8e0c5d.jpg
Not Found: /media/cache/82/83/82832df1859da409d8f702557c0a043a.jpg
Not Found: /media/userprofile/avatar/x_2b8e0c5d.jpg
Not Found: /media/cache/82/83/82832df1859da409d8f702557c0a043a.jpg
Not Found: /media/userprofile/avatar/x_2b8e0c5d.jpg
Not Found: /media/cache/82/83/82832df1859da409d8f702557c0a043a.jpg
Not Found: /media/userprofile/avatar/x_2b8e0c5d.jpg
Not Found: /media/cache/82/83/82832df1859da409d8f702557c0a043a.jpg
Not Found: /media/userprofile/avatar/x_2b8e0c5d.jpg
Not Found: /media/cache/82/83/82832df1859da409d8f702557c0a043a.jpg
Not Found: /media/userprofile/avatar/x_2b8e0c5d.jpg
Not Found: /media/cache/82/83/82832df1859da409d8f702557c0a043a.jpg
Not Found: /media/userprofile/avatar/x_2b8e0c5d.jpg
Not Found: /media/cache/82/83/82832df1859da409d8f702557c0a043a.jpg
Not Found: /media/userprofile/avatar/x_2b8e0c5d.jpg
Not Found: /media/cache/82/83/82832df1859da409d8f702557c0a043a.jpg
Not Found: /media/userprofile/avatar/w.jpg
Not Found: /media/cache/4b/a5/4ba5b0a8f79249df3bb624fc89b12b10.jpg
Not Found: /media/userprofile/avatar/w.jpg
Not Found: /media/cache/4b/a5/4ba5b0a8f79249df3bb624fc89b12b10.jpg
Not Found: /media/userprofile/avatar/w.jpg
Not Found: /media/cache/4b/a5/4ba5b0a8f79249df3bb624fc89b12b10.jpg
Internal Server Error: /change_avatar/
Traceback (most recent call last):
  File "/home/kalinins/.virtualenvs/zapsum/lib/python3.4/site-packages/django/core/urlresolvers.py", line 358, in urlconf_module
    return self._urlconf_module
AttributeError: 'RegexURLResolver' object has no attribute '_urlconf_module'

During handling of the above exception, another exception occurred:

Traceback (most recent call last):
  File "/home/kalinins/.virtualenvs/zapsum/lib/python3.4/site-packages/django/core/handlers/base.py", line 99, in get_response
    resolver_match = resolver.resolve(request.path_info)
  File "/home/kalinins/.virtualenvs/zapsum/lib/python3.4/site-packages/django/core/urlresolvers.py", line 337, in resolve
    for pattern in self.url_patterns:
  File "/home/kalinins/.virtualenvs/zapsum/lib/python3.4/site-packages/django/core/urlresolvers.py", line 365, in url_patterns
    patterns = getattr(self.urlconf_module, "urlpatterns", self.urlconf_module)
  File "/home/kalinins/.virtualenvs/zapsum/lib/python3.4/site-packages/django/core/urlresolvers.py", line 360, in urlconf_module
    self._urlconf_module = import_module(self.urlconf_name)
  File "/home/kalinins/.virtualenvs/zapsum/lib/python3.4/importlib/__init__.py", line 109, in import_module
    return _bootstrap._gcd_import(name[level:], package, level)
  File "<frozen importlib._bootstrap>", line 2231, in _gcd_import
  File "<frozen importlib._bootstrap>", line 2214, in _find_and_load
  File "<frozen importlib._bootstrap>", line 2203, in _find_and_load_unlocked
  File "<frozen importlib._bootstrap>", line 1200, in _load_unlocked
  File "<frozen importlib._bootstrap>", line 1129, in _exec
  File "<frozen importlib._bootstrap>", line 1448, in exec_module
  File "<frozen importlib._bootstrap>", line 321, in _call_with_frames_removed
  File "/home/kalinins/.virtualenvs/zapsum/zapsum/zapsum/urls.py", line 12, in <module>
    if settings.DEBUG:
NameError: name 'settings' is not defined
Internal Server Error: /favicon.ico
Traceback (most recent call last):
  File "/home/kalinins/.virtualenvs/zapsum/lib/python3.4/site-packages/django/core/urlresolvers.py", line 358, in urlconf_module
    return self._urlconf_module
AttributeError: 'RegexURLResolver' object has no attribute '_urlconf_module'

During handling of the above exception, another exception occurred:

Traceback (most recent call last):
  File "/home/kalinins/.virtualenvs/zapsum/lib/python3.4/site-packages/django/core/handlers/base.py", line 88, in get_response
    response = middleware_method(request)
  File "/home/kalinins/.virtualenvs/zapsum/lib/python3.4/site-packages/django/middleware/common.py", line 71, in process_request
    if (not urlresolvers.is_valid_path(request.path_info, urlconf) and
  File "/home/kalinins/.virtualenvs/zapsum/lib/python3.4/site-packages/django/core/urlresolvers.py", line 596, in is_valid_path
    resolve(path, urlconf)
  File "/home/kalinins/.virtualenvs/zapsum/lib/python3.4/site-packages/django/core/urlresolvers.py", line 476, in resolve
    return get_resolver(urlconf).resolve(path)
  File "/home/kalinins/.virtualenvs/zapsum/lib/python3.4/site-packages/django/core/urlresolvers.py", line 337, in resolve
    for pattern in self.url_patterns:
  File "/home/kalinins/.virtualenvs/zapsum/lib/python3.4/site-packages/django/core/urlresolvers.py", line 365, in url_patterns
    patterns = getattr(self.urlconf_module, "urlpatterns", self.urlconf_module)
  File "/home/kalinins/.virtualenvs/zapsum/lib/python3.4/site-packages/django/core/urlresolvers.py", line 360, in urlconf_module
    self._urlconf_module = import_module(self.urlconf_name)
  File "/home/kalinins/.virtualenvs/zapsum/lib/python3.4/importlib/__init__.py", line 109, in import_module
    return _bootstrap._gcd_import(name[level:], package, level)
  File "<frozen importlib._bootstrap>", line 2231, in _gcd_import
  File "<frozen importlib._bootstrap>", line 2214, in _find_and_load
  File "<frozen importlib._bootstrap>", line 2203, in _find_and_load_unlocked
  File "<frozen importlib._bootstrap>", line 1200, in _load_unlocked
  File "<frozen importlib._bootstrap>", line 1129, in _exec
  File "<frozen importlib._bootstrap>", line 1448, in exec_module
  File "<frozen importlib._bootstrap>", line 321, in _call_with_frames_removed
  File "/home/kalinins/.virtualenvs/zapsum/zapsum/zapsum/urls.py", line 12, in <module>
    if settings.DEBUG:
NameError: name 'settings' is not defined
Not Found: /favicon.ico
Internal Server Error: /change_avatar/
Traceback (most recent call last):
  File "/home/kalinins/.virtualenvs/zapsum/lib/python3.4/site-packages/django/core/handlers/base.py", line 99, in get_response
    resolver_match = resolver.resolve(request.path_info)
  File "/home/kalinins/.virtualenvs/zapsum/lib/python3.4/site-packages/django/core/urlresolvers.py", line 339, in resolve
    sub_match = pattern.resolve(new_path)
  File "/home/kalinins/.virtualenvs/zapsum/lib/python3.4/site-packages/django/core/urlresolvers.py", line 339, in resolve
    sub_match = pattern.resolve(new_path)
  File "/home/kalinins/.virtualenvs/zapsum/lib/python3.4/site-packages/django/core/urlresolvers.py", line 223, in resolve
    return ResolverMatch(self.callback, args, kwargs, self.name)
  File "/home/kalinins/.virtualenvs/zapsum/lib/python3.4/site-packages/django/core/urlresolvers.py", line 230, in callback
    self._callback = get_callable(self._callback_str)
  File "/home/kalinins/.virtualenvs/zapsum/lib/python3.4/site-packages/django/utils/functional.py", line 32, in wrapper
    result = func(*args)
  File "/home/kalinins/.virtualenvs/zapsum/lib/python3.4/site-packages/django/core/urlresolvers.py", line 97, in get_callable
    mod = import_module(mod_name)
  File "/home/kalinins/.virtualenvs/zapsum/lib/python3.4/importlib/__init__.py", line 109, in import_module
    return _bootstrap._gcd_import(name[level:], package, level)
  File "<frozen importlib._bootstrap>", line 2231, in _gcd_import
  File "<frozen importlib._bootstrap>", line 2214, in _find_and_load
  File "<frozen importlib._bootstrap>", line 2203, in _find_and_load_unlocked
  File "<frozen importlib._bootstrap>", line 1200, in _load_unlocked
  File "<frozen importlib._bootstrap>", line 1129, in _exec
  File "<frozen importlib._bootstrap>", line 1444, in exec_module
  File "<frozen importlib._bootstrap>", line 1549, in get_code
  File "<frozen importlib._bootstrap>", line 1509, in source_to_code
  File "<frozen importlib._bootstrap>", line 321, in _call_with_frames_removed
  File "/home/kalinins/.virtualenvs/zapsum/zapsum/app_zapsum/views.py", line 93
    print u'отработали'
                      ^
SyntaxError: invalid syntax
Internal Server Error: /change_avatar/
Traceback (most recent call last):
  File "/home/kalinins/.virtualenvs/zapsum/lib/python3.4/site-packages/django/core/handlers/base.py", line 99, in get_response
    resolver_match = resolver.resolve(request.path_info)
  File "/home/kalinins/.virtualenvs/zapsum/lib/python3.4/site-packages/django/core/urlresolvers.py", line 339, in resolve
    sub_match = pattern.resolve(new_path)
  File "/home/kalinins/.virtualenvs/zapsum/lib/python3.4/site-packages/django/core/urlresolvers.py", line 339, in resolve
    sub_match = pattern.resolve(new_path)
  File "/home/kalinins/.virtualenvs/zapsum/lib/python3.4/site-packages/django/core/urlresolvers.py", line 223, in resolve
    return ResolverMatch(self.callback, args, kwargs, self.name)
  File "/home/kalinins/.virtualenvs/zapsum/lib/python3.4/site-packages/django/core/urlresolvers.py", line 230, in callback
    self._callback = get_callable(self._callback_str)
  File "/home/kalinins/.virtualenvs/zapsum/lib/python3.4/site-packages/django/utils/functional.py", line 32, in wrapper
    result = func(*args)
  File "/home/kalinins/.virtualenvs/zapsum/lib/python3.4/site-packages/django/core/urlresolvers.py", line 97, in get_callable
    mod = import_module(mod_name)
  File "/home/kalinins/.virtualenvs/zapsum/lib/python3.4/importlib/__init__.py", line 109, in import_module
    return _bootstrap._gcd_import(name[level:], package, level)
  File "<frozen importlib._bootstrap>", line 2231, in _gcd_import
  File "<frozen importlib._bootstrap>", line 2214, in _find_and_load
  File "<frozen importlib._bootstrap>", line 2203, in _find_and_load_unlocked
  File "<frozen importlib._bootstrap>", line 1200, in _load_unlocked
  File "<frozen importlib._bootstrap>", line 1129, in _exec
  File "<frozen importlib._bootstrap>", line 1444, in exec_module
  File "<frozen importlib._bootstrap>", line 1549, in get_code
  File "<frozen importlib._bootstrap>", line 1509, in source_to_code
  File "<frozen importlib._bootstrap>", line 321, in _call_with_frames_removed
  File "/home/kalinins/.virtualenvs/zapsum/zapsum/app_zapsum/views.py", line 93
    print u'отработали'
                      ^
SyntaxError: invalid syntax
Internal Server Error: /change_avatar/
Traceback (most recent call last):
  File "/home/kalinins/.virtualenvs/zapsum/lib/python3.4/site-packages/django/core/handlers/base.py", line 112, in get_response
    response = wrapped_callback(request, *callback_args, **callback_kwargs)
  File "/home/kalinins/.virtualenvs/zapsum/lib/python3.4/site-packages/django/contrib/auth/decorators.py", line 22, in _wrapped_view
    return view_func(request, *args, **kwargs)
  File "/home/kalinins/.virtualenvs/zapsum/zapsum/app_zapsum/views.py", line 92, in change_avatar
    data=simplejson.dumps({'txt': 'Загрузили'})
NameError: name 'simplejson' is not defined
Internal Server Error: /change_avatar/
Traceback (most recent call last):
  File "/home/kalinins/.virtualenvs/zapsum/lib/python3.4/site-packages/django/core/handlers/base.py", line 112, in get_response
    response = wrapped_callback(request, *callback_args, **callback_kwargs)
  File "/home/kalinins/.virtualenvs/zapsum/lib/python3.4/site-packages/django/contrib/auth/decorators.py", line 22, in _wrapped_view
    return view_func(request, *args, **kwargs)
  File "/home/kalinins/.virtualenvs/zapsum/zapsum/app_zapsum/views.py", line 92, in change_avatar
    return HttpResponse(json.dumps(data), content_type='application/json')
NameError: name 'data' is not defined
Internal Server Error: /change_avatar/
Traceback (most recent call last):
  File "/home/kalinins/.virtualenvs/zapsum/lib/python3.4/site-packages/django/core/handlers/base.py", line 112, in get_response
    response = wrapped_callback(request, *callback_args, **callback_kwargs)
  File "/home/kalinins/.virtualenvs/zapsum/lib/python3.4/site-packages/django/contrib/auth/decorators.py", line 22, in _wrapped_view
    return view_func(request, *args, **kwargs)
  File "/home/kalinins/.virtualenvs/zapsum/zapsum/app_zapsum/views.py", line 92, in change_avatar
    data=simplejson.dumps({'txt': 'Загрузили'})
NameError: name 'simplejson' is not defined
Forbidden (CSRF token missing or incorrect.): /change_avatar/
Not Found: /change_avatar/1
Not Found: /change_avatar/1
Internal Server Error: /change_avatar/
Traceback (most recent call last):
  File "/home/kalinins/.virtualenvs/zapsum/lib/python3.4/site-packages/django/utils/datastructures.py", line 299, in __getitem__
    list_ = super(MultiValueDict, self).__getitem__(key)
KeyError: 'filename'

During handling of the above exception, another exception occurred:

Traceback (most recent call last):
  File "/home/kalinins/.virtualenvs/zapsum/lib/python3.4/site-packages/django/core/handlers/base.py", line 112, in get_response
    response = wrapped_callback(request, *callback_args, **callback_kwargs)
  File "/home/kalinins/.virtualenvs/zapsum/lib/python3.4/site-packages/django/contrib/auth/decorators.py", line 22, in _wrapped_view
    return view_func(request, *args, **kwargs)
  File "/home/kalinins/.virtualenvs/zapsum/zapsum/app_zapsum/views.py", line 90, in change_avatar
    data = {'sourceImg': request.FILES['filename'].name}
  File "/home/kalinins/.virtualenvs/zapsum/lib/python3.4/site-packages/django/utils/datastructures.py", line 301, in __getitem__
    raise MultiValueDictKeyError(repr(key))
django.utils.datastructures.MultiValueDictKeyError: "'filename'"
Internal Server Error: /change_avatar/
Traceback (most recent call last):
  File "/home/kalinins/.virtualenvs/zapsum/lib/python3.4/site-packages/django/utils/datastructures.py", line 299, in __getitem__
    list_ = super(MultiValueDict, self).__getitem__(key)
KeyError: 'filename'

During handling of the above exception, another exception occurred:

Traceback (most recent call last):
  File "/home/kalinins/.virtualenvs/zapsum/lib/python3.4/site-packages/django/core/handlers/base.py", line 112, in get_response
    response = wrapped_callback(request, *callback_args, **callback_kwargs)
  File "/home/kalinins/.virtualenvs/zapsum/lib/python3.4/site-packages/django/contrib/auth/decorators.py", line 22, in _wrapped_view
    return view_func(request, *args, **kwargs)
  File "/home/kalinins/.virtualenvs/zapsum/zapsum/app_zapsum/views.py", line 90, in change_avatar
    data = {'sourceImg': request.FILES['filename'].name}
  File "/home/kalinins/.virtualenvs/zapsum/lib/python3.4/site-packages/django/utils/datastructures.py", line 301, in __getitem__
    raise MultiValueDictKeyError(repr(key))
django.utils.datastructures.MultiValueDictKeyError: "'filename'"
Internal Server Error: /change_avatar/
Traceback (most recent call last):
  File "/home/kalinins/.virtualenvs/zapsum/lib/python3.4/site-packages/django/utils/datastructures.py", line 299, in __getitem__
    list_ = super(MultiValueDict, self).__getitem__(key)
KeyError: 'filename'

During handling of the above exception, another exception occurred:

Traceback (most recent call last):
  File "/home/kalinins/.virtualenvs/zapsum/lib/python3.4/site-packages/django/core/handlers/base.py", line 112, in get_response
    response = wrapped_callback(request, *callback_args, **callback_kwargs)
  File "/home/kalinins/.virtualenvs/zapsum/lib/python3.4/site-packages/django/contrib/auth/decorators.py", line 22, in _wrapped_view
    return view_func(request, *args, **kwargs)
  File "/home/kalinins/.virtualenvs/zapsum/zapsum/app_zapsum/views.py", line 91, in change_avatar
    file = request.FILES['filename']
  File "/home/kalinins/.virtualenvs/zapsum/lib/python3.4/site-packages/django/utils/datastructures.py", line 301, in __getitem__
    raise MultiValueDictKeyError(repr(key))
django.utils.datastructures.MultiValueDictKeyError: "'filename'"
Internal Server Error: /change_avatar/
Traceback (most recent call last):
  File "/home/kalinins/.virtualenvs/zapsum/lib/python3.4/site-packages/django/utils/datastructures.py", line 299, in __getitem__
    list_ = super(MultiValueDict, self).__getitem__(key)
KeyError: 'filename'

During handling of the above exception, another exception occurred:

Traceback (most recent call last):
  File "/home/kalinins/.virtualenvs/zapsum/lib/python3.4/site-packages/django/core/handlers/base.py", line 112, in get_response
    response = wrapped_callback(request, *callback_args, **callback_kwargs)
  File "/home/kalinins/.virtualenvs/zapsum/lib/python3.4/site-packages/django/contrib/auth/decorators.py", line 22, in _wrapped_view
    return view_func(request, *args, **kwargs)
  File "/home/kalinins/.virtualenvs/zapsum/zapsum/app_zapsum/views.py", line 91, in change_avatar
    file = request.FILES['filename']
  File "/home/kalinins/.virtualenvs/zapsum/lib/python3.4/site-packages/django/utils/datastructures.py", line 301, in __getitem__
    raise MultiValueDictKeyError(repr(key))
django.utils.datastructures.MultiValueDictKeyError: "'filename'"
Internal Server Error: /change_avatar/
Traceback (most recent call last):
  File "/home/kalinins/.virtualenvs/zapsum/lib/python3.4/site-packages/django/core/handlers/base.py", line 112, in get_response
    response = wrapped_callback(request, *callback_args, **callback_kwargs)
  File "/home/kalinins/.virtualenvs/zapsum/lib/python3.4/site-packages/django/contrib/auth/decorators.py", line 22, in _wrapped_view
    return view_func(request, *args, **kwargs)
  File "/home/kalinins/.virtualenvs/zapsum/zapsum/app_zapsum/views.py", line 91, in change_avatar
    for filename, file in request.FILES.iteritems():
AttributeError: 'MultiValueDict' object has no attribute 'iteritems'
Internal Server Error: /change_avatar/
Traceback (most recent call last):
  File "/home/kalinins/.virtualenvs/zapsum/lib/python3.4/site-packages/django/core/handlers/base.py", line 112, in get_response
    response = wrapped_callback(request, *callback_args, **callback_kwargs)
  File "/home/kalinins/.virtualenvs/zapsum/lib/python3.4/site-packages/django/contrib/auth/decorators.py", line 22, in _wrapped_view
    return view_func(request, *args, **kwargs)
  File "/home/kalinins/.virtualenvs/zapsum/zapsum/app_zapsum/views.py", line 91, in change_avatar
    for filename, file in request.FILES.iteritems():
AttributeError: 'MultiValueDict' object has no attribute 'iteritems'
Internal Server Error: /change_avatar/
Traceback (most recent call last):
  File "/home/kalinins/.virtualenvs/zapsum/lib/python3.4/site-packages/django/core/handlers/base.py", line 112, in get_response
    response = wrapped_callback(request, *callback_args, **callback_kwargs)
  File "/home/kalinins/.virtualenvs/zapsum/lib/python3.4/site-packages/django/contrib/auth/decorators.py", line 22, in _wrapped_view
    return view_func(request, *args, **kwargs)
  File "/home/kalinins/.virtualenvs/zapsum/zapsum/app_zapsum/views.py", line 91, in change_avatar
    for filename in request.FILES.iteritems():
AttributeError: 'MultiValueDict' object has no attribute 'iteritems'
Internal Server Error: /change_avatar/
Traceback (most recent call last):
  File "/home/kalinins/.virtualenvs/zapsum/lib/python3.4/site-packages/django/core/handlers/base.py", line 112, in get_response
    response = wrapped_callback(request, *callback_args, **callback_kwargs)
  File "/home/kalinins/.virtualenvs/zapsum/lib/python3.4/site-packages/django/contrib/auth/decorators.py", line 22, in _wrapped_view
    return view_func(request, *args, **kwargs)
  File "/home/kalinins/.virtualenvs/zapsum/zapsum/app_zapsum/views.py", line 91, in change_avatar
    for filename in request.FILES.iteritems():
AttributeError: 'MultiValueDict' object has no attribute 'iteritems'
Internal Server Error: /change_avatar/
Traceback (most recent call last):
  File "/home/kalinins/.virtualenvs/zapsum/lib/python3.4/site-packages/django/core/handlers/base.py", line 112, in get_response
    response = wrapped_callback(request, *callback_args, **callback_kwargs)
  File "/home/kalinins/.virtualenvs/zapsum/lib/python3.4/site-packages/django/contrib/auth/decorators.py", line 22, in _wrapped_view
    return view_func(request, *args, **kwargs)
  File "/home/kalinins/.virtualenvs/zapsum/zapsum/app_zapsum/views.py", line 91, in change_avatar
    for filename, blob in request.FILES.iteritems():
AttributeError: 'MultiValueDict' object has no attribute 'iteritems'
Internal Server Error: /change_avatar/
Traceback (most recent call last):
  File "/home/kalinins/.virtualenvs/zapsum/lib/python3.4/site-packages/django/core/handlers/base.py", line 112, in get_response
    response = wrapped_callback(request, *callback_args, **callback_kwargs)
  File "/home/kalinins/.virtualenvs/zapsum/lib/python3.4/site-packages/django/contrib/auth/decorators.py", line 22, in _wrapped_view
    return view_func(request, *args, **kwargs)
  File "/home/kalinins/.virtualenvs/zapsum/zapsum/app_zapsum/views.py", line 91, in change_avatar
    for filename, blob in request.FILES.iteritems():
AttributeError: 'MultiValueDict' object has no attribute 'iteritems'
Internal Server Error: /change_avatar/
Traceback (most recent call last):
  File "/home/kalinins/.virtualenvs/zapsum/lib/python3.4/site-packages/django/core/handlers/base.py", line 112, in get_response
    response = wrapped_callback(request, *callback_args, **callback_kwargs)
  File "/home/kalinins/.virtualenvs/zapsum/lib/python3.4/site-packages/django/contrib/auth/decorators.py", line 22, in _wrapped_view
    return view_func(request, *args, **kwargs)
  File "/home/kalinins/.virtualenvs/zapsum/zapsum/app_zapsum/views.py", line 94, in change_avatar
    data = {'sourceImg': name}
UnboundLocalError: local variable 'name' referenced before assignment
Internal Server Error: /change_avatar/
Traceback (most recent call last):
  File "/home/kalinins/.virtualenvs/zapsum/lib/python3.4/site-packages/django/core/handlers/base.py", line 112, in get_response
    response = wrapped_callback(request, *callback_args, **callback_kwargs)
  File "/home/kalinins/.virtualenvs/zapsum/lib/python3.4/site-packages/django/contrib/auth/decorators.py", line 22, in _wrapped_view
    return view_func(request, *args, **kwargs)
  File "/home/kalinins/.virtualenvs/zapsum/zapsum/app_zapsum/views.py", line 94, in change_avatar
    data = {'sourceImg': name}
UnboundLocalError: local variable 'name' referenced before assignment
Internal Server Error: /change_avatar/
Traceback (most recent call last):
  File "/home/kalinins/.virtualenvs/zapsum/lib/python3.4/site-packages/django/core/handlers/base.py", line 112, in get_response
    response = wrapped_callback(request, *callback_args, **callback_kwargs)
  File "/home/kalinins/.virtualenvs/zapsum/lib/python3.4/site-packages/django/contrib/auth/decorators.py", line 22, in _wrapped_view
    return view_func(request, *args, **kwargs)
  File "/home/kalinins/.virtualenvs/zapsum/zapsum/app_zapsum/views.py", line 94, in change_avatar
    data = {'filename': name}
UnboundLocalError: local variable 'name' referenced before assignment
Internal Server Error: /change_avatar/
Traceback (most recent call last):
  File "/home/kalinins/.virtualenvs/zapsum/lib/python3.4/site-packages/django/core/handlers/base.py", line 112, in get_response
    response = wrapped_callback(request, *callback_args, **callback_kwargs)
  File "/home/kalinins/.virtualenvs/zapsum/lib/python3.4/site-packages/django/contrib/auth/decorators.py", line 22, in _wrapped_view
    return view_func(request, *args, **kwargs)
  File "/home/kalinins/.virtualenvs/zapsum/zapsum/app_zapsum/views.py", line 94, in change_avatar
    data = {'filename': name}
UnboundLocalError: local variable 'name' referenced before assignment
Not Found: /accounts/login/
Not Found: /favicon.ico
Internal Server Error: /add_records/
Traceback (most recent call last):
  File "/home/kalinins/.virtualenvs/zapsum/lib/python3.4/site-packages/django/core/handlers/base.py", line 99, in get_response
    resolver_match = resolver.resolve(request.path_info)
  File "/home/kalinins/.virtualenvs/zapsum/lib/python3.4/site-packages/django/core/urlresolvers.py", line 339, in resolve
    sub_match = pattern.resolve(new_path)
  File "/home/kalinins/.virtualenvs/zapsum/lib/python3.4/site-packages/django/core/urlresolvers.py", line 339, in resolve
    sub_match = pattern.resolve(new_path)
  File "/home/kalinins/.virtualenvs/zapsum/lib/python3.4/site-packages/django/core/urlresolvers.py", line 223, in resolve
    return ResolverMatch(self.callback, args, kwargs, self.name)
  File "/home/kalinins/.virtualenvs/zapsum/lib/python3.4/site-packages/django/core/urlresolvers.py", line 230, in callback
    self._callback = get_callable(self._callback_str)
  File "/home/kalinins/.virtualenvs/zapsum/lib/python3.4/site-packages/django/utils/functional.py", line 32, in wrapper
    result = func(*args)
  File "/home/kalinins/.virtualenvs/zapsum/lib/python3.4/site-packages/django/core/urlresolvers.py", line 97, in get_callable
    mod = import_module(mod_name)
  File "/home/kalinins/.virtualenvs/zapsum/lib/python3.4/importlib/__init__.py", line 109, in import_module
    return _bootstrap._gcd_import(name[level:], package, level)
  File "<frozen importlib._bootstrap>", line 2231, in _gcd_import
  File "<frozen importlib._bootstrap>", line 2214, in _find_and_load
  File "<frozen importlib._bootstrap>", line 2203, in _find_and_load_unlocked
  File "<frozen importlib._bootstrap>", line 1200, in _load_unlocked
  File "<frozen importlib._bootstrap>", line 1129, in _exec
  File "<frozen importlib._bootstrap>", line 1448, in exec_module
  File "<frozen importlib._bootstrap>", line 321, in _call_with_frames_removed
  File "/home/kalinins/.virtualenvs/zapsum/zapsum/app_zapsum/views.py", line 13, in <module>
    from app_zapsum.forms import ChangePasswordForm, ChangeAvatarForm, addMessageForm
  File "/home/kalinins/.virtualenvs/zapsum/zapsum/app_zapsum/forms.py", line 64, in <module>
    class addMessageForm(forms.ModelForm):
  File "/home/kalinins/.virtualenvs/zapsum/zapsum/app_zapsum/forms.py", line 73, in addMessageForm
    class Meta:
  File "/home/kalinins/.virtualenvs/zapsum/zapsum/app_zapsum/forms.py", line 74, in Meta
    model = PathGlory
NameError: name 'PathGlory' is not defined
Internal Server Error: /add_records/
Traceback (most recent call last):
  File "/home/kalinins/.virtualenvs/zapsum/lib/python3.4/site-packages/django/core/handlers/base.py", line 99, in get_response
    resolver_match = resolver.resolve(request.path_info)
  File "/home/kalinins/.virtualenvs/zapsum/lib/python3.4/site-packages/django/core/urlresolvers.py", line 339, in resolve
    sub_match = pattern.resolve(new_path)
  File "/home/kalinins/.virtualenvs/zapsum/lib/python3.4/site-packages/django/core/urlresolvers.py", line 339, in resolve
    sub_match = pattern.resolve(new_path)
  File "/home/kalinins/.virtualenvs/zapsum/lib/python3.4/site-packages/django/core/urlresolvers.py", line 223, in resolve
    return ResolverMatch(self.callback, args, kwargs, self.name)
  File "/home/kalinins/.virtualenvs/zapsum/lib/python3.4/site-packages/django/core/urlresolvers.py", line 230, in callback
    self._callback = get_callable(self._callback_str)
  File "/home/kalinins/.virtualenvs/zapsum/lib/python3.4/site-packages/django/utils/functional.py", line 32, in wrapper
    result = func(*args)
  File "/home/kalinins/.virtualenvs/zapsum/lib/python3.4/site-packages/django/core/urlresolvers.py", line 97, in get_callable
    mod = import_module(mod_name)
  File "/home/kalinins/.virtualenvs/zapsum/lib/python3.4/importlib/__init__.py", line 109, in import_module
    return _bootstrap._gcd_import(name[level:], package, level)
  File "<frozen importlib._bootstrap>", line 2231, in _gcd_import
  File "<frozen importlib._bootstrap>", line 2214, in _find_and_load
  File "<frozen importlib._bootstrap>", line 2203, in _find_and_load_unlocked
  File "<frozen importlib._bootstrap>", line 1200, in _load_unlocked
  File "<frozen importlib._bootstrap>", line 1129, in _exec
  File "<frozen importlib._bootstrap>", line 1448, in exec_module
  File "<frozen importlib._bootstrap>", line 321, in _call_with_frames_removed
  File "/home/kalinins/.virtualenvs/zapsum/zapsum/app_zapsum/views.py", line 13, in <module>
    from app_zapsum.forms import ChangePasswordForm, ChangeAvatarForm, addMessageForm
  File "/home/kalinins/.virtualenvs/zapsum/zapsum/app_zapsum/forms.py", line 64, in <module>
    class addMessageForm(forms.ModelForm):
  File "/home/kalinins/.virtualenvs/zapsum/zapsum/app_zapsum/forms.py", line 73, in addMessageForm
    class Meta:
  File "/home/kalinins/.virtualenvs/zapsum/zapsum/app_zapsum/forms.py", line 74, in Meta
    model = Diary
NameError: name 'Diary' is not defined
Not Found: /accounts/login/
Not Found: /add_records/ya.ru
Internal Server Error: /add_records/
Traceback (most recent call last):
  File "/home/kalinins/.virtualenvs/zapsum/lib/python3.4/site-packages/django/core/handlers/base.py", line 112, in get_response
    response = wrapped_callback(request, *callback_args, **callback_kwargs)
  File "/home/kalinins/.virtualenvs/zapsum/lib/python3.4/site-packages/django/contrib/auth/decorators.py", line 22, in _wrapped_view
    return view_func(request, *args, **kwargs)
  File "/home/kalinins/.virtualenvs/zapsum/zapsum/app_zapsum/views.py", line 80, in add_records
    form = ProfileForm(request.POST, instance=entry_user_profile)
NameError: name 'entry_user_profile' is not defined
Internal Server Error: /add_records/
Traceback (most recent call last):
  File "/home/kalinins/.virtualenvs/zapsum/lib/python3.4/site-packages/django/core/handlers/base.py", line 112, in get_response
    response = wrapped_callback(request, *callback_args, **callback_kwargs)
  File "/home/kalinins/.virtualenvs/zapsum/lib/python3.4/site-packages/django/contrib/auth/decorators.py", line 22, in _wrapped_view
    return view_func(request, *args, **kwargs)
  File "/home/kalinins/.virtualenvs/zapsum/zapsum/app_zapsum/views.py", line 81, in add_records
    print(form.cleaned_data.get('title'));
AttributeError: 'ProfileForm' object has no attribute 'cleaned_data'
Internal Server Error: /add_records/
Traceback (most recent call last):
  File "/home/kalinins/.virtualenvs/zapsum/lib/python3.4/site-packages/django/core/handlers/base.py", line 112, in get_response
    response = wrapped_callback(request, *callback_args, **callback_kwargs)
  File "/home/kalinins/.virtualenvs/zapsum/lib/python3.4/site-packages/django/contrib/auth/decorators.py", line 22, in _wrapped_view
    return view_func(request, *args, **kwargs)
  File "/home/kalinins/.virtualenvs/zapsum/zapsum/app_zapsum/views.py", line 81, in add_records
    print(form.cleaned_data.get('title'));
AttributeError: 'ProfileForm' object has no attribute 'cleaned_data'
Internal Server Error: /add_records/
Traceback (most recent call last):
  File "/home/kalinins/.virtualenvs/zapsum/lib/python3.4/site-packages/django/core/handlers/base.py", line 112, in get_response
    response = wrapped_callback(request, *callback_args, **callback_kwargs)
  File "/home/kalinins/.virtualenvs/zapsum/lib/python3.4/site-packages/django/contrib/auth/decorators.py", line 22, in _wrapped_view
    return view_func(request, *args, **kwargs)
  File "/home/kalinins/.virtualenvs/zapsum/zapsum/app_zapsum/views.py", line 81, in add_records
    print(form.cleaned_data.get('title'));
AttributeError: 'addMessageForm' object has no attribute 'cleaned_data'
Internal Server Error: /add_records/
Traceback (most recent call last):
  File "/home/kalinins/.virtualenvs/zapsum/lib/python3.4/site-packages/django/core/handlers/base.py", line 112, in get_response
    response = wrapped_callback(request, *callback_args, **callback_kwargs)
  File "/home/kalinins/.virtualenvs/zapsum/lib/python3.4/site-packages/django/contrib/auth/decorators.py", line 22, in _wrapped_view
    return view_func(request, *args, **kwargs)
  File "/home/kalinins/.virtualenvs/zapsum/zapsum/app_zapsum/views.py", line 89, in add_records
    text=form.cleaned_data.get('text').strip(),
TypeError: save() got an unexpected keyword argument 'user_id'
Internal Server Error: /add_records/
Traceback (most recent call last):
  File "/home/kalinins/.virtualenvs/zapsum/lib/python3.4/site-packages/django/core/handlers/base.py", line 112, in get_response
    response = wrapped_callback(request, *callback_args, **callback_kwargs)
  File "/home/kalinins/.virtualenvs/zapsum/lib/python3.4/site-packages/django/contrib/auth/decorators.py", line 22, in _wrapped_view
    return view_func(request, *args, **kwargs)
  File "/home/kalinins/.virtualenvs/zapsum/zapsum/app_zapsum/views.py", line 89, in add_records
    text=form.cleaned_data.get('text').strip(),
TypeError: save() got an unexpected keyword argument 'user'
Internal Server Error: /add_records/
Traceback (most recent call last):
  File "/home/kalinins/.virtualenvs/zapsum/lib/python3.4/site-packages/django/core/handlers/base.py", line 112, in get_response
    response = wrapped_callback(request, *callback_args, **callback_kwargs)
  File "/home/kalinins/.virtualenvs/zapsum/lib/python3.4/site-packages/django/contrib/auth/decorators.py", line 22, in _wrapped_view
    return view_func(request, *args, **kwargs)
  File "/home/kalinins/.virtualenvs/zapsum/zapsum/app_zapsum/views.py", line 89, in add_records
    text=form.cleaned_data.get('text').strip(),
TypeError: save() got an unexpected keyword argument 'user_id'
Internal Server Error: /add_records/
Traceback (most recent call last):
  File "/home/kalinins/.virtualenvs/zapsum/lib/python3.4/site-packages/django/core/handlers/base.py", line 112, in get_response
    response = wrapped_callback(request, *callback_args, **callback_kwargs)
  File "/home/kalinins/.virtualenvs/zapsum/lib/python3.4/site-packages/django/contrib/auth/decorators.py", line 22, in _wrapped_view
    return view_func(request, *args, **kwargs)
  File "/home/kalinins/.virtualenvs/zapsum/zapsum/app_zapsum/views.py", line 89, in add_records
    text=form.cleaned_data.get('text').strip(),
TypeError: save() got an unexpected keyword argument 'user_id'
Internal Server Error: /add_records/
Traceback (most recent call last):
  File "/home/kalinins/.virtualenvs/zapsum/lib/python3.4/site-packages/django/core/handlers/base.py", line 112, in get_response
    response = wrapped_callback(request, *callback_args, **callback_kwargs)
  File "/home/kalinins/.virtualenvs/zapsum/lib/python3.4/site-packages/django/contrib/auth/decorators.py", line 22, in _wrapped_view
    return view_func(request, *args, **kwargs)
  File "/home/kalinins/.virtualenvs/zapsum/zapsum/app_zapsum/views.py", line 89, in add_records
    text=form.cleaned_data.get('text').strip(),
TypeError: save() got an unexpected keyword argument 'user_id'
Internal Server Error: /add_records/
Traceback (most recent call last):
  File "/home/kalinins/.virtualenvs/zapsum/lib/python3.4/site-packages/django/core/handlers/base.py", line 112, in get_response
    response = wrapped_callback(request, *callback_args, **callback_kwargs)
  File "/home/kalinins/.virtualenvs/zapsum/lib/python3.4/site-packages/django/contrib/auth/decorators.py", line 22, in _wrapped_view
    return view_func(request, *args, **kwargs)
  File "/home/kalinins/.virtualenvs/zapsum/zapsum/app_zapsum/views.py", line 91, in add_records
    text='324',
TypeError: save() got an unexpected keyword argument 'user_id'
Internal Server Error: /add_records/
Traceback (most recent call last):
  File "/home/kalinins/.virtualenvs/zapsum/lib/python3.4/site-packages/django/core/handlers/base.py", line 112, in get_response
    response = wrapped_callback(request, *callback_args, **callback_kwargs)
  File "/home/kalinins/.virtualenvs/zapsum/lib/python3.4/site-packages/django/contrib/auth/decorators.py", line 22, in _wrapped_view
    return view_func(request, *args, **kwargs)
  File "/home/kalinins/.virtualenvs/zapsum/zapsum/app_zapsum/views.py", line 91, in add_records
    text='324',
TypeError: save() got an unexpected keyword argument 'user_id'
Internal Server Error: /add_records/
Traceback (most recent call last):
  File "/home/kalinins/.virtualenvs/zapsum/lib/python3.4/site-packages/django/core/handlers/base.py", line 112, in get_response
    response = wrapped_callback(request, *callback_args, **callback_kwargs)
  File "/home/kalinins/.virtualenvs/zapsum/lib/python3.4/site-packages/django/contrib/auth/decorators.py", line 22, in _wrapped_view
    return view_func(request, *args, **kwargs)
  File "/home/kalinins/.virtualenvs/zapsum/zapsum/app_zapsum/views.py", line 91, in add_records
    text='324',
TypeError: save() got an unexpected keyword argument 'user_id'
Internal Server Error: /add_records/
Traceback (most recent call last):
  File "/home/kalinins/.virtualenvs/zapsum/lib/python3.4/site-packages/django/db/backends/util.py", line 53, in execute
    return self.cursor.execute(sql, params)
  File "/home/kalinins/.virtualenvs/zapsum/lib/python3.4/site-packages/django/db/backends/sqlite3/base.py", line 451, in execute
    return Database.Cursor.execute(self, query, params)
sqlite3.IntegrityError: NOT NULL constraint failed: app_zapsum_diary.date

The above exception was the direct cause of the following exception:

Traceback (most recent call last):
  File "/home/kalinins/.virtualenvs/zapsum/lib/python3.4/site-packages/django/core/handlers/base.py", line 112, in get_response
    response = wrapped_callback(request, *callback_args, **callback_kwargs)
  File "/home/kalinins/.virtualenvs/zapsum/lib/python3.4/site-packages/django/contrib/auth/decorators.py", line 22, in _wrapped_view
    return view_func(request, *args, **kwargs)
  File "/home/kalinins/.virtualenvs/zapsum/zapsum/app_zapsum/views.py", line 91, in add_records
    text='324',
  File "/home/kalinins/.virtualenvs/zapsum/lib/python3.4/site-packages/django/db/models/manager.py", line 157, in create
    return self.get_queryset().create(**kwargs)
  File "/home/kalinins/.virtualenvs/zapsum/lib/python3.4/site-packages/django/db/models/query.py", line 322, in create
    obj.save(force_insert=True, using=self.db)
  File "/home/kalinins/.virtualenvs/zapsum/lib/python3.4/site-packages/django/db/models/base.py", line 545, in save
    force_update=force_update, update_fields=update_fields)
  File "/home/kalinins/.virtualenvs/zapsum/lib/python3.4/site-packages/django/db/models/base.py", line 573, in save_base
    updated = self._save_table(raw, cls, force_insert, force_update, using, update_fields)
  File "/home/kalinins/.virtualenvs/zapsum/lib/python3.4/site-packages/django/db/models/base.py", line 654, in _save_table
    result = self._do_insert(cls._base_manager, using, fields, update_pk, raw)
  File "/home/kalinins/.virtualenvs/zapsum/lib/python3.4/site-packages/django/db/models/base.py", line 687, in _do_insert
    using=using, raw=raw)
  File "/home/kalinins/.virtualenvs/zapsum/lib/python3.4/site-packages/django/db/models/manager.py", line 232, in _insert
    return insert_query(self.model, objs, fields, **kwargs)
  File "/home/kalinins/.virtualenvs/zapsum/lib/python3.4/site-packages/django/db/models/query.py", line 1514, in insert_query
    return query.get_compiler(using=using).execute_sql(return_id)
  File "/home/kalinins/.virtualenvs/zapsum/lib/python3.4/site-packages/django/db/models/sql/compiler.py", line 903, in execute_sql
    cursor.execute(sql, params)
  File "/home/kalinins/.virtualenvs/zapsum/lib/python3.4/site-packages/django/db/backends/util.py", line 69, in execute
    return super(CursorDebugWrapper, self).execute(sql, params)
  File "/home/kalinins/.virtualenvs/zapsum/lib/python3.4/site-packages/django/db/backends/util.py", line 53, in execute
    return self.cursor.execute(sql, params)
  File "/home/kalinins/.virtualenvs/zapsum/lib/python3.4/site-packages/django/db/utils.py", line 99, in __exit__
    six.reraise(dj_exc_type, dj_exc_value, traceback)
  File "/home/kalinins/.virtualenvs/zapsum/lib/python3.4/site-packages/django/utils/six.py", line 549, in reraise
    raise value.with_traceback(tb)
  File "/home/kalinins/.virtualenvs/zapsum/lib/python3.4/site-packages/django/db/backends/util.py", line 53, in execute
    return self.cursor.execute(sql, params)
  File "/home/kalinins/.virtualenvs/zapsum/lib/python3.4/site-packages/django/db/backends/sqlite3/base.py", line 451, in execute
    return Database.Cursor.execute(self, query, params)
django.db.utils.IntegrityError: NOT NULL constraint failed: app_zapsum_diary.date
Not Found: /accounts/login/
Internal Server Error: /add_records/
Traceback (most recent call last):
  File "/home/kalinins/.virtualenvs/zapsum/lib/python3.4/site-packages/django/db/backends/util.py", line 53, in execute
    return self.cursor.execute(sql, params)
  File "/home/kalinins/.virtualenvs/zapsum/lib/python3.4/site-packages/django/db/backends/sqlite3/base.py", line 451, in execute
    return Database.Cursor.execute(self, query, params)
sqlite3.IntegrityError: NOT NULL constraint failed: app_zapsum_diary.date

The above exception was the direct cause of the following exception:

Traceback (most recent call last):
  File "/home/kalinins/.virtualenvs/zapsum/lib/python3.4/site-packages/django/core/handlers/base.py", line 112, in get_response
    response = wrapped_callback(request, *callback_args, **callback_kwargs)
  File "/home/kalinins/.virtualenvs/zapsum/lib/python3.4/site-packages/django/contrib/auth/decorators.py", line 22, in _wrapped_view
    return view_func(request, *args, **kwargs)
  File "/home/kalinins/.virtualenvs/zapsum/zapsum/app_zapsum/views.py", line 91, in add_records
    text='324',
  File "/home/kalinins/.virtualenvs/zapsum/lib/python3.4/site-packages/django/db/models/manager.py", line 157, in create
    return self.get_queryset().create(**kwargs)
  File "/home/kalinins/.virtualenvs/zapsum/lib/python3.4/site-packages/django/db/models/query.py", line 322, in create
    obj.save(force_insert=True, using=self.db)
  File "/home/kalinins/.virtualenvs/zapsum/lib/python3.4/site-packages/django/db/models/base.py", line 545, in save
    force_update=force_update, update_fields=update_fields)
  File "/home/kalinins/.virtualenvs/zapsum/lib/python3.4/site-packages/django/db/models/base.py", line 573, in save_base
    updated = self._save_table(raw, cls, force_insert, force_update, using, update_fields)
  File "/home/kalinins/.virtualenvs/zapsum/lib/python3.4/site-packages/django/db/models/base.py", line 654, in _save_table
    result = self._do_insert(cls._base_manager, using, fields, update_pk, raw)
  File "/home/kalinins/.virtualenvs/zapsum/lib/python3.4/site-packages/django/db/models/base.py", line 687, in _do_insert
    using=using, raw=raw)
  File "/home/kalinins/.virtualenvs/zapsum/lib/python3.4/site-packages/django/db/models/manager.py", line 232, in _insert
    return insert_query(self.model, objs, fields, **kwargs)
  File "/home/kalinins/.virtualenvs/zapsum/lib/python3.4/site-packages/django/db/models/query.py", line 1514, in insert_query
    return query.get_compiler(using=using).execute_sql(return_id)
  File "/home/kalinins/.virtualenvs/zapsum/lib/python3.4/site-packages/django/db/models/sql/compiler.py", line 903, in execute_sql
    cursor.execute(sql, params)
  File "/home/kalinins/.virtualenvs/zapsum/lib/python3.4/site-packages/django/db/backends/util.py", line 69, in execute
    return super(CursorDebugWrapper, self).execute(sql, params)
  File "/home/kalinins/.virtualenvs/zapsum/lib/python3.4/site-packages/django/db/backends/util.py", line 53, in execute
    return self.cursor.execute(sql, params)
  File "/home/kalinins/.virtualenvs/zapsum/lib/python3.4/site-packages/django/db/utils.py", line 99, in __exit__
    six.reraise(dj_exc_type, dj_exc_value, traceback)
  File "/home/kalinins/.virtualenvs/zapsum/lib/python3.4/site-packages/django/utils/six.py", line 549, in reraise
    raise value.with_traceback(tb)
  File "/home/kalinins/.virtualenvs/zapsum/lib/python3.4/site-packages/django/db/backends/util.py", line 53, in execute
    return self.cursor.execute(sql, params)
  File "/home/kalinins/.virtualenvs/zapsum/lib/python3.4/site-packages/django/db/backends/sqlite3/base.py", line 451, in execute
    return Database.Cursor.execute(self, query, params)
django.db.utils.IntegrityError: NOT NULL constraint failed: app_zapsum_diary.date
Internal Server Error: /add_records/
Traceback (most recent call last):
  File "/home/kalinins/.virtualenvs/zapsum/lib/python3.4/site-packages/django/db/backends/util.py", line 53, in execute
    return self.cursor.execute(sql, params)
  File "/home/kalinins/.virtualenvs/zapsum/lib/python3.4/site-packages/django/db/backends/sqlite3/base.py", line 451, in execute
    return Database.Cursor.execute(self, query, params)
sqlite3.IntegrityError: NOT NULL constraint failed: app_zapsum_diary.date

The above exception was the direct cause of the following exception:

Traceback (most recent call last):
  File "/home/kalinins/.virtualenvs/zapsum/lib/python3.4/site-packages/django/core/handlers/base.py", line 112, in get_response
    response = wrapped_callback(request, *callback_args, **callback_kwargs)
  File "/home/kalinins/.virtualenvs/zapsum/lib/python3.4/site-packages/django/contrib/auth/decorators.py", line 22, in _wrapped_view
    return view_func(request, *args, **kwargs)
  File "/home/kalinins/.virtualenvs/zapsum/zapsum/app_zapsum/views.py", line 91, in add_records
    text='324',
  File "/home/kalinins/.virtualenvs/zapsum/lib/python3.4/site-packages/django/db/models/manager.py", line 157, in create
    return self.get_queryset().create(**kwargs)
  File "/home/kalinins/.virtualenvs/zapsum/lib/python3.4/site-packages/django/db/models/query.py", line 322, in create
    obj.save(force_insert=True, using=self.db)
  File "/home/kalinins/.virtualenvs/zapsum/lib/python3.4/site-packages/django/db/models/base.py", line 545, in save
    force_update=force_update, update_fields=update_fields)
  File "/home/kalinins/.virtualenvs/zapsum/lib/python3.4/site-packages/django/db/models/base.py", line 573, in save_base
    updated = self._save_table(raw, cls, force_insert, force_update, using, update_fields)
  File "/home/kalinins/.virtualenvs/zapsum/lib/python3.4/site-packages/django/db/models/base.py", line 654, in _save_table
    result = self._do_insert(cls._base_manager, using, fields, update_pk, raw)
  File "/home/kalinins/.virtualenvs/zapsum/lib/python3.4/site-packages/django/db/models/base.py", line 687, in _do_insert
    using=using, raw=raw)
  File "/home/kalinins/.virtualenvs/zapsum/lib/python3.4/site-packages/django/db/models/manager.py", line 232, in _insert
    return insert_query(self.model, objs, fields, **kwargs)
  File "/home/kalinins/.virtualenvs/zapsum/lib/python3.4/site-packages/django/db/models/query.py", line 1514, in insert_query
    return query.get_compiler(using=using).execute_sql(return_id)
  File "/home/kalinins/.virtualenvs/zapsum/lib/python3.4/site-packages/django/db/models/sql/compiler.py", line 903, in execute_sql
    cursor.execute(sql, params)
  File "/home/kalinins/.virtualenvs/zapsum/lib/python3.4/site-packages/django/db/backends/util.py", line 69, in execute
    return super(CursorDebugWrapper, self).execute(sql, params)
  File "/home/kalinins/.virtualenvs/zapsum/lib/python3.4/site-packages/django/db/backends/util.py", line 53, in execute
    return self.cursor.execute(sql, params)
  File "/home/kalinins/.virtualenvs/zapsum/lib/python3.4/site-packages/django/db/utils.py", line 99, in __exit__
    six.reraise(dj_exc_type, dj_exc_value, traceback)
  File "/home/kalinins/.virtualenvs/zapsum/lib/python3.4/site-packages/django/utils/six.py", line 549, in reraise
    raise value.with_traceback(tb)
  File "/home/kalinins/.virtualenvs/zapsum/lib/python3.4/site-packages/django/db/backends/util.py", line 53, in execute
    return self.cursor.execute(sql, params)
  File "/home/kalinins/.virtualenvs/zapsum/lib/python3.4/site-packages/django/db/backends/sqlite3/base.py", line 451, in execute
    return Database.Cursor.execute(self, query, params)
django.db.utils.IntegrityError: NOT NULL constraint failed: app_zapsum_diary.date
Internal Server Error: /add_records/
Traceback (most recent call last):
  File "/home/kalinins/.virtualenvs/zapsum/lib/python3.4/site-packages/django/db/backends/util.py", line 53, in execute
    return self.cursor.execute(sql, params)
  File "/home/kalinins/.virtualenvs/zapsum/lib/python3.4/site-packages/django/db/backends/sqlite3/base.py", line 451, in execute
    return Database.Cursor.execute(self, query, params)
sqlite3.IntegrityError: NOT NULL constraint failed: app_zapsum_diary.date

The above exception was the direct cause of the following exception:

Traceback (most recent call last):
  File "/home/kalinins/.virtualenvs/zapsum/lib/python3.4/site-packages/django/core/handlers/base.py", line 112, in get_response
    response = wrapped_callback(request, *callback_args, **callback_kwargs)
  File "/home/kalinins/.virtualenvs/zapsum/lib/python3.4/site-packages/django/contrib/auth/decorators.py", line 22, in _wrapped_view
    return view_func(request, *args, **kwargs)
  File "/home/kalinins/.virtualenvs/zapsum/zapsum/app_zapsum/views.py", line 91, in add_records
    text='324',
  File "/home/kalinins/.virtualenvs/zapsum/lib/python3.4/site-packages/django/db/models/manager.py", line 157, in create
    return self.get_queryset().create(**kwargs)
  File "/home/kalinins/.virtualenvs/zapsum/lib/python3.4/site-packages/django/db/models/query.py", line 322, in create
    obj.save(force_insert=True, using=self.db)
  File "/home/kalinins/.virtualenvs/zapsum/lib/python3.4/site-packages/django/db/models/base.py", line 545, in save
    force_update=force_update, update_fields=update_fields)
  File "/home/kalinins/.virtualenvs/zapsum/lib/python3.4/site-packages/django/db/models/base.py", line 573, in save_base
    updated = self._save_table(raw, cls, force_insert, force_update, using, update_fields)
  File "/home/kalinins/.virtualenvs/zapsum/lib/python3.4/site-packages/django/db/models/base.py", line 654, in _save_table
    result = self._do_insert(cls._base_manager, using, fields, update_pk, raw)
  File "/home/kalinins/.virtualenvs/zapsum/lib/python3.4/site-packages/django/db/models/base.py", line 687, in _do_insert
    using=using, raw=raw)
  File "/home/kalinins/.virtualenvs/zapsum/lib/python3.4/site-packages/django/db/models/manager.py", line 232, in _insert
    return insert_query(self.model, objs, fields, **kwargs)
  File "/home/kalinins/.virtualenvs/zapsum/lib/python3.4/site-packages/django/db/models/query.py", line 1514, in insert_query
    return query.get_compiler(using=using).execute_sql(return_id)
  File "/home/kalinins/.virtualenvs/zapsum/lib/python3.4/site-packages/django/db/models/sql/compiler.py", line 903, in execute_sql
    cursor.execute(sql, params)
  File "/home/kalinins/.virtualenvs/zapsum/lib/python3.4/site-packages/django/db/backends/util.py", line 69, in execute
    return super(CursorDebugWrapper, self).execute(sql, params)
  File "/home/kalinins/.virtualenvs/zapsum/lib/python3.4/site-packages/django/db/backends/util.py", line 53, in execute
    return self.cursor.execute(sql, params)
  File "/home/kalinins/.virtualenvs/zapsum/lib/python3.4/site-packages/django/db/utils.py", line 99, in __exit__
    six.reraise(dj_exc_type, dj_exc_value, traceback)
  File "/home/kalinins/.virtualenvs/zapsum/lib/python3.4/site-packages/django/utils/six.py", line 549, in reraise
    raise value.with_traceback(tb)
  File "/home/kalinins/.virtualenvs/zapsum/lib/python3.4/site-packages/django/db/backends/util.py", line 53, in execute
    return self.cursor.execute(sql, params)
  File "/home/kalinins/.virtualenvs/zapsum/lib/python3.4/site-packages/django/db/backends/sqlite3/base.py", line 451, in execute
    return Database.Cursor.execute(self, query, params)
django.db.utils.IntegrityError: NOT NULL constraint failed: app_zapsum_diary.date
Not Found: /accounts/login/
Not Found: /accounts/login/
Internal Server Error: /add_records/
Traceback (most recent call last):
  File "/home/kalinins/.virtualenvs/zapsum/lib/python3.4/site-packages/django/core/handlers/base.py", line 112, in get_response
    response = wrapped_callback(request, *callback_args, **callback_kwargs)
  File "/home/kalinins/.virtualenvs/zapsum/lib/python3.4/site-packages/django/contrib/auth/decorators.py", line 22, in _wrapped_view
    return view_func(request, *args, **kwargs)
  File "/home/kalinins/.virtualenvs/zapsum/zapsum/app_zapsum/views.py", line 83, in add_records
    if form.is_valid():
  File "/home/kalinins/.virtualenvs/zapsum/lib/python3.4/site-packages/django/forms/forms.py", line 129, in is_valid
    return self.is_bound and not bool(self.errors)
  File "/home/kalinins/.virtualenvs/zapsum/lib/python3.4/site-packages/django/forms/forms.py", line 121, in errors
    self.full_clean()
  File "/home/kalinins/.virtualenvs/zapsum/lib/python3.4/site-packages/django/forms/forms.py", line 273, in full_clean
    self._clean_fields()
  File "/home/kalinins/.virtualenvs/zapsum/lib/python3.4/site-packages/django/forms/forms.py", line 291, in _clean_fields
    value = getattr(self, 'clean_%s' % name)()
  File "/home/kalinins/.virtualenvs/zapsum/zapsum/app_zapsum/forms.py", line 94, in clean_text
    title = self.cleaned_data['title']
KeyError: 'title'
Internal Server Error: /add_records/
Traceback (most recent call last):
  File "/home/kalinins/.virtualenvs/zapsum/lib/python3.4/site-packages/django/core/handlers/base.py", line 112, in get_response
    response = wrapped_callback(request, *callback_args, **callback_kwargs)
  File "/home/kalinins/.virtualenvs/zapsum/lib/python3.4/site-packages/django/contrib/auth/decorators.py", line 22, in _wrapped_view
    return view_func(request, *args, **kwargs)
  File "/home/kalinins/.virtualenvs/zapsum/zapsum/app_zapsum/views.py", line 83, in add_records
    if form.is_valid():
  File "/home/kalinins/.virtualenvs/zapsum/lib/python3.4/site-packages/django/forms/forms.py", line 129, in is_valid
    return self.is_bound and not bool(self.errors)
  File "/home/kalinins/.virtualenvs/zapsum/lib/python3.4/site-packages/django/forms/forms.py", line 121, in errors
    self.full_clean()
  File "/home/kalinins/.virtualenvs/zapsum/lib/python3.4/site-packages/django/forms/forms.py", line 273, in full_clean
    self._clean_fields()
  File "/home/kalinins/.virtualenvs/zapsum/lib/python3.4/site-packages/django/forms/forms.py", line 291, in _clean_fields
    value = getattr(self, 'clean_%s' % name)()
  File "/home/kalinins/.virtualenvs/zapsum/zapsum/app_zapsum/forms.py", line 94, in clean_text
    title = self.cleaned_data['title']
KeyError: 'title'
Not Found: /my_records/ok/
Internal Server Error: /my_records/
Traceback (most recent call last):
  File "/home/kalinins/.virtualenvs/zapsum/lib/python3.4/site-packages/django/core/handlers/base.py", line 112, in get_response
    response = wrapped_callback(request, *callback_args, **callback_kwargs)
  File "/home/kalinins/.virtualenvs/zapsum/lib/python3.4/site-packages/django/contrib/auth/decorators.py", line 22, in _wrapped_view
    return view_func(request, *args, **kwargs)
  File "/home/kalinins/.virtualenvs/zapsum/zapsum/app_zapsum/views.py", line 68, in my_records
    paginator = Paginator(all_user_entries, 3)
NameError: name 'Paginator' is not defined
Internal Server Error: /my_records/
Traceback (most recent call last):
  File "/home/kalinins/.virtualenvs/zapsum/lib/python3.4/site-packages/django/core/handlers/base.py", line 99, in get_response
    resolver_match = resolver.resolve(request.path_info)
  File "/home/kalinins/.virtualenvs/zapsum/lib/python3.4/site-packages/django/core/urlresolvers.py", line 339, in resolve
    sub_match = pattern.resolve(new_path)
  File "/home/kalinins/.virtualenvs/zapsum/lib/python3.4/site-packages/django/core/urlresolvers.py", line 339, in resolve
    sub_match = pattern.resolve(new_path)
  File "/home/kalinins/.virtualenvs/zapsum/lib/python3.4/site-packages/django/core/urlresolvers.py", line 223, in resolve
    return ResolverMatch(self.callback, args, kwargs, self.name)
  File "/home/kalinins/.virtualenvs/zapsum/lib/python3.4/site-packages/django/core/urlresolvers.py", line 230, in callback
    self._callback = get_callable(self._callback_str)
  File "/home/kalinins/.virtualenvs/zapsum/lib/python3.4/site-packages/django/utils/functional.py", line 32, in wrapper
    result = func(*args)
  File "/home/kalinins/.virtualenvs/zapsum/lib/python3.4/site-packages/django/core/urlresolvers.py", line 97, in get_callable
    mod = import_module(mod_name)
  File "/home/kalinins/.virtualenvs/zapsum/lib/python3.4/importlib/__init__.py", line 109, in import_module
    return _bootstrap._gcd_import(name[level:], package, level)
  File "<frozen importlib._bootstrap>", line 2231, in _gcd_import
  File "<frozen importlib._bootstrap>", line 2214, in _find_and_load
  File "<frozen importlib._bootstrap>", line 2203, in _find_and_load_unlocked
  File "<frozen importlib._bootstrap>", line 1200, in _load_unlocked
  File "<frozen importlib._bootstrap>", line 1129, in _exec
  File "<frozen importlib._bootstrap>", line 1444, in exec_module
  File "<frozen importlib._bootstrap>", line 1549, in get_code
  File "<frozen importlib._bootstrap>", line 1509, in source_to_code
  File "<frozen importlib._bootstrap>", line 321, in _call_with_frames_removed
  File "/home/kalinins/.virtualenvs/zapsum/zapsum/app_zapsum/views.py", line 121
    entry = Diary.get_entry(id=)
                               ^
SyntaxError: invalid syntax
Not Found: /my_records/2/
Internal Server Error: /edit_records/3/
Traceback (most recent call last):
  File "/home/kalinins/.virtualenvs/zapsum/lib/python3.4/site-packages/django/core/handlers/base.py", line 112, in get_response
    response = wrapped_callback(request, *callback_args, **callback_kwargs)
  File "/home/kalinins/.virtualenvs/zapsum/lib/python3.4/site-packages/django/contrib/auth/decorators.py", line 22, in _wrapped_view
    return view_func(request, *args, **kwargs)
TypeError: edit_records() got an unexpected keyword argument 'id'
Internal Server Error: /edit_records/3/
Traceback (most recent call last):
  File "/home/kalinins/.virtualenvs/zapsum/lib/python3.4/site-packages/django/core/handlers/base.py", line 112, in get_response
    response = wrapped_callback(request, *callback_args, **callback_kwargs)
  File "/home/kalinins/.virtualenvs/zapsum/lib/python3.4/site-packages/django/contrib/auth/decorators.py", line 22, in _wrapped_view
    return view_func(request, *args, **kwargs)
  File "/home/kalinins/.virtualenvs/zapsum/zapsum/app_zapsum/views.py", line 126, in edit_records
    'form': form,
NameError: name 'form' is not defined
Internal Server Error: /edit_records/3/
Traceback (most recent call last):
  File "/home/kalinins/.virtualenvs/zapsum/lib/python3.4/site-packages/django/template/defaulttags.py", line 441, in render
    current_app=context.current_app)
  File "/home/kalinins/.virtualenvs/zapsum/lib/python3.4/site-packages/django/core/urlresolvers.py", line 532, in reverse
    return iri_to_uri(resolver._reverse_with_prefix(view, prefix, *args, **kwargs))
  File "/home/kalinins/.virtualenvs/zapsum/lib/python3.4/site-packages/django/core/urlresolvers.py", line 452, in _reverse_with_prefix
    (lookup_view_s, args, kwargs, len(patterns), patterns))
django.core.urlresolvers.NoReverseMatch: Reverse for 'zapsum.edit_records' with arguments '()' and keyword arguments '{}' not found. 0 pattern(s) tried: []

During handling of the above exception, another exception occurred:

Traceback (most recent call last):
  File "/home/kalinins/.virtualenvs/zapsum/lib/python3.4/site-packages/django/core/handlers/base.py", line 112, in get_response
    response = wrapped_callback(request, *callback_args, **callback_kwargs)
  File "/home/kalinins/.virtualenvs/zapsum/lib/python3.4/site-packages/django/contrib/auth/decorators.py", line 22, in _wrapped_view
    return view_func(request, *args, **kwargs)
  File "/home/kalinins/.virtualenvs/zapsum/zapsum/app_zapsum/views.py", line 131, in edit_records
    return HttpResponse(t.render(c))
  File "/home/kalinins/.virtualenvs/zapsum/lib/python3.4/site-packages/django/template/base.py", line 140, in render
    return self._render(context)
  File "/home/kalinins/.virtualenvs/zapsum/lib/python3.4/site-packages/django/template/base.py", line 134, in _render
    return self.nodelist.render(context)
  File "/home/kalinins/.virtualenvs/zapsum/lib/python3.4/site-packages/django/template/base.py", line 840, in render
    bit = self.render_node(node, context)
  File "/home/kalinins/.virtualenvs/zapsum/lib/python3.4/site-packages/django/template/debug.py", line 78, in render_node
    return node.render(context)
  File "/home/kalinins/.virtualenvs/zapsum/lib/python3.4/site-packages/django/template/loader_tags.py", line 123, in render
    return compiled_parent._render(context)
  File "/home/kalinins/.virtualenvs/zapsum/lib/python3.4/site-packages/django/template/base.py", line 134, in _render
    return self.nodelist.render(context)
  File "/home/kalinins/.virtualenvs/zapsum/lib/python3.4/site-packages/django/template/base.py", line 840, in render
    bit = self.render_node(node, context)
  File "/home/kalinins/.virtualenvs/zapsum/lib/python3.4/site-packages/django/template/debug.py", line 78, in render_node
    return node.render(context)
  File "/home/kalinins/.virtualenvs/zapsum/lib/python3.4/site-packages/django/template/loader_tags.py", line 62, in render
    result = block.nodelist.render(context)
  File "/home/kalinins/.virtualenvs/zapsum/lib/python3.4/site-packages/django/template/base.py", line 840, in render
    bit = self.render_node(node, context)
  File "/home/kalinins/.virtualenvs/zapsum/lib/python3.4/site-packages/django/template/debug.py", line 78, in render_node
    return node.render(context)
  File "/home/kalinins/.virtualenvs/zapsum/lib/python3.4/site-packages/django/template/defaulttags.py", line 447, in render
    six.reraise(*exc_info)
  File "/home/kalinins/.virtualenvs/zapsum/lib/python3.4/site-packages/django/utils/six.py", line 550, in reraise
    raise value
  File "/home/kalinins/.virtualenvs/zapsum/lib/python3.4/site-packages/django/template/defaulttags.py", line 433, in render
    url = reverse(view_name, args=args, kwargs=kwargs, current_app=context.current_app)
  File "/home/kalinins/.virtualenvs/zapsum/lib/python3.4/site-packages/django/core/urlresolvers.py", line 532, in reverse
    return iri_to_uri(resolver._reverse_with_prefix(view, prefix, *args, **kwargs))
  File "/home/kalinins/.virtualenvs/zapsum/lib/python3.4/site-packages/django/core/urlresolvers.py", line 452, in _reverse_with_prefix
    (lookup_view_s, args, kwargs, len(patterns), patterns))
django.core.urlresolvers.NoReverseMatch: Reverse for 'edit_records' with arguments '()' and keyword arguments '{}' not found. 1 pattern(s) tried: ['edit_records/(?P<id_record>[0-9]+)/$']
Internal Server Error: /edit_records/3/
Traceback (most recent call last):
  File "/home/kalinins/.virtualenvs/zapsum/lib/python3.4/site-packages/django/core/handlers/base.py", line 112, in get_response
    response = wrapped_callback(request, *callback_args, **callback_kwargs)
  File "/home/kalinins/.virtualenvs/zapsum/lib/python3.4/site-packages/django/contrib/auth/decorators.py", line 22, in _wrapped_view
    return view_func(request, *args, **kwargs)
  File "/home/kalinins/.virtualenvs/zapsum/zapsum/app_zapsum/views.py", line 126, in edit_records
    if form.is_valid():
AttributeError: 'Diary' object has no attribute 'is_valid'
Not Found: /accounts/login/
Not Found: /accounts/login/
Not Found: /active_record/
Internal Server Error: /active_record/
Traceback (most recent call last):
  File "/home/kalinins/.virtualenvs/zapsum/lib/python3.4/site-packages/django/core/handlers/base.py", line 112, in get_response
    response = wrapped_callback(request, *callback_args, **callback_kwargs)
  File "/home/kalinins/.virtualenvs/zapsum/lib/python3.4/site-packages/django/contrib/auth/decorators.py", line 22, in _wrapped_view
    return view_func(request, *args, **kwargs)
  File "/home/kalinins/.virtualenvs/zapsum/zapsum/app_zapsum/views.py", line 193, in active_record
    result = Diary.active_entry(id_rec=id_rec, user_id=request.user.pk)
  File "/home/kalinins/.virtualenvs/zapsum/zapsum/app_zapsum/models.py", line 49, in active_entry
    result = state(is_active=False).save()
TypeError: 'Diary' object is not callable
Not Found: /search_author/search_author
Forbidden (CSRF token missing or incorrect.): /search_author/
Internal Server Error: /search_author/
Traceback (most recent call last):
  File "/home/kalinins/.virtualenvs/zapsum/lib/python3.4/site-packages/django/core/handlers/base.py", line 112, in get_response
    response = wrapped_callback(request, *callback_args, **callback_kwargs)
  File "/home/kalinins/.virtualenvs/zapsum/zapsum/app_zapsum/views.py", line 31, in search_author
    authors_list = UserProfile.get_search_authors_entries()
TypeError: get_search_authors_entries() missing 1 required positional argument: 'author'
Internal Server Error: /search_author/
Traceback (most recent call last):
  File "/home/kalinins/.virtualenvs/zapsum/lib/python3.4/site-packages/django/core/handlers/base.py", line 112, in get_response
    response = wrapped_callback(request, *callback_args, **callback_kwargs)
  File "/home/kalinins/.virtualenvs/zapsum/zapsum/app_zapsum/views.py", line 36, in search_author
    return HttpResponse(json.dumps(data), content_type='application/json')
  File "/usr/lib/python3.4/json/__init__.py", line 230, in dumps
    return _default_encoder.encode(obj)
  File "/usr/lib/python3.4/json/encoder.py", line 192, in encode
    chunks = self.iterencode(o, _one_shot=True)
  File "/usr/lib/python3.4/json/encoder.py", line 250, in iterencode
    return _iterencode(o, 0)
  File "/usr/lib/python3.4/json/encoder.py", line 173, in default
    raise TypeError(repr(o) + " is not JSON serializable")
TypeError: [] is not JSON serializable
Internal Server Error: /search_author/
Traceback (most recent call last):
  File "/home/kalinins/.virtualenvs/zapsum/lib/python3.4/site-packages/django/core/handlers/base.py", line 112, in get_response
    response = wrapped_callback(request, *callback_args, **callback_kwargs)
  File "/home/kalinins/.virtualenvs/zapsum/zapsum/app_zapsum/views.py", line 36, in search_author
    data = serializers.serialize("result", authors_list)
  File "/home/kalinins/.virtualenvs/zapsum/lib/python3.4/site-packages/django/core/serializers/__init__.py", line 121, in serialize
    s = get_serializer(format)()
  File "/home/kalinins/.virtualenvs/zapsum/lib/python3.4/site-packages/django/core/serializers/__init__.py", line 96, in get_serializer
    raise SerializerDoesNotExist(format)
django.core.serializers.base.SerializerDoesNotExist: 'result'
Internal Server Error: /search_author/
Traceback (most recent call last):
  File "/home/kalinins/.virtualenvs/zapsum/lib/python3.4/site-packages/django/core/handlers/base.py", line 112, in get_response
    response = wrapped_callback(request, *callback_args, **callback_kwargs)
  File "/home/kalinins/.virtualenvs/zapsum/zapsum/app_zapsum/views.py", line 32, in search_author
    print(data)
NameError: name 'data' is not defined
Internal Server Error: /add_records/
Traceback (most recent call last):
  File "/home/kalinins/.virtualenvs/zapsum/lib/python3.4/site-packages/django/template/base.py", line 274, in parse
    compile_func = self.tags[command]
KeyError: 'wysiwyg_editor'

During handling of the above exception, another exception occurred:

Traceback (most recent call last):
  File "/home/kalinins/.virtualenvs/zapsum/lib/python3.4/site-packages/django/core/handlers/base.py", line 112, in get_response
    response = wrapped_callback(request, *callback_args, **callback_kwargs)
  File "/home/kalinins/.virtualenvs/zapsum/lib/python3.4/site-packages/django/contrib/auth/decorators.py", line 22, in _wrapped_view
    return view_func(request, *args, **kwargs)
  File "/home/kalinins/.virtualenvs/zapsum/zapsum/app_zapsum/views.py", line 119, in add_records
    t = loader.get_template('page_add_records.html')
  File "/home/kalinins/.virtualenvs/zapsum/lib/python3.4/site-packages/django/template/loader.py", line 138, in get_template
    template, origin = find_template(template_name)
  File "/home/kalinins/.virtualenvs/zapsum/lib/python3.4/site-packages/django/template/loader.py", line 127, in find_template
    source, display_name = loader(name, dirs)
  File "/home/kalinins/.virtualenvs/zapsum/lib/python3.4/site-packages/django/template/loader.py", line 43, in __call__
    return self.load_template(template_name, template_dirs)
  File "/home/kalinins/.virtualenvs/zapsum/lib/python3.4/site-packages/django/template/loader.py", line 49, in load_template
    template = get_template_from_string(source, origin, template_name)
  File "/home/kalinins/.virtualenvs/zapsum/lib/python3.4/site-packages/django/template/loader.py", line 149, in get_template_from_string
    return Template(source, origin, name)
  File "/home/kalinins/.virtualenvs/zapsum/lib/python3.4/site-packages/django/template/base.py", line 125, in __init__
    self.nodelist = compile_string(template_string, origin)
  File "/home/kalinins/.virtualenvs/zapsum/lib/python3.4/site-packages/django/template/base.py", line 153, in compile_string
    return parser.parse()
  File "/home/kalinins/.virtualenvs/zapsum/lib/python3.4/site-packages/django/template/base.py", line 278, in parse
    compiled_result = compile_func(self, token)
  File "/home/kalinins/.virtualenvs/zapsum/lib/python3.4/site-packages/django/template/loader_tags.py", line 215, in do_extends
    nodelist = parser.parse()
  File "/home/kalinins/.virtualenvs/zapsum/lib/python3.4/site-packages/django/template/base.py", line 278, in parse
    compiled_result = compile_func(self, token)
  File "/home/kalinins/.virtualenvs/zapsum/lib/python3.4/site-packages/django/template/loader_tags.py", line 190, in do_block
    nodelist = parser.parse(('endblock',))
  File "/home/kalinins/.virtualenvs/zapsum/lib/python3.4/site-packages/django/template/base.py", line 276, in parse
    self.invalid_block_tag(token, command, parse_until)
  File "/home/kalinins/.virtualenvs/zapsum/lib/python3.4/site-packages/django/template/base.py", line 331, in invalid_block_tag
    (command, get_text_list(["'%s'" % p for p in parse_until])))
django.template.base.TemplateSyntaxError: Invalid block tag: 'wysiwyg_editor', expected 'endblock'
Internal Server Error: /edit_records/1/
Traceback (most recent call last):
  File "/home/kalinins/.virtualenvs/zapsum/lib/python3.4/site-packages/django/core/handlers/base.py", line 99, in get_response
    resolver_match = resolver.resolve(request.path_info)
  File "/home/kalinins/.virtualenvs/zapsum/lib/python3.4/site-packages/django/core/urlresolvers.py", line 339, in resolve
    sub_match = pattern.resolve(new_path)
  File "/home/kalinins/.virtualenvs/zapsum/lib/python3.4/site-packages/django/core/urlresolvers.py", line 339, in resolve
    sub_match = pattern.resolve(new_path)
  File "/home/kalinins/.virtualenvs/zapsum/lib/python3.4/site-packages/django/core/urlresolvers.py", line 223, in resolve
    return ResolverMatch(self.callback, args, kwargs, self.name)
  File "/home/kalinins/.virtualenvs/zapsum/lib/python3.4/site-packages/django/core/urlresolvers.py", line 230, in callback
    self._callback = get_callable(self._callback_str)
  File "/home/kalinins/.virtualenvs/zapsum/lib/python3.4/site-packages/django/utils/functional.py", line 32, in wrapper
    result = func(*args)
  File "/home/kalinins/.virtualenvs/zapsum/lib/python3.4/site-packages/django/core/urlresolvers.py", line 97, in get_callable
    mod = import_module(mod_name)
  File "/home/kalinins/.virtualenvs/zapsum/lib/python3.4/importlib/__init__.py", line 109, in import_module
    return _bootstrap._gcd_import(name[level:], package, level)
  File "<frozen importlib._bootstrap>", line 2231, in _gcd_import
  File "<frozen importlib._bootstrap>", line 2214, in _find_and_load
  File "<frozen importlib._bootstrap>", line 2203, in _find_and_load_unlocked
  File "<frozen importlib._bootstrap>", line 1200, in _load_unlocked
  File "<frozen importlib._bootstrap>", line 1129, in _exec
  File "<frozen importlib._bootstrap>", line 1448, in exec_module
  File "<frozen importlib._bootstrap>", line 321, in _call_with_frames_removed
  File "/home/kalinins/.virtualenvs/zapsum/zapsum/app_zapsum/views.py", line 14, in <module>
    from app_zapsum.forms import ChangePasswordForm, ChangeAvatarForm, addMessageForm
  File "/home/kalinins/.virtualenvs/zapsum/zapsum/app_zapsum/forms.py", line 67, in <module>
    class addMessageForm(forms.ModelForm):
  File "/home/kalinins/.virtualenvs/zapsum/zapsum/app_zapsum/forms.py", line 84, in addMessageForm
    'minHeight': null,
NameError: name 'null' is not defined
Internal Server Error: /change_profile/
Traceback (most recent call last):
  File "/home/kalinins/.virtualenvs/zapsum/lib/python3.4/site-packages/django/core/handlers/base.py", line 99, in get_response
    resolver_match = resolver.resolve(request.path_info)
  File "/home/kalinins/.virtualenvs/zapsum/lib/python3.4/site-packages/django/core/urlresolvers.py", line 339, in resolve
    sub_match = pattern.resolve(new_path)
  File "/home/kalinins/.virtualenvs/zapsum/lib/python3.4/site-packages/django/core/urlresolvers.py", line 339, in resolve
    sub_match = pattern.resolve(new_path)
  File "/home/kalinins/.virtualenvs/zapsum/lib/python3.4/site-packages/django/core/urlresolvers.py", line 223, in resolve
    return ResolverMatch(self.callback, args, kwargs, self.name)
  File "/home/kalinins/.virtualenvs/zapsum/lib/python3.4/site-packages/django/core/urlresolvers.py", line 230, in callback
    self._callback = get_callable(self._callback_str)
  File "/home/kalinins/.virtualenvs/zapsum/lib/python3.4/site-packages/django/utils/functional.py", line 32, in wrapper
    result = func(*args)
  File "/home/kalinins/.virtualenvs/zapsum/lib/python3.4/site-packages/django/core/urlresolvers.py", line 97, in get_callable
    mod = import_module(mod_name)
  File "/home/kalinins/.virtualenvs/zapsum/lib/python3.4/importlib/__init__.py", line 109, in import_module
    return _bootstrap._gcd_import(name[level:], package, level)
  File "<frozen importlib._bootstrap>", line 2231, in _gcd_import
  File "<frozen importlib._bootstrap>", line 2214, in _find_and_load
  File "<frozen importlib._bootstrap>", line 2203, in _find_and_load_unlocked
  File "<frozen importlib._bootstrap>", line 1200, in _load_unlocked
  File "<frozen importlib._bootstrap>", line 1129, in _exec
  File "<frozen importlib._bootstrap>", line 1448, in exec_module
  File "<frozen importlib._bootstrap>", line 321, in _call_with_frames_removed
  File "/home/kalinins/.virtualenvs/zapsum/zapsum/app_zapsum/views.py", line 11, in <module>
    from app_accounts.forms import ProfileForm
  File "/home/kalinins/.virtualenvs/zapsum/zapsum/app_accounts/forms.py", line 80, in <module>
    class ProfileForm(forms.ModelForm):
  File "/home/kalinins/.virtualenvs/zapsum/zapsum/app_accounts/forms.py", line 101, in ProfileForm
    widget=SummernoteWidget({
NameError: name 'SummernoteWidget' is not defined
Internal Server Error: /new_authors/
Traceback (most recent call last):
  File "/home/kalinins/.virtualenvs/zapsum/lib/python3.4/site-packages/django/core/handlers/base.py", line 112, in get_response
    response = wrapped_callback(request, *callback_args, **callback_kwargs)
  File "/home/kalinins/.virtualenvs/zapsum/zapsum/app_zapsum/views.py", line 66, in new_authors
    new_authors = get_new_authors_entries()
NameError: name 'get_new_authors_entries' is not defined
