Internal Server Error: /accounts/ajax_username_check/
Traceback (most recent call last):
  File "/home/kalinins/.virtualenvs/zapsum/lib/python3.4/site-packages/django/core/handlers/base.py", line 112, in get_response
    response = wrapped_callback(request, *callback_args, **callback_kwargs)
  File "/home/kalinins/.virtualenvs/zapsum/zapsum/app_accounts/views.py", line 90, in ajax_username_check
    f.write(bytes(username_exist, 'UTF-8'))
TypeError: encoding or errors without a string argument
Internal Server Error: /accounts/ajax_username_check/
Traceback (most recent call last):
  File "/home/kalinins/.virtualenvs/zapsum/lib/python3.4/site-packages/django/core/handlers/base.py", line 112, in get_response
    response = wrapped_callback(request, *callback_args, **callback_kwargs)
  File "/home/kalinins/.virtualenvs/zapsum/zapsum/app_accounts/views.py", line 95, in ajax_username_check
    return HttpResponse(json.dumps({'result':'result'}))
NameError: name 'json' is not defined
Internal Server Error: /accounts/ajax_username_check/
Traceback (most recent call last):
  File "/home/kalinins/.virtualenvs/zapsum/lib/python3.4/site-packages/django/core/handlers/base.py", line 112, in get_response
    response = wrapped_callback(request, *callback_args, **callback_kwargs)
  File "/home/kalinins/.virtualenvs/zapsum/zapsum/app_accounts/views.py", line 96, in ajax_username_check
    return HttpResponse(json.dumps({'result':'result'}))
NameError: name 'json' is not defined
Internal Server Error: /accounts/ajax_username_check/
Traceback (most recent call last):
  File "/home/kalinins/.virtualenvs/zapsum/lib/python3.4/site-packages/django/core/handlers/base.py", line 112, in get_response
    response = wrapped_callback(request, *callback_args, **callback_kwargs)
  File "/home/kalinins/.virtualenvs/zapsum/zapsum/app_accounts/views.py", line 96, in ajax_username_check
    return HttpResponse(json.dumps({'result': result}))
NameError: name 'json' is not defined
Internal Server Error: /accounts/ajax_username_check/
Traceback (most recent call last):
  File "/home/kalinins/.virtualenvs/zapsum/lib/python3.4/site-packages/django/core/handlers/base.py", line 112, in get_response
    response = wrapped_callback(request, *callback_args, **callback_kwargs)
  File "/home/kalinins/.virtualenvs/zapsum/zapsum/app_accounts/views.py", line 94, in ajax_username_check
    json_data = json.dumps(data)
  File "/usr/lib/python3.4/json/__init__.py", line 230, in dumps
    return _default_encoder.encode(obj)
  File "/usr/lib/python3.4/json/encoder.py", line 192, in encode
    chunks = self.iterencode(o, _one_shot=True)
  File "/usr/lib/python3.4/json/encoder.py", line 250, in iterencode
    return _iterencode(o, 0)
  File "/usr/lib/python3.4/json/encoder.py", line 173, in default
    raise TypeError(repr(o) + " is not JSON serializable")
TypeError: <User: admin> is not JSON serializable
Internal Server Error: /accounts/ajax_username_check/
Traceback (most recent call last):
  File "/home/kalinins/.virtualenvs/zapsum/lib/python3.4/site-packages/django/core/handlers/base.py", line 112, in get_response
    response = wrapped_callback(request, *callback_args, **callback_kwargs)
  File "/home/kalinins/.virtualenvs/zapsum/zapsum/app_accounts/views.py", line 88, in ajax_username_check
    username_exist = User.objects.get(username=username)
  File "/home/kalinins/.virtualenvs/zapsum/lib/python3.4/site-packages/django/db/models/manager.py", line 151, in get
    return self.get_queryset().get(*args, **kwargs)
  File "/home/kalinins/.virtualenvs/zapsum/lib/python3.4/site-packages/django/db/models/query.py", line 310, in get
    self.model._meta.object_name)
django.contrib.auth.models.DoesNotExist: User matching query does not exist.
Internal Server Error: /accounts/ajax_username_check/
Traceback (most recent call last):
  File "/home/kalinins/.virtualenvs/zapsum/lib/python3.4/site-packages/django/core/handlers/base.py", line 112, in get_response
    response = wrapped_callback(request, *callback_args, **callback_kwargs)
  File "/home/kalinins/.virtualenvs/zapsum/zapsum/app_accounts/views.py", line 88, in ajax_username_check
    username_exist = User.objects.get(username=username)
  File "/home/kalinins/.virtualenvs/zapsum/lib/python3.4/site-packages/django/db/models/manager.py", line 151, in get
    return self.get_queryset().get(*args, **kwargs)
  File "/home/kalinins/.virtualenvs/zapsum/lib/python3.4/site-packages/django/db/models/query.py", line 310, in get
    self.model._meta.object_name)
django.contrib.auth.models.DoesNotExist: User matching query does not exist.
Internal Server Error: /accounts/ajax_username_check/
Traceback (most recent call last):
  File "/home/kalinins/.virtualenvs/zapsum/lib/python3.4/site-packages/django/core/handlers/base.py", line 112, in get_response
    response = wrapped_callback(request, *callback_args, **callback_kwargs)
  File "/home/kalinins/.virtualenvs/zapsum/zapsum/app_accounts/views.py", line 88, in ajax_username_check
    username_exist = User.objects.get(username=username)
  File "/home/kalinins/.virtualenvs/zapsum/lib/python3.4/site-packages/django/db/models/manager.py", line 151, in get
    return self.get_queryset().get(*args, **kwargs)
  File "/home/kalinins/.virtualenvs/zapsum/lib/python3.4/site-packages/django/db/models/query.py", line 310, in get
    self.model._meta.object_name)
django.contrib.auth.models.DoesNotExist: User matching query does not exist.
Internal Server Error: /accounts/ajax_username_check/
Traceback (most recent call last):
  File "/home/kalinins/.virtualenvs/zapsum/lib/python3.4/site-packages/django/core/handlers/base.py", line 112, in get_response
    response = wrapped_callback(request, *callback_args, **callback_kwargs)
  File "/home/kalinins/.virtualenvs/zapsum/zapsum/app_accounts/views.py", line 86, in ajax_username_check
    username_exist = User.objects.get(username=username)
  File "/home/kalinins/.virtualenvs/zapsum/lib/python3.4/site-packages/django/db/models/manager.py", line 151, in get
    return self.get_queryset().get(*args, **kwargs)
  File "/home/kalinins/.virtualenvs/zapsum/lib/python3.4/site-packages/django/db/models/query.py", line 310, in get
    self.model._meta.object_name)
django.contrib.auth.models.DoesNotExist: User matching query does not exist.
Internal Server Error: /accounts/ajax_username_check/
Traceback (most recent call last):
  File "/home/kalinins/.virtualenvs/zapsum/lib/python3.4/site-packages/django/core/handlers/base.py", line 112, in get_response
    response = wrapped_callback(request, *callback_args, **callback_kwargs)
  File "/home/kalinins/.virtualenvs/zapsum/zapsum/app_accounts/views.py", line 86, in ajax_username_check
    username_exist = User.objects.get(username=username)
  File "/home/kalinins/.virtualenvs/zapsum/lib/python3.4/site-packages/django/db/models/manager.py", line 151, in get
    return self.get_queryset().get(*args, **kwargs)
  File "/home/kalinins/.virtualenvs/zapsum/lib/python3.4/site-packages/django/db/models/query.py", line 310, in get
    self.model._meta.object_name)
django.contrib.auth.models.DoesNotExist: User matching query does not exist.
Internal Server Error: /accounts/ajax_username_check/
Traceback (most recent call last):
  File "/home/kalinins/.virtualenvs/zapsum/lib/python3.4/site-packages/django/core/handlers/base.py", line 112, in get_response
    response = wrapped_callback(request, *callback_args, **callback_kwargs)
  File "/home/kalinins/.virtualenvs/zapsum/zapsum/app_accounts/views.py", line 86, in ajax_username_check
    username_exist = User.objects.get(username=username)
  File "/home/kalinins/.virtualenvs/zapsum/lib/python3.4/site-packages/django/db/models/manager.py", line 151, in get
    return self.get_queryset().get(*args, **kwargs)
  File "/home/kalinins/.virtualenvs/zapsum/lib/python3.4/site-packages/django/db/models/query.py", line 310, in get
    self.model._meta.object_name)
django.contrib.auth.models.DoesNotExist: User matching query does not exist.
Internal Server Error: /accounts/ajax_username_check/
Traceback (most recent call last):
  File "/home/kalinins/.virtualenvs/zapsum/lib/python3.4/site-packages/django/core/handlers/base.py", line 112, in get_response
    response = wrapped_callback(request, *callback_args, **callback_kwargs)
  File "/home/kalinins/.virtualenvs/zapsum/zapsum/app_accounts/views.py", line 86, in ajax_username_check
    username_exist = User.objects.get(username=username)
  File "/home/kalinins/.virtualenvs/zapsum/lib/python3.4/site-packages/django/db/models/manager.py", line 151, in get
    return self.get_queryset().get(*args, **kwargs)
  File "/home/kalinins/.virtualenvs/zapsum/lib/python3.4/site-packages/django/db/models/query.py", line 310, in get
    self.model._meta.object_name)
django.contrib.auth.models.DoesNotExist: User matching query does not exist.
Internal Server Error: /accounts/ajax_username_check/
Traceback (most recent call last):
  File "/home/kalinins/.virtualenvs/zapsum/lib/python3.4/site-packages/django/core/handlers/base.py", line 112, in get_response
    response = wrapped_callback(request, *callback_args, **callback_kwargs)
  File "/home/kalinins/.virtualenvs/zapsum/zapsum/app_accounts/views.py", line 86, in ajax_username_check
    username_exist = User.objects.get(username=username).exist()
AttributeError: 'User' object has no attribute 'exist'
Internal Server Error: /accounts/ajax_username_check/
Traceback (most recent call last):
  File "/home/kalinins/.virtualenvs/zapsum/lib/python3.4/site-packages/django/core/handlers/base.py", line 112, in get_response
    response = wrapped_callback(request, *callback_args, **callback_kwargs)
  File "/home/kalinins/.virtualenvs/zapsum/zapsum/app_accounts/views.py", line 86, in ajax_username_check
    username_exist = User.objects.get(username=username).exist()
  File "/home/kalinins/.virtualenvs/zapsum/lib/python3.4/site-packages/django/db/models/manager.py", line 151, in get
    return self.get_queryset().get(*args, **kwargs)
  File "/home/kalinins/.virtualenvs/zapsum/lib/python3.4/site-packages/django/db/models/query.py", line 310, in get
    self.model._meta.object_name)
django.contrib.auth.models.DoesNotExist: User matching query does not exist.
Internal Server Error: /accounts/ajax_username_check/
Traceback (most recent call last):
  File "/home/kalinins/.virtualenvs/zapsum/lib/python3.4/site-packages/django/core/handlers/base.py", line 112, in get_response
    response = wrapped_callback(request, *callback_args, **callback_kwargs)
  File "/home/kalinins/.virtualenvs/zapsum/zapsum/app_accounts/views.py", line 87, in ajax_username_check
    username_exist = username_req.exist()
AttributeError: 'User' object has no attribute 'exist'
Internal Server Error: /accounts/ajax_username_check/
Traceback (most recent call last):
  File "/home/kalinins/.virtualenvs/zapsum/lib/python3.4/site-packages/django/core/handlers/base.py", line 112, in get_response
    response = wrapped_callback(request, *callback_args, **callback_kwargs)
  File "/home/kalinins/.virtualenvs/zapsum/zapsum/app_accounts/views.py", line 86, in ajax_username_check
    username_req = User.objects.get(username=username)
  File "/home/kalinins/.virtualenvs/zapsum/lib/python3.4/site-packages/django/db/models/manager.py", line 151, in get
    return self.get_queryset().get(*args, **kwargs)
  File "/home/kalinins/.virtualenvs/zapsum/lib/python3.4/site-packages/django/db/models/query.py", line 310, in get
    self.model._meta.object_name)
django.contrib.auth.models.DoesNotExist: User matching query does not exist.
Internal Server Error: /accounts/ajax_username_check/
Traceback (most recent call last):
  File "/home/kalinins/.virtualenvs/zapsum/lib/python3.4/site-packages/django/core/handlers/base.py", line 112, in get_response
    response = wrapped_callback(request, *callback_args, **callback_kwargs)
  File "/home/kalinins/.virtualenvs/zapsum/zapsum/app_accounts/views.py", line 88, in ajax_username_check
    if username_req.exist():
AttributeError: 'User' object has no attribute 'exist'
Internal Server Error: /accounts/ajax_username_check/
Traceback (most recent call last):
  File "/home/kalinins/.virtualenvs/zapsum/lib/python3.4/site-packages/django/core/handlers/base.py", line 112, in get_response
    response = wrapped_callback(request, *callback_args, **callback_kwargs)
  File "/home/kalinins/.virtualenvs/zapsum/zapsum/app_accounts/views.py", line 88, in ajax_username_check
    if username_req.exist():
AttributeError: 'User' object has no attribute 'exist'
Internal Server Error: /accounts/ajax_username_check/
Traceback (most recent call last):
  File "/home/kalinins/.virtualenvs/zapsum/lib/python3.4/site-packages/django/core/handlers/base.py", line 112, in get_response
    response = wrapped_callback(request, *callback_args, **callback_kwargs)
  File "/home/kalinins/.virtualenvs/zapsum/zapsum/app_accounts/views.py", line 88, in ajax_username_check
    if username_req.exist():
AttributeError: 'User' object has no attribute 'exist'
Internal Server Error: /accounts/ajax_username_check/
Traceback (most recent call last):
  File "/home/kalinins/.virtualenvs/zapsum/lib/python3.4/site-packages/django/core/handlers/base.py", line 112, in get_response
    response = wrapped_callback(request, *callback_args, **callback_kwargs)
  File "/home/kalinins/.virtualenvs/zapsum/zapsum/app_accounts/views.py", line 88, in ajax_username_check
    if username_req.exist():
AttributeError: 'User' object has no attribute 'exist'
Internal Server Error: /accounts/ajax_username_check/
Traceback (most recent call last):
  File "/home/kalinins/.virtualenvs/zapsum/lib/python3.4/site-packages/django/core/handlers/base.py", line 112, in get_response
    response = wrapped_callback(request, *callback_args, **callback_kwargs)
  File "/home/kalinins/.virtualenvs/zapsum/zapsum/app_accounts/views.py", line 90, in ajax_username_check
    if username_req.exist():
AttributeError: 'User' object has no attribute 'exist'
Internal Server Error: /accounts/ajax_username_check/
Traceback (most recent call last):
  File "/home/kalinins/.virtualenvs/zapsum/lib/python3.4/site-packages/django/core/handlers/base.py", line 112, in get_response
    response = wrapped_callback(request, *callback_args, **callback_kwargs)
  File "/home/kalinins/.virtualenvs/zapsum/zapsum/app_accounts/views.py", line 90, in ajax_username_check
    if username_req.exist():
AttributeError: 'User' object has no attribute 'exist'
Internal Server Error: /accounts/ajax_username_check/
Traceback (most recent call last):
  File "/home/kalinins/.virtualenvs/zapsum/lib/python3.4/site-packages/django/core/handlers/base.py", line 112, in get_response
    response = wrapped_callback(request, *callback_args, **callback_kwargs)
  File "/home/kalinins/.virtualenvs/zapsum/zapsum/app_accounts/views.py", line 88, in ajax_username_check
    f.write(bytes(username_req, 'UTF-8'))
TypeError: encoding or errors without a string argument
Internal Server Error: /accounts/ajax_username_check/
Traceback (most recent call last):
  File "/home/kalinins/.virtualenvs/zapsum/lib/python3.4/site-packages/django/core/handlers/base.py", line 112, in get_response
    response = wrapped_callback(request, *callback_args, **callback_kwargs)
  File "/home/kalinins/.virtualenvs/zapsum/zapsum/app_accounts/views.py", line 88, in ajax_username_check
    f.write(bytes(username_req.exist(), 'UTF-8'))
AttributeError: 'User' object has no attribute 'exist'
Internal Server Error: /accounts/ajax_username_check/
Traceback (most recent call last):
  File "/home/kalinins/.virtualenvs/zapsum/lib/python3.4/site-packages/django/core/handlers/base.py", line 112, in get_response
    response = wrapped_callback(request, *callback_args, **callback_kwargs)
  File "/home/kalinins/.virtualenvs/zapsum/zapsum/app_accounts/views.py", line 88, in ajax_username_check
    f.write(bytes(username_req, 'UTF-8'))
TypeError: encoding or errors without a string argument
Internal Server Error: /accounts/ajax_username_check/
Traceback (most recent call last):
  File "/home/kalinins/.virtualenvs/zapsum/lib/python3.4/site-packages/django/core/handlers/base.py", line 112, in get_response
    response = wrapped_callback(request, *callback_args, **callback_kwargs)
  File "/home/kalinins/.virtualenvs/zapsum/zapsum/app_accounts/views.py", line 88, in ajax_username_check
    f.write(bytes(username_req, 'UTF-8'))
TypeError: encoding or errors without a string argument
Internal Server Error: /accounts/ajax_username_check/
Traceback (most recent call last):
  File "/home/kalinins/.virtualenvs/zapsum/lib/python3.4/site-packages/django/core/handlers/base.py", line 112, in get_response
    response = wrapped_callback(request, *callback_args, **callback_kwargs)
  File "/home/kalinins/.virtualenvs/zapsum/zapsum/app_accounts/views.py", line 90, in ajax_username_check
    if username_req.exist():
AttributeError: 'User' object has no attribute 'exist'
Internal Server Error: /accounts/authentication/
Traceback (most recent call last):
  File "/home/kalinins/.virtualenvs/zapsum/lib/python3.4/site-packages/django/core/handlers/base.py", line 99, in get_response
    resolver_match = resolver.resolve(request.path_info)
  File "/home/kalinins/.virtualenvs/zapsum/lib/python3.4/site-packages/django/core/urlresolvers.py", line 339, in resolve
    sub_match = pattern.resolve(new_path)
  File "/home/kalinins/.virtualenvs/zapsum/lib/python3.4/site-packages/django/core/urlresolvers.py", line 339, in resolve
    sub_match = pattern.resolve(new_path)
  File "/home/kalinins/.virtualenvs/zapsum/lib/python3.4/site-packages/django/core/urlresolvers.py", line 223, in resolve
    return ResolverMatch(self.callback, args, kwargs, self.name)
  File "/home/kalinins/.virtualenvs/zapsum/lib/python3.4/site-packages/django/core/urlresolvers.py", line 230, in callback
    self._callback = get_callable(self._callback_str)
  File "/home/kalinins/.virtualenvs/zapsum/lib/python3.4/site-packages/django/utils/functional.py", line 32, in wrapper
    result = func(*args)
  File "/home/kalinins/.virtualenvs/zapsum/lib/python3.4/site-packages/django/core/urlresolvers.py", line 97, in get_callable
    mod = import_module(mod_name)
  File "/home/kalinins/.virtualenvs/zapsum/lib/python3.4/importlib/__init__.py", line 109, in import_module
    return _bootstrap._gcd_import(name[level:], package, level)
  File "<frozen importlib._bootstrap>", line 2231, in _gcd_import
  File "<frozen importlib._bootstrap>", line 2214, in _find_and_load
  File "<frozen importlib._bootstrap>", line 2203, in _find_and_load_unlocked
  File "<frozen importlib._bootstrap>", line 1200, in _load_unlocked
  File "<frozen importlib._bootstrap>", line 1129, in _exec
  File "<frozen importlib._bootstrap>", line 1444, in exec_module
  File "<frozen importlib._bootstrap>", line 1549, in get_code
  File "<frozen importlib._bootstrap>", line 1509, in source_to_code
  File "<frozen importlib._bootstrap>", line 321, in _call_with_frames_removed
  File "/home/kalinins/.virtualenvs/zapsum/zapsum/app_accounts/views.py", line 92
    with open(os.path.join(settings.BASE_DIR, "debug_local.txt"), "wb") as f:
       ^
IndentationError: expected an indented block
Internal Server Error: /accounts/ajax_username_check/
Traceback (most recent call last):
  File "/home/kalinins/.virtualenvs/zapsum/lib/python3.4/site-packages/django/core/handlers/base.py", line 112, in get_response
    response = wrapped_callback(request, *callback_args, **callback_kwargs)
  File "/home/kalinins/.virtualenvs/zapsum/zapsum/app_accounts/views.py", line 88, in ajax_username_check
    if username_req.exist():
AttributeError: 'User' object has no attribute 'exist'
Internal Server Error: /accounts/ajax_username_check/
Traceback (most recent call last):
  File "/home/kalinins/.virtualenvs/zapsum/lib/python3.4/site-packages/django/core/handlers/base.py", line 112, in get_response
    response = wrapped_callback(request, *callback_args, **callback_kwargs)
  File "/home/kalinins/.virtualenvs/zapsum/zapsum/app_accounts/views.py", line 88, in ajax_username_check
    if username_req.exist():
AttributeError: 'User' object has no attribute 'exist'
Internal Server Error: /accounts/ajax_username_check/
Traceback (most recent call last):
  File "/home/kalinins/.virtualenvs/zapsum/lib/python3.4/site-packages/django/core/handlers/base.py", line 112, in get_response
    response = wrapped_callback(request, *callback_args, **callback_kwargs)
  File "/home/kalinins/.virtualenvs/zapsum/zapsum/app_accounts/views.py", line 88, in ajax_username_check
    if username_req.count() > 0:
AttributeError: 'User' object has no attribute 'count'
Internal Server Error: /accounts/authentication/
Traceback (most recent call last):
  File "/home/kalinins/.virtualenvs/zapsum/lib/python3.4/site-packages/django/core/handlers/base.py", line 99, in get_response
    resolver_match = resolver.resolve(request.path_info)
  File "/home/kalinins/.virtualenvs/zapsum/lib/python3.4/site-packages/django/core/urlresolvers.py", line 339, in resolve
    sub_match = pattern.resolve(new_path)
  File "/home/kalinins/.virtualenvs/zapsum/lib/python3.4/site-packages/django/core/urlresolvers.py", line 339, in resolve
    sub_match = pattern.resolve(new_path)
  File "/home/kalinins/.virtualenvs/zapsum/lib/python3.4/site-packages/django/core/urlresolvers.py", line 223, in resolve
    return ResolverMatch(self.callback, args, kwargs, self.name)
  File "/home/kalinins/.virtualenvs/zapsum/lib/python3.4/site-packages/django/core/urlresolvers.py", line 230, in callback
    self._callback = get_callable(self._callback_str)
  File "/home/kalinins/.virtualenvs/zapsum/lib/python3.4/site-packages/django/utils/functional.py", line 32, in wrapper
    result = func(*args)
  File "/home/kalinins/.virtualenvs/zapsum/lib/python3.4/site-packages/django/core/urlresolvers.py", line 97, in get_callable
    mod = import_module(mod_name)
  File "/home/kalinins/.virtualenvs/zapsum/lib/python3.4/importlib/__init__.py", line 109, in import_module
    return _bootstrap._gcd_import(name[level:], package, level)
  File "<frozen importlib._bootstrap>", line 2231, in _gcd_import
  File "<frozen importlib._bootstrap>", line 2214, in _find_and_load
  File "<frozen importlib._bootstrap>", line 2203, in _find_and_load_unlocked
  File "<frozen importlib._bootstrap>", line 1200, in _load_unlocked
  File "<frozen importlib._bootstrap>", line 1129, in _exec
  File "<frozen importlib._bootstrap>", line 1444, in exec_module
  File "<frozen importlib._bootstrap>", line 1549, in get_code
  File "<frozen importlib._bootstrap>", line 1509, in source_to_code
  File "<frozen importlib._bootstrap>", line 321, in _call_with_frames_removed
  File "/home/kalinins/.virtualenvs/zapsum/zapsum/app_accounts/views.py", line 89
    f.write(bytes(username_req.count() 'UTF-8'))
                                             ^
SyntaxError: invalid syntax
Internal Server Error: /accounts/ajax_username_check/
Traceback (most recent call last):
  File "/home/kalinins/.virtualenvs/zapsum/lib/python3.4/site-packages/django/core/handlers/base.py", line 112, in get_response
    response = wrapped_callback(request, *callback_args, **callback_kwargs)
  File "/home/kalinins/.virtualenvs/zapsum/zapsum/app_accounts/views.py", line 89, in ajax_username_check
    f.write(bytes(username_req.count(), 'UTF-8'))
AttributeError: 'User' object has no attribute 'count'
Internal Server Error: /accounts/ajax_username_check/
Traceback (most recent call last):
  File "/home/kalinins/.virtualenvs/zapsum/lib/python3.4/site-packages/django/core/handlers/base.py", line 112, in get_response
    response = wrapped_callback(request, *callback_args, **callback_kwargs)
  File "/home/kalinins/.virtualenvs/zapsum/zapsum/app_accounts/views.py", line 89, in ajax_username_check
    f.write(bytes(len(username_req), 'UTF-8'))
TypeError: object of type 'User' has no len()
Internal Server Error: /accounts/ajax_username_check/
Traceback (most recent call last):
  File "/home/kalinins/.virtualenvs/zapsum/lib/python3.4/site-packages/django/core/handlers/base.py", line 112, in get_response
    response = wrapped_callback(request, *callback_args, **callback_kwargs)
  File "/home/kalinins/.virtualenvs/zapsum/zapsum/app_accounts/views.py", line 90, in ajax_username_check
    f.write(bytes('e' 'UTF-8'))
TypeError: string argument without an encoding
Internal Server Error: /accounts/ajax_username_check/
Traceback (most recent call last):
  File "/home/kalinins/.virtualenvs/zapsum/lib/python3.4/site-packages/django/core/handlers/base.py", line 112, in get_response
    response = wrapped_callback(request, *callback_args, **callback_kwargs)
  File "/home/kalinins/.virtualenvs/zapsum/zapsum/app_accounts/views.py", line 90, in ajax_username_check
    f.write(bytes('e' 'UTF-8'))
TypeError: string argument without an encoding
Internal Server Error: /accounts/ajax_username_check/
Traceback (most recent call last):
  File "/home/kalinins/.virtualenvs/zapsum/lib/python3.4/site-packages/django/core/handlers/base.py", line 112, in get_response
    response = wrapped_callback(request, *callback_args, **callback_kwargs)
  File "/home/kalinins/.virtualenvs/zapsum/zapsum/app_accounts/views.py", line 86, in ajax_username_check
    username_req = User.objects.get(username=username)
  File "/home/kalinins/.virtualenvs/zapsum/lib/python3.4/site-packages/django/db/models/manager.py", line 151, in get
    return self.get_queryset().get(*args, **kwargs)
  File "/home/kalinins/.virtualenvs/zapsum/lib/python3.4/site-packages/django/db/models/query.py", line 310, in get
    self.model._meta.object_name)
django.contrib.auth.models.DoesNotExist: User matching query does not exist.
Internal Server Error: /accounts/ajax_username_check/
Traceback (most recent call last):
  File "/home/kalinins/.virtualenvs/zapsum/lib/python3.4/site-packages/django/core/handlers/base.py", line 112, in get_response
    response = wrapped_callback(request, *callback_args, **callback_kwargs)
  File "/home/kalinins/.virtualenvs/zapsum/zapsum/app_accounts/views.py", line 86, in ajax_username_check
    username_req = User.objects.get(username=username)
  File "/home/kalinins/.virtualenvs/zapsum/lib/python3.4/site-packages/django/db/models/manager.py", line 151, in get
    return self.get_queryset().get(*args, **kwargs)
  File "/home/kalinins/.virtualenvs/zapsum/lib/python3.4/site-packages/django/db/models/query.py", line 310, in get
    self.model._meta.object_name)
django.contrib.auth.models.DoesNotExist: User matching query does not exist.
Internal Server Error: /accounts/authentication/
Traceback (most recent call last):
  File "/home/kalinins/.virtualenvs/zapsum/lib/python3.4/site-packages/django/core/handlers/base.py", line 99, in get_response
    resolver_match = resolver.resolve(request.path_info)
  File "/home/kalinins/.virtualenvs/zapsum/lib/python3.4/site-packages/django/core/urlresolvers.py", line 339, in resolve
    sub_match = pattern.resolve(new_path)
  File "/home/kalinins/.virtualenvs/zapsum/lib/python3.4/site-packages/django/core/urlresolvers.py", line 339, in resolve
    sub_match = pattern.resolve(new_path)
  File "/home/kalinins/.virtualenvs/zapsum/lib/python3.4/site-packages/django/core/urlresolvers.py", line 223, in resolve
    return ResolverMatch(self.callback, args, kwargs, self.name)
  File "/home/kalinins/.virtualenvs/zapsum/lib/python3.4/site-packages/django/core/urlresolvers.py", line 230, in callback
    self._callback = get_callable(self._callback_str)
  File "/home/kalinins/.virtualenvs/zapsum/lib/python3.4/site-packages/django/utils/functional.py", line 32, in wrapper
    result = func(*args)
  File "/home/kalinins/.virtualenvs/zapsum/lib/python3.4/site-packages/django/core/urlresolvers.py", line 97, in get_callable
    mod = import_module(mod_name)
  File "/home/kalinins/.virtualenvs/zapsum/lib/python3.4/importlib/__init__.py", line 109, in import_module
    return _bootstrap._gcd_import(name[level:], package, level)
  File "<frozen importlib._bootstrap>", line 2231, in _gcd_import
  File "<frozen importlib._bootstrap>", line 2214, in _find_and_load
  File "<frozen importlib._bootstrap>", line 2203, in _find_and_load_unlocked
  File "<frozen importlib._bootstrap>", line 1200, in _load_unlocked
  File "<frozen importlib._bootstrap>", line 1129, in _exec
  File "<frozen importlib._bootstrap>", line 1444, in exec_module
  File "<frozen importlib._bootstrap>", line 1549, in get_code
  File "<frozen importlib._bootstrap>", line 1509, in source_to_code
  File "<frozen importlib._bootstrap>", line 321, in _call_with_frames_removed
  File "/home/kalinins/.virtualenvs/zapsum/zapsum/app_accounts/views.py", line 92
    with open(os.path.join(settings.BASE_DIR, "debug_local.txt"), "wb") as f:
       ^
IndentationError: expected an indented block
Internal Server Error: /accounts/ajax_username_check/
Traceback (most recent call last):
  File "/home/kalinins/.virtualenvs/zapsum/lib/python3.4/site-packages/django/core/handlers/base.py", line 112, in get_response
    response = wrapped_callback(request, *callback_args, **callback_kwargs)
  File "/home/kalinins/.virtualenvs/zapsum/zapsum/app_accounts/views.py", line 88, in ajax_username_check
    if username_req.exists():
AttributeError: 'User' object has no attribute 'exists'
Internal Server Error: /accounts/ajax_username_check/
Traceback (most recent call last):
  File "/home/kalinins/.virtualenvs/zapsum/lib/python3.4/site-packages/django/core/handlers/base.py", line 112, in get_response
    response = wrapped_callback(request, *callback_args, **callback_kwargs)
  File "/home/kalinins/.virtualenvs/zapsum/zapsum/app_accounts/views.py", line 86, in ajax_username_check
    username_req = User.objects.get(username=username)
  File "/home/kalinins/.virtualenvs/zapsum/lib/python3.4/site-packages/django/db/models/manager.py", line 151, in get
    return self.get_queryset().get(*args, **kwargs)
  File "/home/kalinins/.virtualenvs/zapsum/lib/python3.4/site-packages/django/db/models/query.py", line 310, in get
    self.model._meta.object_name)
django.contrib.auth.models.DoesNotExist: User matching query does not exist.
Internal Server Error: /accounts/ajax_username_check/
Traceback (most recent call last):
  File "/home/kalinins/.virtualenvs/zapsum/lib/python3.4/site-packages/django/core/handlers/base.py", line 112, in get_response
    response = wrapped_callback(request, *callback_args, **callback_kwargs)
  File "/home/kalinins/.virtualenvs/zapsum/zapsum/app_accounts/views.py", line 88, in ajax_username_check
    if username_req.exists():
AttributeError: 'User' object has no attribute 'exists'
Internal Server Error: /accounts/ajax_username_check/
Traceback (most recent call last):
  File "/home/kalinins/.virtualenvs/zapsum/lib/python3.4/site-packages/django/core/handlers/base.py", line 112, in get_response
    response = wrapped_callback(request, *callback_args, **callback_kwargs)
  File "/home/kalinins/.virtualenvs/zapsum/zapsum/app_accounts/views.py", line 88, in ajax_username_check
    if username_req.exists():
AttributeError: 'User' object has no attribute 'exists'
Internal Server Error: /accounts/ajax_username_check/
Traceback (most recent call last):
  File "/home/kalinins/.virtualenvs/zapsum/lib/python3.4/site-packages/django/core/handlers/base.py", line 112, in get_response
    response = wrapped_callback(request, *callback_args, **callback_kwargs)
  File "/home/kalinins/.virtualenvs/zapsum/zapsum/app_accounts/views.py", line 86, in ajax_username_check
    username_req = User.objects.get(username=username)
  File "/home/kalinins/.virtualenvs/zapsum/lib/python3.4/site-packages/django/db/models/manager.py", line 151, in get
    return self.get_queryset().get(*args, **kwargs)
  File "/home/kalinins/.virtualenvs/zapsum/lib/python3.4/site-packages/django/db/models/query.py", line 310, in get
    self.model._meta.object_name)
django.contrib.auth.models.DoesNotExist: User matching query does not exist.
Internal Server Error: /accounts/ajax_username_check/
Traceback (most recent call last):
  File "/home/kalinins/.virtualenvs/zapsum/lib/python3.4/site-packages/django/core/handlers/base.py", line 112, in get_response
    response = wrapped_callback(request, *callback_args, **callback_kwargs)
  File "/home/kalinins/.virtualenvs/zapsum/zapsum/app_accounts/views.py", line 86, in ajax_username_check
    username_req = User.objects.get(username=username)
  File "/home/kalinins/.virtualenvs/zapsum/lib/python3.4/site-packages/django/db/models/manager.py", line 151, in get
    return self.get_queryset().get(*args, **kwargs)
  File "/home/kalinins/.virtualenvs/zapsum/lib/python3.4/site-packages/django/db/models/query.py", line 310, in get
    self.model._meta.object_name)
django.contrib.auth.models.DoesNotExist: User matching query does not exist.
Internal Server Error: /accounts/ajax_username_check/
Traceback (most recent call last):
  File "/home/kalinins/.virtualenvs/zapsum/lib/python3.4/site-packages/django/core/handlers/base.py", line 112, in get_response
    response = wrapped_callback(request, *callback_args, **callback_kwargs)
  File "/home/kalinins/.virtualenvs/zapsum/zapsum/app_accounts/views.py", line 88, in ajax_username_check
    if username_req.username.exists():
AttributeError: 'str' object has no attribute 'exists'
Internal Server Error: /accounts/ajax_username_check/
Traceback (most recent call last):
  File "/home/kalinins/.virtualenvs/zapsum/lib/python3.4/site-packages/django/core/handlers/base.py", line 112, in get_response
    response = wrapped_callback(request, *callback_args, **callback_kwargs)
  File "/home/kalinins/.virtualenvs/zapsum/zapsum/app_accounts/views.py", line 88, in ajax_username_check
    if username_req.count():
AttributeError: 'User' object has no attribute 'count'
Internal Server Error: /accounts/ajax_username_check/
Traceback (most recent call last):
  File "/home/kalinins/.virtualenvs/zapsum/lib/python3.4/site-packages/django/core/handlers/base.py", line 112, in get_response
    response = wrapped_callback(request, *callback_args, **callback_kwargs)
  File "/home/kalinins/.virtualenvs/zapsum/zapsum/app_accounts/views.py", line 86, in ajax_username_check
    username_req = User.objects.get(username=username)
  File "/home/kalinins/.virtualenvs/zapsum/lib/python3.4/site-packages/django/db/models/manager.py", line 151, in get
    return self.get_queryset().get(*args, **kwargs)
  File "/home/kalinins/.virtualenvs/zapsum/lib/python3.4/site-packages/django/db/models/query.py", line 310, in get
    self.model._meta.object_name)
django.contrib.auth.models.DoesNotExist: User matching query does not exist.
Internal Server Error: /accounts/ajax_username_check/
Traceback (most recent call last):
  File "/home/kalinins/.virtualenvs/zapsum/lib/python3.4/site-packages/django/core/handlers/base.py", line 112, in get_response
    response = wrapped_callback(request, *callback_args, **callback_kwargs)
  File "/home/kalinins/.virtualenvs/zapsum/zapsum/app_accounts/views.py", line 88, in ajax_username_check
    result = username_req.count()
AttributeError: 'User' object has no attribute 'count'
Internal Server Error: /accounts/ajax_username_check/
Traceback (most recent call last):
  File "/home/kalinins/.virtualenvs/zapsum/lib/python3.4/site-packages/django/core/handlers/base.py", line 112, in get_response
    response = wrapped_callback(request, *callback_args, **callback_kwargs)
  File "/home/kalinins/.virtualenvs/zapsum/zapsum/app_accounts/views.py", line 88, in ajax_username_check
    if username_req.username.exists():
AttributeError: 'str' object has no attribute 'exists'
Internal Server Error: /accounts/ajax_username_check/
Traceback (most recent call last):
  File "/home/kalinins/.virtualenvs/zapsum/lib/python3.4/site-packages/django/core/handlers/base.py", line 112, in get_response
    response = wrapped_callback(request, *callback_args, **callback_kwargs)
  File "/home/kalinins/.virtualenvs/zapsum/zapsum/app_accounts/views.py", line 88, in ajax_username_check
    if username_req.exists():
AttributeError: 'User' object has no attribute 'exists'
Internal Server Error: /accounts/ajax_username_check/
Traceback (most recent call last):
  File "/home/kalinins/.virtualenvs/zapsum/lib/python3.4/site-packages/django/core/handlers/base.py", line 112, in get_response
    response = wrapped_callback(request, *callback_args, **callback_kwargs)
  File "/home/kalinins/.virtualenvs/zapsum/zapsum/app_accounts/views.py", line 88, in ajax_username_check
    if username_req.exists():
AttributeError: 'User' object has no attribute 'exists'
Internal Server Error: /accounts/ajax_username_check/
Traceback (most recent call last):
  File "/home/kalinins/.virtualenvs/zapsum/lib/python3.4/site-packages/django/core/handlers/base.py", line 112, in get_response
    response = wrapped_callback(request, *callback_args, **callback_kwargs)
  File "/home/kalinins/.virtualenvs/zapsum/zapsum/app_accounts/views.py", line 89, in ajax_username_check
    result = username_req.username
AttributeError: 'QuerySet' object has no attribute 'username'
Internal Server Error: /accounts/ajax_username_check/
Traceback (most recent call last):
  File "/home/kalinins/.virtualenvs/zapsum/lib/python3.4/site-packages/django/core/handlers/base.py", line 112, in get_response
    response = wrapped_callback(request, *callback_args, **callback_kwargs)
  File "/home/kalinins/.virtualenvs/zapsum/zapsum/app_accounts/views.py", line 101, in ajax_username_check
    'error_login_login': error_login_login,
UnboundLocalError: local variable 'error_login_login' referenced before assignment
Internal Server Error: /accounts/ajax_username_check/
Traceback (most recent call last):
  File "/home/kalinins/.virtualenvs/zapsum/lib/python3.4/site-packages/django/core/handlers/base.py", line 112, in get_response
    response = wrapped_callback(request, *callback_args, **callback_kwargs)
  File "/home/kalinins/.virtualenvs/zapsum/zapsum/app_accounts/views.py", line 101, in ajax_username_check
    'error_login_login': error_login_login,
UnboundLocalError: local variable 'error_login_login' referenced before assignment
Internal Server Error: /accounts/ajax_username_check/
Traceback (most recent call last):
  File "/home/kalinins/.virtualenvs/zapsum/lib/python3.4/site-packages/django/core/handlers/base.py", line 112, in get_response
    response = wrapped_callback(request, *callback_args, **callback_kwargs)
  File "/home/kalinins/.virtualenvs/zapsum/zapsum/app_accounts/views.py", line 91, in ajax_username_check
    f.write(bytes(username_req[0].username, 'UTF-8'))
  File "/home/kalinins/.virtualenvs/zapsum/lib/python3.4/site-packages/django/db/models/query.py", line 132, in __getitem__
    return list(qs)[0]
IndexError: list index out of range
Internal Server Error: /accounts/ajax_username_check/
Traceback (most recent call last):
  File "/home/kalinins/.virtualenvs/zapsum/lib/python3.4/site-packages/django/core/handlers/base.py", line 112, in get_response
    response = wrapped_callback(request, *callback_args, **callback_kwargs)
  File "/home/kalinins/.virtualenvs/zapsum/zapsum/app_accounts/views.py", line 91, in ajax_username_check
    if username_req[0].username == username:
  File "/home/kalinins/.virtualenvs/zapsum/lib/python3.4/site-packages/django/db/models/query.py", line 132, in __getitem__
    return list(qs)[0]
IndexError: list index out of range
Internal Server Error: /accounts/ajax_username_check/
Traceback (most recent call last):
  File "/home/kalinins/.virtualenvs/zapsum/lib/python3.4/site-packages/django/core/handlers/base.py", line 112, in get_response
    response = wrapped_callback(request, *callback_args, **callback_kwargs)
  File "/home/kalinins/.virtualenvs/zapsum/zapsum/app_accounts/views.py", line 106, in ajax_username_check
    f.write(bytes(username_req.password, 'UTF-8'))
AttributeError: 'QuerySet' object has no attribute 'password'
Internal Server Error: /accounts/ajax_username_check/
Traceback (most recent call last):
  File "/home/kalinins/.virtualenvs/zapsum/lib/python3.4/site-packages/django/core/handlers/base.py", line 112, in get_response
    response = wrapped_callback(request, *callback_args, **callback_kwargs)
  File "/home/kalinins/.virtualenvs/zapsum/zapsum/app_accounts/views.py", line 110, in ajax_username_check
    'pass': username_req.password,
AttributeError: 'QuerySet' object has no attribute 'password'
Internal Server Error: /accounts/ajax_username_check/
Traceback (most recent call last):
  File "/home/kalinins/.virtualenvs/zapsum/lib/python3.4/site-packages/django/core/handlers/base.py", line 112, in get_response
    response = wrapped_callback(request, *callback_args, **callback_kwargs)
  File "/home/kalinins/.virtualenvs/zapsum/zapsum/app_accounts/views.py", line 110, in ajax_username_check
    'pass': username_req[0].password,
  File "/home/kalinins/.virtualenvs/zapsum/lib/python3.4/site-packages/django/db/models/query.py", line 132, in __getitem__
    return list(qs)[0]
IndexError: list index out of range
Internal Server Error: /accounts/ajax_registration_check/
Traceback (most recent call last):
  File "/home/kalinins/.virtualenvs/zapsum/lib/python3.4/site-packages/django/core/handlers/base.py", line 112, in get_response
    response = wrapped_callback(request, *callback_args, **callback_kwargs)
  File "/home/kalinins/.virtualenvs/zapsum/zapsum/app_accounts/views.py", line 197, in ajax_registration_check
    if(password1 != password2):
NameError: name 'password2' is not defined
Internal Server Error: /accounts/ajax_registration_check/
Traceback (most recent call last):
  File "/home/kalinins/.virtualenvs/zapsum/lib/python3.4/site-packages/django/core/handlers/base.py", line 112, in get_response
    response = wrapped_callback(request, *callback_args, **callback_kwargs)
  File "/home/kalinins/.virtualenvs/zapsum/zapsum/app_accounts/views.py", line 201, in ajax_registration_check
    console.log(error_password1);
NameError: name 'console' is not defined
Internal Server Error: /accounts/ajax_registration_check/
Traceback (most recent call last):
  File "/home/kalinins/.virtualenvs/zapsum/lib/python3.4/site-packages/django/core/handlers/base.py", line 112, in get_response
    response = wrapped_callback(request, *callback_args, **callback_kwargs)
  File "/home/kalinins/.virtualenvs/zapsum/zapsum/app_accounts/views.py", line 201, in ajax_registration_check
    console.log(error_password1);
NameError: name 'console' is not defined
Internal Server Error: /accounts/ajax_registration_check/
Traceback (most recent call last):
  File "/home/kalinins/.virtualenvs/zapsum/lib/python3.4/site-packages/django/core/handlers/base.py", line 112, in get_response
    response = wrapped_callback(request, *callback_args, **callback_kwargs)
  File "/home/kalinins/.virtualenvs/zapsum/zapsum/app_accounts/views.py", line 178, in ajax_registration_check
    EMAIL_REGEX = re.compile(r')@(?:[A-Z0-9-]+\.)+[A-Z]{2,6}$')
  File "/home/kalinins/.virtualenvs/zapsum/lib/python3.4/re.py", line 219, in compile
    return _compile(pattern, flags)
  File "/home/kalinins/.virtualenvs/zapsum/lib/python3.4/re.py", line 288, in _compile
    p = sre_compile.compile(pattern, flags)
  File "/home/kalinins/.virtualenvs/zapsum/lib/python3.4/sre_compile.py", line 465, in compile
    p = sre_parse.parse(p, flags)
  File "/home/kalinins/.virtualenvs/zapsum/lib/python3.4/sre_parse.py", line 751, in parse
    raise error("unbalanced parenthesis")
sre_constants.error: unbalanced parenthesis
Internal Server Error: /accounts/registration/
Traceback (most recent call last):
  File "/home/kalinins/.virtualenvs/zapsum/lib/python3.4/site-packages/django/core/handlers/base.py", line 112, in get_response
    response = wrapped_callback(request, *callback_args, **callback_kwargs)
  File "/home/kalinins/.virtualenvs/zapsum/zapsum/app_accounts/views.py", line 27, in registration
    auth.login(request, user)
NameError: name 'user' is not defined
Not Found: /favicon.ico
Internal Server Error: /accounts/registration/
Traceback (most recent call last):
  File "/home/kalinins/.virtualenvs/zapsum/lib/python3.4/site-packages/django/core/handlers/base.py", line 112, in get_response
    response = wrapped_callback(request, *callback_args, **callback_kwargs)
  File "/home/kalinins/.virtualenvs/zapsum/zapsum/app_accounts/views.py", line 31, in registration
    auth.login(request, user)
  File "/home/kalinins/.virtualenvs/zapsum/lib/python3.4/site-packages/django/contrib/auth/__init__.py", line 85, in login
    request.session[BACKEND_SESSION_KEY] = user.backend
  File "/home/kalinins/.virtualenvs/zapsum/lib/python3.4/site-packages/django/utils/functional.py", line 214, in inner
    return func(self._wrapped, *args)
AttributeError: 'AnonymousUser' object has no attribute 'backend'
Internal Server Error: /accounts/registration/
Traceback (most recent call last):
  File "/home/kalinins/.virtualenvs/zapsum/lib/python3.4/site-packages/django/core/handlers/base.py", line 112, in get_response
    response = wrapped_callback(request, *callback_args, **callback_kwargs)
  File "/home/kalinins/.virtualenvs/zapsum/zapsum/app_accounts/views.py", line 31, in registration
    auth.login(request, user)
  File "/home/kalinins/.virtualenvs/zapsum/lib/python3.4/site-packages/django/contrib/auth/__init__.py", line 85, in login
    request.session[BACKEND_SESSION_KEY] = user.backend
  File "/home/kalinins/.virtualenvs/zapsum/lib/python3.4/site-packages/django/utils/functional.py", line 214, in inner
    return func(self._wrapped, *args)
AttributeError: 'AnonymousUser' object has no attribute 'backend'
Internal Server Error: /accounts/ajax_login_check/
Traceback (most recent call last):
  File "/home/kalinins/.virtualenvs/zapsum/lib/python3.4/site-packages/django/core/handlers/base.py", line 112, in get_response
    response = wrapped_callback(request, *callback_args, **callback_kwargs)
  File "/home/kalinins/.virtualenvs/zapsum/zapsum/app_accounts/views.py", line 101, in ajax_login_check
    if username_req.active == 0:
AttributeError: 'QuerySet' object has no attribute 'active'
Internal Server Error: /accounts/ajax_login_check/
Traceback (most recent call last):
  File "/home/kalinins/.virtualenvs/zapsum/lib/python3.4/site-packages/django/core/handlers/base.py", line 112, in get_response
    response = wrapped_callback(request, *callback_args, **callback_kwargs)
  File "/home/kalinins/.virtualenvs/zapsum/zapsum/app_accounts/views.py", line 101, in ajax_login_check
    if username_req.active == 0:
AttributeError: 'QuerySet' object has no attribute 'active'
Internal Server Error: /accounts/ajax_login_check/
Traceback (most recent call last):
  File "/home/kalinins/.virtualenvs/zapsum/lib/python3.4/site-packages/django/core/handlers/base.py", line 112, in get_response
    response = wrapped_callback(request, *callback_args, **callback_kwargs)
  File "/home/kalinins/.virtualenvs/zapsum/zapsum/app_accounts/views.py", line 101, in ajax_login_check
    if username_req.active == 0:
AttributeError: 'QuerySet' object has no attribute 'active'
Internal Server Error: /accounts/ajax_login_check/
Traceback (most recent call last):
  File "/home/kalinins/.virtualenvs/zapsum/lib/python3.4/site-packages/django/core/handlers/base.py", line 112, in get_response
    response = wrapped_callback(request, *callback_args, **callback_kwargs)
  File "/home/kalinins/.virtualenvs/zapsum/zapsum/app_accounts/views.py", line 101, in ajax_login_check
    if username_req.active == 0:
AttributeError: 'QuerySet' object has no attribute 'active'
Internal Server Error: /accounts/ajax_login_check/
Traceback (most recent call last):
  File "/home/kalinins/.virtualenvs/zapsum/lib/python3.4/site-packages/django/core/handlers/base.py", line 112, in get_response
    response = wrapped_callback(request, *callback_args, **callback_kwargs)
  File "/home/kalinins/.virtualenvs/zapsum/zapsum/app_accounts/views.py", line 101, in ajax_login_check
    if username_req.active == 0:
AttributeError: 'QuerySet' object has no attribute 'active'
Internal Server Error: /accounts/ajax_login_check/
Traceback (most recent call last):
  File "/home/kalinins/.virtualenvs/zapsum/lib/python3.4/site-packages/django/core/handlers/base.py", line 112, in get_response
    response = wrapped_callback(request, *callback_args, **callback_kwargs)
  File "/home/kalinins/.virtualenvs/zapsum/zapsum/app_accounts/views.py", line 101, in ajax_login_check
    if username_req.active == 0:
AttributeError: 'QuerySet' object has no attribute 'active'
Internal Server Error: /accounts/ajax_login_check/
Traceback (most recent call last):
  File "/home/kalinins/.virtualenvs/zapsum/lib/python3.4/site-packages/django/core/handlers/base.py", line 112, in get_response
    response = wrapped_callback(request, *callback_args, **callback_kwargs)
  File "/home/kalinins/.virtualenvs/zapsum/zapsum/app_accounts/views.py", line 101, in ajax_login_check
    if username_req.active == 0:
AttributeError: 'QuerySet' object has no attribute 'active'
Internal Server Error: /accounts/ajax_login_check/
Traceback (most recent call last):
  File "/home/kalinins/.virtualenvs/zapsum/lib/python3.4/site-packages/django/core/handlers/base.py", line 112, in get_response
    response = wrapped_callback(request, *callback_args, **callback_kwargs)
  File "/home/kalinins/.virtualenvs/zapsum/zapsum/app_accounts/views.py", line 101, in ajax_login_check
    if username_req.active == 0:
AttributeError: 'QuerySet' object has no attribute 'active'
Internal Server Error: /accounts/ajax_login_check/
Traceback (most recent call last):
  File "/home/kalinins/.virtualenvs/zapsum/lib/python3.4/site-packages/django/core/handlers/base.py", line 112, in get_response
    response = wrapped_callback(request, *callback_args, **callback_kwargs)
  File "/home/kalinins/.virtualenvs/zapsum/zapsum/app_accounts/views.py", line 101, in ajax_login_check
    if username_req.active == 0:
AttributeError: 'QuerySet' object has no attribute 'active'
Internal Server Error: /accounts/ajax_login_check/
Traceback (most recent call last):
  File "/home/kalinins/.virtualenvs/zapsum/lib/python3.4/site-packages/django/core/handlers/base.py", line 112, in get_response
    response = wrapped_callback(request, *callback_args, **callback_kwargs)
  File "/home/kalinins/.virtualenvs/zapsum/zapsum/app_accounts/views.py", line 101, in ajax_login_check
    if username_req.active == 0:
AttributeError: 'QuerySet' object has no attribute 'active'
Internal Server Error: /accounts/ajax_login_check/
Traceback (most recent call last):
  File "/home/kalinins/.virtualenvs/zapsum/lib/python3.4/site-packages/django/core/handlers/base.py", line 112, in get_response
    response = wrapped_callback(request, *callback_args, **callback_kwargs)
  File "/home/kalinins/.virtualenvs/zapsum/zapsum/app_accounts/views.py", line 101, in ajax_login_check
    if username_req.active == 0:
AttributeError: 'QuerySet' object has no attribute 'active'
Internal Server Error: /accounts/ajax_login_check/
Traceback (most recent call last):
  File "/home/kalinins/.virtualenvs/zapsum/lib/python3.4/site-packages/django/core/handlers/base.py", line 112, in get_response
    response = wrapped_callback(request, *callback_args, **callback_kwargs)
  File "/home/kalinins/.virtualenvs/zapsum/zapsum/app_accounts/views.py", line 101, in ajax_login_check
    if username_req.active == 0:
AttributeError: 'QuerySet' object has no attribute 'active'
Internal Server Error: /accounts/ajax_login_check/
Traceback (most recent call last):
  File "/home/kalinins/.virtualenvs/zapsum/lib/python3.4/site-packages/django/core/handlers/base.py", line 112, in get_response
    response = wrapped_callback(request, *callback_args, **callback_kwargs)
  File "/home/kalinins/.virtualenvs/zapsum/zapsum/app_accounts/views.py", line 101, in ajax_login_check
    if username_req.active == 0:
AttributeError: 'QuerySet' object has no attribute 'active'
Internal Server Error: /accounts/ajax_login_check/
Traceback (most recent call last):
  File "/home/kalinins/.virtualenvs/zapsum/lib/python3.4/site-packages/django/core/handlers/base.py", line 112, in get_response
    response = wrapped_callback(request, *callback_args, **callback_kwargs)
  File "/home/kalinins/.virtualenvs/zapsum/zapsum/app_accounts/views.py", line 101, in ajax_login_check
    if username_req.active == 0:
AttributeError: 'QuerySet' object has no attribute 'active'
Internal Server Error: /accounts/ajax_login_check/
Traceback (most recent call last):
  File "/home/kalinins/.virtualenvs/zapsum/lib/python3.4/site-packages/django/core/handlers/base.py", line 112, in get_response
    response = wrapped_callback(request, *callback_args, **callback_kwargs)
  File "/home/kalinins/.virtualenvs/zapsum/zapsum/app_accounts/views.py", line 101, in ajax_login_check
    if username_req.active == 0:
AttributeError: 'QuerySet' object has no attribute 'active'
Internal Server Error: /accounts/ajax_login_check/
Traceback (most recent call last):
  File "/home/kalinins/.virtualenvs/zapsum/lib/python3.4/site-packages/django/core/handlers/base.py", line 112, in get_response
    response = wrapped_callback(request, *callback_args, **callback_kwargs)
  File "/home/kalinins/.virtualenvs/zapsum/zapsum/app_accounts/views.py", line 101, in ajax_login_check
    if username_req.active == 0:
AttributeError: 'QuerySet' object has no attribute 'active'
Internal Server Error: /accounts/ajax_login_check/
Traceback (most recent call last):
  File "/home/kalinins/.virtualenvs/zapsum/lib/python3.4/site-packages/django/core/handlers/base.py", line 112, in get_response
    response = wrapped_callback(request, *callback_args, **callback_kwargs)
  File "/home/kalinins/.virtualenvs/zapsum/zapsum/app_accounts/views.py", line 101, in ajax_login_check
    if username_req.active == 0:
AttributeError: 'QuerySet' object has no attribute 'active'
Internal Server Error: /accounts/ajax_login_check/
Traceback (most recent call last):
  File "/home/kalinins/.virtualenvs/zapsum/lib/python3.4/site-packages/django/core/handlers/base.py", line 112, in get_response
    response = wrapped_callback(request, *callback_args, **callback_kwargs)
  File "/home/kalinins/.virtualenvs/zapsum/zapsum/app_accounts/views.py", line 101, in ajax_login_check
    if username_req.active == 0:
AttributeError: 'QuerySet' object has no attribute 'active'
Internal Server Error: /accounts/ajax_login_check/
Traceback (most recent call last):
  File "/home/kalinins/.virtualenvs/zapsum/lib/python3.4/site-packages/django/core/handlers/base.py", line 112, in get_response
    response = wrapped_callback(request, *callback_args, **callback_kwargs)
  File "/home/kalinins/.virtualenvs/zapsum/zapsum/app_accounts/views.py", line 101, in ajax_login_check
    if username_req.active == 0:
AttributeError: 'QuerySet' object has no attribute 'active'
Internal Server Error: /accounts/ajax_login_check/
Traceback (most recent call last):
  File "/home/kalinins/.virtualenvs/zapsum/lib/python3.4/site-packages/django/core/handlers/base.py", line 112, in get_response
    response = wrapped_callback(request, *callback_args, **callback_kwargs)
  File "/home/kalinins/.virtualenvs/zapsum/zapsum/app_accounts/views.py", line 101, in ajax_login_check
    if username_req.active == 0:
AttributeError: 'QuerySet' object has no attribute 'active'
Internal Server Error: /accounts/ajax_login_check/
Traceback (most recent call last):
  File "/home/kalinins/.virtualenvs/zapsum/lib/python3.4/site-packages/django/core/handlers/base.py", line 112, in get_response
    response = wrapped_callback(request, *callback_args, **callback_kwargs)
  File "/home/kalinins/.virtualenvs/zapsum/zapsum/app_accounts/views.py", line 101, in ajax_login_check
    if username_req.active == 0:
AttributeError: 'QuerySet' object has no attribute 'active'
Internal Server Error: /accounts/ajax_login_check/
Traceback (most recent call last):
  File "/home/kalinins/.virtualenvs/zapsum/lib/python3.4/site-packages/django/core/handlers/base.py", line 112, in get_response
    response = wrapped_callback(request, *callback_args, **callback_kwargs)
  File "/home/kalinins/.virtualenvs/zapsum/zapsum/app_accounts/views.py", line 101, in ajax_login_check
    if username_req.active == 0:
AttributeError: 'QuerySet' object has no attribute 'active'
Internal Server Error: /accounts/ajax_login_check/
Traceback (most recent call last):
  File "/home/kalinins/.virtualenvs/zapsum/lib/python3.4/site-packages/django/core/handlers/base.py", line 112, in get_response
    response = wrapped_callback(request, *callback_args, **callback_kwargs)
  File "/home/kalinins/.virtualenvs/zapsum/zapsum/app_accounts/views.py", line 101, in ajax_login_check
    if username_req.active == 0:
AttributeError: 'QuerySet' object has no attribute 'active'
Internal Server Error: /accounts/ajax_login_check/
Traceback (most recent call last):
  File "/home/kalinins/.virtualenvs/zapsum/lib/python3.4/site-packages/django/core/handlers/base.py", line 112, in get_response
    response = wrapped_callback(request, *callback_args, **callback_kwargs)
  File "/home/kalinins/.virtualenvs/zapsum/zapsum/app_accounts/views.py", line 101, in ajax_login_check
    if username_req.active == 0:
AttributeError: 'QuerySet' object has no attribute 'active'
Internal Server Error: /accounts/ajax_login_check/
Traceback (most recent call last):
  File "/home/kalinins/.virtualenvs/zapsum/lib/python3.4/site-packages/django/core/handlers/base.py", line 112, in get_response
    response = wrapped_callback(request, *callback_args, **callback_kwargs)
  File "/home/kalinins/.virtualenvs/zapsum/zapsum/app_accounts/views.py", line 101, in ajax_login_check
    if username_req.active == 0:
AttributeError: 'QuerySet' object has no attribute 'active'
Internal Server Error: /accounts/ajax_login_check/
Traceback (most recent call last):
  File "/home/kalinins/.virtualenvs/zapsum/lib/python3.4/site-packages/django/core/handlers/base.py", line 112, in get_response
    response = wrapped_callback(request, *callback_args, **callback_kwargs)
  File "/home/kalinins/.virtualenvs/zapsum/zapsum/app_accounts/views.py", line 101, in ajax_login_check
    if username_req.active == 0:
AttributeError: 'QuerySet' object has no attribute 'active'
Internal Server Error: /accounts/ajax_login_check/
Traceback (most recent call last):
  File "/home/kalinins/.virtualenvs/zapsum/lib/python3.4/site-packages/django/core/handlers/base.py", line 112, in get_response
    response = wrapped_callback(request, *callback_args, **callback_kwargs)
  File "/home/kalinins/.virtualenvs/zapsum/zapsum/app_accounts/views.py", line 101, in ajax_login_check
    if username_req.active == 0:
AttributeError: 'QuerySet' object has no attribute 'active'
Internal Server Error: /accounts/ajax_login_check/
Traceback (most recent call last):
  File "/home/kalinins/.virtualenvs/zapsum/lib/python3.4/site-packages/django/core/handlers/base.py", line 112, in get_response
    response = wrapped_callback(request, *callback_args, **callback_kwargs)
  File "/home/kalinins/.virtualenvs/zapsum/zapsum/app_accounts/views.py", line 101, in ajax_login_check
    if username_req.active == 0:
AttributeError: 'QuerySet' object has no attribute 'active'
Internal Server Error: /accounts/ajax_login_check/
Traceback (most recent call last):
  File "/home/kalinins/.virtualenvs/zapsum/lib/python3.4/site-packages/django/core/handlers/base.py", line 112, in get_response
    response = wrapped_callback(request, *callback_args, **callback_kwargs)
  File "/home/kalinins/.virtualenvs/zapsum/zapsum/app_accounts/views.py", line 101, in ajax_login_check
    if username_req.active == 0:
AttributeError: 'QuerySet' object has no attribute 'active'
Internal Server Error: /accounts/ajax_login_check/
Traceback (most recent call last):
  File "/home/kalinins/.virtualenvs/zapsum/lib/python3.4/site-packages/django/core/handlers/base.py", line 112, in get_response
    response = wrapped_callback(request, *callback_args, **callback_kwargs)
  File "/home/kalinins/.virtualenvs/zapsum/zapsum/app_accounts/views.py", line 101, in ajax_login_check
    if username_req.is_active == 0:
AttributeError: 'QuerySet' object has no attribute 'is_active'
Not Found: /account/delete_profile/
Forbidden (CSRF token missing or incorrect.): /accounts/delete_profile/
Forbidden (CSRF token missing or incorrect.): /accounts/delete_profile/
Forbidden (CSRF token missing or incorrect.): /accounts/delete_profile/
Not Found: /accounts/login/
Internal Server Error: /change_password/
Traceback (most recent call last):
  File "/home/kalinins/.virtualenvs/zapsum/lib/python3.4/site-packages/django/core/handlers/base.py", line 112, in get_response
    response = wrapped_callback(request, *callback_args, **callback_kwargs)
  File "/home/kalinins/.virtualenvs/zapsum/lib/python3.4/site-packages/django/contrib/auth/decorators.py", line 22, in _wrapped_view
    return view_func(request, *args, **kwargs)
  File "/home/kalinins/.virtualenvs/zapsum/zapsum/app_zapsum/views.py", line 86, in change_password
    form = ChangePasswordForm(instance=request)
  File "/home/kalinins/.virtualenvs/zapsum/zapsum/app_zapsum/forms.py", line 24, in __init__
    super(ChangePasswordForm, self).__init__(*args, **kwargs)
TypeError: __init__() got an unexpected keyword argument 'instance'
Internal Server Error: /change_password/
Traceback (most recent call last):
  File "/home/kalinins/.virtualenvs/zapsum/lib/python3.4/site-packages/django/core/handlers/base.py", line 112, in get_response
    response = wrapped_callback(request, *callback_args, **callback_kwargs)
  File "/home/kalinins/.virtualenvs/zapsum/lib/python3.4/site-packages/django/contrib/auth/decorators.py", line 22, in _wrapped_view
    return view_func(request, *args, **kwargs)
  File "/home/kalinins/.virtualenvs/zapsum/zapsum/app_zapsum/views.py", line 86, in change_password
    form = ChangePasswordForm(instance=request)
TypeError: __init__() got an unexpected keyword argument 'instance'
Internal Server Error: /change_password/
Traceback (most recent call last):
  File "/home/kalinins/.virtualenvs/zapsum/lib/python3.4/site-packages/django/core/handlers/base.py", line 112, in get_response
    response = wrapped_callback(request, *callback_args, **callback_kwargs)
  File "/home/kalinins/.virtualenvs/zapsum/lib/python3.4/site-packages/django/contrib/auth/decorators.py", line 22, in _wrapped_view
    return view_func(request, *args, **kwargs)
  File "/home/kalinins/.virtualenvs/zapsum/zapsum/app_zapsum/views.py", line 86, in change_password
    form = ChangePasswordForm(instance=request)
TypeError: __init__() got an unexpected keyword argument 'instance'
Internal Server Error: /change_password/
Traceback (most recent call last):
  File "/home/kalinins/.virtualenvs/zapsum/lib/python3.4/site-packages/django/core/handlers/base.py", line 112, in get_response
    response = wrapped_callback(request, *callback_args, **callback_kwargs)
  File "/home/kalinins/.virtualenvs/zapsum/lib/python3.4/site-packages/django/contrib/auth/decorators.py", line 22, in _wrapped_view
    return view_func(request, *args, **kwargs)
  File "/home/kalinins/.virtualenvs/zapsum/zapsum/app_zapsum/views.py", line 86, in change_password
    form = ChangePasswordForm(instance=request)
TypeError: __init__() got an unexpected keyword argument 'instance'
Internal Server Error: /change_password/
Traceback (most recent call last):
  File "/home/kalinins/.virtualenvs/zapsum/lib/python3.4/site-packages/django/core/handlers/base.py", line 112, in get_response
    response = wrapped_callback(request, *callback_args, **callback_kwargs)
  File "/home/kalinins/.virtualenvs/zapsum/lib/python3.4/site-packages/django/contrib/auth/decorators.py", line 22, in _wrapped_view
    return view_func(request, *args, **kwargs)
  File "/home/kalinins/.virtualenvs/zapsum/zapsum/app_zapsum/views.py", line 86, in change_password
    form = ChangePasswordForm(instance=request)
TypeError: __init__() got an unexpected keyword argument 'instance'
Internal Server Error: /change_password/
Traceback (most recent call last):
  File "/home/kalinins/.virtualenvs/zapsum/lib/python3.4/site-packages/django/core/handlers/base.py", line 112, in get_response
    response = wrapped_callback(request, *callback_args, **callback_kwargs)
  File "/home/kalinins/.virtualenvs/zapsum/lib/python3.4/site-packages/django/contrib/auth/decorators.py", line 22, in _wrapped_view
    return view_func(request, *args, **kwargs)
  File "/home/kalinins/.virtualenvs/zapsum/zapsum/app_zapsum/views.py", line 86, in change_password
    form = ChangePasswordForm(instance=request)
TypeError: __init__() got an unexpected keyword argument 'instance'
Internal Server Error: /change_password/
Traceback (most recent call last):
  File "/home/kalinins/.virtualenvs/zapsum/lib/python3.4/site-packages/django/core/handlers/base.py", line 112, in get_response
    response = wrapped_callback(request, *callback_args, **callback_kwargs)
  File "/home/kalinins/.virtualenvs/zapsum/lib/python3.4/site-packages/django/contrib/auth/decorators.py", line 22, in _wrapped_view
    return view_func(request, *args, **kwargs)
  File "/home/kalinins/.virtualenvs/zapsum/zapsum/app_zapsum/views.py", line 86, in change_password
    form = ChangePasswordForm(instance=request)
TypeError: __init__() got an unexpected keyword argument 'instance'
Internal Server Error: /change_password/
Traceback (most recent call last):
  File "/home/kalinins/.virtualenvs/zapsum/lib/python3.4/site-packages/django/core/handlers/base.py", line 112, in get_response
    response = wrapped_callback(request, *callback_args, **callback_kwargs)
  File "/home/kalinins/.virtualenvs/zapsum/lib/python3.4/site-packages/django/contrib/auth/decorators.py", line 22, in _wrapped_view
    return view_func(request, *args, **kwargs)
  File "/home/kalinins/.virtualenvs/zapsum/zapsum/app_zapsum/views.py", line 86, in change_password
    form = ChangePasswordForm(request=request)
TypeError: __init__() got an unexpected keyword argument 'request'
Internal Server Error: /change_password/
Traceback (most recent call last):
  File "/home/kalinins/.virtualenvs/zapsum/lib/python3.4/site-packages/django/core/handlers/base.py", line 112, in get_response
    response = wrapped_callback(request, *callback_args, **callback_kwargs)
  File "/home/kalinins/.virtualenvs/zapsum/lib/python3.4/site-packages/django/contrib/auth/decorators.py", line 22, in _wrapped_view
    return view_func(request, *args, **kwargs)
  File "/home/kalinins/.virtualenvs/zapsum/zapsum/app_zapsum/views.py", line 86, in change_password
    form = ChangePasswordForm(request=request)
TypeError: __init__() got an unexpected keyword argument 'request'
Internal Server Error: /change_password/
Traceback (most recent call last):
  File "/home/kalinins/.virtualenvs/zapsum/lib/python3.4/site-packages/django/core/handlers/base.py", line 112, in get_response
    response = wrapped_callback(request, *callback_args, **callback_kwargs)
  File "/home/kalinins/.virtualenvs/zapsum/lib/python3.4/site-packages/django/contrib/auth/decorators.py", line 22, in _wrapped_view
    return view_func(request, *args, **kwargs)
  File "/home/kalinins/.virtualenvs/zapsum/zapsum/app_zapsum/views.py", line 86, in change_password
    form = ChangePasswordForm(request=request)
TypeError: __init__() got an unexpected keyword argument 'request'
Internal Server Error: /change_password/
Traceback (most recent call last):
  File "/home/kalinins/.virtualenvs/zapsum/lib/python3.4/site-packages/django/core/handlers/base.py", line 112, in get_response
    response = wrapped_callback(request, *callback_args, **callback_kwargs)
  File "/home/kalinins/.virtualenvs/zapsum/lib/python3.4/site-packages/django/contrib/auth/decorators.py", line 22, in _wrapped_view
    return view_func(request, *args, **kwargs)
  File "/home/kalinins/.virtualenvs/zapsum/zapsum/app_zapsum/views.py", line 86, in change_password
    form = ChangePasswordForm(request=request)
TypeError: __init__() got an unexpected keyword argument 'request'
Internal Server Error: /change_password/
Traceback (most recent call last):
  File "/home/kalinins/.virtualenvs/zapsum/lib/python3.4/site-packages/django/core/urlresolvers.py", line 109, in get_callable
    lookup_view = getattr(mod, func_name)
AttributeError: 'module' object has no attribute 'changed_password'

During handling of the above exception, another exception occurred:

Traceback (most recent call last):
  File "/home/kalinins/.virtualenvs/zapsum/lib/python3.4/site-packages/django/core/handlers/base.py", line 112, in get_response
    response = wrapped_callback(request, *callback_args, **callback_kwargs)
  File "/home/kalinins/.virtualenvs/zapsum/lib/python3.4/site-packages/django/contrib/auth/decorators.py", line 22, in _wrapped_view
    return view_func(request, *args, **kwargs)
  File "/home/kalinins/.virtualenvs/zapsum/zapsum/app_zapsum/views.py", line 101, in change_password
    return HttpResponse(t.render(c))
  File "/home/kalinins/.virtualenvs/zapsum/lib/python3.4/site-packages/django/template/base.py", line 140, in render
    return self._render(context)
  File "/home/kalinins/.virtualenvs/zapsum/lib/python3.4/site-packages/django/template/base.py", line 134, in _render
    return self.nodelist.render(context)
  File "/home/kalinins/.virtualenvs/zapsum/lib/python3.4/site-packages/django/template/base.py", line 840, in render
    bit = self.render_node(node, context)
  File "/home/kalinins/.virtualenvs/zapsum/lib/python3.4/site-packages/django/template/debug.py", line 78, in render_node
    return node.render(context)
  File "/home/kalinins/.virtualenvs/zapsum/lib/python3.4/site-packages/django/template/loader_tags.py", line 123, in render
    return compiled_parent._render(context)
  File "/home/kalinins/.virtualenvs/zapsum/lib/python3.4/site-packages/django/template/base.py", line 134, in _render
    return self.nodelist.render(context)
  File "/home/kalinins/.virtualenvs/zapsum/lib/python3.4/site-packages/django/template/base.py", line 840, in render
    bit = self.render_node(node, context)
  File "/home/kalinins/.virtualenvs/zapsum/lib/python3.4/site-packages/django/template/debug.py", line 78, in render_node
    return node.render(context)
  File "/home/kalinins/.virtualenvs/zapsum/lib/python3.4/site-packages/django/template/defaulttags.py", line 433, in render
    url = reverse(view_name, args=args, kwargs=kwargs, current_app=context.current_app)
  File "/home/kalinins/.virtualenvs/zapsum/lib/python3.4/site-packages/django/core/urlresolvers.py", line 532, in reverse
    return iri_to_uri(resolver._reverse_with_prefix(view, prefix, *args, **kwargs))
  File "/home/kalinins/.virtualenvs/zapsum/lib/python3.4/site-packages/django/core/urlresolvers.py", line 403, in _reverse_with_prefix
    self._populate()
  File "/home/kalinins/.virtualenvs/zapsum/lib/python3.4/site-packages/django/core/urlresolvers.py", line 290, in _populate
    for name in pattern.reverse_dict:
  File "/home/kalinins/.virtualenvs/zapsum/lib/python3.4/site-packages/django/core/urlresolvers.py", line 315, in reverse_dict
    self._populate()
  File "/home/kalinins/.virtualenvs/zapsum/lib/python3.4/site-packages/django/core/urlresolvers.py", line 303, in _populate
    lookups.appendlist(pattern.callback, (bits, p_pattern, pattern.default_args))
  File "/home/kalinins/.virtualenvs/zapsum/lib/python3.4/site-packages/django/core/urlresolvers.py", line 230, in callback
    self._callback = get_callable(self._callback_str)
  File "/home/kalinins/.virtualenvs/zapsum/lib/python3.4/site-packages/django/utils/functional.py", line 32, in wrapper
    result = func(*args)
  File "/home/kalinins/.virtualenvs/zapsum/lib/python3.4/site-packages/django/core/urlresolvers.py", line 118, in get_callable
    (lookup_view, mod_name))
django.core.exceptions.ViewDoesNotExist: Could not import app_zapsum.views.changed_password. View does not exist in module app_zapsum.views.
Internal Server Error: /change_password/
Traceback (most recent call last):
  File "/home/kalinins/.virtualenvs/zapsum/lib/python3.4/site-packages/django/core/handlers/base.py", line 112, in get_response
    response = wrapped_callback(request, *callback_args, **callback_kwargs)
  File "/home/kalinins/.virtualenvs/zapsum/lib/python3.4/site-packages/django/contrib/auth/decorators.py", line 22, in _wrapped_view
    return view_func(request, *args, **kwargs)
  File "/home/kalinins/.virtualenvs/zapsum/zapsum/app_zapsum/views.py", line 90, in change_password
    if form.is_valid():
  File "/home/kalinins/.virtualenvs/zapsum/lib/python3.4/site-packages/django/forms/forms.py", line 129, in is_valid
    return self.is_bound and not bool(self.errors)
  File "/home/kalinins/.virtualenvs/zapsum/lib/python3.4/site-packages/django/forms/forms.py", line 121, in errors
    self.full_clean()
  File "/home/kalinins/.virtualenvs/zapsum/lib/python3.4/site-packages/django/forms/forms.py", line 273, in full_clean
    self._clean_fields()
  File "/home/kalinins/.virtualenvs/zapsum/lib/python3.4/site-packages/django/forms/forms.py", line 291, in _clean_fields
    value = getattr(self, 'clean_%s' % name)()
  File "/home/kalinins/.virtualenvs/zapsum/zapsum/app_zapsum/forms.py", line 33, in clean_password_old
    if not self.request.user.check_password(password_old):
AttributeError: 'ChangePasswordForm' object has no attribute 'request'
Internal Server Error: /change_password/
Traceback (most recent call last):
  File "/home/kalinins/.virtualenvs/zapsum/lib/python3.4/site-packages/django/core/handlers/base.py", line 112, in get_response
    response = wrapped_callback(request, *callback_args, **callback_kwargs)
  File "/home/kalinins/.virtualenvs/zapsum/lib/python3.4/site-packages/django/contrib/auth/decorators.py", line 22, in _wrapped_view
    return view_func(request, *args, **kwargs)
  File "/home/kalinins/.virtualenvs/zapsum/zapsum/app_zapsum/views.py", line 86, in change_password
    form = ChangePasswordForm(instance=request.POST)
TypeError: __init__() got an unexpected keyword argument 'instance'
Internal Server Error: /change_password/
Traceback (most recent call last):
  File "/home/kalinins/.virtualenvs/zapsum/lib/python3.4/site-packages/django/core/handlers/base.py", line 112, in get_response
    response = wrapped_callback(request, *callback_args, **callback_kwargs)
  File "/home/kalinins/.virtualenvs/zapsum/lib/python3.4/site-packages/django/contrib/auth/decorators.py", line 22, in _wrapped_view
    return view_func(request, *args, **kwargs)
  File "/home/kalinins/.virtualenvs/zapsum/zapsum/app_zapsum/views.py", line 86, in change_password
    form = ChangePasswordForm(request=request)
TypeError: __init__() got an unexpected keyword argument 'request'
Internal Server Error: /change_password/
Traceback (most recent call last):
  File "/home/kalinins/.virtualenvs/zapsum/lib/python3.4/site-packages/django/core/handlers/base.py", line 112, in get_response
    response = wrapped_callback(request, *callback_args, **callback_kwargs)
  File "/home/kalinins/.virtualenvs/zapsum/lib/python3.4/site-packages/django/contrib/auth/decorators.py", line 22, in _wrapped_view
    return view_func(request, *args, **kwargs)
  File "/home/kalinins/.virtualenvs/zapsum/zapsum/app_zapsum/views.py", line 96, in change_password
    form = ChangePasswordForm(request=request)
TypeError: __init__() got an unexpected keyword argument 'request'
Internal Server Error: /change_password/
Traceback (most recent call last):
  File "/home/kalinins/.virtualenvs/zapsum/lib/python3.4/site-packages/django/core/handlers/base.py", line 112, in get_response
    response = wrapped_callback(request, *callback_args, **callback_kwargs)
  File "/home/kalinins/.virtualenvs/zapsum/lib/python3.4/site-packages/django/contrib/auth/decorators.py", line 22, in _wrapped_view
    return view_func(request, *args, **kwargs)
  File "/home/kalinins/.virtualenvs/zapsum/zapsum/app_zapsum/views.py", line 96, in change_password
    form = ChangePasswordForm(request=request)
TypeError: __init__() got an unexpected keyword argument 'request'
Internal Server Error: /change_password/
Traceback (most recent call last):
  File "/home/kalinins/.virtualenvs/zapsum/lib/python3.4/site-packages/django/core/handlers/base.py", line 112, in get_response
    response = wrapped_callback(request, *callback_args, **callback_kwargs)
  File "/home/kalinins/.virtualenvs/zapsum/lib/python3.4/site-packages/django/contrib/auth/decorators.py", line 22, in _wrapped_view
    return view_func(request, *args, **kwargs)
  File "/home/kalinins/.virtualenvs/zapsum/zapsum/app_zapsum/views.py", line 96, in change_password
    form = ChangePasswordForm(request=request)
TypeError: __init__() got an unexpected keyword argument 'request'
Internal Server Error: /change_password/
Traceback (most recent call last):
  File "/home/kalinins/.virtualenvs/zapsum/lib/python3.4/site-packages/django/core/handlers/base.py", line 112, in get_response
    response = wrapped_callback(request, *callback_args, **callback_kwargs)
  File "/home/kalinins/.virtualenvs/zapsum/lib/python3.4/site-packages/django/contrib/auth/decorators.py", line 22, in _wrapped_view
    return view_func(request, *args, **kwargs)
  File "/home/kalinins/.virtualenvs/zapsum/zapsum/app_zapsum/views.py", line 96, in change_password
    form = ChangePasswordForm(request=request)
TypeError: __init__() got an unexpected keyword argument 'request'
Internal Server Error: /change_password/
Traceback (most recent call last):
  File "/home/kalinins/.virtualenvs/zapsum/lib/python3.4/site-packages/django/core/handlers/base.py", line 112, in get_response
    response = wrapped_callback(request, *callback_args, **callback_kwargs)
  File "/home/kalinins/.virtualenvs/zapsum/lib/python3.4/site-packages/django/contrib/auth/decorators.py", line 22, in _wrapped_view
    return view_func(request, *args, **kwargs)
  File "/home/kalinins/.virtualenvs/zapsum/zapsum/app_zapsum/views.py", line 96, in change_password
    form = ChangePasswordForm(request=request)
TypeError: __init__() got an unexpected keyword argument 'request'
Internal Server Error: /change_password/
Traceback (most recent call last):
  File "/home/kalinins/.virtualenvs/zapsum/lib/python3.4/site-packages/django/core/handlers/base.py", line 112, in get_response
    response = wrapped_callback(request, *callback_args, **callback_kwargs)
  File "/home/kalinins/.virtualenvs/zapsum/lib/python3.4/site-packages/django/contrib/auth/decorators.py", line 22, in _wrapped_view
    return view_func(request, *args, **kwargs)
  File "/home/kalinins/.virtualenvs/zapsum/zapsum/app_zapsum/views.py", line 96, in change_password
    form = ChangePasswordForm(request=request)
TypeError: __init__() got an unexpected keyword argument 'request'
Internal Server Error: /change_password/
Traceback (most recent call last):
  File "/home/kalinins/.virtualenvs/zapsum/lib/python3.4/site-packages/django/core/handlers/base.py", line 112, in get_response
    response = wrapped_callback(request, *callback_args, **callback_kwargs)
  File "/home/kalinins/.virtualenvs/zapsum/lib/python3.4/site-packages/django/contrib/auth/decorators.py", line 22, in _wrapped_view
    return view_func(request, *args, **kwargs)
  File "/home/kalinins/.virtualenvs/zapsum/zapsum/app_zapsum/views.py", line 96, in change_password
    form = ChangePasswordForm(request=request)
TypeError: __init__() got an unexpected keyword argument 'request'
Internal Server Error: /change_password/
Traceback (most recent call last):
  File "/home/kalinins/.virtualenvs/zapsum/lib/python3.4/site-packages/django/core/handlers/base.py", line 112, in get_response
    response = wrapped_callback(request, *callback_args, **callback_kwargs)
  File "/home/kalinins/.virtualenvs/zapsum/lib/python3.4/site-packages/django/contrib/auth/decorators.py", line 22, in _wrapped_view
    return view_func(request, *args, **kwargs)
  File "/home/kalinins/.virtualenvs/zapsum/zapsum/app_zapsum/views.py", line 96, in change_password
    form = ChangePasswordForm(request=request)
TypeError: __init__() got an unexpected keyword argument 'request'
Internal Server Error: /change_password/
Traceback (most recent call last):
  File "/home/kalinins/.virtualenvs/zapsum/lib/python3.4/site-packages/django/core/handlers/base.py", line 112, in get_response
    response = wrapped_callback(request, *callback_args, **callback_kwargs)
  File "/home/kalinins/.virtualenvs/zapsum/lib/python3.4/site-packages/django/contrib/auth/decorators.py", line 22, in _wrapped_view
    return view_func(request, *args, **kwargs)
  File "/home/kalinins/.virtualenvs/zapsum/zapsum/app_zapsum/views.py", line 90, in change_password
    if form.is_valid():
  File "/home/kalinins/.virtualenvs/zapsum/lib/python3.4/site-packages/django/forms/forms.py", line 129, in is_valid
    return self.is_bound and not bool(self.errors)
  File "/home/kalinins/.virtualenvs/zapsum/lib/python3.4/site-packages/django/forms/forms.py", line 121, in errors
    self.full_clean()
  File "/home/kalinins/.virtualenvs/zapsum/lib/python3.4/site-packages/django/forms/forms.py", line 273, in full_clean
    self._clean_fields()
  File "/home/kalinins/.virtualenvs/zapsum/lib/python3.4/site-packages/django/forms/forms.py", line 291, in _clean_fields
    value = getattr(self, 'clean_%s' % name)()
  File "/home/kalinins/.virtualenvs/zapsum/zapsum/app_zapsum/forms.py", line 36, in clean_password_old
    if not self.request.user.check_password(password_old):
AttributeError: 'ChangePasswordForm' object has no attribute 'request'
Internal Server Error: /change_password/
Traceback (most recent call last):
  File "/home/kalinins/.virtualenvs/zapsum/lib/python3.4/site-packages/django/core/handlers/base.py", line 112, in get_response
    response = wrapped_callback(request, *callback_args, **callback_kwargs)
  File "/home/kalinins/.virtualenvs/zapsum/lib/python3.4/site-packages/django/contrib/auth/decorators.py", line 22, in _wrapped_view
    return view_func(request, *args, **kwargs)
  File "/home/kalinins/.virtualenvs/zapsum/zapsum/app_zapsum/views.py", line 91, in change_password
    username = User.objects.get(username__exact=request.user.username)
NameError: name 'User' is not defined
Not Found: /accounts/page_changed_password/
Not Found: /accounts/page_changed_password/
Not Found: /accounts/page_changed_password/
Not Found: /accounts/page_changed_password/
Not Found: /accounts/page_changed_password/
Not Found: /accounts/page_changed_password/
Not Found: /accounts/page_changed_password/
Not Found: /accounts/page_changed_password/
Not Found: /accounts/page_changed_password/
Not Found: /accounts/page_changed_password/
Not Found: /accounts/page_changed_password/
Not Found: /accounts/page_changed_password/
Not Found: /accounts/page_changed_password/
Not Found: /accounts/page_changed_password/
Not Found: /accounts/page_changed_password/
Not Found: /accounts/page_changed_password/
Not Found: /accounts/page_changed_password/
Not Found: /accounts/page_changed_password/
Not Found: /accounts/page_changed_password/
Not Found: /accounts/page_changed_password/
Not Found: /accounts/page_changed_password/
Not Found: /accounts/page_changed_password/
Not Found: /accounts/page_changed_password/
Not Found: /accounts/page_changed_password/
Not Found: /accounts/page_changed_password/
Not Found: /accounts/page_changed_password/
Not Found: /accounts/page_changed_password/
Not Found: /accounts/page_changed_password/
Not Found: /accounts/page_changed_password/
Not Found: /accounts/page_changed_password/
Not Found: /accounts/page_changed_password/
Not Found: /accounts/page_changed_password/
Not Found: /accounts/page_changed_password/
Not Found: /accounts/page_changed_password/
Not Found: /accounts/page_changed_password/
Not Found: /accounts/page_changed_password/
Not Found: /accounts/page_changed_password/
Not Found: /accounts/page_changed_password/
Not Found: /accounts/page_changed_password/
Not Found: /accounts/page_changed_password/
Not Found: /accounts/page_changed_password/
Not Found: /accounts/page_changed_password/
Internal Server Error: /accounts/changed_password/
Traceback (most recent call last):
  File "/home/kalinins/.virtualenvs/zapsum/lib/python3.4/site-packages/django/core/handlers/base.py", line 99, in get_response
    resolver_match = resolver.resolve(request.path_info)
  File "/home/kalinins/.virtualenvs/zapsum/lib/python3.4/site-packages/django/core/urlresolvers.py", line 339, in resolve
    sub_match = pattern.resolve(new_path)
  File "/home/kalinins/.virtualenvs/zapsum/lib/python3.4/site-packages/django/core/urlresolvers.py", line 339, in resolve
    sub_match = pattern.resolve(new_path)
  File "/home/kalinins/.virtualenvs/zapsum/lib/python3.4/site-packages/django/core/urlresolvers.py", line 223, in resolve
    return ResolverMatch(self.callback, args, kwargs, self.name)
  File "/home/kalinins/.virtualenvs/zapsum/lib/python3.4/site-packages/django/core/urlresolvers.py", line 230, in callback
    self._callback = get_callable(self._callback_str)
  File "/home/kalinins/.virtualenvs/zapsum/lib/python3.4/site-packages/django/utils/functional.py", line 32, in wrapper
    result = func(*args)
  File "/home/kalinins/.virtualenvs/zapsum/lib/python3.4/site-packages/django/core/urlresolvers.py", line 97, in get_callable
    mod = import_module(mod_name)
  File "/home/kalinins/.virtualenvs/zapsum/lib/python3.4/importlib/__init__.py", line 109, in import_module
    return _bootstrap._gcd_import(name[level:], package, level)
  File "<frozen importlib._bootstrap>", line 2231, in _gcd_import
  File "<frozen importlib._bootstrap>", line 2214, in _find_and_load
  File "<frozen importlib._bootstrap>", line 2203, in _find_and_load_unlocked
  File "<frozen importlib._bootstrap>", line 1200, in _load_unlocked
  File "<frozen importlib._bootstrap>", line 1129, in _exec
  File "<frozen importlib._bootstrap>", line 1448, in exec_module
  File "<frozen importlib._bootstrap>", line 321, in _call_with_frames_removed
  File "/home/kalinins/.virtualenvs/zapsum/zapsum/app_accounts/views.py", line 81, in <module>
    @login_required
NameError: name 'login_required' is not defined
Internal Server Error: /
Traceback (most recent call last):
  File "/home/kalinins/.virtualenvs/zapsum/lib/python3.4/site-packages/django/core/handlers/base.py", line 112, in get_response
    response = wrapped_callback(request, *callback_args, **callback_kwargs)
  File "/home/kalinins/.virtualenvs/zapsum/zapsum/app_zapsum/views.py", line 23, in rules
    return HttpResponse(t.render(c))
  File "/home/kalinins/.virtualenvs/zapsum/lib/python3.4/site-packages/django/template/base.py", line 140, in render
    return self._render(context)
  File "/home/kalinins/.virtualenvs/zapsum/lib/python3.4/site-packages/django/template/base.py", line 134, in _render
    return self.nodelist.render(context)
  File "/home/kalinins/.virtualenvs/zapsum/lib/python3.4/site-packages/django/template/base.py", line 840, in render
    bit = self.render_node(node, context)
  File "/home/kalinins/.virtualenvs/zapsum/lib/python3.4/site-packages/django/template/debug.py", line 78, in render_node
    return node.render(context)
  File "/home/kalinins/.virtualenvs/zapsum/lib/python3.4/site-packages/django/template/loader_tags.py", line 123, in render
    return compiled_parent._render(context)
  File "/home/kalinins/.virtualenvs/zapsum/lib/python3.4/site-packages/django/template/base.py", line 134, in _render
    return self.nodelist.render(context)
  File "/home/kalinins/.virtualenvs/zapsum/lib/python3.4/site-packages/django/template/base.py", line 840, in render
    bit = self.render_node(node, context)
  File "/home/kalinins/.virtualenvs/zapsum/lib/python3.4/site-packages/django/template/debug.py", line 78, in render_node
    return node.render(context)
  File "/home/kalinins/.virtualenvs/zapsum/lib/python3.4/site-packages/django/template/defaulttags.py", line 433, in render
    url = reverse(view_name, args=args, kwargs=kwargs, current_app=context.current_app)
  File "/home/kalinins/.virtualenvs/zapsum/lib/python3.4/site-packages/django/core/urlresolvers.py", line 532, in reverse
    return iri_to_uri(resolver._reverse_with_prefix(view, prefix, *args, **kwargs))
  File "/home/kalinins/.virtualenvs/zapsum/lib/python3.4/site-packages/django/core/urlresolvers.py", line 403, in _reverse_with_prefix
    self._populate()
  File "/home/kalinins/.virtualenvs/zapsum/lib/python3.4/site-packages/django/core/urlresolvers.py", line 290, in _populate
    for name in pattern.reverse_dict:
  File "/home/kalinins/.virtualenvs/zapsum/lib/python3.4/site-packages/django/core/urlresolvers.py", line 315, in reverse_dict
    self._populate()
  File "/home/kalinins/.virtualenvs/zapsum/lib/python3.4/site-packages/django/core/urlresolvers.py", line 303, in _populate
    lookups.appendlist(pattern.callback, (bits, p_pattern, pattern.default_args))
  File "/home/kalinins/.virtualenvs/zapsum/lib/python3.4/site-packages/django/core/urlresolvers.py", line 230, in callback
    self._callback = get_callable(self._callback_str)
  File "/home/kalinins/.virtualenvs/zapsum/lib/python3.4/site-packages/django/utils/functional.py", line 32, in wrapper
    result = func(*args)
  File "/home/kalinins/.virtualenvs/zapsum/lib/python3.4/site-packages/django/core/urlresolvers.py", line 97, in get_callable
    mod = import_module(mod_name)
  File "/home/kalinins/.virtualenvs/zapsum/lib/python3.4/importlib/__init__.py", line 109, in import_module
    return _bootstrap._gcd_import(name[level:], package, level)
  File "<frozen importlib._bootstrap>", line 2231, in _gcd_import
  File "<frozen importlib._bootstrap>", line 2214, in _find_and_load
  File "<frozen importlib._bootstrap>", line 2203, in _find_and_load_unlocked
  File "<frozen importlib._bootstrap>", line 1200, in _load_unlocked
  File "<frozen importlib._bootstrap>", line 1129, in _exec
  File "<frozen importlib._bootstrap>", line 1448, in exec_module
  File "<frozen importlib._bootstrap>", line 321, in _call_with_frames_removed
  File "/home/kalinins/.virtualenvs/zapsum/zapsum/app_accounts/views.py", line 81, in <module>
    @login_required
NameError: name 'login_required' is not defined
